Workbook

Sheet E2
C1: 44809
B2: Nominal (g) | C2: Konvensional (g) | D2: Ketidakpastian (mg)
B3: 5000 | C3: 4999.9987 | D3: 0.6
B4: 2000* | C4: 2000.032 | D4: 24
B5: 2000 | C5: 2000.032 | D5: 24
B6: 1000 | C6: 1000.0008 | D6: 0.099
B7: 500 | C7: 500.00008 | D7: 0.056
B8: 200 | C8: 199.99992 | D8: 0.025
B9: 200* | C9: 199.99998 | D9: 0.025
B10: 100 | C10: 99.999909 | D10: 0.022
B11: 50 | C11: 49.999976 | D11: 0.012
B12: 20 | C12: 19.999989 | D12: 0.009
B13: 20* | C13: 19.999989 | D13: 0.009
B14: 10 | C14: 9.999966 | D14: 0.0083
B15: 5 | C15: 5.0000099 | D15: 0.0051
B16: 2 | C16: 2.0000124 | D16: 0.0039
B17: 2* | C17: 1.9999897 | D17: 0.0039
B18: 1 | C18: 0.9999856 | D18: 0.0035
B19: 0.5 | C19: 0.500018 | D19: 0.003
B20: 0.2 | C20: 0.20001 | D20: 0.003
B21: 0,2* | C21: 0.200014 | D21: 0.003
B22: 0.1 | C22: 0.100005 | D22: 0.002
B23: 0.05 | C23: 0.050004 | D23: 0.002
B24: 0.02 | C24: 0.020005 | D24: 0.002
B25: 0,02* | C25: 0.019996 | D25: 0.002
B26: 0.01 | C26: 0.009995 | D26: 0.002
B27: 0.005 | C27: 0.005004 | D27: 0.002
B28: 0.002 | C28: 0.001999 | D28: 0.002
B29: 0,002* | C29: 0.002005 | D29: 0.002
B30: 0.001 | C30: 0.001004 | D30: 0.002

Sheet U95
A1: E2 2024 | E1: F1 (B4T 2024) | I1: M1 | M1: E2 METTLER TOLEDO 2025 | Q1: TABEL MPE OIML R111-1
A2: Nominal (g) | B2: Massa konvensional (g) | C2: U95 (mg) | E2: Nominal (g) | F2: Massa konvensional (g) | G2: U95 (mg) | I2: Identitas | J2: Massa konvensional (g) | K2: U95 (mg) | M2: Nominal (g) | N2: Massa konvensional (g) | O2: U95 (mg) | Q2: Nominal Value | R2: Class E1 | S2: Class E2 | T2: Class F1 | U2: Class F2 | V2: Class M1 | W2: Class M2 | X2: Class M3
A3: 2000 | B3: 1999.9985 | C3: 0.32 | E3: 20000 | F3: 20000.022 | G3: 13 | I3: M1 | J3: 19999.414 | K3: 45 | M3: 1000 | N3: 1000.0005 | O3: 0.00031 | Q3: 50 kg | R3: 25 | S3: 75 | T3: 250 | U3: 750 | V3: 2500 | W3: 7500 | X3: 25000
A4: 1000 | B4: 1000.0005 | C4: 0.14 | E4: 10000 | F4: 10000.041 | G4: 4.6 | I4: M2 | J4: 19999.234 | K4: 45 | M4: 500 | N4: 500.0006 | O4: 0.00016 | Q4: 20 kg | R4: 10 | S4: 30 | T4: 100 | U4: 300 | V4: 1000 | W4: 3000 | X4: 10000
A5: 500 | B5: 500.00001 | C5: 0.08 | E5: 5000 | F5: 5000.005 | G5: 8 | I5: M3 | J5: 19999.627 | K5: 45 | M5: 200 | N5: 200.0002 | O5: 6e-05 | Q5: 10 kg | R5: 5 | S5: 15 | T5: 50 | U5: 150 | V5: 500 | W5: 1500 | X5: 5000
A6: 200 | B6: 200.00001 | C6: 0.04 | E6: 2000* | F6: 1999.999 | G6: 3 | I6: M4 | J6: 20000.346 | K6: 45 | M6: 200* | N6: 200.0002 | O6: 7.2e-05 | Q6: 5 kg | R6: 2.5 | S6: 7.5 | T6: 25 | U6: 75 | V6: 250 | W6: 750 | X6: 2500
A7: 200* | B7: 200.00005 | C7: 0.04 | E7: 2000 | F7: 1999.996 | G7: 3 | I7: M5 | J7: 20000.124 | K7: 45 | M7: 100 | N7: 100.00001 | O7: 3.6e-05 | Q7: 2 kg | R7: 1 | S7: 3 | T7: 10 | U7: 30 | V7: 100 | W7: 300 | X7: 1000
A8: 100 | B8: 100.00008 | C8: 0.03 | E8: 1000 | F8: 1000.001 | G8: 1.7 | I8: M6 | J8: 20000.154 | K8: 45 | M8: 50 | N8: 50.00002 | O8: 2.1e-05 | Q8: 1 kg | R8: 0.5 | S8: 1.5 | T8: 5 | U8: 15 | V8: 50 | W8: 150 | X8: 500
A9: 50 | B9: 50.00002 | C9: 0.02 | E9: 500 | F9: 500 | G9: 1.1 | I9: M7 | J9: 19999.125 | K9: 45 | M9: 20 | N9: 20.00003 | O9: 1.6e-05 | Q9: 500 g | R9: 0.25 | S9: 0.75 | T9: 2.5 | U9: 7.5 | V9: 25 | W9: 75 | X9: 250
A10: 20 | B10: 19.999978 | C10: 0.009 | E10: 200 | F10: 199.99953 | G10: 0.3 | I10: M8 | J10: 19999.806 | K10: 45 | M10: 20* | N10: 20.00001 | O10: 1.6e-05 | Q10: 200 g | R10: 0.01 | S10: 0.3 | T10: 1 | U10: 3 | V10: 10 | W10: 30 | X10: 100
A11: 20* | B11: 19.999977 | C11: 0.009 | E11: 200* | F11: 199.99873 | G11: 0.3 | I11: M9 | J11: 20000.237 | K11: 45 | M11: 10 | N11: 10.000023 | O11: 1.4e-05 | Q11: 100 g | R11: 0.05 | S11: 0.15 | T11: 0.5 | U11: 1.5 | V11: 5 | W11: 15 | X11: 50
A12: 10 | B12: 9.999976 | C12: 0.008 | E12: 100 | F12: 99.99961 | G12: 0.16 | I12: M10 | J12: 19999.832 | K12: 45 | M12: 5 | N12: 5.000003 | O12: 8.9e-06 | Q12: 50 g | R12: 0.03 | S12: 0.1 | T12: 0.3 | U12: 1 | V12: 3 | W12: 10 | X12: 30
A13: 5 | B13: 5.000006 | C13: 0.007 | E13: 50 | F13: 49.99956 | G13: 0.1 | I13: M11 | J13: 19999.934 | K13: 45 | M13: 2 | N13: 2.000015 | O13: 7.1e-06 | Q13: 20 g | R13: 0.025 | S13: 0.08 | T13: 0.25 | U13: 0.8 | V13: 2.5 | W13: 8 | X13: 25
A14: 2 | B14: 2.000013 | C14: 0.005 | E14: 20 | F14: 20.00001 | G14: 0.08 | I14: M12 | J14: 19999.845 | K14: 45 | M14: 2* | N14: 2.000003 | O14: 7.1e-06 | Q14: 10 g | R14: 0.02 | S14: 0.06 | T14: 0.2 | U14: 0.6 | V14: 2 | W14: 6 | X14: 20
A15: 2* | B15: 2.000015 | C15: 0.005 | E15: 20* | F15: 20.00004 | G15: 0.08 | I15: M13 | J15: 20000.802 | K15: 45 | M15: 1 | N15: 1.000013 | O15: 6.8e-06 | Q15: 5 g | R15: 0.015 | S15: 0.05 | T15: 0.15 | U15: 0.5 | V15: 1.5 | W15: 5 | X15: 15
A16: 1 | B16: 0.999997 | C16: 0.005 | E16: 10 | F16: 10.00001 | G16: 0.06 | I16: M14 | J16: 19999.575 | K16: 45 | M16: 0.5 | N16: =500.011/1000 -> 0.500011 | O16: 0.0051 | Q16: 2 g | R16: 0.012 | S16: 0.04 | T16: 0.12 | U16: 0.4 | V16: 1.2 | W16: 4 | X16: 12
A17: 0.5 | B17: 0.500018 | C17: 0.004 | E17: 5 | F17: 4.99994 | G17: 0.05 | I17: M15 | J17: 20000.329 | K17: 45 | M17: 0.2 | N17: =200.001/1000 -> 0.200001 | O17: 0.0031 | Q17: 1 g | R17: 0.01 | S17: 0.03 | T17: 0.1 | U17: 0.3 | V17: 1 | W17: 3 | X17: 10
A18: 0.2 | B18: 0.200013 | C18: 0.003 | E18: 2 | F18: 2 | G18: 0.04 | I18: M16 | J18: 20000.932 | K18: 45 | M18: 0.2* | N18: =199.999/1000 -> 0.199999 | O18: 0.0036 | Q18: 500 mg | R18: 0.008 | S18: 0.025 | T18: 0.08 | U18: 0.25 | V18: 0.8 | W18: 2.5 | X18: -
A19: 0.2* | B19: 0.200015 | C19: 0.003 | E19: 2* | F19: 1.99998 | G19: 0.04 | I19: 20LZ1 | J19: 20001.683 | K19: 45 | M19: 0.1 | N19: =100.009/1000 -> 0.100009 | O19: 0.0031 | Q19: 200 mg | R19: 0.006 | S19: 0.02 | T19: 0.06 | U19: 0.2 | V19: 0.6 | W19: 2 | X19: -
A20: 0.1 | B20: 0.100003 | C20: 0.002 | E20: 1 | F20: 1 | G20: 0.03 | I20: 10LZ1 | J20: 10001.617 | K20: 26 | Q20: 100 mg | R20: 0.005 | S20: 0.015 | T20: 0.05 | U20: 0.15 | V20: 0.5 | W20: 1.5 | X20: -
I21: 5A | J21: 4998.996 | K21: 5.7 | Q21: 50 mg | R21: 0.004 | S21: 0.012 | T21: 0.04 | U21: 0.12 | V21: 0.4 | W21: - | X21: -
I22: 10A | J22: 9999.566 | K22: 26 | Q22: 20 mg | R22: 0.003 | S22: 0.01 | T22: 0.03 | U22: 0.1 | V22: 0.3 | W22: - | X22: -
B23: ISI DATA | I23: A | J23: 19999.312 | K23: 45 | Q23: 10 mg | R23: 0.002 | S23: 0.008 | T23: 0.025 | U23: 0.08 | V23: 0.25 | W23: - | X23: -
B24: Deskripsi | C24: Isi | D24: Satuan | I24: B | J24: 19999.19 | K24: 45 | Q24: 5 mg | R24: 0.002 | S24: 0.006 | T24: 0.02 | U24: 0.06 | V24: 0.2 | W24: - | X24: -
B25: No Order | C25: K519-1 | I25: C | J25: 19999.069 | K25: 45 | Q25: 2 mg | R25: 0.002 | S25: 0.006 | T25: 0.02 | U25: 0.06 | V25: 0.2 | W25: - | X25: -
B26: Pemilik Alat | C26: PT. XXXXXX | I26: D | J26: 19999.282 | K26: 45 | Q26: 1 mg | R26: 0.002 | S26: 0.006 | T26: 0.02 | U26: 0.06 | V26: 0.2 | W26: - | X26: -
B27: Alamat Pemilik Alat | C27: Jalan, Desa, Kecamatan, Kabupaten, Provinsi | I27: E | J27: 19999.268 | K27: 45
B28: Lokasi Alat | C28: Lab massa BBLM | I28: F | J28: 19999.33 | K28: 45
B29: Nama Alat | C29: Anak timbangan | I29: G | J29: 19999.21 | K29: 45
B30: Merk | C30: - | I30: H | J30: 20000.486 | K30: 45
B31: Tipe | C31: F1 | I31: I | J31: 19999.254 | K31: 45
B32: No Seri | C32: 124918
B33: No. Identifikasi | C33: -
B34: Temperatur Awal | C34: 20.1 | D34: °C
B35: Temperatur Akhir | C35: 20.1 | D35: °C
B36: Temperatur rata2 | C36: =AVERAGE(C34,C35) -> 20.1 | D36: °C
B37: Kelembaban Awal | C37: 60 | D37: %RH
B38: Kelembaban Akhir | C38: 60 | D38: %RH
B39: Kelembapan rata2 | C39: =AVERAGE(C37,C38) -> 60 | D39: %RH
B40: Tekanan awal | C40: 922 | D40: hPa | E40: =C40*H40 -> 691.55901 | F40: mmHg | G40: 1 hPa | H40: 0.750064 | I40: mmHg
...

Sheet Koreksi themohygro rotronic 202
C2: Suhu (°C) | D2: %RH | F2: Thermohygro Rotronic data 2025
B3: Awal | C3: ='U95'!C34 -> 20.1 | D3: ='U95'!C37 -> 60 | F3: Koreksi suhu | I3: Koreksi RH
B4: Akhir | C4: ='U95'!C35 -> 20.1 | D4: ='U95'!C38 -> 60 | F4: T (°C) | G4: Koreksi | H4: U95 | I4: RH (%) | J4: Koreksi | K4: U95
B5: Rata2 | C5: =AVERAGE(C3:C4) -> 20.1 | D5: =AVERAGE(D3:D4) -> 60 | F5: 20 | G5: 0.1 | H5: 2 | I5: 40 | J5: 0.2 | K5: 2.5
B6: Terkoreksi | C6: =C5+FORECAST(C5,G5:G9,F5:F9) -> 20.156 | D6: =D5+FORECAST(D5,J5:J9,I5:I9) -> 59.78 | F6: 25 | G6: -0.2 | H6: 2 | I6: 50 | J6: -0.3 | K6: 2.8
B7: U95 | C7: 2 | D7: =FORECAST(D6,K5:K9,I5:I9) -> 2.62132 | F7: 30 | G7: -0.3 | H7: 2 | I7: 60 | J7: -0.3 | K7: 3.2
B8: Fluktuasi suhu | C8: =(MAX(C3:C4)-C5+C5-MIN(C3:C4))/2 -> 0 | D8: =(MAX(D3:D4)-D5+D5-MIN(D3:D4))/2 -> 0 | F8: 35 | G8: -0.6 | H8: 2 | I8: 70 | J8: -0.1 | K8: 2
B9: Flu+U95 | C9: =C7+C8 -> 2 | D9: =D7+D8 -> 2.62132 | F9: 40 | G9: -0.7 | H9: 2 | I9: 80 | J9: -0.6 | K9: 2.6
B10: Kondisi Ruang | C10: =FIXED(C6,2) & " ± "&FIXED(C8,2) -> 20,16 ± 0,00 | D10: =FIXED(D6,2) & " ± "&FIXED(D8,2) -> 59,78 ± 0,00

Sheet Sertifikat
A7: S E R T I F I K A T K A L I B R A S I
A8: C A L I B R A T I O N C E R T I F I C A T E
D9: Nomor / Number : | F9: 013-2.1/INT/KALIBRASI BBLM/I/2026
C14: IDENTITAS ALAT
C15: INSTRUMENT DETAILS
C17: Nama Alat | F17: : Anak Timbangan
C18: Instrument Name
C19: Merek | F19: =CONCATENATE(":"," ",'U95'!C30) -> : -
C20: Brand
C21: Tipe | F21: =CONCATENATE(":"," ",'U95'!C31) -> : F1
C22: Type
C23: Nomor Identifikasi | F23: =CONCATENATE(":"," ",'U95'!C33) -> : -
C24: Identification Number
C25: Nomor Seri | F25: =CONCATENATE(":"," ",'U95'!C32) -> : 124918
C26: Serial Number
C27: Lain-lain | F27: : Kapasitas | H27: =CONCATENATE(":","0,001 g -2000g ",) -> :0,001 g -2000g
C28: Others | F28: Kecermatan | H28: : -
C30: IDENTITAS PEMILIK
C31: Owner’s Identification
C33: Nama | D33: =CONCATENATE(":"," ",'U95'!C26) -> : PT. XXXXXX
C34: Designation
C35: Alamat | D35: =CONCATENATE(":"," ",'U95'!C27) -> : Jalan, Desa, Kecamatan, Kabupaten, Provinsi
C36: Address
I40: Halaman 1 dari 3 halaman
I41: Page of page
I43: Diterbitkan Tanggal 8 Maret 2026
I44: Date of Issue
F45: Ketua Tim Laboratorium Kalibrasi Dan Penguji,
F46: Elis Sofianti
F47: NIP. 197109301994032002
F67: Nomor | G67: =CONCATENATE(":"," ",$F$9) -> : 013-2.1/INT/KALIBRASI BBLM/I/2026
F68: No. Order | G68: =CONCATENATE(": ",'U95'!C25) -> : K519-1
F69: Halaman | G69: : 2 dari 3
C71: SPESIFIKASI ALAT
C72: Nama | E72: =F17 -> : Anak Timbangan
C73: Merk / Tipe | E73: =CONCATENATE(":"," ",'U95'!C30," ","/"," ",'U95'!C31) -> : - / F1
C74: No. Identifikasi | E74: =F23 -> : -
C75: No. Seri | E75: =F25 -> : 124918
C76: Kapasitas | E76: =H27 -> :0,001 g -2000g
C77: Kecermatan | E77: =H28 -> : - | G77: Kondisi ruang
...

Sheet 0,001
A1: E2 2024 | E1: F1 (B4T 2024) | I1: M1 | M1: E2 METTLER TOLEDO 2025 | Q1: TABEL MPE OIML R111-1
A2: Nominal (g) | B2: Massa konvensional (g) | C2: U95 (mg) | E2: Nominal (g) | F2: Massa konvensional (g) | G2: U95 (mg) | I2: Identitas | J2: Massa konvensional (g) | K2: U95 (mg) | M2: Nominal (g) | N2: Massa konvensional (g) | O2: U95 (mg) | Q2: Nominal Value | R2: Class E1 | S2: Class E2 | T2: Class F1 | U2: Class F2 | V2: Class M1 | W2: Class M2 | X2: Class M3
A3: 2000 | B3: 1999.9985 | C3: 0.32 | E3: 20000 | F3: 20000.022 | G3: 13 | I3: M1 | J3: 19999.414 | K3: 45 | M3: 0.001 | N3: 0.001003 | O3: 0.002 | Q3: 50 kg | R3: 25 | S3: 75 | T3: 250 | U3: 750 | V3: 2500 | W3: 7500 | X3: 25000
A4: 1000 | B4: 1000.0005 | C4: 0.14 | E4: 10000 | F4: 10000.041 | G4: 4.6 | I4: M2 | J4: 19999.234 | K4: 45 | M4: 0.002 | N4: 0.002003 | O4: 0.002 | Q4: 20 kg | R4: 10 | S4: 30 | T4: 100 | U4: 300 | V4: 1000 | W4: 3000 | X4: 10000
A5: 500 | B5: 500.00001 | C5: 0.08 | E5: 5000 | F5: 5000.005 | G5: 8 | I5: M3 | J5: 19999.627 | K5: 45 | M5: 0,002t | N5: 0.002001 | O5: 0.002 | Q5: 10 kg | R5: 5 | S5: 15 | T5: 50 | U5: 150 | V5: 500 | W5: 1500 | X5: 5000
A6: 200 | B6: 200.00001 | C6: 0.04 | E6: 2000* | F6: 1999.999 | G6: 3 | I6: M4 | J6: 20000.346 | K6: 45 | M6: 0.005 | N6: 0.005004 | O6: 0.002 | Q6: 5 kg | R6: 2.5 | S6: 7.5 | T6: 25 | U6: 75 | V6: 250 | W6: 750 | X6: 2500
A7: 200* | B7: 200.00005 | C7: 0.04 | E7: 2000 | F7: 1999.996 | G7: 3 | I7: M5 | J7: 20000.124 | K7: 45 | M7: 0.01 | N7: 0.010002 | O7: 0.003 | Q7: 2 kg | R7: 1 | S7: 3 | T7: 10 | U7: 30 | V7: 100 | W7: 300 | X7: 1000
A8: 100 | B8: 100.00008 | C8: 0.03 | E8: 1000 | F8: 1000.001 | G8: 1.7 | I8: M6 | J8: 20000.154 | K8: 45 | M8: 0.02 | N8: 0.020003 | O8: 0.003 | Q8: 1 kg | R8: 0.5 | S8: 1.5 | T8: 5 | U8: 15 | V8: 50 | W8: 150 | X8: 500
A9: 50 | B9: 50.00002 | C9: 0.02 | E9: 500 | F9: 500 | G9: 1.1 | I9: M7 | J9: 19999.125 | K9: 45 | M9: 0,02t | N9: 0.020005 | O9: 0.003 | Q9: 500 g | R9: 0.25 | S9: 0.75 | T9: 2.5 | U9: 7.5 | V9: 25 | W9: 75 | X9: 250
A10: 20 | B10: 19.999978 | C10: 0.009 | E10: 200 | F10: 199.99953 | G10: 0.3 | I10: M8 | J10: 19999.806 | K10: 45 | M10: 0.05 | N10: 0.050005 | O10: 0.003 | Q10: 200 g | R10: 0.01 | S10: 0.3 | T10: 1 | U10: 3 | V10: 10 | W10: 30 | X10: 100
A11: 20* | B11: 19.999977 | C11: 0.009 | E11: 200* | F11: 199.99873 | G11: 0.3 | I11: M9 | J11: 20000.237 | K11: 45 | M11: 0.1 | N11: 0.100008 | O11: 0.003 | Q11: 100 g | R11: 0.05 | S11: 0.15 | T11: 0.5 | U11: 1.5 | V11: 5 | W11: 15 | X11: 50
A12: 10 | B12: 9.999976 | C12: 0.008 | E12: 100 | F12: 99.99961 | G12: 0.16 | I12: M10 | J12: 19999.832 | K12: 45 | M12: 0.2 | N12: 0.200009 | O12: 0.005 | Q12: 50 g | R12: 0.03 | S12: 0.1 | T12: 0.3 | U12: 1 | V12: 3 | W12: 10 | X12: 30
A13: 5 | B13: 5.000006 | C13: 0.007 | E13: 50 | F13: 49.99956 | G13: 0.1 | I13: M11 | J13: 19999.934 | K13: 45 | M13: 0,2t | N13: 0.200002 | O13: 0.005 | Q13: 20 g | R13: 0.025 | S13: 0.08 | T13: 0.25 | U13: 0.8 | V13: 2.5 | W13: 8 | X13: 25
A14: 2 | B14: 2.000013 | C14: 0.005 | E14: 20 | F14: 20.00001 | G14: 0.08 | I14: M12 | J14: 19999.845 | K14: 45 | M14: 0.5 | N14: 0.500006 | O14: 0.006 | Q14: 10 g | R14: 0.02 | S14: 0.06 | T14: 0.2 | U14: 0.6 | V14: 2 | W14: 6 | X14: 20
A15: 2* | B15: 2.000015 | C15: 0.005 | E15: 20* | F15: 20.00004 | G15: 0.08 | I15: M13 | J15: 20000.802 | K15: 45 | M15: 1 | N15: 1.000016 | O15: 0.007 | Q15: 5 g | R15: 0.015 | S15: 0.05 | T15: 0.15 | U15: 0.5 | V15: 1.5 | W15: 5 | X15: 15
A16: 1 | B16: 0.999997 | C16: 0.005 | E16: 10 | F16: 10.00001 | G16: 0.06 | I16: M14 | J16: 19999.575 | K16: 45 | M16: 2 | N16: 1.999992 | O16: 0.009 | Q16: 2 g | R16: 0.012 | S16: 0.04 | T16: 0.12 | U16: 0.4 | V16: 1.2 | W16: 4 | X16: 12
A17: 0.5 | B17: 0.500018 | C17: 0.004 | E17: 5 | F17: 4.99994 | G17: 0.05 | I17: M15 | J17: 20000.329 | K17: 45 | M17: 2t | N17: 1.999991 | O17: 0.009 | Q17: 1 g | R17: 0.01 | S17: 0.03 | T17: 0.1 | U17: 0.3 | V17: 1 | W17: 3 | X17: 10
A18: 0.2 | B18: 0.200013 | C18: 0.003 | E18: 2 | F18: 2 | G18: 0.04 | I18: M16 | J18: 20000.932 | K18: 45 | M18: 5 | N18: 0.500006 | O18: 0.011 | Q18: 500 mg | R18: 0.008 | S18: 0.025 | T18: 0.08 | U18: 0.25 | V18: 0.8 | W18: 2.5 | X18: -
A19: 0.2* | B19: 0.200015 | C19: 0.003 | E19: 2* | F19: 1.99998 | G19: 0.04 | I19: 20LZ1 | J19: 20001.683 | K19: 45 | M19: 10 | N19: 10.000033 | O19: 0.014 | Q19: 200 mg | R19: 0.006 | S19: 0.02 | T19: 0.06 | U19: 0.2 | V19: 0.6 | W19: 2 | X19: -
A20: 0.1 | B20: 0.100003 | C20: 0.002 | E20: 1 | F20: 1 | G20: 0.03 | I20: 10LZ1 | J20: 10001.617 | K20: 26 | M20: 20 | N20: 20.000035 | O20: 0.018 | Q20: 100 mg | R20: 0.005 | S20: 0.015 | T20: 0.05 | U20: 0.15 | V20: 0.5 | W20: 1.5 | X20: -
I21: 5A | J21: 4998.996 | K21: 5.7 | M21: 20t | N21: 20.000038 | O21: 0.018 | Q21: 50 mg | R21: 0.004 | S21: 0.012 | T21: 0.04 | U21: 0.12 | V21: 0.4 | W21: - | X21: -
I22: 10A | J22: 9999.566 | K22: 26 | M22: 50 | N22: 50.00002 | O22: 0.03 | Q22: 20 mg | R22: 0.003 | S22: 0.01 | T22: 0.03 | U22: 0.1 | V22: 0.3 | W22: - | X22: -
B23: ISI DATA | I23: A | J23: 19999.312 | K23: 45 | M23: 100 | N23: 100.00029 | O23: 0.05 | Q23: 10 mg | R23: 0.002 | S23: 0.008 | T23: 0.025 | U23: 0.08 | V23: 0.25 | W23: - | X23: -
B24: Deskripsi | C24: Isi | D24: Satuan | I24: B | J24: 19999.19 | K24: 45 | M24: 200 | N24: 200.00025 | O24: 0.08 | Q24: 5 mg | R24: 0.002 | S24: 0.006 | T24: 0.02 | U24: 0.06 | V24: 0.2 | W24: - | X24: -
B25: No Order | C25: K519-1 | I25: C | J25: 19999.069 | K25: 45 | M25: 200t | N25: 200.00025 | O25: 0.08 | Q25: 2 mg | R25: 0.002 | S25: 0.006 | T25: 0.02 | U25: 0.06 | V25: 0.2 | W25: - | X25: -
B26: Pemilik Alat | C26: PT. XXXXXX | I26: D | J26: 19999.282 | K26: 45 | M26: 500 | N26: 500.00075 | O26: 0.16 | Q26: 1 mg | R26: 0.002 | S26: 0.006 | T26: 0.02 | U26: 0.06 | V26: 0.2 | W26: - | X26: -
B27: Alamat Pemilik Alat | C27: Jalan, Desa, Kecamatan, Kabupaten, Provinsi | I27: E | J27: 19999.268 | K27: 45 | M27: 1000 | N27: 1000.0009 | O27: 0.16
B28: Lokasi Alat | C28: Lab massa BBLM | I28: F | J28: 19999.33 | K28: 45
B29: Nama Alat | C29: Anak timbangan | I29: G | J29: 19999.21 | K29: 45
B30: Merk | C30: - | I30: H | J30: 20000.486 | K30: 45
B31: Tipe | C31: F1 | I31: I | J31: 19999.254 | K31: 45
B32: No Seri | C32: 124918
B33: No. Identifikasi | C33: -
B34: Temperatur Awal | C34: 20.1 | D34: °C
B35: Temperatur Akhir | C35: 20.1 | D35: °C
B36: Temperatur rata2 | C36: =AVERAGE(C34,C35) -> 20.1 | D36: °C
B37: Kelembaban Awal | C37: 60 | D37: %RH
B38: Kelembaban Akhir | C38: 60 | D38: %RH
B39: Kelembapan rata2 | C39: =AVERAGE(C37,C38) -> 60 | D39: %RH
B40: Tekanan awal | C40: 922 | D40: hPa | E40: =C40*H40 -> 691.55901 | F40: mmHg | G40: 1 hPa | H40: 0.750064 | I40: mmHg
...

Sheet 0,002
A1: E2 2024 | E1: F1 (B4T 2024) | I1: M1 | M1: E2 METTLER TOLEDO 2025 | Q1: TABEL MPE OIML R111-1
A2: Nominal (g) | B2: Massa konvensional (g) | C2: U95 (mg) | E2: Nominal (g) | F2: Massa konvensional (g) | G2: U95 (mg) | I2: Identitas | J2: Massa konvensional (g) | K2: U95 (mg) | M2: Nominal (g) | N2: Massa konvensional (g) | O2: U95 (mg) | Q2: Nominal Value | R2: Class E1 | S2: Class E2 | T2: Class F1 | U2: Class F2 | V2: Class M1 | W2: Class M2 | X2: Class M3
A3: 2000 | B3: 1999.9985 | C3: 0.32 | E3: 20000 | F3: 20000.022 | G3: 13 | I3: M1 | J3: 19999.414 | K3: 45 | M3: 0.001 | N3: 0.001003 | O3: 0.002 | Q3: 50 kg | R3: 25 | S3: 75 | T3: 250 | U3: 750 | V3: 2500 | W3: 7500 | X3: 25000
A4: 1000 | B4: 1000.0005 | C4: 0.14 | E4: 10000 | F4: 10000.041 | G4: 4.6 | I4: M2 | J4: 19999.234 | K4: 45 | M4: 0.002 | N4: 0.002003 | O4: 0.002 | Q4: 20 kg | R4: 10 | S4: 30 | T4: 100 | U4: 300 | V4: 1000 | W4: 3000 | X4: 10000
A5: 500 | B5: 500.00001 | C5: 0.08 | E5: 5000 | F5: 5000.005 | G5: 8 | I5: M3 | J5: 19999.627 | K5: 45 | M5: 0,002t | N5: 0.002001 | O5: 0.002 | Q5: 10 kg | R5: 5 | S5: 15 | T5: 50 | U5: 150 | V5: 500 | W5: 1500 | X5: 5000
A6: 200 | B6: 200.00001 | C6: 0.04 | E6: 2000* | F6: 1999.999 | G6: 3 | I6: M4 | J6: 20000.346 | K6: 45 | M6: 0.005 | N6: 0.005004 | O6: 0.002 | Q6: 5 kg | R6: 2.5 | S6: 7.5 | T6: 25 | U6: 75 | V6: 250 | W6: 750 | X6: 2500
A7: 200* | B7: 200.00005 | C7: 0.04 | E7: 2000 | F7: 1999.996 | G7: 3 | I7: M5 | J7: 20000.124 | K7: 45 | M7: 0.01 | N7: 0.010002 | O7: 0.003 | Q7: 2 kg | R7: 1 | S7: 3 | T7: 10 | U7: 30 | V7: 100 | W7: 300 | X7: 1000
A8: 100 | B8: 100.00008 | C8: 0.03 | E8: 1000 | F8: 1000.001 | G8: 1.7 | I8: M6 | J8: 20000.154 | K8: 45 | M8: 0.02 | N8: 0.020003 | O8: 0.003 | Q8: 1 kg | R8: 0.5 | S8: 1.5 | T8: 5 | U8: 15 | V8: 50 | W8: 150 | X8: 500
A9: 50 | B9: 50.00002 | C9: 0.02 | E9: 500 | F9: 500 | G9: 1.1 | I9: M7 | J9: 19999.125 | K9: 45 | M9: 0,02t | N9: 0.020005 | O9: 0.003 | Q9: 500 g | R9: 0.25 | S9: 0.75 | T9: 2.5 | U9: 7.5 | V9: 25 | W9: 75 | X9: 250
A10: 20 | B10: 19.999978 | C10: 0.009 | E10: 200 | F10: 199.99953 | G10: 0.3 | I10: M8 | J10: 19999.806 | K10: 45 | M10: 0.05 | N10: 0.050005 | O10: 0.003 | Q10: 200 g | R10: 0.01 | S10: 0.3 | T10: 1 | U10: 3 | V10: 10 | W10: 30 | X10: 100
A11: 20* | B11: 19.999977 | C11: 0.009 | E11: 200* | F11: 199.99873 | G11: 0.3 | I11: M9 | J11: 20000.237 | K11: 45 | M11: 0.1 | N11: 0.100008 | O11: 0.003 | Q11: 100 g | R11: 0.05 | S11: 0.15 | T11: 0.5 | U11: 1.5 | V11: 5 | W11: 15 | X11: 50
A12: 10 | B12: 9.999976 | C12: 0.008 | E12: 100 | F12: 99.99961 | G12: 0.16 | I12: M10 | J12: 19999.832 | K12: 45 | M12: 0.2 | N12: 0.200009 | O12: 0.005 | Q12: 50 g | R12: 0.03 | S12: 0.1 | T12: 0.3 | U12: 1 | V12: 3 | W12: 10 | X12: 30
A13: 5 | B13: 5.000006 | C13: 0.007 | E13: 50 | F13: 49.99956 | G13: 0.1 | I13: M11 | J13: 19999.934 | K13: 45 | M13: 0,2t | N13: 0.200002 | O13: 0.005 | Q13: 20 g | R13: 0.025 | S13: 0.08 | T13: 0.25 | U13: 0.8 | V13: 2.5 | W13: 8 | X13: 25
A14: 2 | B14: 2.000013 | C14: 0.005 | E14: 20 | F14: 20.00001 | G14: 0.08 | I14: M12 | J14: 19999.845 | K14: 45 | M14: 0.5 | N14: 0.500006 | O14: 0.006 | Q14: 10 g | R14: 0.02 | S14: 0.06 | T14: 0.2 | U14: 0.6 | V14: 2 | W14: 6 | X14: 20
A15: 2* | B15: 2.000015 | C15: 0.005 | E15: 20* | F15: 20.00004 | G15: 0.08 | I15: M13 | J15: 20000.802 | K15: 45 | M15: 1 | N15: 1.000016 | O15: 0.007 | Q15: 5 g | R15: 0.015 | S15: 0.05 | T15: 0.15 | U15: 0.5 | V15: 1.5 | W15: 5 | X15: 15
A16: 1 | B16: 0.999997 | C16: 0.005 | E16: 10 | F16: 10.00001 | G16: 0.06 | I16: M14 | J16: 19999.575 | K16: 45 | M16: 2 | N16: 1.999992 | O16: 0.009 | Q16: 2 g | R16: 0.012 | S16: 0.04 | T16: 0.12 | U16: 0.4 | V16: 1.2 | W16: 4 | X16: 12
A17: 0.5 | B17: 0.500018 | C17: 0.004 | E17: 5 | F17: 4.99994 | G17: 0.05 | I17: M15 | J17: 20000.329 | K17: 45 | M17: 2t | N17: 1.999991 | O17: 0.009 | Q17: 1 g | R17: 0.01 | S17: 0.03 | T17: 0.1 | U17: 0.3 | V17: 1 | W17: 3 | X17: 10
A18: 0.2 | B18: 0.200013 | C18: 0.003 | E18: 2 | F18: 2 | G18: 0.04 | I18: M16 | J18: 20000.932 | K18: 45 | M18: 5 | N18: 0.500006 | O18: 0.011 | Q18: 500 mg | R18: 0.008 | S18: 0.025 | T18: 0.08 | U18: 0.25 | V18: 0.8 | W18: 2.5 | X18: -
A19: 0.2* | B19: 0.200015 | C19: 0.003 | E19: 2* | F19: 1.99998 | G19: 0.04 | I19: 20LZ1 | J19: 20001.683 | K19: 45 | M19: 10 | N19: 10.000033 | O19: 0.014 | Q19: 200 mg | R19: 0.006 | S19: 0.02 | T19: 0.06 | U19: 0.2 | V19: 0.6 | W19: 2 | X19: -
A20: 0.1 | B20: 0.100003 | C20: 0.002 | E20: 1 | F20: 1 | G20: 0.03 | I20: 10LZ1 | J20: 10001.617 | K20: 26 | M20: 20 | N20: 20.000035 | O20: 0.018 | Q20: 100 mg | R20: 0.005 | S20: 0.015 | T20: 0.05 | U20: 0.15 | V20: 0.5 | W20: 1.5 | X20: -
I21: 5A | J21: 4998.996 | K21: 5.7 | M21: 20t | N21: 20.000038 | O21: 0.018 | Q21: 50 mg | R21: 0.004 | S21: 0.012 | T21: 0.04 | U21: 0.12 | V21: 0.4 | W21: - | X21: -
I22: 10A | J22: 9999.566 | K22: 26 | M22: 50 | N22: 50.00002 | O22: 0.03 | Q22: 20 mg | R22: 0.003 | S22: 0.01 | T22: 0.03 | U22: 0.1 | V22: 0.3 | W22: - | X22: -
B23: ISI DATA | I23: A | J23: 19999.312 | K23: 45 | M23: 100 | N23: 100.00029 | O23: 0.05 | Q23: 10 mg | R23: 0.002 | S23: 0.008 | T23: 0.025 | U23: 0.08 | V23: 0.25 | W23: - | X23: -
B24: Deskripsi | C24: Isi | D24: Satuan | I24: B | J24: 19999.19 | K24: 45 | M24: 200 | N24: 200.00025 | O24: 0.08 | Q24: 5 mg | R24: 0.002 | S24: 0.006 | T24: 0.02 | U24: 0.06 | V24: 0.2 | W24: - | X24: -
B25: No Order | C25: K519-1 | I25: C | J25: 19999.069 | K25: 45 | M25: 200t | N25: 200.00025 | O25: 0.08 | Q25: 2 mg | R25: 0.002 | S25: 0.006 | T25: 0.02 | U25: 0.06 | V25: 0.2 | W25: - | X25: -
B26: Pemilik Alat | C26: PT. XXXXXX | I26: D | J26: 19999.282 | K26: 45 | M26: 500 | N26: 500.00075 | O26: 0.16 | Q26: 1 mg | R26: 0.002 | S26: 0.006 | T26: 0.02 | U26: 0.06 | V26: 0.2 | W26: - | X26: -
B27: Alamat Pemilik Alat | C27: Jalan, Desa, Kecamatan, Kabupaten, Provinsi | I27: E | J27: 19999.268 | K27: 45 | M27: 1000 | N27: 1000.0009 | O27: 0.16
B28: Lokasi Alat | C28: Lab massa BBLM | I28: F | J28: 19999.33 | K28: 45
B29: Nama Alat | C29: Anak timbangan | I29: G | J29: 19999.21 | K29: 45
B30: Merk | C30: - | I30: H | J30: 20000.486 | K30: 45
B31: Tipe | C31: F1 | I31: I | J31: 19999.254 | K31: 45
B32: No Seri | C32: 124918
B33: No. Identifikasi | C33: -
B34: Temperatur Awal | C34: 20.1 | D34: °C
B35: Temperatur Akhir | C35: 20.1 | D35: °C
B36: Temperatur rata2 | C36: =AVERAGE(C34,C35) -> 20.1 | D36: °C
B37: Kelembaban Awal | C37: 60 | D37: %RH
B38: Kelembaban Akhir | C38: 60 | D38: %RH
B39: Kelembapan rata2 | C39: =AVERAGE(C37,C38) -> 60 | D39: %RH
B40: Tekanan awal | C40: 922 | D40: hPa | E40: =C40*H40 -> 691.55901 | F40: mmHg | G40: 1 hPa | H40: 0.750064 | I40: mmHg
...

Sheet 0,002t
A1: E2 2024 | E1: F1 (B4T 2024) | I1: M1 | M1: E2 METTLER TOLEDO 2025 | Q1: TABEL MPE OIML R111-1
A2: Nominal (g) | B2: Massa konvensional (g) | C2: U95 (mg) | E2: Nominal (g) | F2: Massa konvensional (g) | G2: U95 (mg) | I2: Identitas | J2: Massa konvensional (g) | K2: U95 (mg) | M2: Nominal (g) | N2: Massa konvensional (g) | O2: U95 (mg) | Q2: Nominal Value | R2: Class E1 | S2: Class E2 | T2: Class F1 | U2: Class F2 | V2: Class M1 | W2: Class M2 | X2: Class M3
A3: 2000 | B3: 1999.9985 | C3: 0.32 | E3: 20000 | F3: 20000.022 | G3: 13 | I3: M1 | J3: 19999.414 | K3: 45 | M3: 0.001 | N3: 0.001003 | O3: 0.002 | Q3: 50 kg | R3: 25 | S3: 75 | T3: 250 | U3: 750 | V3: 2500 | W3: 7500 | X3: 25000
A4: 1000 | B4: 1000.0005 | C4: 0.14 | E4: 10000 | F4: 10000.041 | G4: 4.6 | I4: M2 | J4: 19999.234 | K4: 45 | M4: 0.002 | N4: 0.002003 | O4: 0.002 | Q4: 20 kg | R4: 10 | S4: 30 | T4: 100 | U4: 300 | V4: 1000 | W4: 3000 | X4: 10000
A5: 500 | B5: 500.00001 | C5: 0.08 | E5: 5000 | F5: 5000.005 | G5: 8 | I5: M3 | J5: 19999.627 | K5: 45 | M5: 0,002t | N5: 0.002001 | O5: 0.002 | Q5: 10 kg | R5: 5 | S5: 15 | T5: 50 | U5: 150 | V5: 500 | W5: 1500 | X5: 5000
A6: 200 | B6: 200.00001 | C6: 0.04 | E6: 2000* | F6: 1999.999 | G6: 3 | I6: M4 | J6: 20000.346 | K6: 45 | M6: 0.005 | N6: 0.005004 | O6: 0.002 | Q6: 5 kg | R6: 2.5 | S6: 7.5 | T6: 25 | U6: 75 | V6: 250 | W6: 750 | X6: 2500
A7: 200* | B7: 200.00005 | C7: 0.04 | E7: 2000 | F7: 1999.996 | G7: 3 | I7: M5 | J7: 20000.124 | K7: 45 | M7: 0.01 | N7: 0.010002 | O7: 0.003 | Q7: 2 kg | R7: 1 | S7: 3 | T7: 10 | U7: 30 | V7: 100 | W7: 300 | X7: 1000
A8: 100 | B8: 100.00008 | C8: 0.03 | E8: 1000 | F8: 1000.001 | G8: 1.7 | I8: M6 | J8: 20000.154 | K8: 45 | M8: 0.02 | N8: 0.020003 | O8: 0.003 | Q8: 1 kg | R8: 0.5 | S8: 1.5 | T8: 5 | U8: 15 | V8: 50 | W8: 150 | X8: 500
A9: 50 | B9: 50.00002 | C9: 0.02 | E9: 500 | F9: 500 | G9: 1.1 | I9: M7 | J9: 19999.125 | K9: 45 | M9: 0,02t | N9: 0.020005 | O9: 0.003 | Q9: 500 g | R9: 0.25 | S9: 0.75 | T9: 2.5 | U9: 7.5 | V9: 25 | W9: 75 | X9: 250
A10: 20 | B10: 19.999978 | C10: 0.009 | E10: 200 | F10: 199.99953 | G10: 0.3 | I10: M8 | J10: 19999.806 | K10: 45 | M10: 0.05 | N10: 0.050005 | O10: 0.003 | Q10: 200 g | R10: 0.01 | S10: 0.3 | T10: 1 | U10: 3 | V10: 10 | W10: 30 | X10: 100
A11: 20* | B11: 19.999977 | C11: 0.009 | E11: 200* | F11: 199.99873 | G11: 0.3 | I11: M9 | J11: 20000.237 | K11: 45 | M11: 0.1 | N11: 0.100008 | O11: 0.003 | Q11: 100 g | R11: 0.05 | S11: 0.15 | T11: 0.5 | U11: 1.5 | V11: 5 | W11: 15 | X11: 50
A12: 10 | B12: 9.999976 | C12: 0.008 | E12: 100 | F12: 99.99961 | G12: 0.16 | I12: M10 | J12: 19999.832 | K12: 45 | M12: 0.2 | N12: 0.200009 | O12: 0.005 | Q12: 50 g | R12: 0.03 | S12: 0.1 | T12: 0.3 | U12: 1 | V12: 3 | W12: 10 | X12: 30
A13: 5 | B13: 5.000006 | C13: 0.007 | E13: 50 | F13: 49.99956 | G13: 0.1 | I13: M11 | J13: 19999.934 | K13: 45 | M13: 0,2t | N13: 0.200002 | O13: 0.005 | Q13: 20 g | R13: 0.025 | S13: 0.08 | T13: 0.25 | U13: 0.8 | V13: 2.5 | W13: 8 | X13: 25
A14: 2 | B14: 2.000013 | C14: 0.005 | E14: 20 | F14: 20.00001 | G14: 0.08 | I14: M12 | J14: 19999.845 | K14: 45 | M14: 0.5 | N14: 0.500006 | O14: 0.006 | Q14: 10 g | R14: 0.02 | S14: 0.06 | T14: 0.2 | U14: 0.6 | V14: 2 | W14: 6 | X14: 20
A15: 2* | B15: 2.000015 | C15: 0.005 | E15: 20* | F15: 20.00004 | G15: 0.08 | I15: M13 | J15: 20000.802 | K15: 45 | M15: 1 | N15: 1.000016 | O15: 0.007 | Q15: 5 g | R15: 0.015 | S15: 0.05 | T15: 0.15 | U15: 0.5 | V15: 1.5 | W15: 5 | X15: 15
A16: 1 | B16: 0.999997 | C16: 0.005 | E16: 10 | F16: 10.00001 | G16: 0.06 | I16: M14 | J16: 19999.575 | K16: 45 | M16: 2 | N16: 1.999992 | O16: 0.009 | Q16: 2 g | R16: 0.012 | S16: 0.04 | T16: 0.12 | U16: 0.4 | V16: 1.2 | W16: 4 | X16: 12
A17: 0.5 | B17: 0.500018 | C17: 0.004 | E17: 5 | F17: 4.99994 | G17: 0.05 | I17: M15 | J17: 20000.329 | K17: 45 | M17: 2t | N17: 1.999991 | O17: 0.009 | Q17: 1 g | R17: 0.01 | S17: 0.03 | T17: 0.1 | U17: 0.3 | V17: 1 | W17: 3 | X17: 10
A18: 0.2 | B18: 0.200013 | C18: 0.003 | E18: 2 | F18: 2 | G18: 0.04 | I18: M16 | J18: 20000.932 | K18: 45 | M18: 5 | N18: 0.500006 | O18: 0.011 | Q18: 500 mg | R18: 0.008 | S18: 0.025 | T18: 0.08 | U18: 0.25 | V18: 0.8 | W18: 2.5 | X18: -
A19: 0.2* | B19: 0.200015 | C19: 0.003 | E19: 2* | F19: 1.99998 | G19: 0.04 | I19: 20LZ1 | J19: 20001.683 | K19: 45 | M19: 10 | N19: 10.000033 | O19: 0.014 | Q19: 200 mg | R19: 0.006 | S19: 0.02 | T19: 0.06 | U19: 0.2 | V19: 0.6 | W19: 2 | X19: -
A20: 0.1 | B20: 0.100003 | C20: 0.002 | E20: 1 | F20: 1 | G20: 0.03 | I20: 10LZ1 | J20: 10001.617 | K20: 26 | M20: 20 | N20: 20.000035 | O20: 0.018 | Q20: 100 mg | R20: 0.005 | S20: 0.015 | T20: 0.05 | U20: 0.15 | V20: 0.5 | W20: 1.5 | X20: -
I21: 5A | J21: 4998.996 | K21: 5.7 | M21: 20t | N21: 20.000038 | O21: 0.018 | Q21: 50 mg | R21: 0.004 | S21: 0.012 | T21: 0.04 | U21: 0.12 | V21: 0.4 | W21: - | X21: -
I22: 10A | J22: 9999.566 | K22: 26 | M22: 50 | N22: 50.00002 | O22: 0.03 | Q22: 20 mg | R22: 0.003 | S22: 0.01 | T22: 0.03 | U22: 0.1 | V22: 0.3 | W22: - | X22: -
B23: ISI DATA | I23: A | J23: 19999.312 | K23: 45 | M23: 100 | N23: 100.00029 | O23: 0.05 | Q23: 10 mg | R23: 0.002 | S23: 0.008 | T23: 0.025 | U23: 0.08 | V23: 0.25 | W23: - | X23: -
B24: Deskripsi | C24: Isi | D24: Satuan | I24: B | J24: 19999.19 | K24: 45 | M24: 200 | N24: 200.00025 | O24: 0.08 | Q24: 5 mg | R24: 0.002 | S24: 0.006 | T24: 0.02 | U24: 0.06 | V24: 0.2 | W24: - | X24: -
B25: No Order | C25: K519-1 | I25: C | J25: 19999.069 | K25: 45 | M25: 200t | N25: 200.00025 | O25: 0.08 | Q25: 2 mg | R25: 0.002 | S25: 0.006 | T25: 0.02 | U25: 0.06 | V25: 0.2 | W25: - | X25: -
B26: Pemilik Alat | C26: PT. XXXXXX | I26: D | J26: 19999.282 | K26: 45 | M26: 500 | N26: 500.00075 | O26: 0.16 | Q26: 1 mg | R26: 0.002 | S26: 0.006 | T26: 0.02 | U26: 0.06 | V26: 0.2 | W26: - | X26: -
B27: Alamat Pemilik Alat | C27: Jalan, Desa, Kecamatan, Kabupaten, Provinsi | I27: E | J27: 19999.268 | K27: 45 | M27: 1000 | N27: 1000.0009 | O27: 0.16
B28: Lokasi Alat | C28: Lab massa BBLM | I28: F | J28: 19999.33 | K28: 45
B29: Nama Alat | C29: Anak timbangan | I29: G | J29: 19999.21 | K29: 45
B30: Merk | C30: - | I30: H | J30: 20000.486 | K30: 45
B31: Tipe | C31: F1 | I31: I | J31: 19999.254 | K31: 45
B32: No Seri | C32: 124918
B33: No. Identifikasi | C33: -
B34: Temperatur Awal | C34: 20.1 | D34: °C
B35: Temperatur Akhir | C35: 20.1 | D35: °C
B36: Temperatur rata2 | C36: =AVERAGE(C34,C35) -> 20.1 | D36: °C
B37: Kelembaban Awal | C37: 60 | D37: %RH
B38: Kelembaban Akhir | C38: 60 | D38: %RH
B39: Kelembapan rata2 | C39: =AVERAGE(C37,C38) -> 60 | D39: %RH
B40: Tekanan awal | C40: 922 | D40: hPa | E40: =C40*H40 -> 691.55901 | F40: mmHg | G40: 1 hPa | H40: 0.750064 | I40: mmHg
...

Sheet 0,005
A1: E2 2024 | E1: F1 (B4T 2024) | I1: M1 | M1: E2 METTLER TOLEDO 2025 | Q1: TABEL MPE OIML R111-1
A2: Nominal (g) | B2: Massa konvensional (g) | C2: U95 (mg) | E2: Nominal (g) | F2: Massa konvensional (g) | G2: U95 (mg) | I2: Identitas | J2: Massa konvensional (g) | K2: U95 (mg) | M2: Nominal (g) | N2: Massa konvensional (g) | O2: U95 (mg) | Q2: Nominal Value | R2: Class E1 | S2: Class E2 | T2: Class F1 | U2: Class F2 | V2: Class M1 | W2: Class M2 | X2: Class M3
A3: 2000 | B3: 1999.9985 | C3: 0.32 | E3: 20000 | F3: 20000.022 | G3: 13 | I3: M1 | J3: 19999.414 | K3: 45 | M3: 0.001 | N3: 0.001003 | O3: 0.002 | Q3: 50 kg | R3: 25 | S3: 75 | T3: 250 | U3: 750 | V3: 2500 | W3: 7500 | X3: 25000
A4: 1000 | B4: 1000.0005 | C4: 0.14 | E4: 10000 | F4: 10000.041 | G4: 4.6 | I4: M2 | J4: 19999.234 | K4: 45 | M4: 0.002 | N4: 0.002003 | O4: 0.002 | Q4: 20 kg | R4: 10 | S4: 30 | T4: 100 | U4: 300 | V4: 1000 | W4: 3000 | X4: 10000
A5: 500 | B5: 500.00001 | C5: 0.08 | E5: 5000 | F5: 5000.005 | G5: 8 | I5: M3 | J5: 19999.627 | K5: 45 | M5: 0,002t | N5: 0.002001 | O5: 0.002 | Q5: 10 kg | R5: 5 | S5: 15 | T5: 50 | U5: 150 | V5: 500 | W5: 1500 | X5: 5000
A6: 200 | B6: 200.00001 | C6: 0.04 | E6: 2000* | F6: 1999.999 | G6: 3 | I6: M4 | J6: 20000.346 | K6: 45 | M6: 0.005 | N6: 0.005004 | O6: 0.002 | Q6: 5 kg | R6: 2.5 | S6: 7.5 | T6: 25 | U6: 75 | V6: 250 | W6: 750 | X6: 2500
A7: 200* | B7: 200.00005 | C7: 0.04 | E7: 2000 | F7: 1999.996 | G7: 3 | I7: M5 | J7: 20000.124 | K7: 45 | M7: 0.01 | N7: 0.010002 | O7: 0.003 | Q7: 2 kg | R7: 1 | S7: 3 | T7: 10 | U7: 30 | V7: 100 | W7: 300 | X7: 1000
A8: 100 | B8: 100.00008 | C8: 0.03 | E8: 1000 | F8: 1000.001 | G8: 1.7 | I8: M6 | J8: 20000.154 | K8: 45 | M8: 0.02 | N8: 0.020003 | O8: 0.003 | Q8: 1 kg | R8: 0.5 | S8: 1.5 | T8: 5 | U8: 15 | V8: 50 | W8: 150 | X8: 500
A9: 50 | B9: 50.00002 | C9: 0.02 | E9: 500 | F9: 500 | G9: 1.1 | I9: M7 | J9: 19999.125 | K9: 45 | M9: 0,02t | N9: 0.020005 | O9: 0.003 | Q9: 500 g | R9: 0.25 | S9: 0.75 | T9: 2.5 | U9: 7.5 | V9: 25 | W9: 75 | X9: 250
A10: 20 | B10: 19.999978 | C10: 0.009 | E10: 200 | F10: 199.99953 | G10: 0.3 | I10: M8 | J10: 19999.806 | K10: 45 | M10: 0.05 | N10: 0.050005 | O10: 0.003 | Q10: 200 g | R10: 0.01 | S10: 0.3 | T10: 1 | U10: 3 | V10: 10 | W10: 30 | X10: 100
A11: 20* | B11: 19.999977 | C11: 0.009 | E11: 200* | F11: 199.99873 | G11: 0.3 | I11: M9 | J11: 20000.237 | K11: 45 | M11: 0.1 | N11: 0.100008 | O11: 0.003 | Q11: 100 g | R11: 0.05 | S11: 0.15 | T11: 0.5 | U11: 1.5 | V11: 5 | W11: 15 | X11: 50
A12: 10 | B12: 9.999976 | C12: 0.008 | E12: 100 | F12: 99.99961 | G12: 0.16 | I12: M10 | J12: 19999.832 | K12: 45 | M12: 0.2 | N12: 0.200009 | O12: 0.005 | Q12: 50 g | R12: 0.03 | S12: 0.1 | T12: 0.3 | U12: 1 | V12: 3 | W12: 10 | X12: 30
A13: 5 | B13: 5.000006 | C13: 0.007 | E13: 50 | F13: 49.99956 | G13: 0.1 | I13: M11 | J13: 19999.934 | K13: 45 | M13: 0,2t | N13: 0.200002 | O13: 0.005 | Q13: 20 g | R13: 0.025 | S13: 0.08 | T13: 0.25 | U13: 0.8 | V13: 2.5 | W13: 8 | X13: 25
A14: 2 | B14: 2.000013 | C14: 0.005 | E14: 20 | F14: 20.00001 | G14: 0.08 | I14: M12 | J14: 19999.845 | K14: 45 | M14: 0.5 | N14: 0.500006 | O14: 0.006 | Q14: 10 g | R14: 0.02 | S14: 0.06 | T14: 0.2 | U14: 0.6 | V14: 2 | W14: 6 | X14: 20
A15: 2* | B15: 2.000015 | C15: 0.005 | E15: 20* | F15: 20.00004 | G15: 0.08 | I15: M13 | J15: 20000.802 | K15: 45 | M15: 1 | N15: 1.000016 | O15: 0.007 | Q15: 5 g | R15: 0.015 | S15: 0.05 | T15: 0.15 | U15: 0.5 | V15: 1.5 | W15: 5 | X15: 15
A16: 1 | B16: 0.999997 | C16: 0.005 | E16: 10 | F16: 10.00001 | G16: 0.06 | I16: M14 | J16: 19999.575 | K16: 45 | M16: 2 | N16: 1.999992 | O16: 0.009 | Q16: 2 g | R16: 0.012 | S16: 0.04 | T16: 0.12 | U16: 0.4 | V16: 1.2 | W16: 4 | X16: 12
A17: 0.5 | B17: 0.500018 | C17: 0.004 | E17: 5 | F17: 4.99994 | G17: 0.05 | I17: M15 | J17: 20000.329 | K17: 45 | M17: 2t | N17: 1.999991 | O17: 0.009 | Q17: 1 g | R17: 0.01 | S17: 0.03 | T17: 0.1 | U17: 0.3 | V17: 1 | W17: 3 | X17: 10
A18: 0.2 | B18: 0.200013 | C18: 0.003 | E18: 2 | F18: 2 | G18: 0.04 | I18: M16 | J18: 20000.932 | K18: 45 | M18: 5 | N18: 0.500006 | O18: 0.011 | Q18: 500 mg | R18: 0.008 | S18: 0.025 | T18: 0.08 | U18: 0.25 | V18: 0.8 | W18: 2.5 | X18: -
A19: 0.2* | B19: 0.200015 | C19: 0.003 | E19: 2* | F19: 1.99998 | G19: 0.04 | I19: 20LZ1 | J19: 20001.683 | K19: 45 | M19: 10 | N19: 10.000033 | O19: 0.014 | Q19: 200 mg | R19: 0.006 | S19: 0.02 | T19: 0.06 | U19: 0.2 | V19: 0.6 | W19: 2 | X19: -
A20: 0.1 | B20: 0.100003 | C20: 0.002 | E20: 1 | F20: 1 | G20: 0.03 | I20: 10LZ1 | J20: 10001.617 | K20: 26 | M20: 20 | N20: 20.000035 | O20: 0.018 | Q20: 100 mg | R20: 0.005 | S20: 0.015 | T20: 0.05 | U20: 0.15 | V20: 0.5 | W20: 1.5 | X20: -
I21: 5A | J21: 4998.996 | K21: 5.7 | M21: 20t | N21: 20.000038 | O21: 0.018 | Q21: 50 mg | R21: 0.004 | S21: 0.012 | T21: 0.04 | U21: 0.12 | V21: 0.4 | W21: - | X21: -
I22: 10A | J22: 9999.566 | K22: 26 | M22: 50 | N22: 50.00002 | O22: 0.03 | Q22: 20 mg | R22: 0.003 | S22: 0.01 | T22: 0.03 | U22: 0.1 | V22: 0.3 | W22: - | X22: -
B23: ISI DATA | I23: A | J23: 19999.312 | K23: 45 | M23: 100 | N23: 100.00029 | O23: 0.05 | Q23: 10 mg | R23: 0.002 | S23: 0.008 | T23: 0.025 | U23: 0.08 | V23: 0.25 | W23: - | X23: -
B24: Deskripsi | C24: Isi | D24: Satuan | I24: B | J24: 19999.19 | K24: 45 | M24: 200 | N24: 200.00025 | O24: 0.08 | Q24: 5 mg | R24: 0.002 | S24: 0.006 | T24: 0.02 | U24: 0.06 | V24: 0.2 | W24: - | X24: -
B25: No Order | C25: K519-1 | I25: C | J25: 19999.069 | K25: 45 | M25: 200t | N25: 200.00025 | O25: 0.08 | Q25: 2 mg | R25: 0.002 | S25: 0.006 | T25: 0.02 | U25: 0.06 | V25: 0.2 | W25: - | X25: -
B26: Pemilik Alat | C26: PT. XXXXXX | I26: D | J26: 19999.282 | K26: 45 | M26: 500 | N26: 500.00075 | O26: 0.16 | Q26: 1 mg | R26: 0.002 | S26: 0.006 | T26: 0.02 | U26: 0.06 | V26: 0.2 | W26: - | X26: -
B27: Alamat Pemilik Alat | C27: Jalan, Desa, Kecamatan, Kabupaten, Provinsi | I27: E | J27: 19999.268 | K27: 45 | M27: 1000 | N27: 1000.0009 | O27: 0.16
B28: Lokasi Alat | C28: Lab massa BBLM | I28: F | J28: 19999.33 | K28: 45
B29: Nama Alat | C29: Anak timbangan | I29: G | J29: 19999.21 | K29: 45
B30: Merk | C30: - | I30: H | J30: 20000.486 | K30: 45
B31: Tipe | C31: F1 | I31: I | J31: 19999.254 | K31: 45
B32: No Seri | C32: 124918
B33: No. Identifikasi | C33: -
B34: Temperatur Awal | C34: 20.1 | D34: °C
B35: Temperatur Akhir | C35: 20.1 | D35: °C
B36: Temperatur rata2 | C36: =AVERAGE(C34,C35) -> 20.1 | D36: °C
B37: Kelembaban Awal | C37: 60 | D37: %RH
B38: Kelembaban Akhir | C38: 60 | D38: %RH
B39: Kelembapan rata2 | C39: =AVERAGE(C37,C38) -> 60 | D39: %RH
B40: Tekanan awal | C40: 922 | D40: hPa | E40: =C40*H40 -> 691.55901 | F40: mmHg | G40: 1 hPa | H40: 0.750064 | I40: mmHg
...

Sheet 0,01
A1: E2 2024 | E1: F1 (B4T 2024) | I1: M1 | M1: E2 METTLER TOLEDO 2025 | Q1: TABEL MPE OIML R111-1
A2: Nominal (g) | B2: Massa konvensional (g) | C2: U95 (mg) | E2: Nominal (g) | F2: Massa konvensional (g) | G2: U95 (mg) | I2: Identitas | J2: Massa konvensional (g) | K2: U95 (mg) | M2: Nominal (g) | N2: Massa konvensional (g) | O2: U95 (mg) | Q2: Nominal Value | R2: Class E1 | S2: Class E2 | T2: Class F1 | U2: Class F2 | V2: Class M1 | W2: Class M2 | X2: Class M3
A3: 2000 | B3: 1999.9985 | C3: 0.32 | E3: 20000 | F3: 20000.022 | G3: 13 | I3: M1 | J3: 19999.414 | K3: 45 | M3: 0.001 | N3: 0.001003 | O3: 0.002 | Q3: 50 kg | R3: 25 | S3: 75 | T3: 250 | U3: 750 | V3: 2500 | W3: 7500 | X3: 25000
A4: 1000 | B4: 1000.0005 | C4: 0.14 | E4: 10000 | F4: 10000.041 | G4: 4.6 | I4: M2 | J4: 19999.234 | K4: 45 | M4: 0.002 | N4: 0.002003 | O4: 0.002 | Q4: 20 kg | R4: 10 | S4: 30 | T4: 100 | U4: 300 | V4: 1000 | W4: 3000 | X4: 10000
A5: 500 | B5: 500.00001 | C5: 0.08 | E5: 5000 | F5: 5000.005 | G5: 8 | I5: M3 | J5: 19999.627 | K5: 45 | M5: 0,002t | N5: 0.002001 | O5: 0.002 | Q5: 10 kg | R5: 5 | S5: 15 | T5: 50 | U5: 150 | V5: 500 | W5: 1500 | X5: 5000
A6: 200 | B6: 200.00001 | C6: 0.04 | E6: 2000* | F6: 1999.999 | G6: 3 | I6: M4 | J6: 20000.346 | K6: 45 | M6: 0.005 | N6: 0.005004 | O6: 0.002 | Q6: 5 kg | R6: 2.5 | S6: 7.5 | T6: 25 | U6: 75 | V6: 250 | W6: 750 | X6: 2500
A7: 200* | B7: 200.00005 | C7: 0.04 | E7: 2000 | F7: 1999.996 | G7: 3 | I7: M5 | J7: 20000.124 | K7: 45 | M7: 0.01 | N7: 0.010002 | O7: 0.003 | Q7: 2 kg | R7: 1 | S7: 3 | T7: 10 | U7: 30 | V7: 100 | W7: 300 | X7: 1000
A8: 100 | B8: 100.00008 | C8: 0.03 | E8: 1000 | F8: 1000.001 | G8: 1.7 | I8: M6 | J8: 20000.154 | K8: 45 | M8: 0.02 | N8: 0.020003 | O8: 0.003 | Q8: 1 kg | R8: 0.5 | S8: 1.5 | T8: 5 | U8: 15 | V8: 50 | W8: 150 | X8: 500
A9: 50 | B9: 50.00002 | C9: 0.02 | E9: 500 | F9: 500 | G9: 1.1 | I9: M7 | J9: 19999.125 | K9: 45 | M9: 0,02t | N9: 0.020005 | O9: 0.003 | Q9: 500 g | R9: 0.25 | S9: 0.75 | T9: 2.5 | U9: 7.5 | V9: 25 | W9: 75 | X9: 250
A10: 20 | B10: 19.999978 | C10: 0.009 | E10: 200 | F10: 199.99953 | G10: 0.3 | I10: M8 | J10: 19999.806 | K10: 45 | M10: 0.05 | N10: 0.050005 | O10: 0.003 | Q10: 200 g | R10: 0.01 | S10: 0.3 | T10: 1 | U10: 3 | V10: 10 | W10: 30 | X10: 100
A11: 20* | B11: 19.999977 | C11: 0.009 | E11: 200* | F11: 199.99873 | G11: 0.3 | I11: M9 | J11: 20000.237 | K11: 45 | M11: 0.1 | N11: 0.100008 | O11: 0.003 | Q11: 100 g | R11: 0.05 | S11: 0.15 | T11: 0.5 | U11: 1.5 | V11: 5 | W11: 15 | X11: 50
A12: 10 | B12: 9.999976 | C12: 0.008 | E12: 100 | F12: 99.99961 | G12: 0.16 | I12: M10 | J12: 19999.832 | K12: 45 | M12: 0.2 | N12: 0.200009 | O12: 0.005 | Q12: 50 g | R12: 0.03 | S12: 0.1 | T12: 0.3 | U12: 1 | V12: 3 | W12: 10 | X12: 30
A13: 5 | B13: 5.000006 | C13: 0.007 | E13: 50 | F13: 49.99956 | G13: 0.1 | I13: M11 | J13: 19999.934 | K13: 45 | M13: 0,2t | N13: 0.200002 | O13: 0.005 | Q13: 20 g | R13: 0.025 | S13: 0.08 | T13: 0.25 | U13: 0.8 | V13: 2.5 | W13: 8 | X13: 25
A14: 2 | B14: 2.000013 | C14: 0.005 | E14: 20 | F14: 20.00001 | G14: 0.08 | I14: M12 | J14: 19999.845 | K14: 45 | M14: 0.5 | N14: 0.500006 | O14: 0.006 | Q14: 10 g | R14: 0.02 | S14: 0.06 | T14: 0.2 | U14: 0.6 | V14: 2 | W14: 6 | X14: 20
A15: 2* | B15: 2.000015 | C15: 0.005 | E15: 20* | F15: 20.00004 | G15: 0.08 | I15: M13 | J15: 20000.802 | K15: 45 | M15: 1 | N15: 1.000016 | O15: 0.007 | Q15: 5 g | R15: 0.015 | S15: 0.05 | T15: 0.15 | U15: 0.5 | V15: 1.5 | W15: 5 | X15: 15
A16: 1 | B16: 0.999997 | C16: 0.005 | E16: 10 | F16: 10.00001 | G16: 0.06 | I16: M14 | J16: 19999.575 | K16: 45 | M16: 2 | N16: 1.999992 | O16: 0.009 | Q16: 2 g | R16: 0.012 | S16: 0.04 | T16: 0.12 | U16: 0.4 | V16: 1.2 | W16: 4 | X16: 12
A17: 0.5 | B17: 0.500018 | C17: 0.004 | E17: 5 | F17: 4.99994 | G17: 0.05 | I17: M15 | J17: 20000.329 | K17: 45 | M17: 2t | N17: 1.999991 | O17: 0.009 | Q17: 1 g | R17: 0.01 | S17: 0.03 | T17: 0.1 | U17: 0.3 | V17: 1 | W17: 3 | X17: 10
A18: 0.2 | B18: 0.200013 | C18: 0.003 | E18: 2 | F18: 2 | G18: 0.04 | I18: M16 | J18: 20000.932 | K18: 45 | M18: 5 | N18: 0.500006 | O18: 0.011 | Q18: 500 mg | R18: 0.008 | S18: 0.025 | T18: 0.08 | U18: 0.25 | V18: 0.8 | W18: 2.5 | X18: -
A19: 0.2* | B19: 0.200015 | C19: 0.003 | E19: 2* | F19: 1.99998 | G19: 0.04 | I19: 20LZ1 | J19: 20001.683 | K19: 45 | M19: 10 | N19: 10.000033 | O19: 0.014 | Q19: 200 mg | R19: 0.006 | S19: 0.02 | T19: 0.06 | U19: 0.2 | V19: 0.6 | W19: 2 | X19: -
A20: 0.1 | B20: 0.100003 | C20: 0.002 | E20: 1 | F20: 1 | G20: 0.03 | I20: 10LZ1 | J20: 10001.617 | K20: 26 | M20: 20 | N20: 20.000035 | O20: 0.018 | Q20: 100 mg | R20: 0.005 | S20: 0.015 | T20: 0.05 | U20: 0.15 | V20: 0.5 | W20: 1.5 | X20: -
I21: 5A | J21: 4998.996 | K21: 5.7 | M21: 20t | N21: 20.000038 | O21: 0.018 | Q21: 50 mg | R21: 0.004 | S21: 0.012 | T21: 0.04 | U21: 0.12 | V21: 0.4 | W21: - | X21: -
I22: 10A | J22: 9999.566 | K22: 26 | M22: 50 | N22: 50.00002 | O22: 0.03 | Q22: 20 mg | R22: 0.003 | S22: 0.01 | T22: 0.03 | U22: 0.1 | V22: 0.3 | W22: - | X22: -
B23: ISI DATA | I23: A | J23: 19999.312 | K23: 45 | M23: 100 | N23: 100.00029 | O23: 0.05 | Q23: 10 mg | R23: 0.002 | S23: 0.008 | T23: 0.025 | U23: 0.08 | V23: 0.25 | W23: - | X23: -
B24: Deskripsi | C24: Isi | D24: Satuan | I24: B | J24: 19999.19 | K24: 45 | M24: 200 | N24: 200.00025 | O24: 0.08 | Q24: 5 mg | R24: 0.002 | S24: 0.006 | T24: 0.02 | U24: 0.06 | V24: 0.2 | W24: - | X24: -
B25: No Order | C25: K519-1 | I25: C | J25: 19999.069 | K25: 45 | M25: 200t | N25: 200.00025 | O25: 0.08 | Q25: 2 mg | R25: 0.002 | S25: 0.006 | T25: 0.02 | U25: 0.06 | V25: 0.2 | W25: - | X25: -
B26: Pemilik Alat | C26: PT. XXXXXX | I26: D | J26: 19999.282 | K26: 45 | M26: 500 | N26: 500.00075 | O26: 0.16 | Q26: 1 mg | R26: 0.002 | S26: 0.006 | T26: 0.02 | U26: 0.06 | V26: 0.2 | W26: - | X26: -
B27: Alamat Pemilik Alat | C27: Jalan, Desa, Kecamatan, Kabupaten, Provinsi | I27: E | J27: 19999.268 | K27: 45 | M27: 1000 | N27: 1000.0009 | O27: 0.16
B28: Lokasi Alat | C28: Lab massa BBLM | I28: F | J28: 19999.33 | K28: 45
B29: Nama Alat | C29: Anak timbangan | I29: G | J29: 19999.21 | K29: 45
B30: Merk | C30: - | I30: H | J30: 20000.486 | K30: 45
B31: Tipe | C31: F1 | I31: I | J31: 19999.254 | K31: 45
B32: No Seri | C32: 124918
B33: No. Identifikasi | C33: -
B34: Temperatur Awal | C34: 20.1 | D34: °C
B35: Temperatur Akhir | C35: 20.1 | D35: °C
B36: Temperatur rata2 | C36: =AVERAGE(C34,C35) -> 20.1 | D36: °C
B37: Kelembaban Awal | C37: 60 | D37: %RH
B38: Kelembaban Akhir | C38: 60 | D38: %RH
B39: Kelembapan rata2 | C39: =AVERAGE(C37,C38) -> 60 | D39: %RH
B40: Tekanan awal | C40: 922 | D40: hPa | E40: =C40*H40 -> 691.55901 | F40: mmHg | G40: 1 hPa | H40: 0.750064 | I40: mmHg
...

Sheet 0,02
A1: E2 2024 | E1: F1 (B4T 2024) | I1: M1 | M1: E2 METTLER TOLEDO 2025 | Q1: TABEL MPE OIML R111-1
A2: Nominal (g) | B2: Massa konvensional (g) | C2: U95 (mg) | E2: Nominal (g) | F2: Massa konvensional (g) | G2: U95 (mg) | I2: Identitas | J2: Massa konvensional (g) | K2: U95 (mg) | M2: Nominal (g) | N2: Massa konvensional (g) | O2: U95 (mg) | Q2: Nominal Value | R2: Class E1 | S2: Class E2 | T2: Class F1 | U2: Class F2 | V2: Class M1 | W2: Class M2 | X2: Class M3
A3: 2000 | B3: 1999.9985 | C3: 0.32 | E3: 20000 | F3: 20000.022 | G3: 13 | I3: M1 | J3: 19999.414 | K3: 45 | M3: 0.001 | N3: 0.001003 | O3: 0.002 | Q3: 50 kg | R3: 25 | S3: 75 | T3: 250 | U3: 750 | V3: 2500 | W3: 7500 | X3: 25000
A4: 1000 | B4: 1000.0005 | C4: 0.14 | E4: 10000 | F4: 10000.041 | G4: 4.6 | I4: M2 | J4: 19999.234 | K4: 45 | M4: 0.002 | N4: 0.002003 | O4: 0.002 | Q4: 20 kg | R4: 10 | S4: 30 | T4: 100 | U4: 300 | V4: 1000 | W4: 3000 | X4: 10000
A5: 500 | B5: 500.00001 | C5: 0.08 | E5: 5000 | F5: 5000.005 | G5: 8 | I5: M3 | J5: 19999.627 | K5: 45 | M5: 0,002t | N5: 0.002001 | O5: 0.002 | Q5: 10 kg | R5: 5 | S5: 15 | T5: 50 | U5: 150 | V5: 500 | W5: 1500 | X5: 5000
A6: 200 | B6: 200.00001 | C6: 0.04 | E6: 2000* | F6: 1999.999 | G6: 3 | I6: M4 | J6: 20000.346 | K6: 45 | M6: 0.005 | N6: 0.005004 | O6: 0.002 | Q6: 5 kg | R6: 2.5 | S6: 7.5 | T6: 25 | U6: 75 | V6: 250 | W6: 750 | X6: 2500
A7: 200* | B7: 200.00005 | C7: 0.04 | E7: 2000 | F7: 1999.996 | G7: 3 | I7: M5 | J7: 20000.124 | K7: 45 | M7: 0.01 | N7: 0.010002 | O7: 0.003 | Q7: 2 kg | R7: 1 | S7: 3 | T7: 10 | U7: 30 | V7: 100 | W7: 300 | X7: 1000
A8: 100 | B8: 100.00008 | C8: 0.03 | E8: 1000 | F8: 1000.001 | G8: 1.7 | I8: M6 | J8: 20000.154 | K8: 45 | M8: 0.02 | N8: 0.020003 | O8: 0.003 | Q8: 1 kg | R8: 0.5 | S8: 1.5 | T8: 5 | U8: 15 | V8: 50 | W8: 150 | X8: 500
A9: 50 | B9: 50.00002 | C9: 0.02 | E9: 500 | F9: 500 | G9: 1.1 | I9: M7 | J9: 19999.125 | K9: 45 | M9: 0,02t | N9: 0.020005 | O9: 0.003 | Q9: 500 g | R9: 0.25 | S9: 0.75 | T9: 2.5 | U9: 7.5 | V9: 25 | W9: 75 | X9: 250
A10: 20 | B10: 19.999978 | C10: 0.009 | E10: 200 | F10: 199.99953 | G10: 0.3 | I10: M8 | J10: 19999.806 | K10: 45 | M10: 0.05 | N10: 0.050005 | O10: 0.003 | Q10: 200 g | R10: 0.01 | S10: 0.3 | T10: 1 | U10: 3 | V10: 10 | W10: 30 | X10: 100
A11: 20* | B11: 19.999977 | C11: 0.009 | E11: 200* | F11: 199.99873 | G11: 0.3 | I11: M9 | J11: 20000.237 | K11: 45 | M11: 0.1 | N11: 0.100008 | O11: 0.003 | Q11: 100 g | R11: 0.05 | S11: 0.15 | T11: 0.5 | U11: 1.5 | V11: 5 | W11: 15 | X11: 50
A12: 10 | B12: 9.999976 | C12: 0.008 | E12: 100 | F12: 99.99961 | G12: 0.16 | I12: M10 | J12: 19999.832 | K12: 45 | M12: 0.2 | N12: 0.200009 | O12: 0.005 | Q12: 50 g | R12: 0.03 | S12: 0.1 | T12: 0.3 | U12: 1 | V12: 3 | W12: 10 | X12: 30
A13: 5 | B13: 5.000006 | C13: 0.007 | E13: 50 | F13: 49.99956 | G13: 0.1 | I13: M11 | J13: 19999.934 | K13: 45 | M13: 0,2t | N13: 0.200002 | O13: 0.005 | Q13: 20 g | R13: 0.025 | S13: 0.08 | T13: 0.25 | U13: 0.8 | V13: 2.5 | W13: 8 | X13: 25
A14: 2 | B14: 2.000013 | C14: 0.005 | E14: 20 | F14: 20.00001 | G14: 0.08 | I14: M12 | J14: 19999.845 | K14: 45 | M14: 0.5 | N14: 0.500006 | O14: 0.006 | Q14: 10 g | R14: 0.02 | S14: 0.06 | T14: 0.2 | U14: 0.6 | V14: 2 | W14: 6 | X14: 20
A15: 2* | B15: 2.000015 | C15: 0.005 | E15: 20* | F15: 20.00004 | G15: 0.08 | I15: M13 | J15: 20000.802 | K15: 45 | M15: 1 | N15: 1.000016 | O15: 0.007 | Q15: 5 g | R15: 0.015 | S15: 0.05 | T15: 0.15 | U15: 0.5 | V15: 1.5 | W15: 5 | X15: 15
A16: 1 | B16: 0.999997 | C16: 0.005 | E16: 10 | F16: 10.00001 | G16: 0.06 | I16: M14 | J16: 19999.575 | K16: 45 | M16: 2 | N16: 1.999992 | O16: 0.009 | Q16: 2 g | R16: 0.012 | S16: 0.04 | T16: 0.12 | U16: 0.4 | V16: 1.2 | W16: 4 | X16: 12
A17: 0.5 | B17: 0.500018 | C17: 0.004 | E17: 5 | F17: 4.99994 | G17: 0.05 | I17: M15 | J17: 20000.329 | K17: 45 | M17: 2t | N17: 1.999991 | O17: 0.009 | Q17: 1 g | R17: 0.01 | S17: 0.03 | T17: 0.1 | U17: 0.3 | V17: 1 | W17: 3 | X17: 10
A18: 0.2 | B18: 0.200013 | C18: 0.003 | E18: 2 | F18: 2 | G18: 0.04 | I18: M16 | J18: 20000.932 | K18: 45 | M18: 5 | N18: 0.500006 | O18: 0.011 | Q18: 500 mg | R18: 0.008 | S18: 0.025 | T18: 0.08 | U18: 0.25 | V18: 0.8 | W18: 2.5 | X18: -
A19: 0.2* | B19: 0.200015 | C19: 0.003 | E19: 2* | F19: 1.99998 | G19: 0.04 | I19: 20LZ1 | J19: 20001.683 | K19: 45 | M19: 10 | N19: 10.000033 | O19: 0.014 | Q19: 200 mg | R19: 0.006 | S19: 0.02 | T19: 0.06 | U19: 0.2 | V19: 0.6 | W19: 2 | X19: -
A20: 0.1 | B20: 0.100003 | C20: 0.002 | E20: 1 | F20: 1 | G20: 0.03 | I20: 10LZ1 | J20: 10001.617 | K20: 26 | M20: 20 | N20: 20.000035 | O20: 0.018 | Q20: 100 mg | R20: 0.005 | S20: 0.015 | T20: 0.05 | U20: 0.15 | V20: 0.5 | W20: 1.5 | X20: -
I21: 5A | J21: 4998.996 | K21: 5.7 | M21: 20t | N21: 20.000038 | O21: 0.018 | Q21: 50 mg | R21: 0.004 | S21: 0.012 | T21: 0.04 | U21: 0.12 | V21: 0.4 | W21: - | X21: -
I22: 10A | J22: 9999.566 | K22: 26 | M22: 50 | N22: 50.00002 | O22: 0.03 | Q22: 20 mg | R22: 0.003 | S22: 0.01 | T22: 0.03 | U22: 0.1 | V22: 0.3 | W22: - | X22: -
B23: ISI DATA | I23: A | J23: 19999.312 | K23: 45 | M23: 100 | N23: 100.00029 | O23: 0.05 | Q23: 10 mg | R23: 0.002 | S23: 0.008 | T23: 0.025 | U23: 0.08 | V23: 0.25 | W23: - | X23: -
B24: Deskripsi | C24: Isi | D24: Satuan | I24: B | J24: 19999.19 | K24: 45 | M24: 200 | N24: 200.00025 | O24: 0.08 | Q24: 5 mg | R24: 0.002 | S24: 0.006 | T24: 0.02 | U24: 0.06 | V24: 0.2 | W24: - | X24: -
B25: No Order | C25: K519-1 | I25: C | J25: 19999.069 | K25: 45 | M25: 200t | N25: 200.00025 | O25: 0.08 | Q25: 2 mg | R25: 0.002 | S25: 0.006 | T25: 0.02 | U25: 0.06 | V25: 0.2 | W25: - | X25: -
B26: Pemilik Alat | C26: PT. XXXXXX | I26: D | J26: 19999.282 | K26: 45 | M26: 500 | N26: 500.00075 | O26: 0.16 | Q26: 1 mg | R26: 0.002 | S26: 0.006 | T26: 0.02 | U26: 0.06 | V26: 0.2 | W26: - | X26: -
B27: Alamat Pemilik Alat | C27: Jalan, Desa, Kecamatan, Kabupaten, Provinsi | I27: E | J27: 19999.268 | K27: 45 | M27: 1000 | N27: 1000.0009 | O27: 0.16
B28: Lokasi Alat | C28: Lab massa BBLM | I28: F | J28: 19999.33 | K28: 45
B29: Nama Alat | C29: Anak timbangan | I29: G | J29: 19999.21 | K29: 45
B30: Merk | C30: - | I30: H | J30: 20000.486 | K30: 45
B31: Tipe | C31: F1 | I31: I | J31: 19999.254 | K31: 45
B32: No Seri | C32: 124918
B33: No. Identifikasi | C33: -
B34: Temperatur Awal | C34: 20.1 | D34: °C
B35: Temperatur Akhir | C35: 20.1 | D35: °C
B36: Temperatur rata2 | C36: =AVERAGE(C34,C35) -> 20.1 | D36: °C
B37: Kelembaban Awal | C37: 60 | D37: %RH
B38: Kelembaban Akhir | C38: 60 | D38: %RH
B39: Kelembapan rata2 | C39: =AVERAGE(C37,C38) -> 60 | D39: %RH
B40: Tekanan awal | C40: 922 | D40: hPa | E40: =C40*H40 -> 691.55901 | F40: mmHg | G40: 1 hPa | H40: 0.750064 | I40: mmHg
...

Sheet 0,02t
A1: E2 2024 | E1: F1 (B4T 2024) | I1: M1 | M1: E2 METTLER TOLEDO 2025 | Q1: TABEL MPE OIML R111-1
A2: Nominal (g) | B2: Massa konvensional (g) | C2: U95 (mg) | E2: Nominal (g) | F2: Massa konvensional (g) | G2: U95 (mg) | I2: Identitas | J2: Massa konvensional (g) | K2: U95 (mg) | M2: Nominal (g) | N2: Massa konvensional (g) | O2: U95 (mg) | Q2: Nominal Value | R2: Class E1 | S2: Class E2 | T2: Class F1 | U2: Class F2 | V2: Class M1 | W2: Class M2 | X2: Class M3
A3: 2000 | B3: 1999.9985 | C3: 0.32 | E3: 20000 | F3: 20000.022 | G3: 13 | I3: M1 | J3: 19999.414 | K3: 45 | M3: 0.001 | N3: 0.001003 | O3: 0.002 | Q3: 50 kg | R3: 25 | S3: 75 | T3: 250 | U3: 750 | V3: 2500 | W3: 7500 | X3: 25000
A4: 1000 | B4: 1000.0005 | C4: 0.14 | E4: 10000 | F4: 10000.041 | G4: 4.6 | I4: M2 | J4: 19999.234 | K4: 45 | M4: 0.002 | N4: 0.002003 | O4: 0.002 | Q4: 20 kg | R4: 10 | S4: 30 | T4: 100 | U4: 300 | V4: 1000 | W4: 3000 | X4: 10000
A5: 500 | B5: 500.00001 | C5: 0.08 | E5: 5000 | F5: 5000.005 | G5: 8 | I5: M3 | J5: 19999.627 | K5: 45 | M5: 0,002t | N5: 0.002001 | O5: 0.002 | Q5: 10 kg | R5: 5 | S5: 15 | T5: 50 | U5: 150 | V5: 500 | W5: 1500 | X5: 5000
A6: 200 | B6: 200.00001 | C6: 0.04 | E6: 2000* | F6: 1999.999 | G6: 3 | I6: M4 | J6: 20000.346 | K6: 45 | M6: 0.005 | N6: 0.005004 | O6: 0.002 | Q6: 5 kg | R6: 2.5 | S6: 7.5 | T6: 25 | U6: 75 | V6: 250 | W6: 750 | X6: 2500
A7: 200* | B7: 200.00005 | C7: 0.04 | E7: 2000 | F7: 1999.996 | G7: 3 | I7: M5 | J7: 20000.124 | K7: 45 | M7: 0.01 | N7: 0.010002 | O7: 0.003 | Q7: 2 kg | R7: 1 | S7: 3 | T7: 10 | U7: 30 | V7: 100 | W7: 300 | X7: 1000
A8: 100 | B8: 100.00008 | C8: 0.03 | E8: 1000 | F8: 1000.001 | G8: 1.7 | I8: M6 | J8: 20000.154 | K8: 45 | M8: 0.02 | N8: 0.020003 | O8: 0.003 | Q8: 1 kg | R8: 0.5 | S8: 1.5 | T8: 5 | U8: 15 | V8: 50 | W8: 150 | X8: 500
A9: 50 | B9: 50.00002 | C9: 0.02 | E9: 500 | F9: 500 | G9: 1.1 | I9: M7 | J9: 19999.125 | K9: 45 | M9: 0,02t | N9: 0.020005 | O9: 0.003 | Q9: 500 g | R9: 0.25 | S9: 0.75 | T9: 2.5 | U9: 7.5 | V9: 25 | W9: 75 | X9: 250
A10: 20 | B10: 19.999978 | C10: 0.009 | E10: 200 | F10: 199.99953 | G10: 0.3 | I10: M8 | J10: 19999.806 | K10: 45 | M10: 0.05 | N10: 0.050005 | O10: 0.003 | Q10: 200 g | R10: 0.01 | S10: 0.3 | T10: 1 | U10: 3 | V10: 10 | W10: 30 | X10: 100
A11: 20* | B11: 19.999977 | C11: 0.009 | E11: 200* | F11: 199.99873 | G11: 0.3 | I11: M9 | J11: 20000.237 | K11: 45 | M11: 0.1 | N11: 0.100008 | O11: 0.003 | Q11: 100 g | R11: 0.05 | S11: 0.15 | T11: 0.5 | U11: 1.5 | V11: 5 | W11: 15 | X11: 50
A12: 10 | B12: 9.999976 | C12: 0.008 | E12: 100 | F12: 99.99961 | G12: 0.16 | I12: M10 | J12: 19999.832 | K12: 45 | M12: 0.2 | N12: 0.200009 | O12: 0.005 | Q12: 50 g | R12: 0.03 | S12: 0.1 | T12: 0.3 | U12: 1 | V12: 3 | W12: 10 | X12: 30
A13: 5 | B13: 5.000006 | C13: 0.007 | E13: 50 | F13: 49.99956 | G13: 0.1 | I13: M11 | J13: 19999.934 | K13: 45 | M13: 0,2t | N13: 0.200002 | O13: 0.005 | Q13: 20 g | R13: 0.025 | S13: 0.08 | T13: 0.25 | U13: 0.8 | V13: 2.5 | W13: 8 | X13: 25
A14: 2 | B14: 2.000013 | C14: 0.005 | E14: 20 | F14: 20.00001 | G14: 0.08 | I14: M12 | J14: 19999.845 | K14: 45 | M14: 0.5 | N14: 0.500006 | O14: 0.006 | Q14: 10 g | R14: 0.02 | S14: 0.06 | T14: 0.2 | U14: 0.6 | V14: 2 | W14: 6 | X14: 20
A15: 2* | B15: 2.000015 | C15: 0.005 | E15: 20* | F15: 20.00004 | G15: 0.08 | I15: M13 | J15: 20000.802 | K15: 45 | M15: 1 | N15: 1.000016 | O15: 0.007 | Q15: 5 g | R15: 0.015 | S15: 0.05 | T15: 0.15 | U15: 0.5 | V15: 1.5 | W15: 5 | X15: 15
A16: 1 | B16: 0.999997 | C16: 0.005 | E16: 10 | F16: 10.00001 | G16: 0.06 | I16: M14 | J16: 19999.575 | K16: 45 | M16: 2 | N16: 1.999992 | O16: 0.009 | Q16: 2 g | R16: 0.012 | S16: 0.04 | T16: 0.12 | U16: 0.4 | V16: 1.2 | W16: 4 | X16: 12
A17: 0.5 | B17: 0.500018 | C17: 0.004 | E17: 5 | F17: 4.99994 | G17: 0.05 | I17: M15 | J17: 20000.329 | K17: 45 | M17: 2t | N17: 1.999991 | O17: 0.009 | Q17: 1 g | R17: 0.01 | S17: 0.03 | T17: 0.1 | U17: 0.3 | V17: 1 | W17: 3 | X17: 10
A18: 0.2 | B18: 0.200013 | C18: 0.003 | E18: 2 | F18: 2 | G18: 0.04 | I18: M16 | J18: 20000.932 | K18: 45 | M18: 5 | N18: 0.500006 | O18: 0.011 | Q18: 500 mg | R18: 0.008 | S18: 0.025 | T18: 0.08 | U18: 0.25 | V18: 0.8 | W18: 2.5 | X18: -
A19: 0.2* | B19: 0.200015 | C19: 0.003 | E19: 2* | F19: 1.99998 | G19: 0.04 | I19: 20LZ1 | J19: 20001.683 | K19: 45 | M19: 10 | N19: 10.000033 | O19: 0.014 | Q19: 200 mg | R19: 0.006 | S19: 0.02 | T19: 0.06 | U19: 0.2 | V19: 0.6 | W19: 2 | X19: -
A20: 0.1 | B20: 0.100003 | C20: 0.002 | E20: 1 | F20: 1 | G20: 0.03 | I20: 10LZ1 | J20: 10001.617 | K20: 26 | M20: 20 | N20: 20.000035 | O20: 0.018 | Q20: 100 mg | R20: 0.005 | S20: 0.015 | T20: 0.05 | U20: 0.15 | V20: 0.5 | W20: 1.5 | X20: -
I21: 5A | J21: 4998.996 | K21: 5.7 | M21: 20t | N21: 20.000038 | O21: 0.018 | Q21: 50 mg | R21: 0.004 | S21: 0.012 | T21: 0.04 | U21: 0.12 | V21: 0.4 | W21: - | X21: -
I22: 10A | J22: 9999.566 | K22: 26 | M22: 50 | N22: 50.00002 | O22: 0.03 | Q22: 20 mg | R22: 0.003 | S22: 0.01 | T22: 0.03 | U22: 0.1 | V22: 0.3 | W22: - | X22: -
B23: ISI DATA | I23: A | J23: 19999.312 | K23: 45 | M23: 100 | N23: 100.00029 | O23: 0.05 | Q23: 10 mg | R23: 0.002 | S23: 0.008 | T23: 0.025 | U23: 0.08 | V23: 0.25 | W23: - | X23: -
B24: Deskripsi | C24: Isi | D24: Satuan | I24: B | J24: 19999.19 | K24: 45 | M24: 200 | N24: 200.00025 | O24: 0.08 | Q24: 5 mg | R24: 0.002 | S24: 0.006 | T24: 0.02 | U24: 0.06 | V24: 0.2 | W24: - | X24: -
B25: No Order | C25: K519-1 | I25: C | J25: 19999.069 | K25: 45 | M25: 200t | N25: 200.00025 | O25: 0.08 | Q25: 2 mg | R25: 0.002 | S25: 0.006 | T25: 0.02 | U25: 0.06 | V25: 0.2 | W25: - | X25: -
B26: Pemilik Alat | C26: PT. XXXXXX | I26: D | J26: 19999.282 | K26: 45 | M26: 500 | N26: 500.00075 | O26: 0.16 | Q26: 1 mg | R26: 0.002 | S26: 0.006 | T26: 0.02 | U26: 0.06 | V26: 0.2 | W26: - | X26: -
B27: Alamat Pemilik Alat | C27: Jalan, Desa, Kecamatan, Kabupaten, Provinsi | I27: E | J27: 19999.268 | K27: 45 | M27: 1000 | N27: 1000.0009 | O27: 0.16
B28: Lokasi Alat | C28: Lab massa BBLM | I28: F | J28: 19999.33 | K28: 45
B29: Nama Alat | C29: Anak timbangan | I29: G | J29: 19999.21 | K29: 45
B30: Merk | C30: - | I30: H | J30: 20000.486 | K30: 45
B31: Tipe | C31: F1 | I31: I | J31: 19999.254 | K31: 45
B32: No Seri | C32: 124918
B33: No. Identifikasi | C33: -
B34: Temperatur Awal | C34: 20.1 | D34: °C
B35: Temperatur Akhir | C35: 20.1 | D35: °C
B36: Temperatur rata2 | C36: =AVERAGE(C34,C35) -> 20.1 | D36: °C
B37: Kelembaban Awal | C37: 60 | D37: %RH
B38: Kelembaban Akhir | C38: 60 | D38: %RH
B39: Kelembapan rata2 | C39: =AVERAGE(C37,C38) -> 60 | D39: %RH
B40: Tekanan awal | C40: 922 | D40: hPa | E40: =C40*H40 -> 691.55901 | F40: mmHg | G40: 1 hPa | H40: 0.750064 | I40: mmHg
...

Sheet 0,05
A1: E2 2024 | E1: F1 (B4T 2024) | I1: M1 | M1: E2 METTLER TOLEDO 2025 | Q1: TABEL MPE OIML R111-1
A2: Nominal (g) | B2: Massa konvensional (g) | C2: U95 (mg) | E2: Nominal (g) | F2: Massa konvensional (g) | G2: U95 (mg) | I2: Identitas | J2: Massa konvensional (g) | K2: U95 (mg) | M2: Nominal (g) | N2: Massa konvensional (g) | O2: U95 (mg) | Q2: Nominal Value | R2: Class E1 | S2: Class E2 | T2: Class F1 | U2: Class F2 | V2: Class M1 | W2: Class M2 | X2: Class M3
A3: 2000 | B3: 1999.9985 | C3: 0.32 | E3: 20000 | F3: 20000.022 | G3: 13 | I3: M1 | J3: 19999.414 | K3: 45 | M3: 0.001 | N3: 0.001003 | O3: 0.002 | Q3: 50 kg | R3: 25 | S3: 75 | T3: 250 | U3: 750 | V3: 2500 | W3: 7500 | X3: 25000
A4: 1000 | B4: 1000.0005 | C4: 0.14 | E4: 10000 | F4: 10000.041 | G4: 4.6 | I4: M2 | J4: 19999.234 | K4: 45 | M4: 0.002 | N4: 0.002003 | O4: 0.002 | Q4: 20 kg | R4: 10 | S4: 30 | T4: 100 | U4: 300 | V4: 1000 | W4: 3000 | X4: 10000
A5: 500 | B5: 500.00001 | C5: 0.08 | E5: 5000 | F5: 5000.005 | G5: 8 | I5: M3 | J5: 19999.627 | K5: 45 | M5: 0,002t | N5: 0.002001 | O5: 0.002 | Q5: 10 kg | R5: 5 | S5: 15 | T5: 50 | U5: 150 | V5: 500 | W5: 1500 | X5: 5000
A6: 200 | B6: 200.00001 | C6: 0.04 | E6: 2000* | F6: 1999.999 | G6: 3 | I6: M4 | J6: 20000.346 | K6: 45 | M6: 0.005 | N6: 0.005004 | O6: 0.002 | Q6: 5 kg | R6: 2.5 | S6: 7.5 | T6: 25 | U6: 75 | V6: 250 | W6: 750 | X6: 2500
A7: 200* | B7: 200.00005 | C7: 0.04 | E7: 2000 | F7: 1999.996 | G7: 3 | I7: M5 | J7: 20000.124 | K7: 45 | M7: 0.01 | N7: 0.010002 | O7: 0.003 | Q7: 2 kg | R7: 1 | S7: 3 | T7: 10 | U7: 30 | V7: 100 | W7: 300 | X7: 1000
A8: 100 | B8: 100.00008 | C8: 0.03 | E8: 1000 | F8: 1000.001 | G8: 1.7 | I8: M6 | J8: 20000.154 | K8: 45 | M8: 0.02 | N8: 0.020003 | O8: 0.003 | Q8: 1 kg | R8: 0.5 | S8: 1.5 | T8: 5 | U8: 15 | V8: 50 | W8: 150 | X8: 500
A9: 50 | B9: 50.00002 | C9: 0.02 | E9: 500 | F9: 500 | G9: 1.1 | I9: M7 | J9: 19999.125 | K9: 45 | M9: 0,02t | N9: 0.020005 | O9: 0.003 | Q9: 500 g | R9: 0.25 | S9: 0.75 | T9: 2.5 | U9: 7.5 | V9: 25 | W9: 75 | X9: 250
A10: 20 | B10: 19.999978 | C10: 0.009 | E10: 200 | F10: 199.99953 | G10: 0.3 | I10: M8 | J10: 19999.806 | K10: 45 | M10: 0.05 | N10: 0.050005 | O10: 0.003 | Q10: 200 g | R10: 0.01 | S10: 0.3 | T10: 1 | U10: 3 | V10: 10 | W10: 30 | X10: 100
A11: 20* | B11: 19.999977 | C11: 0.009 | E11: 200* | F11: 199.99873 | G11: 0.3 | I11: M9 | J11: 20000.237 | K11: 45 | M11: 0.1 | N11: 0.100008 | O11: 0.003 | Q11: 100 g | R11: 0.05 | S11: 0.15 | T11: 0.5 | U11: 1.5 | V11: 5 | W11: 15 | X11: 50
