Workbook

Sheet MPE
A1: Nominal Value | B1: Class E1 | C1: Class E2 | D1: Class F1 | E1: Class F2 | F1: Class M1 | G1: Class M2 | H1: Class M3
A2: 50 kg | B2: 25 | C2: 75 | D2: 250 | E2: 750 | F2: 2500 | G2: 7500 | H2: 25000
A3: 20 kg | B3: 10 | C3: 30 | D3: 100 | E3: 300 | F3: 1000 | G3: 3000 | H3: 10000
A4: 10 kg | B4: 5 | C4: 15 | D4: 50 | E4: 150 | F4: 500 | G4: 1500 | H4: 5000
A5: 5 kg | B5: 2.5 | C5: 7.5 | D5: 25 | E5: 75 | F5: 250 | G5: 750 | H5: 2500
A6: 2 kg | B6: 1 | C6: 3 | D6: 10 | E6: 30 | F6: 100 | G6: 300 | H6: 1000
A7: 1 kg | B7: 0.5 | C7: 1.5 | D7: 5 | E7: 15 | F7: 50 | G7: 150 | H7: 500
A8: 500 g | B8: 0.25 | C8: 0.75 | D8: 2.5 | E8: 7.5 | F8: 25 | G8: 75 | H8: 250
A9: 200 g | B9: 0.01 | C9: 0.3 | D9: 1 | E9: 3 | F9: 10 | G9: 30 | H9: 100
A10: 100 g | B10: 0.05 | C10: 0.15 | D10: 0.5 | E10: 1.5 | F10: 5 | G10: 15 | H10: 50
A11: 50 g | B11: 0.03 | C11: 0.1 | D11: 0.3 | E11: 1 | F11: 3 | G11: 10 | H11: 30
A12: 20 g | B12: 0.025 | C12: 0.08 | D12: 0.25 | E12: 0.8 | F12: 2.5 | G12: 8 | H12: 25
A13: 10 g | B13: 0.02 | C13: 0.06 | D13: 0.2 | E13: 0.6 | F13: 2 | G13: 6 | H13: 20
... A16: 1 g | B16: 0.01 | C16: 0.03 | D16: 0.1 | E16: 0.3 | F16: 1 | G16: 3 | H16: 10
A17: 500 mg | B17: 0.008 | C17: 0.025 | D17: 0.08 | E17: 0.25 | F17: 0.8 | G17: 2.5 | H17: -
A18: 200 mg | B18: 0.006 | C18: 0.02 | D18: 0.06 | E18: 0.2 | F18: 0.6 | G18: 2 | H18: -
A19: 100 mg | B19: 0.005 | C19: 0.015 | D19: 0.05 | E19: 0.15 | F19: 0.5 | G19: 1.5 | H19: -
A20: 50 mg | B20: 0.004 | C20: 0.012 | D20: 0.04 | E20: 0.12 | F20: 0.4 | G20: - | H20: -
A21: 20 mg | B21: 0.003 | C21: 0.01 | D21: 0.03 | E21: 0.1 | F21: 0.3 | G21: - | H21: -
A22: 10 mg | B22: 0.002 | C22: 0.008 | D22: 0.025 | E22: 0.08 | F22: 0.25 | G22: - | H22: -
A23: 5 mg | B23: 0.002 | C23: 0.006 | D23: 0.02 | E23: 0.06 | F23: 0.2 | G23: - | H23: -
A24: 2 mg | B24: 0.002 | C24: 0.006 | D24: 0.02 | E24: 0.06 | F24: 0.2 | G24: - | H24: -
A25: 1 mg | B25: 0.002 | C25: 0.006 | D25: 0.02 | E25: 0.06 | F25: 0.2 | G25: - | H25: -

Sheet E2
C1: 44809
B2: Nominal (g) | C2: Konvensional (g) | D2: Ketidakpastian (mg)
B3: 5000 | C3: 4999.9987 | D3: 0.6
B4: 2000* | C4: 2000.032 | D4: 24
B5: 2000 | C5: 2000.032 | D5: 24
B6: 1000 | C6: 1000.0008 | D6: 0.099
B7: 500 | C7: 500.00008 | D7: 0.056
B8: 200 | C8: 199.99992 | D8: 0.025
B9: 200* | C9: 199.99998 | D9: 0.025
B10: 100 | C10: 99.999909 | D10: 0.022
B11: 50 | C11: 49.999976 | D11: 0.012
B12: 20 | C12: 19.999989 | D12: 0.009
B13: 20* | C13: 19.999989 | D13: 0.009
B14: 10 | C14: 9.999966 | D14: 0.0083
B15: 5 | C15: 5.0000099 | D15: 0.0051
B16: 2 | C16: 2.0000124 | D16: 0.0039
B17: 2* | C17: 1.9999897 | D17: 0.0039
B18: 1 | C18: 0.9999856 | D18: 0.0035
B19: 0.5 | C19: 0.500018 | D19: 0.003
B20: 0.2 | C20: 0.20001 | D20: 0.003
B21: 0,2* | C21: 0.200014 | D21: 0.003
B22: 0.1 | C22: 0.100005 | D22: 0.002
B23: 0.05 | C23: 0.050004 | D23: 0.002
B24: 0.02 | C24: 0.020005 | D24: 0.002
B25: 0,02* | C25: 0.019996 | D25: 0.002
B26: 0.01 | C26: 0.009995 | D26: 0.002
B27: 0.005 | C27: 0.005004 | D27: 0.002
B28: 0.002 | C28: 0.001999 | D28: 0.002
B29: 0,002* | C29: 0.002005 | D29: 0.002
B30: 0.001 | C30: 0.001004 | D30: 0.002

Sheet FORM 
A1: Deskripsi | B1: Isi | C1: Satuan
A2: No Order
A3: Pemilik Alat | B3: Internal BBLM
A4: Alamat Pemilik Alat | B4: jjajsdfds jajsdjf jasdjfasdjf jadsfjadsj asdjfajdsf jasdjfajdsf asdfjasd asjdfasd j
A5: Lokasi Alat
A6: Nama Alat | B6: Anak Timbangan
A7: Merk | B7: -
A8: Tipe | B8: F1
A9: No Seri | B9: YCS-01-653-00
A10: Kapasitas | B10: 0,001-5000 g
A11: No. Identifikasi | B11: -
A12: Tanggal Terima | B12: 29 Desember 2025 | D12: Tanggal ditulis dengan format text
A13: Tanggal Kalibrasi | B13: 29 Desember 2025 | D13: Tanggal ditulis dengan format text
A14: Mass Comparator
A16: No. Seri Mass comp | B16: 90803270
A17: Kalibrator | B17: E2 METTLER TOLEDO
A18: Merk Kalibrator | B18: =VLOOKUP('FORM '!B17,Database!J1:L5,2,FALSE) -> Mettler Toledo
A19: No Seri Kalibrator | B19: =VLOOKUP(B17,Database!J1:L5,3,FALSE) -> 158856

Sheet 0,001
A1: E2 | E1: F1 | I1: M1 | M1: E2 METTLER TOLEDO | Q1: TABEL MPE OIML R111-1
A2: Nominal (g) | B2: Massa konvensional (g) | C2: U95 (mg) | E2: Nominal (g) | F2: Massa konvensional (g) | G2: U95 (mg) | I2: Identitas | J2: Massa konvensional (g) | K2: U95 (mg) | M2: Nominal (g) | N2: Massa konvensional (g) | O2: U95 (mg) | Q2: Nominal Value (g) | R2: Class E1 | S2: Class E2 | T2: Class F1 | U2: Class F2 | V2: Class M1 | W2: Class M2 | X2: Class M3
A3: 2000 | B3: 1999.9985 | C3: 0.32 | E3: 20000 | F3: 20000.022 | G3: 13 | I3: M1 | J3: 19999.414 | K3: 45 | M3: 5000 | N3: 4999.9986 | O3: 0.72 | Q3: 50000 g | R3: 25 | S3: 75 | T3: 250 | U3: 750 | V3: 2500 | W3: 7500 | X3: 25000
A4: 1000 | B4: 1000.0005 | C4: 0.14 | E4: 10000 | F4: 10000.041 | G4: 4.6 | I4: M2 | J4: 19999.234 | K4: 45 | M4: 1000 | N4: 1000.0005 | O4: 0.00031 | Q4: 20000 g | R4: 10 | S4: 30 | T4: 100 | U4: 300 | V4: 1000 | W4: 3000 | X4: 10000
A5: 500 | B5: 500.00001 | C5: 0.08 | E5: 5000 | F5: 5000.0163 | G5: 2.6 | I5: M3 | J5: 19999.627 | K5: 45 | M5: 500 | N5: 500.0006 | O5: 0.00016 | Q5: 10000 g | R5: 5 | S5: 15 | T5: 50 | U5: 150 | V5: 500 | W5: 1500 | X5: 5000
A6: 200 | B6: 200.00001 | C6: 0.04 | E6: 2000t | F6: 2000.0015 | G6: 1.4 | I6: M4 | J6: 20000.346 | K6: 45 | M6: 200 | N6: 200.0002 | O6: 6e-05 | Q6: 5000 g | R6: 2.5 | S6: 7.5 | T6: 25 | U6: 75 | V6: 250 | W6: 750 | X6: 2500
A7: 200t | B7: 200.00005 | C7: 0.04 | E7: 2000 | F7: 1999.9994 | G7: 1.4 | I7: M5 | J7: 20000.124 | K7: 45 | M7: 200t | N7: 200.0002 | O7: 7.2e-05 | Q7: 2000 g | R7: 1 | S7: 3 | T7: 10 | U7: 30 | V7: 100 | W7: 300 | X7: 1000
A8: 100 | B8: 100.00008 | C8: 0.03 | E8: 1000 | F8: 1000.001 | G8: 1.1 | I8: M6 | J8: 20000.154 | K8: 45 | M8: 100 | N8: 100.00001 | O8: 3.6e-05 | Q8: 1000 g | R8: 0.5 | S8: 1.5 | T8: 5 | U8: 15 | V8: 50 | W8: 150 | X8: 500
A9: 50 | B9: 50.00002 | C9: 0.02 | E9: 500 | F9: 499.99861 | G9: 1 | I9: M7 | J9: 19999.125 | K9: 45 | M9: 50 | N9: 50.00002 | O9: 2.1e-05 | Q9: 500 g | R9: 0.25 | S9: 0.75 | T9: 2.5 | U9: 7.5 | V9: 25 | W9: 75 | X9: 250
A10: 20 | B10: 19.999978 | C10: 0.009 | E10: 200 | F10: 199.99968 | G10: 0.11 | I10: M8 | J10: 19999.806 | K10: 45 | M10: 20 | N10: 20.00003 | O10: 1.6e-05 | Q10: 200 g | R10: 0.01 | S10: 0.3 | T10: 1 | U10: 3 | V10: 10 | W10: 30 | X10: 100
A11: 20t | B11: 19.999977 | C11: 0.009 | E11: 200t | F11: 199.99882 | G11: 0.11 | I11: M9 | J11: 20000.237 | K11: 45 | M11: 20t | N11: 20.00001 | O11: 1.6e-05 | Q11: 100 g | R11: 0.05 | S11: 0.15 | T11: 0.5 | U11: 1.5 | V11: 5 | W11: 15 | X11: 50
A12: 10 | B12: 9.999976 | C12: 0.008 | E12: 100 | F12: 99.999763 | G12: 0.067 | I12: M10 | J12: 19999.832 | K12: 45 | M12: 10 | N12: 10.000023 | O12: 1.4e-05 | Q12: 50 g | R12: 0.03 | S12: 0.1 | T12: 0.3 | U12: 1 | V12: 3 | W12: 10 | X12: 30
A13: 5 | B13: 5.000006 | C13: 0.007 | E13: 50 | F13: 49.999814 | G13: 0.042 | I13: M11 | J13: 19999.934 | K13: 45 | M13: 5 | N13: 5.000003 | O13: 8.9e-06 | Q13: 20 g | R13: 0.025 | S13: 0.08 | T13: 0.25 | U13: 0.8 | V13: 2.5 | W13: 8 | X13: 25
A14: 2 | B14: 2.000013 | C14: 0.005 | E14: 20 | F14: 20.000009 | G14: 0.036 | I14: M12 | J14: 19999.845 | K14: 45 | M14: 2 | N14: 2.000015 | O14: 7.1e-06 | Q14: 10 g | R14: 0.02 | S14: 0.06 | T14: 0.2 | U14: 0.6 | V14: 2 | W14: 6 | X14: 20
A15: 2t | B15: 2.000015 | C15: 0.005 | E15: 20t | F15: 20.000048 | G15: 0.036 | I15: M13 | J15: 20000.802 | K15: 45 | M15: 2t | N15: 2.000003 | O15: 7.1e-06 | Q15: 5 g | R15: 0.015 | S15: 0.05 | T15: 0.15 | U15: 0.5 | V15: 1.5 | W15: 5 | X15: 15
A16: 1 | B16: 0.999997 | C16: 0.005 | E16: 10 | F16: 10.000017 | G16: 0.032 | I16: M14 | J16: 19999.575 | K16: 45 | M16: 1 | N16: 1.000013 | O16: 6.8e-06 | Q16: 2 g | R16: 0.012 | S16: 0.04 | T16: 0.12 | U16: 0.4 | V16: 1.2 | W16: 4 | X16: 12
A17: 0.5 | B17: 0.500018 | C17: 0.004 | E17: 5 | F17: 4.99994 | G17: 0.05 | I17: M15 | J17: 20000.329 | K17: 45 | M17: 0.5 | N17: =500.011/1000 -> 0.500011 | O17: 0.0051 | Q17: 1 g | R17: 0.01 | S17: 0.03 | T17: 0.1 | U17: 0.3 | V17: 1 | W17: 3 | X17: 10
A18: 0.2 | B18: 0.200013 | C18: 0.003 | E18: 2 | F18: 2 | G18: 0.04 | I18: M16 | J18: 20000.932 | K18: 45 | M18: 0.2 | N18: =200.001/1000 -> 0.200001 | O18: 0.0031 | Q18: 0,5 g | R18: 0.008 | S18: 0.025 | T18: 0.08 | U18: 0.25 | V18: 0.8 | W18: 2.5 | X18: -
A19: 0,2t | B19: 0.200015 | C19: 0.003 | E19: 2t | F19: 1.99998 | G19: 0.04 | I19: 20LZ1 | J19: 20001.683 | K19: 45 | M19: 0,2t | N19: =199.999/1000 -> 0.199999 | O19: 0.0036 | Q19: 0,2 g | R19: 0.006 | S19: 0.02 | T19: 0.06 | U19: 0.2 | V19: 0.6 | W19: 2 | X19: -
A20: 0.1 | B20: 0.100003 | C20: 0.002 | E20: 1 | F20: 1 | G20: 0.03 | I20: 10LZ1 | J20: 10001.617 | K20: 26 | M20: 0.1 | N20: =100.009/1000 -> 0.100009 | O20: 0.0031 | Q20: 0,1 g | R20: 0.005 | S20: 0.015 | T20: 0.05 | U20: 0.15 | V20: 0.5 | W20: 1.5 | X20: -
I21: 5A | J21: 4998.996 | K21: 5.7 | M21: 0.05 | N21: =50.005/1000 -> 0.050005 | O21: 0.0024 | Q21: 0,05 g | R21: 0.004 | S21: 0.012 | T21: 0.04 | U21: 0.12 | V21: 0.4 | W21: - | X21: -
I22: 10A | J22: 9999.566 | K22: 26 | M22: 0.02 | N22: =20.003/1000 -> 0.020003 | O22: 0.0022 | Q22: 0,02 g | R22: 0.003 | S22: 0.01 | T22: 0.03 | U22: 0.1 | V22: 0.3 | W22: - | X22: -
I23: A | J23: 19999.312 | K23: 45 | M23: 0,02t | N23: =20.001/1000 -> 0.020001 | O23: 0.002 | Q23: 0,01 g | R23: 0.002 | S23: 0.008 | T23: 0.025 | U23: 0.08 | V23: 0.25 | W23: - | X23: -
I24: B | J24: 19999.19 | K24: 45 | M24: 0.01 | N24: =10.002/1000 -> 0.010002 | O24: 0.0016 | Q24: 0,005 g | R24: 0.002 | S24: 0.006 | T24: 0.02 | U24: 0.06 | V24: 0.2 | W24: - | X24: -
I25: C | J25: 19999.069 | K25: 45 | M25: 0.005 | N25: =5.002/1000 -> 0.005002 | O25: 0.0018 | Q25: 0,002 g | R25: 0.002 | S25: 0.006 | T25: 0.02 | U25: 0.06 | V25: 0.2 | W25: - | X25: -
I26: D | J26: 19999.282 | K26: 45 | M26: 0.002 | N26: =2.002/1000 -> 0.002002 | O26: 0.0014 | Q26: 0,001 g | R26: 0.002 | S26: 0.006 | T26: 0.02 | U26: 0.06 | V26: 0.2 | W26: - | X26: -
I27: E | J27: 19999.268 | K27: 45 | M27: 0,002t | N27: =2/1000 -> 0.002 | O27: 0.0014
I28: F | J28: 19999.33 | K28: 45 | M28: 0.001 | N28: =1.001/1000 -> 0.001001 | O28: 0.0014
I29: G | J29: 19999.21 | K29: 45
I30: H | J30: 20000.486 | K30: 45
I31: I | J31: 19999.254 | K31: 45
B36: ISI DATA
B37: Temperatur Awal | C37: 20.4 | D37: °C | E37: <----------- Warna kuning, isian manual
B38: Temperatur Akhir | C38: 20.9 | D38: °C
B39: Temperatur rata2 | C39: =AVERAGE(C37,C38) -> 20.65 | D39: °C
B40: Kelembaban Awal | C40: 64.3 | D40: %RH
B41: Kelembaban Akhir | C41: 62.8 | D41: %RH
B42: Kelembapan rata2 | C42: =AVERAGE(C40,C41) -> 63.55 | D42: %RH
B43: Tekanan awal | C43: 924 | D43: hPa | E43: =C43*H43 -> 693.05914 | F43: mmHg | G43: 1 hPa | H43: 0.750064 | I43: mmHg
B44: Tekanan akhir | C44: 923 | D44: hPa | E44: =C44*H44 -> 692.30907 | F44: mmHg | G44: 1 hPa | H44: 0.750064 | I44: mmHg
...

Sheet Koreksi themohygro rotronic 202
C2: Suhu (°C) | D2: %RH | F2: Thermohygro Rotronic data 2025
B3: Awal | C3: ='0,001'!C37 -> 20.4 | D3: ='0,001'!C40 -> 64.3 | F3: Koreksi suhu | I3: Koreksi RH
B4: Akhir | C4: ='0,001'!C38 -> 20.9 | D4: ='0,001'!C41 -> 62.8 | F4: T (°C) | G4: Koreksi | H4: U95 | I4: RH (%) | J4: Koreksi | K4: U95
B5: Rata2 | C5: =AVERAGE(C3:C4) -> 20.65 | D5: =AVERAGE(D3:D4) -> 63.55 | F5: 20 | G5: 0.1 | H5: 2 | I5: 40 | J5: 0.2 | K5: 2.5
B6: Terkoreksi | C6: =C5+FORECAST(C5,G5:G9,F5:F9) -> 20.684 | D6: =D5+FORECAST(D5,J5:J9,I5:I9) -> 63.2803 | F6: 25 | G6: -0.2 | H6: 2 | I6: 50 | J6: -0.3 | K6: 2.8
B7: U95 | C7: 2 | D7: =FORECAST(D6,K5:K9,I5:I9) -> 2.6003182 | F7: 30 | G7: -0.3 | H7: 2 | I7: 60 | J7: -0.3 | K7: 3.2
B8: Fluktuasi suhu | C8: =(MAX(C3:C4)-C5+C5-MIN(C3:C4))/2 -> 0.25 | D8: =(MAX(D3:D4)-D5+D5-MIN(D3:D4))/2 -> 0.75 | F8: 35 | G8: -0.6 | H8: 2 | I8: 70 | J8: -0.1 | K8: 2
B9: Flu+U95 | C9: =C7+C8 -> 2.25 | D9: =D7+D8 -> 3.3503182 | F9: 40 | G9: -0.7 | H9: 2 | I9: 80 | J9: -0.6 | K9: 2.6
B10: Kondisi Ruang | C10: =FIXED(C6,1)&" ± "&FIXED(C8,1) -> 20,7 ± 0,3 | D10: =FIXED(D6,1)&" ± "&FIXED(D8,1) -> 63,3 ± 0,8

Sheet Sertifikat
A7: S E R T I F I K A T K A L I B R A S I
A8: C A L I B R A T I O N C E R T I F I C A T E
A9: Nomor / Number :
B14: IDENTITAS ALAT
B15: INSTRUMENT DETAILS
B17: Nama Alat | D17: : | E17: Anak Timbangan
B18: Instrument Name
B19: Merek | D19: : | E19: =CONCATENATE(,'FORM '!B7) -> -
B20: Brand
B21: Tipe | D21: : | E21: =CONCATENATE('FORM '!B8) -> F1
B22: Type
B23: Nomor Identifikasi | D23: : | E23: =CONCATENATE('FORM '!B11) -> -
B24: Identification Number
B25: Nomor Seri | D25: : | E25: =CONCATENATE('FORM '!B9) -> YCS-01-653-00
B26: Serial Number
B27: Lain-lain | D27: : | E27: Kapasitas | F27: : | G27: =CONCATENATE('FORM '!B10) -> 0,001-5000 g
B28: Others | E28: Kecermatan | F28: : | G28: -
B30: IDENTITAS PEMILIK
B31: Owner’s Identification
B33: Nama | D33: : | E33: =CONCATENATE('FORM '!B3) -> Internal BBLM
B34: Designation
B35: Alamat | D35: : | E35: =CONCATENATE('FORM '!B4) -> jjajsdfds jajsdjf jasdjfasdjf jadsfjadsj asdjfajdsf jasdjfajdsf asdfjasd asjdfasd j
B36: Address
H40: Halaman 1 dari 3 halaman
H41: Page of page
H43: Diterbitkan Tanggal 29 Desember 2025
H44: Date of Issue
E45: Penguji Mutu Barang Ahli Madya,
E46: Elis Sofianti
E47: NIP. 197109301994032002
E62: Nomor | F62: =CONCATENATE(": ",MID(A9,18,33)) -> :
E63: No. Order | F63: =CONCATENATE(": ",'FORM '!B2) -> :
E64: Halaman | F64: : 2 dari 3
B66: SPESIFIKASI ALAT
B67: Nama | D67: =D17 -> :
B68: Merk / Tipe | D68: =CONCATENATE(":"," ",'FORM '!B7," ","/"," ",'FORM '!B8) -> : - / F1
B69: No. Identifikasi | D69: =D23 -> :
B70: No. Seri | D70: =D25 -> :
B71: Kapasitas | D71: =F27 -> :
B72: Kecermatan | D72: =F28 -> : | G72: Kondisi ruang
...

Sheet Database
A1: Titik Ukur | B1: Kalibrator | C1: Merek Timbangan | D1: No S/N Timbangan | E1: Resolusi timbangan | G1: Nominal | H1: CMC KAN | J1: Kalibrator | K1: Merek | L1: Nomor Seri | M1: Terkalibrasi
A2: 20000 | B2: E2 | C2: Sartorius MC 210 P (R1) | D2: 90803270 | E2: 1e-05 | G2: 20000 | H2: 45 | J2: E2 | K2: Kern Germany | L2: G982106
A3: 10000 | B3: F1 | C3: Sartorius LC 5101 S | D3: 90602105 | E3: 0.001 | G3: 10000 | H3: 26 | J3: F1 | K3: YCS | L3: YCS-01-653-00
A4: 5000 | B4: M1 | C4: AND MC-30 K | D4: 14904962 | E4: 0.01 | G4: 5000 | H4: 2.6 | J4: M1 | K4: - | L4: -
A5: 2000t | B5: E2 METTLER TOLEDO | C5: Sartorius MC 210 P (R1) | D5: 90803270 | E5: 5e-05 | G5: 2000 | H5: 1.4 | J5: E2 METTLER TOLEDO | K5: Mettler Toledo | L5: 158856
A6: 2000 | G6: 1000 | H6: 1.1
A7: 1000 | G7: 500 | H7: 1
A8: 500 | G8: 200 | H8: 0.11
A9: 200 | G9: 100 | H9: 0.067
A10: 200t | G10: 50 | H10: 0.042
A11: 100 | G11: 20 | H11: 0.036
A12: 50 | G12: 10 | H12: 0.032
A13: 20 | G13: 5 | H13: 0.029
A14: 20t | G14: 2 | H14: 0.028
A15: 10 | G15: 1 | H15: 0.027
A16: 5 | G16: 0.5 | H16: 0.027
A17: 2 | G17: 0.2 | H17: 0.026
A18: 2t | G18: 0.1 | H18: 0.026
A19: 1 | G19: 0.05 | H19: 0.026
A20: 0.5 | G20: 0.02 | H20: 0.026
A21: 0.2 | G21: 0.01 | H21: 0.026
A22: 0,2t | G22: 0.005 | H22: 0.026
A23: 0.1 | G23: 0.002 | H23: 0.026
A24: 0.05 | G24: 0.001 | H24: 0.026
A25: 0.02
A26: 0,02t
A27: 0.01
A28: 0.005
A29: 0.002
A30: 0,002t
A31: 0.001
