Workbook

Sheet E2
C1: 44809
B2: Nominal (g) | C2: Konvensional (g) | D2: Ketidakpastian (mg)
B3: 5000 | C3: 4999.9987 | D3: 0.6
B4: 2000* | C4: 2000.032 | D4: 24
B5: 2000 | C5: 2000.032 | D5: 24
B6: 1000 | C6: 1000.0008 | D6: 0.099
B7: 500 | C7: 500.00008 | D7: 0.056
B8: 200 | C8: 199.99992 | D8: 0.025
B9: 200* | C9: 199.99998 | D9: 0.025
B10: 100 | C10: 99.999909 | D10: 0.022
B11: 50 | C11: 49.999976 | D11: 0.012
B12: 20 | C12: 19.999989 | D12: 0.009
B13: 20* | C13: 19.999989 | D13: 0.009
B14: 10 | C14: 9.999966 | D14: 0.0083
B15: 5 | C15: 5.0000099 | D15: 0.0051
B16: 2 | C16: 2.0000124 | D16: 0.0039
B17: 2* | C17: 1.9999897 | D17: 0.0039
B18: 1 | C18: 0.9999856 | D18: 0.0035
B19: 0.5 | C19: 0.500018 | D19: 0.003
B20: 0.2 | C20: 0.20001 | D20: 0.003
B21: 0,2* | C21: 0.200014 | D21: 0.003
B22: 0.1 | C22: 0.100005 | D22: 0.002
B23: 0.05 | C23: 0.050004 | D23: 0.002
B24: 0.02 | C24: 0.020005 | D24: 0.002
B25: 0,02* | C25: 0.019996 | D25: 0.002
B26: 0.01 | C26: 0.009995 | D26: 0.002
B27: 0.005 | C27: 0.005004 | D27: 0.002
B28: 0.002 | C28: 0.001999 | D28: 0.002
B29: 0,002* | C29: 0.002005 | D29: 0.002
B30: 0.001 | C30: 0.001004 | D30: 0.002

Sheet Isi data
A1: Deskripsi | B1: Isi | C1: Satuan
A2: No Order | B2: K023_2026
A3: Pemilik Alat | B3: PT GATRA PERDANA TRUSTRUE
A4: Alamat Pemilik Alat | B4: Kawasan Komplek Ruko Golden BCI Blok T3 No. 12 Bengkong Laut, Kec. Bengkong, Kota Batam - Kepulauan Riau
A5: Lokasi Alat | B5: Lab.Massa BBSPJILM
A6: Nama Alat | B6: Beban
A7: Merk | B7: -
A8: Tipe | B8: TB-10 Weight LIFT Test Bar
A9: No Seri | B9: 25914
A10: Kapasitas | B10: 10 lb
A11: No. Identifikasi | B11: -
A12: Tanggal Terima | B12: 15 Januari 2026 | D12: Tanggal ditulis dengan format text
A13: Tanggal Kalibrasi | B13: 19 Januari 2026 | D13: Tanggal ditulis dengan format text
A14: Mass Comparator
A15: No. Seri Mass comp | B15: 90602105
A16: Kalibrator | B16: F1
A17: Merk Kalibrator | B17: Kern
A18: No Seri Kalibrator | B18: YCS-01-653-00

Sheet Pooled STDV Repeatability  MC
A2: Siklus ke-1 | F2: u Pooled STDV | G2: <--------- Pooled Standard Deviation, Menggunakan 6 kali siklus data historis
A3: r1 | B3: r2 | C3: r3 | D3: r4 | F3: =SQRT(((9*D18^2)+(9*D36^2)+(9*D54^2)+(9*D72^2)+(9*D90^2)+(9*D108^2))/54) -> 0.021606755
A4: 15000.12 | B4: 15000.17 | C4: 15000.18 | D4: 15000.18 | F4: =SQRT((D18^2+D36^2+D54^2+D72^2+D90^2+D108^2)/6) -> 0.021606755 | G4: <--------- Menggunkaan rumus SNSU PK.M-04:2.2022
A5: =A4-B4 -> -0.05 | C5: =C4-D4 -> 0
A6: r5 | B6: r6 | C6: r7 | D6: r8 | I6: Tabel maksimum nilai F pada perhitungan F-Test
A7: 15000.18 | B7: 15000.18 | C7: 15000.12 | D7: 15000.14 | F7: F TEST | I7: n (siklus) | J7: vm=9
A8: =A7-B7 -> 0 | C8: =C7-D7 -> -0.02 | F8: F-Test value | G8: =$D$108^2/$F$3^2 -> 0.62118207 | I8: 6 | J8: 2.06
A9: r9 | B9: r10 | C9: r11 | D9: R12 | F9: Judgement | G9: =IF(G8<J8,"OK","NOT GOOD") -> OK | I9: 8 | J9: 2.01
A10: 15000.18 | B10: 15000.12 | C10: 15000.12 | D10: 15000.15 | I10: 10 | J10: 1.99
A11: =A10-B10 -> 0.06 | C11: =C10-D10 -> -0.03 | I11: 12 | J11: 1.97
A12: r13 | B12: r14 | C12: r15 | D12: r16
A13: 15000.18 | B13: 15000.16 | C13: 15000.17 | D13: 15000.13
A14: =A13-B13 -> 0.02 | C14: =C13-D13 -> 0.04
A15: r17 | B15: r18 | C15: r19 | D15: r20
A16: 15000.11 | B16: 15000.13 | C16: 15000.14 | D16: 15000.15
A17: =A16-B16 -> -0.02 | C17: =C16-D16 -> -0.01
A18: STDV | D18: =_xlfn.STDEV.S(A5,C5,A8,C8,A11,C11,A14,C14,A17,C17) -> 0.033149493
A20: Siklus ke-2
A21: r1 | B21: r2 | C21: r3 | D21: r4
A22: 15000.11 | B22: 15000.11 | C22: 15000.08 | D22: 15000.12
A23: =A22-B22 -> 0 | C23: =C22-D22 -> -0.04
A24: r5 | B24: r6 | C24: r7 | D24: r8
A25: 15000.06 | B25: 15000.05 | C25: 15000.06 | D25: 15000.1
A26: =A25-B25 -> 0.01 | C26: =C25-D25 -> -0.04
A27: r9 | B27: r10 | C27: r11 | D27: R12
A28: 15000.11 | B28: 15000.1 | C28: 15000.1 | D28: 15000.07
A29: =A28-B28 -> 0.01 | C29: =C28-D28 -> 0.03
A30: r13 | B30: r14 | C30: r15 | D30: r16
A31: 15000.12 | B31: 15000.08 | C31: 15000.09 | D31: 15000.05
A32: =A31-B31 -> 0.04 | C32: =C31-D31 -> 0.04
A33: r17 | B33: r18 | C33: r19 | D33: r20
A34: 15000.1 | B34: 15000.11 | C34: 15000.09 | D34: 15000.08
A35: =A34-B34 -> -0.01 | C35: =C34-D34 -> 0.01
A36: STDV | D36: =_xlfn.STDEV.S(A23,C23,A26,C26,A29,C29,A32,C32,A35,C35) -> 0.028771128
A38: Siklus ke-3
A39: r1 | B39: r2 | C39: r3 | D39: r4
A40: 15000.09 | B40: 15000.08 | C40: 15000.1 | D40: 15000.09
A41: =A40-B40 -> 0.01 | C41: =C40-D40 -> 0.01
A42: r5 | B42: r6 | C42: r7 | D42: r8
A43: 15000.07 | B43: 15000.06 | C43: 15000.09 | D43: 15000.07
...

Sheet Koreksi themohygro rotronic 202
C2: Suhu (°C) | D2: %RH | F2: Thermohygro Rotronic data 2025
B3: Awal | C3: ='U95 Beban'!D34 -> 20.5 | D3: ='U95 Beban'!D37 -> 51.6 | F3: Koreksi suhu | I3: Koreksi RH
B4: Akhir | C4: ='U95 Beban'!D35 -> 20.4 | D4: ='U95 Beban'!D38 -> 51 | F4: T (°C) | G4: Koreksi | H4: U95 | I4: RH (%) | J4: Koreksi | K4: U95
B5: Rata2 | C5: =AVERAGE(C3:C4) -> 20.45 | D5: =AVERAGE(D3:D4) -> 51.3 | F5: 20 | G5: 0.1 | H5: 2 | I5: 40 | J5: 0.2 | K5: 2.5
B6: Terkoreksi | C6: =C5+FORECAST(C5,G5:G9,F5:F9) -> 20.492 | D6: =D5+FORECAST(D5,J5:J9,I5:I9) -> 51.2018 | F6: 25 | G6: -0.2 | H6: 2 | I6: 50 | J6: -0.3 | K6: 2.8
B7: U95 | C7: 2 | D7: =FORECAST(D6,K5:K9,I5:I9) -> 2.6727892 | F7: 30 | G7: -0.3 | H7: 2 | I7: 60 | J7: -0.3 | K7: 3.2
B8: Fluktuasi suhu | C8: =(MAX(C3:C4)-C5+C5-MIN(C3:C4))/2 -> 0.05 | D8: =(MAX(D3:D4)-D5+D5-MIN(D3:D4))/2 -> 0.3 | F8: 35 | G8: -0.6 | H8: 2 | I8: 70 | J8: -0.1 | K8: 2
B9: Flu+U95 | C9: =C7+C8 -> 2.05 | D9: =D7+D8 -> 2.9727892 | F9: 40 | G9: -0.7 | H9: 2 | I9: 80 | J9: -0.6 | K9: 2.6
B10: Kondisi Ruang | C10: =FIXED(C6,1)&" ± "&FIXED(C8,1) -> 20,5 ± 0,1 | D10: =FIXED(D6,1)&" ± "&FIXED(D8,1) -> 51,2 ± 0,3

Sheet U95 Beban
B1: E2 | F1: F1 | J1: M1 | N1: E2 METTLER TOLEDO | R1: TABEL MPE OIML R111-1
B2: Nominal (g) | C2: Massa konvensional (g) | D2: U95 (mg) | F2: Nominal (g) | G2: Massa konvensional (g) | H2: U95 (mg) | J2: Identitas | K2: Massa konvensional (g) | L2: U95 (mg) | N2: Nominal (g) | O2: Massa konvensional (g) | P2: U95 (mg) | R2: Nominal Value (g) | S2: Class E1 | T2: Class E2 | U2: Class F1 | V2: Class F2 | W2: Class M1 | X2: Class M2 | Y2: Class M3
B3: 2000 | C3: 1999.9985 | D3: 0.32 | F3: 0.001 | G3: 0.000929 | H3: 0.026 | J3: M1 | K3: 19999.414 | L3: 45 | N3: 5000 | O3: 4999.9986 | P3: 0.72 | R3: 50000 g | S3: 25 | T3: 75 | U3: 250 | V3: 750 | W3: 2500 | X3: 7500 | Y3: 25000
B4: 1000 | C4: 1000.0005 | D4: 0.14 | F4: 0.002 | G4: 0.001981 | H4: 0.028 | J4: M2 | K4: 19999.234 | L4: 45 | N4: 1000 | O4: 1000.0005 | P4: 0.00031 | R4: 20000 g | S4: 10 | T4: 30 | U4: 100 | V4: 300 | W4: 1000 | X4: 3000 | Y4: 10000
B5: 500 | C5: 500.00001 | D5: 0.08 | F5: 0.005 | G5: 0.005006 | H5: 0.026 | J5: M3 | K5: 19999.627 | L5: 45 | N5: 500 | O5: 500.0006 | P5: 0.00016 | R5: 10000 g | S5: 5 | T5: 15 | U5: 50 | V5: 150 | W5: 500 | X5: 1500 | Y5: 5000
B6: 200 | C6: 200.00001 | D6: 0.04 | F6: 0.01 | G6: 0.0099971 | H6: 0.026 | J6: M4 | K6: 20000.346 | L6: 45 | N6: 200 | O6: 200.0002 | P6: 6e-05 | R6: 5000 g | S6: 2.5 | T6: 7.5 | U6: 25 | V6: 75 | W6: 250 | X6: 750 | Y6: 2500
B7: 200t | C7: 200.00005 | D7: 0.04 | F7: 0.02 | G7: 0.019991 | H7: 0.028 | J7: M5 | K7: 20000.124 | L7: 45 | N7: 200t | O7: 200.0002 | P7: 7.2e-05 | R7: 2000 g | S7: 1 | T7: 3 | U7: 10 | V7: 30 | W7: 100 | X7: 300 | Y7: 1000
B8: 100 | C8: 100.00008 | D8: 0.03 | F8: 0.05 | G8: 0.049997 | H8: 0.026 | J8: M6 | K8: 20000.154 | L8: 45 | N8: 100 | O8: 100.00001 | P8: 3.6e-05 | R8: 1000 g | S8: 0.5 | T8: 1.5 | U8: 5 | V8: 15 | W8: 50 | X8: 150 | Y8: 500
B9: 50 | C9: 50.00002 | D9: 0.02 | F9: 0.1 | G9: 0.100014 | H9: 0.026 | J9: M7 | K9: 19999.125 | L9: 45 | N9: 50 | O9: 50.00002 | P9: 2.1e-05 | R9: 500 g | S9: 0.25 | T9: 0.75 | U9: 2.5 | V9: 7.5 | W9: 25 | X9: 75 | Y9: 250
B10: 20 | C10: 19.999978 | D10: 0.009 | F10: 0.2 | G10: 0.200015 | H10: 0.028 | J10: M8 | K10: 19999.806 | L10: 45 | N10: 20 | O10: 20.00003 | P10: 1.6e-05 | R10: 200 g | S10: 0.01 | T10: 0.3 | U10: 1 | V10: 3 | W10: 10 | X10: 30 | Y10: 100
B11: 20t | C11: 19.999977 | D11: 0.009 | F11: 0.5 | G11: 0.500019 | H11: 0.027 | J11: M9 | K11: 20000.237 | L11: 45 | N11: 20t | O11: 20.00001 | P11: 1.6e-05 | R11: 100 g | S11: 0.05 | T11: 0.15 | U11: 0.5 | V11: 1.5 | W11: 5 | X11: 15 | Y11: 50
B12: 10 | C12: 9.999976 | D12: 0.008 | F12: 1 | G12: 0.999993 | H12: 0.027 | J12: M10 | K12: 19999.832 | L12: 45 | N12: 10 | O12: 10.000023 | P12: 1.4e-05 | R12: 50 g | S12: 0.03 | T12: 0.1 | U12: 0.3 | V12: 1 | W12: 3 | X12: 10 | Y12: 30
B13: 5 | C13: 5.000006 | D13: 0.007 | F13: 2 | G13: 2.0000089 | H13: 0.028 | J13: M11 | K13: 19999.934 | L13: 45 | N13: 5 | O13: 5.000003 | P13: 8.9e-06 | R13: 20 g | S13: 0.025 | T13: 0.08 | U13: 0.25 | V13: 0.8 | W13: 2.5 | X13: 8 | Y13: 25
B14: 2 | C14: 2.000013 | D14: 0.005 | F14: 5 | G14: 4.99992 | H14: 0.029 | J14: M12 | K14: 19999.845 | L14: 45 | N14: 2 | O14: 2.000015 | P14: 7.1e-06 | R14: 10 g | S14: 0.02 | T14: 0.06 | U14: 0.2 | V14: 0.6 | W14: 2 | X14: 6 | Y14: 20
B15: 2t | C15: 2.000015 | D15: 0.005 | F15: 10 | G15: 10.000017 | H15: 0.032 | J15: M13 | K15: 20000.802 | L15: 45 | N15: 2t | O15: 2.000003 | P15: 7.1e-06 | R15: 5 g | S15: 0.015 | T15: 0.05 | U15: 0.15 | V15: 0.5 | W15: 1.5 | X15: 5 | Y15: 15
B16: 1 | C16: 0.999997 | D16: 0.005 | F16: 20 | G16: 20.000009 | H16: 0.036 | J16: M14 | K16: 19999.575 | L16: 45 | N16: 1 | O16: 1.000013 | P16: 6.8e-06 | R16: 2 g | S16: 0.012 | T16: 0.04 | U16: 0.12 | V16: 0.4 | W16: 1.2 | X16: 4 | Y16: 12
B17: 0.5 | C17: 0.500018 | D17: 0.004 | F17: 50 | G17: 49.999814 | H17: 0.042 | J17: M15 | K17: 20000.329 | L17: 45 | N17: 0.5 | O17: =500.011/1000 -> 0.500011 | P17: 0.0051 | R17: 1 g | S17: 0.01 | T17: 0.03 | U17: 0.1 | V17: 0.3 | W17: 1 | X17: 3 | Y17: 10
B18: 0.2 | C18: 0.200013 | D18: 0.003 | F18: 100 | G18: 99.999763 | H18: 0.067 | J18: M16 | K18: 20000.932 | L18: 45 | N18: 0.2 | O18: =200.001/1000 -> 0.200001 | P18: 0.0031 | R18: 0,5 g | S18: 0.008 | T18: 0.025 | U18: 0.08 | V18: 0.25 | W18: 0.8 | X18: 2.5 | Y18: -
B19: 0,2t | C19: 0.200015 | D19: 0.003 | F19: 200 | G19: 199.99967 | H19: 0.11 | J19: 20LZ1 | K19: 20001.683 | L19: 45 | N19: 0,2t | O19: =199.999/1000 -> 0.199999 | P19: 0.0036 | R19: 0,2 g | S19: 0.006 | T19: 0.02 | U19: 0.06 | V19: 0.2 | W19: 0.6 | X19: 2 | Y19: -
B20: 0.1 | C20: 0.100003 | D20: 0.002 | F20: 500 | G20: 499.99861 | H20: 1 | J20: 10LZ1 | K20: 10001.617 | L20: 26 | N20: 0.1 | O20: =100.009/1000 -> 0.100009 | P20: 0.0031 | R20: 0,1 g | S20: 0.005 | T20: 0.015 | U20: 0.05 | V20: 0.15 | W20: 0.5 | X20: 1.5 | Y20: -
F21: 1000 | G21: 1000.001 | H21: 1.1 | J21: 5A | K21: 4998.996 | L21: 5.7 | N21: 0.05 | O21: =50.005/1000 -> 0.050005 | P21: 0.0024 | R21: 0,05 g | S21: 0.004 | T21: 0.012 | U21: 0.04 | V21: 0.12 | W21: 0.4 | X21: - | Y21: -
F22: 2000 | G22: 1999.9994 | H22: 1.4 | J22: 10A | K22: 9999.566 | L22: 26 | N22: 0.02 | O22: =20.003/1000 -> 0.020003 | P22: 0.0022 | R22: 0,02 g | S22: 0.003 | T22: 0.01 | U22: 0.03 | V22: 0.1 | W22: 0.3 | X22: - | Y22: -
F23: 5000 | G23: 5000.0163 | H23: 2.6 | J23: A | K23: 19999.312 | L23: 45 | N23: 0,02t | O23: =20.001/1000 -> 0.020001 | P23: 0.002 | R23: 0,01 g | S23: 0.002 | T23: 0.008 | U23: 0.025 | V23: 0.08 | W23: 0.25 | X23: - | Y23: -
F24: 10000 | G24: 10000.041 | H24: 4.6 | J24: B | K24: 19999.19 | L24: 45 | N24: 0.01 | O24: =10.002/1000 -> 0.010002 | P24: 0.0016 | R24: 0,005 g | S24: 0.002 | T24: 0.006 | U24: 0.02 | V24: 0.06 | W24: 0.2 | X24: - | Y24: -
F25: 20000 | G25: 20000.022 | H25: 13 | J25: C | K25: 19999.069 | L25: 45 | N25: 0.005 | O25: =5.002/1000 -> 0.005002 | P25: 0.0018 | R25: 0,002 g | S25: 0.002 | T25: 0.006 | U25: 0.02 | V25: 0.06 | W25: 0.2 | X25: - | Y25: -
F26: 0,002t | G26: 0.002053 | H26: 0.028 | J26: D | K26: 19999.282 | L26: 45 | N26: 0.002 | O26: =2.002/1000 -> 0.002002 | P26: 0.0014 | R26: 0,001 g | S26: 0.002 | T26: 0.006 | U26: 0.02 | V26: 0.06 | W26: 0.2 | X26: - | Y26: -
F27: 0,02t | G27: 0.0200133 | H27: 0.028 | J27: E | K27: 19999.268 | L27: 45 | N27: 0,002t | O27: =2/1000 -> 0.002 | P27: 0.0014
F28: 0,2t | G28: 0.200023 | H28: 0.026 | J28: F | K28: 19999.33 | L28: 45 | N28: 0.001 | O28: =1.001/1000 -> 0.001001 | P28: 0.0014
F29: 2000t | G29: 2000.0015 | H29: 1.4 | J29: G | K29: 19999.21 | L29: 45
F30: 200t | G30: 199.99882 | H30: 0.11 | J30: H | K30: 20000.486 | L30: 45
F31: 20t | G31: 20.000048 | H31: 0.036 | J31: I | K31: 19999.254 | L31: 45
F32: 2t | G32: 1.999995 | H32: 0.028
C33: ISI DATA
C34: Temperatur Awal | D34: 20.5 | E34: °C | F34: <----------- Warna kuning, isian manual
C35: Temperatur Akhir | D35: 20.4 | E35: °C
C36: Temperatur rata2 | D36: =AVERAGE(D34,D35) -> 20.45 | E36: °C
C37: Kelembaban Awal | D37: 51.6 | E37: %RH
C38: Kelembaban Akhir | D38: 51 | E38: %RH
C39: Kelembapan rata2 | D39: =AVERAGE(D37,D38) -> 51.3 | E39: %RH
C40: Tekanan awal | D40: 923 | E40: hPa | F40: =D40*I40 -> 692.30907 | G40: mmHg | H40: 1 hPa | I40: 0.750064 | J40: mmHg
...

Sheet Database
A1: Titik Ukur | B1: Kalibrator | D1: Merek | E1: No S/N Timbangan | F1: Resolusi timbangan | H1: Nominal | I1: CMC KAN | J1: Nominal Timbangan | K1: Kalibrator | L1: Merek | M1: Nomor Seri
A2: 20000 | B2: E2 | E2: 90803270 | F2: 1e-05 | H2: 20000 | I2: 45 | K2: E2 | L2: Kern Germany | M2: G982106
A3: 10000 | B3: F1 | E3: 90602105 | F3: 0.001 | H3: 10000 | I3: 26 | K3: F1 | L3: YCS | M3: YCS-01-653-00
A4: 5000 | B4: M1 | E4: 14904962 | F4: 0.01 | H4: 5000 | I4: 2.6 | K4: M1 | L4: - | M4: -
A5: 2000t | B5: E2 METTLER TOLEDO | E5: 90803270 | F5: 5e-05 | H5: 2000 | I5: 1.4 | K5: E2 METTLER TOLEDO | L5: Mettler Toledo | M5: 158856
A6: 2000 | H6: 1000 | I6: 1.1
A7: 1000 | H7: 500 | I7: 1
A8: 500 | H8: 200 | I8: 0.11
A9: 200 | H9: 100 | I9: 0.067
A10: 200t | H10: 50 | I10: 0.042
A11: 100 | H11: 20 | I11: 0.036
A12: 50 | H12: 10 | I12: 0.032
A13: 20 | H13: 5 | I13: 0.029
A14: 20t | H14: 2 | I14: 0.028
A15: 10 | H15: 1 | I15: 0.027
A16: 5 | H16: 0.5 | I16: 0.027
A17: 2 | H17: 0.2 | I17: 0.026
A18: 2t | H18: 0.1 | I18: 0.026
A19: 1 | H19: 0.05 | I19: 0.026
A20: 0.5 | H20: 0.02 | I20: 0.026
A21: 0.2 | H21: 0.01 | I21: 0.026
A22: 0,2t | H22: 0.005 | I22: 0.026
A23: 0.1 | H23: 0.002 | I23: 0.026
A24: 0.05 | H24: 0.001 | I24: 0.026
A25: 0.02
A26: 0,02t
A27: 0.01
A28: 0.005
A29: 0.002
A30: 0,002t
A31: 0.001
A32: 0

Sheet Sertifikat
A7: S E R T I F I K A T K A L I B R A S I
A8: C A L I B R A T I O N C E R T I F I C A T E
A9: Nomor / Number : 0002-2.11/A1/KALIBRASI BBLM/I/2026
B14: IDENTITAS ALAT
B15: INSTRUMENT DETAILS
B17: Nama Alat | D17: : | E17: Anak Timbangan
B18: Instrument Name
B19: Merek | D19: : | E19: =CONCATENATE(," ",'Isi data'!B7) -> -
B20: Brand
B21: Tipe | D21: : | E21: =CONCATENATE(," ",'Isi data'!B8) -> TB-10 Weight LIFT Test Bar
B22: Type
B23: Nomor Identifikasi | D23: : | E23: =CONCATENATE(," ",'Isi data'!B11) -> -
B24: Identification Number
B25: Nomor Seri | D25: : | E25: =CONCATENATE(," ",'Isi data'!B9) -> 25914
B26: Serial Number
B27: Lain-lain | D27: : | E27: Kapasitas | G27: =CONCATENATE(":"," ",'Isi data'!B10) -> : 10 lb
B28: Others | E28: Kecermatan | G28: : -
B30: IDENTITAS PEMILIK
B31: Owner’s Identification
B33: Nama | D33: : | E33: =CONCATENATE(,'Isi data'!B3) -> PT GATRA PERDANA TRUSTRUE
B34: Designation
B35: Alamat | D35: : | E35: =CONCATENATE(,'Isi data'!B4) -> Kawasan Komplek Ruko Golden BCI Blok T3 No. 12 Bengkong Laut, Kec. Bengkong, Kota Batam - Kepulauan Riau
B36: Address
H40: Halaman 1 dari 2 halaman
H41: Page of page
H43: Diterbitkan Tanggal 22 Januari 2026
H44: Date of Issue
E45: Penguji Mutu Barang Ahli Madya,
E46: Elis Sofianti
E47: NIP. 197109301994032002
E64: Nomor | F64: =CONCATENATE(": ",MID(A9,18,40)) -> : 0002-2.11/A1/KALIBRASI BBLM/I/2026
E65: No. Order | F65: =CONCATENATE(": ",'Isi data'!B2) -> : K023_2026
E66: Halaman | F66: : 2 dari 2
B68: SPESIFIKASI ALAT
B69: Nama | D69: =E17 -> Anak Timbangan
B70: Merk / Tipe | D70: =CONCATENATE(":"," ",'Isi data'!B7," ","/"," ",'Isi data'!B8) -> : - / TB-10 Weight LIFT Test Bar
B71: No. Identifikasi | D71: =E23 -> -
B72: No. Seri | D72: =E25 -> 25914
B73: Kapasitas | D73: =G27 -> : 10 lb
B74: Kecermatan | D74: =G28 -> : - | G74: Kondisi ruang
...

Sheet Komparasi dengan CSIRO
Q3: Dari CSIRO 2010
A4: Komponen | B4: Satuan | C4: Distribusi | D4: U | E4: Pembagi | F4: vi | G4: ui | H4: ci | I4: uici | J4: (uici)2 | K4: (uici)4/vi
A5: 1 | B5: 2 | C5: 3 | D5: 4 | E5: 5 | F5: 6 | G5: 7 | H5: 8 | I5: 9 | J5: 10 | K5: 11
A6: Callibration of Mr | B6: mg | C6: Normal | D6: 0.0625 | E6: 1 | F6: 60 | G6: =D6/E6 -> 0.0625 | H6: 1 | I6: =G6*H6 -> 0.0625 | J6: =I6^2 -> 0.00390625 | K6: =I6^4/F6 -> 2.5431315e-07
A7: Callibration of Msens | B7: mg | C7: Normal | D7: 0.012 | E7: 2 | F7: 60 | G7: =D7/E7 -> 0.006 | H7: 0.7 | I7: =G7*H7 -> 0.0042 | J7: =I7^2 -> 1.764e-05 | K7: =I7^4/F7 -> 5.18616e-12
A8: Instability in 50 g | B8: mg | C8: Normal | D8: 0.024 | E8: 1 | F8: 4 | G8: =D8/E8 -> 0.024 | H8: 1 | I8: =G8*H8 -> 0.024 | J8: =I8^2 -> 0.000576 | K8: =I8^4/F8 -> 8.2944e-08
A9: Instability in 5 g | B9: mg | C9: Normal | D9: 0.013 | E9: 1 | F9: 4 | G9: =D9/E9 -> 0.013 | H9: 1 | I9: =G9*H9 -> 0.013 | J9: =I9^2 -> 0.000169 | K9: =I9^4/F9 -> 7.14025e-09
A10: Instability in 0 g | B10: mg | C10: Normal | D10: =0.08*$G$91 -> 0 | E10: 1 | F10: 4 | G10: =D10/E10 -> 0 | H10: 1 | I10: =G10*H10 -> 0 | J10: =I10^2 -> 0 | K10: =I10^4/F10 -> 0
A11: Instability in 0 g | B11: mg | C11: Normal | D11: =0.08*$G$92 -> 0 | E11: 1 | F11: 4 | G11: =D11/E11 -> 0 | H11: 1 | I11: =G11*H11 -> 0 | J11: =I11^2 -> 0 | K11: =I11^4/F11 -> 0
A12: Instability in 0 g | B12: mg | C12: Normal | D12: =0.08*$J$89 -> 0 | E12: 1 | F12: 4 | G12: =D12/E12 -> 0 | H12: 1 | I12: =G12*H12 -> 0 | J12: =I12^2 -> 0 | K12: =I12^4/F12 -> 0
A13: Instability in Msens | B13: mg | C13: Normal | D13: 0.004 | E13: 1 | F13: 4 | G13: =D13/E13 -> 0.004 | H13: 0.7 | I13: =G13*H13 -> 0.0028 | J13: =I13^2 -> 7.84e-06 | K13: =I13^4/F13 -> 1.53664e-11
A14: Balance Repeatability | B14: mg | C14: Normal | D14: 0.095 | E14: 1 | F14: 9 | G14: =D14/E14 -> 0.095 | H14: 1 | I14: =G14*H14 -> 0.095 | J14: =I14^2 -> 0.009025 | K14: =I14^4/F14 -> 9.0500694e-06
A15: Balance Repeatability r sens | B15: mg | C15: Normal | D15: 0.19 | E15: 1 | F15: 9 | G15: =D15/E15 -> 0.19 | H15: 0.7 | I15: =G15*H15 -> 0.133 | J15: =I15^2 -> 0.017689 | K15: =I15^4/F15 -> 3.4766747e-05
A16: Buoyancy | B16: mg | C16: Rectangular | D16: =4.5*10^-9*440*0.114*55 -> 1.24146e-05 | E16: 1 | F16: 1000 | G16: =D16/E16 -> 1.24146e-05 | H16: 1 | I16: =G16*H16 -> 1.24146e-05 | J16: =I16^2 -> 1.5412229e-10 | K16: =I16^4/F16 -> 2.3753681e-23
A17: Rounding | B17: mg | C17: Rectangular | D17: =IF(AND(J26<10,J26>=1),0.1/2,IF(AND(J26<1,J26>=0.1),0.01/2,IF(AND(J26<0.1,J26>=0.01),0.001/2,IF(AND(J26<0.01,J26>=0.0001),0.0001/2,0)))) -> 0.005 | E17: =SQRT(3) -> 1.7320508 | F17: 1000 | G17: =D17/E17 -> 0.0028867513 | H17: 1 | I17: =G17*H17 -> 0.0028867513 | J17: =I17^2 -> 8.3333333e-06 | K17: =I17^4/F17 -> 6.9444444e-14
A18: Sums | J18: =SUM(J6:J16) -> 0.03139073 | K18: =SUM(K6:K16) -> 4.4161234e-05
A19: Sums | J19: =SUM(J6:J17) -> 0.031399063 | K19: =SUM(K6:K17) -> 4.4161234e-05
A20: Ketidakpastian baku gabungan, uc, mg | J20: =SQRT(J18) -> 0.17717429
A21: Ketidakpastian baku gabungan, uc, mg | J21: =SQRT(J19) -> 0.17719781
A22: Dearajat kebebasan efektif, veff | J22: =(J20^4)/K18 -> 22.313188
A23: Dearajat kebebasan efektif, veff | J23: =(J21^4)/K19 -> 22.325037
A24: Faktor cakupan, k-student for veff and CL 95% | J24: =TINV(0.05,J22) -> 2.0738731
A25: Faktor cakupan, k-student for veff and CL 95% | J25: =TINV(0.05,J23) -> 2.0738731
A26: Ketidakpastian bentangan, U = kuc, mg | J26: =J24*J20 -> 0.36743699
A27: Rounding ketidakpastian bentangan, U = kuc, mg | J27: =J25*J21 -> 0.36748576
A28: KAN
