Workbook
Name sert: #REF!

Sheet Sertifikat
A7: S E R T I F I K A T K A L I B R A S I
A8: C A L I B R A T I O N C E R T I F I C A T E
A9: Nomor / Number : 0064-7.4/KALIBRASI BBLM/XII/2025
B14: IDENTITAS ALAT
B15: INSTRUMENT DETAILS
B17: Nama Alat | D17: : Conductivity Meter
B18: Instrument Name
B19: Merek | D19: =CONCATENATE(":"," ",'Budget conducti meter'!B7) -> : Thermo Scientific
B20: Brand
B21: Tipe | D21: =CONCATENATE(":"," ",'Budget conducti meter'!B8) -> : Orion Star A325
B22: Type
B23: Nomor Identifikasi | D23: : -
B24: Identification Number
B25: Nomor Seri | D25: =CONCATENATE(":"," ",'Budget conducti meter'!B10) -> : G13040
B26: Serial Number
B27: Lain-lain | D27: : Kapasitas | F27: =CONCATENATE(":"," ",'Budget conducti meter'!B11) -> : 0,001 𝜇S/cm - 3000 mS/cm
B28: Others | D28: Kecermatan | F28: =CONCATENATE(":"," ",'Budget conducti meter'!D11," ",'Budget conducti meter'!E11) -> : 1 𝜇S/cm
B30: IDENTITAS PEMILIK
B31: Owner’s Identification
B33: Nama | D33: =CONCATENATE(":"," ",'Budget conducti meter'!B6) -> : UPTD. Laboratorium Lingkungan Hidup, DLH Jawa Barat
B34: Designation
B35: Alamat | D35: =CONCATENATE(":"," ",'Budget conducti meter'!B2) -> : Jl. A. H. Nasution No. 117, Pasir Endah, Kec. Ujung Berung, Bandung 40619
B36: Address
H40: Halaman 1 dari 2 halaman
H41: Page of page
H43: Diterbitkan Tanggal 16 Desember 2025
H44: Date of Issue
F45: Penguji Mutu Barang Ahli Madya,
F46: Elis Sofianti
F47: NIP. 197109301994032002
G70: Nomor | H70: =CONCATENATE(":"," ",MID(A9,18,100)) -> : 0064-7.4/KALIBRASI BBLM/XII/2025
G71: No. Order | H71: =": " &'Budget conducti meter'!B3 -> : K663-3
G72: Halaman | H72: : 2 dari 2
B74: SPESIFIKASI ALAT
B75: Nama | D75: =D17 -> : Conductivity Meter
B76: Merk / Tipe | D76: =CONCATENATE(":"," ",'Budget conducti meter'!B7," ","/"," ",'Budget conducti meter'!B8) -> : Thermo Scientific / Orion Star A325
B77: No. Identifikasi | D77: =D23 -> : -
B78: No. Seri | D78: =D25 -> : G13040
B79: Kapasitas | D79: =F27 -> : 0,001 𝜇S/cm - 3000 mS/cm
B80: Kecermatan | D80: =F28 -> : 1 𝜇S/cm | G80: Kondisi ruang
...

Sheet Budget conducti  meter
A1: data kalibrasi
A2: Alamat | B2: Jl. A. H. Nasution No. 117, Pasir Endah, Kec. Ujung Berung, Bandung 40619 | K2: Thermohygro Beureur data 2025
A3: no. order | B3: K663-3 | G3: Suhu (°C) | H3: %RH | K3: Koreksi suhu | N3: Koreksi RH
A4: tanggal terima | B4: 25 November 2025 | F4: Awal | G4: 25.1 | H4: 78.1 | K4: T (°C) | L4: Koreksi | M4: U95 | N4: RH (%) | O4: Koreksi | P4: U95
A5: tanggal kalibrasi | B5: 1 Desember 2025 | F5: Akhir | G5: 25.2 | H5: 78.2 | K5: 20.01 | L5: 0.3 | M5: 2 | N5: 40.01 | O5: -2 | P5: 3
A6: Pemilik | B6: UPTD. Laboratorium Lingkungan Hidup, DLH Jawa Barat | F6: Rata2 | G6: =AVERAGE(G4:G5) -> 25.15 | H6: =AVERAGE(H4:H5) -> 78.15 | K6: 25 | L6: 0.4 | M6: 2 | N6: 50.01 | O6: -3 | P6: 3
A7: merk | B7: Thermo Scientific | F7: Terkoreksi | G7: =G6+FORECAST(G6,L5:L9,K5:K9) -> 25.620477 | H7: =H6+FORECAST(H6,O5:O9,N5:N9) -> 77.028455 | K7: 30 | L7: 0.5 | M7: 2 | N7: 60.02 | O7: -1 | P7: 3
A8: Tipe | B8: Orion Star A325 | F8: U95 | G8: 2 | H8: =FORECAST(H7,P5:P9,N5:N9) -> 2.6527359 | K8: 35 | L8: 1.2 | M8: 2 | N8: 70 | O8: 0 | P8: 2
A9: no Id | B9: - | F9: Fluktuasi suhu | G9: =(MAX(G4:G5)-G6+G6-MIN(G4:G5))/2 -> 0.05 | H9: =(MAX(H4:H5)-H6+H6-MIN(H4:H5))/2 -> 0.05 | K9: 40 | L9: 1.7 | M9: 2 | N9: 82 | O9: -2 | P9: 3
A10: no seri | B10: G13040 | F10: Flu+U95 | G10: =G8+G9 -> 2.05 | H10: =H8+H9 -> 2.7027359
A11: kapasitas/resolusi | B11: 0,001 𝜇S/cm - 3000 mS/cm | C11: / | D11: 1 | E11: 𝜇S/cm | F11: Kondisi Ruang | G11: =FIXED(G7,1) & " ± "&FIXED(G10,1) -> 25,6 ± 2,1 | H11: =FIXED(H7,1) & " ± "&FIXED(H10,1) -> 77,0 ± 2,7
G16: Suhu Awal | H16: Suhu Akhir
A17: COND 1413 𝜇S/cm | F17: suhu buffer | G17: 24.9 | H17: 24.8 | I17: °C | N17: koreksi temperatur | Q17: Nilai koreksi termometer digital tahun 2025
A18: buffer standar | B18: suhu °C | C18: pembacaan alat | I18: stdev | J18: standar terkoreksi | K18: =IF(K19<=25,Q23,IF(K19>=25,Q24,0)) -> 24.2 | L18: =VLOOKUP(K18,$Q$18:$S$26,3,FALSE) -> 24 | Q18: pembacaan alat | R18: koreksi | S18: pembacaan alat terkoreksi
C19: X1 | D19: X2 | E19: X3 | F19: X4 | G19: X5 | H19: X rata | K19: =AVERAGE(G17,H16) -> 24.9 | L19: =(K19-K18)*(L20-L18)/(K20-K18)+L18 -> 24.777778 | N19: =L19-K19 -> -0.12222222 | Q19: °C | R19: °C | S19: °C
A20: 1413 | B20: =L19 -> 24.777778 | C20: 1421 | D20: 1423 | E20: 1423 | F20: 1424 | G20: 1424 | H20: =AVERAGE(C20:G20) -> 1423 | I20: =STDEV(C20:G20) -> 1.2247449 | J20: =A20-R41 -> 1407 | K20: =IF(K19<=25,Q24,IF(K19>=25,Q25,0)) -> 25.1 | L20: =VLOOKUP(K20,$Q$18:$S$26,3,FALSE) -> 25 | Q20: 19.3 | R20: -0.2 | S20: =Q20+R20 -> 19.1
Q21: 20.1 | R21: -0.2 | S21: =Q21+R21 -> 19.9
A22: COND 12880 𝜇S/cm | F22: suhu buffer | G22: 24.9 | H22: 24.9 | I22: °C | Q22: 21.1 | R22: -0.1 | S22: =Q22+R22 -> 21
A23: buffer standar | B23: suhu °C | C23: pembacaan alat | I23: stdev | J23: standar terkoreksi | K23: =IF(K24<=25,Q23,IF(K24>=25,Q24,0)) -> 24.2 | L23: =VLOOKUP(K23,$Q$18:$S$26,3,FALSE) -> 24 | Q23: 24.2 | R23: -0.2 | S23: =Q23+R23 -> 24
C24: X1 | D24: X2 | E24: X3 | F24: X4 | G24: X5 | H24: X rata | K24: =AVERAGE(G22,H22) -> 24.9 | L24: =(K24-K23)*(L25-L23)/(K25-K23)+L23 -> 24.777778 | N24: =L24-K24 -> -0.12222222 | Q24: 25.1 | R24: -0.1 | S24: =Q24+R24 -> 25
A25: 12880 | B25: =L24 -> 24.777778 | C25: =12.96*1000 -> 12960 | D25: =12.97*1000 -> 12970 | E25: =12.97*1000 -> 12970 | F25: =12.97*1000 -> 12970 | G25: =12.98*1000 -> 12980 | H25: =AVERAGE(C25:G25) -> 12970 | I25: =STDEV(C25:G25) -> 7.0710678 | J25: =A25+R59 -> 12933.778 | K25: =IF(K24<=25,Q24,IF(K24>=25,Q25,0)) -> 25.1 | L25: =VLOOKUP(K25,$Q$18:$S$26,3,FALSE) -> 25 | Q25: 26.1 | R25: -0.1 | S25: =Q25+R25 -> 26
Q26: 30.1 | R26: -0.1 | S26: =Q26+R26 -> 30
A27: COND 84 𝜇S/cm | F27: suhu buffer | G27: 0 | H27: 0 | I27: °C
A28: buffer standar | B28: suhu °C | C28: pembacaan alat | I28: stdev | J28: standar terkoreksi | K28: =IF(K29<=25,Q23,IF(K29>=25,Q24,0)) -> 24.2 | L28: =VLOOKUP(K28,$Q$18:$S$26,3,FALSE) -> 24
C29: X1 | D29: X2 | E29: X3 | F29: X4 | G29: X5 | H29: X rata | K29: =AVERAGE(G27,H27) -> 0 | L29: =(K29-K28)*(L30-L28)/(K30-K28)+L28 -> -2.8888889 | N29: =L29-K29 -> -2.8888889
A30: 84 | B30: =L29 -> -2.8888889 | H30: =AVERAGE(C30:G30) -> #DIV/0! | I30: =STDEV(C30:G30) -> #DIV/0! | J30: =A30+R77 -> 129.73778 | K30: =IF(K29<=25,Q24,IF(K29>=25,Q25,0)) -> 25.1 | L30: =VLOOKUP(K30,$Q$18:$S$26,3,FALSE) -> 25
A35: St. deviasi | D35: U sertifikat | E35: =A20*15/1000 -> 21.195 | G35: Koreksi | H35: =R41 -> 6 | N35: temperatur °C | O35: Δcond (𝜇S/cm) | Q35: temperatur °C | R35: ΔPH
D36: U sertifikat thermometer | E36: =0.4 -> 0.4 | N36: 0 | O36: 637
A37: Skala terkecil alat | B37: =D11 -> 1 | N37: 5 | O37: 517
N38: 10 | O38: 393
A39: 1413 𝜇S/cm | N39: 15 | O39: 266 | Q39: Koreksi temperatur
A40: Komponen | B40: Satuan | C40: Distribusi | D40: U | E40: Pembagi | F40: vi | G40: ui | H40: ci | I40: uici | J40: (uici)2 | K40: (uici)4/vi | N40: 20 | O40: 135 | Q40: =IF(Q41<=25,N40,IF(Q41>=25,N41,0)) -> 20 | R40: =VLOOKUP(Q40,$N$35:$O$45,2,FALSE) -> 135
A41: Repeatability | B41: 𝜇S/cm | C41: Normal | D41: =I20 -> 1.2247449 | E41: =SQRT(5) -> 2.236068 | F41: 4 | G41: =D41/E41 -> 0.54772256 | H41: 1 | I41: =G41*H41 -> 0.54772256 | J41: =I41^2 -> 0.3 | K41: =I41^4/F41 -> 0.0225 | N41: 25 | O41: 0 | Q41: =B20 -> 24.777778 | R41: =(Q41-Q40)*(R42-R40)/(Q42-Q40)+R40 -> 6
A42: Larutan Buffer | B42: 𝜇S/cm | C42: t-student | D42: =E35 -> 21.195 | E42: 2 | F42: 60 | G42: =D42/E42 -> 10.5975 | H42: 1 | I42: =G42*H42 -> 10.5975 | J42: =I42^2 -> 112.30701 | K42: =I42^4/F42 -> 210.21439 | N42: 30 | O42: -139 | Q42: =IF(Q41<=25,N41,IF(Q41>=25,N42,0)) -> 25 | R42: =VLOOKUP(Q42,$N$35:$O$45,2,FALSE) -> 0
A43: Koreksi pengaruh ΔT | B43: 𝜇S/cm | C43: Rect | D43: =R41 -> 6 | E43: =SQRT(3) -> 1.7320508 | F43: 50 | G43: =D43/E43 -> 3.4641016 | H43: 1 | I43: =G43*H43 -> 3.4641016 | J43: =I43^2 -> 12 | K43: =I43^4/F43 -> 2.88 | N43: 35 | O43: -283 | Q43: =A83 -> Pengaruh ketidakpastian Termometer digital
A44: Readability | B44: 𝜇S/cm | C44: Rect | D44: =B37/2 -> 0.5 | E44: =SQRT(3) -> 1.7320508 | F44: 50 | G44: =D44/E44 -> 0.28867513 | H44: 1 | I44: =G44*H44 -> 0.28867513 | J44: =I44^2 -> 0.083333333 | K44: =I44^4/F44 -> 0.00013888889 | Q44: 15 | R44: =O40 -> 135
A45: Pengaruh ketidakpastian Termometer digital | B45: oC | C45: Normal | D45: =E36 -> 0.4 | E45: 2 | F45: 60 | G45: =D45/E45 -> 0.2 | H45: =0.01/5 -> 0.002 | I45: =G45*H45 -> 0.0004 | J45: =I45^2 -> 1.6e-07 | K45: =I45^4/F45 -> 4.2666667e-16 | Q45: =E36+B20 -> 25.177778 | R45: =(Q45-Q44)*(R46-R44)/(Q46-Q44)+R44 -> -2.3898222
A46: Sums | J46: =SUM(J41:J44) -> 124.69034 | K46: =SUM(K41:K44) -> 213.11703 | Q46: 25 | R46: 0.01
A47: Ketidakpastian baku gabungan, uc, Unit | J47: =SQRT(J46) -> 11.166483
A48: Dearajat kebebasan efektif, veff | J48: =J47^4/K46 -> 72.953722
...

Sheet Sheet1
B2: temperatur °C | C2: Δcond
B3: 0 | C3: 0 | D3: =12.88-C3 -> 12.88
B4: 5 | C4: 8.22 | D4: =12.88-C4 -> 4.66
B5: 10 | C5: 9.33 | D5: =12.88-C5 -> 3.55
B6: 15 | C6: 10.48 | D6: =12.88-C6 -> 2.4
B7: 20 | C7: 11.67 | D7: =12.88-C7 -> 1.21
B8: 25 | C8: 12.88 | D8: =12.88-C8 -> 0
B9: 30 | C9: 14.12 | D9: =12.88-C9 -> -1.24
B10: 35 | C10: 15.39 | D10: =12.88-C10 -> -2.51
B15: 18 | C15: 72.52 | D15: =84-C15 -> 11.48
B16: 20 | C16: 75.8 | D16: =84-C16 -> 8.2
B17: 23 | C17: 80.72 | D17: =84-C17 -> 3.28
B18: 25 | C18: 84 | D18: =84-C18 -> 0
B19: 28 | C19: =C18+D17 -> 87.28 | D19: =84-C19 -> -3.28
