Workbook

Sheet Sertifikat
B2: S E R T I F I K A T K A L I B R A S I
B3: C A L I B R A T I O N C E R T I F I C A T E
G4: Nomor / | H4: Number | K4: : | N4: 0092-6.1 | O4: =CONCATENATE("/KALIBRASI BBLM/",ROMAN(TEXT(T36,"m")),"/",TEXT(T36,"yyyy")) -> /KALIBRASI BBLM/XI/2025
B7: IDENTITAS ALAT
B8: INSTRUMENT DETAILS
B10: Nama Alat | H10: =PROPER(RIGHT(Data!F2,11)) -> Multi Meter
B11: Instrument Name
B12: Merek | H12: =Data!D8 -> FLUKE
B13: Brand
B14: Tipe | H14: =Data!J8 -> 179
B15: Type
B16: Nomor Identitas | H16: =Data!J10 -> -
B17: Identity Number
B18: Nomor Seri | H18: =Data!D10 -> 66340242
B19: Serial Number
B20: Lain-lain | H20: Kapasitas | M20: =Data!D9 -> -
B21: Others | H21: Kecermatan | M21: -
B24: IDENTITAS PEMILIK
B25: OWNER'S IDENTIFICATION
B27: Nama | H27: PT Rukun Sejahtera Teknik
B28: Designation
B29: Alamat | H29: Karawang Sentral Bizhub, Jl. Raya Telukjambe No. 8 Karawang, Jawa Barat
B30: Address
P33: Halaman | Q33: 1 | R33: dari | T33: 4 | U33: halaman
P34: Page | R34: of | U34: pages
S36: Diterbitkan Tanggal | T36: 45965
S37: Date of Issue
L40: Ketua Tim Laboratorium Kalibrasi dan Penguji,
L41: Yoyon Suyono
L42: NIP. 196804111996031001
M51: Nomor | Q51: =CONCATENATE($N$4,$O$4) -> 0092-6.1/KALIBRASI BBLM/XI/2025
M52: No. Order | Q52: =Data!C$15 -> K560
M53: Halaman | Q53: =CONCATENATE(INT(ROW()/49)+1, " dari ",T$33) -> 2 dari 4
B56: SPESIFIKASI ALAT
B57: Nama | J57: =PROPER(RIGHT(Data!F2,11)) -> Multi Meter
B58: Merek / Tipe | J58: =CONCATENATE(Data!D8," / ",Data!J8) -> FLUKE / 179
B59: No. Identitas / No. Seri | J59: =CONCATENATE(Data!J10," / ",Data!D10) -> - / 66340242
B60: Kapasitas | J60: =Data!D9 -> -
B61: Kecermatan | J61: -
B62: Prosedur Kalibrasi | J62: =Data!D11 -> IK-K-KL-01
...

Sheet Data
F2: KALIBRASI MULTI METER
F3: LABORATORIUM KALIBRASI DAN PENGUJI
F4: BALAI BESAR LOGAM DAN MESIN
F5: BANDUNG
A8: Merk | D8: FLUKE | I8: Tipe | J8: 179 | K8: 6000 Count
A9: Kapasitas/Graduasi | D9: - | H9: / | I9: -
A10: No. Seri | D10: 66340242 | I10: No. ID | J10: -
A11: Standar Acuan | D11: IK-K-KL-01 | G11: (Euramet cg-15 versi 3.0 (02/15))
A12: Temperatur (°C) | D12: Awal | F12: 23.2 | G12: =FORECAST(F12,'24_THM A21011892'!B4:B5,'24_THM A21011892'!A4:A5) -> 0.16363636 | H12: Kelembaban (%RH) | K12: Awal | L12: 63.4 | M12: =FORECAST(L12,'24_THM A21011892'!F6:F7,'24_THM A21011892'!E6:E7) -> 1.2938776
D13: Akhir | F13: 22.5 | G13: =FORECAST(F13,'24_THM A21011892'!B4:B5,'24_THM A21011892'!A4:A5) -> 0.22727273 | K13: Akhir | L13: 63.2 | M13: =FORECAST(L13,'24_THM A21011892'!F6:F7,'24_THM A21011892'!E6:E7) -> 1.2897959
F14: =AVERAGE(F12:F13) -> 22.85 | G14: =MAX(MAX(SUM(F12:G12),SUM(F13:G13))-F14,F14-MIN(SUM(F12:G12),SUM(F13:G13))) -> 0.51363636 | L14: =AVERAGE(L12:L13) -> 63.3 | M14: =MAX(MAX(SUM(L12:M12),SUM(L13:M13))-L14,L14-MIN(SUM(L12:M12),SUM(L13:M13))) -> 1.3938776
A15: No. Order | C15: K560 | E15: Dikalibrasi | G15: Firman/Suratmaji | J15: Paraf
A16: Tgl. terima | C16: 45937 | E16: Diperiksa | G16: Nur
A17: Tgl. kalibrasi | C17: 45952 | E17: Disetujui | G17: Yoyon
A18: Kalibrator yang digunakan:
B19: Multiproduct Calibrator Fluke 5500A No. Seri 6790012 yang tertelusur ke SI melalui Laboratorium SNSU BSN.
A24: DATA VOLTAGE DC
A25: Range/Freq/ EMF/Shunt | C25: Pembacaan Standar/Alat | E25: Pembacaan Alat/Standar
E26: X1 | G26: X2 | I26: X3 | K26: X4 | M26: X5 | P26: Biarkan saja lur
A27: 600 | B27: mV | P27: Data Linear | Q27: Satuan
A28: -60 | B28: =IF(P28<=0.1,(ABS(SUM(AVERAGE(E28:N28),A28)/2)), "Non EMF") -> 0 | C28: =IF(0.1*A27 <329.9999, 0.1*A27,0.1*A27/1000) -> 60 | D28: =IF(P28<=0.329999,"mV", IF(P28<=3.29999, "V1", IF(P28<=32.9999,"V2", IF(P28<=329.9999,"V3", IF(P28<=1020,"V4", "Number Out of Range" ))))) -> mV | E28: 60 | G28: 60 | I28: 60 | K28: 60 | M28: 60 | P28: =IF(B27="mV",A27*0.1/1000) -> 0.06 | Q28: V
B29: =IF(P29<=0.1,(ABS(SUM(AVERAGE(E29:N29),A29)/2)), "Non EMF") -> Non EMF | C29: =IF(0.5*A27 <329.9999, 0.5*A27,0.1*A27/1000) -> 300 | D29: =IF(P29<=0.329999,"mV", IF(P29<=3.29999, "V1", IF(P29<=32.9999,"V2", IF(P29<=329.9999,"V3", IF(P29<=1020,"V4", "Number Out of Range" ))))) -> mV | E29: 299.9 | G29: 299.9 | I29: 299.9 | K29: 299.9 | M29: 299.9 | P29: =IF(B27="mV",A27*0.5/1000) -> 0.3 | Q29: V
B30: =IF(P30<=0.1,(ABS(SUM(AVERAGE(E30:N30),A30)/2)), "Non EMF") -> Non EMF | C30: =IF(0.9*A27<329.9999,0.9*A27,(0.9*A27)/1000) -> 0.54 | D30: =IF(P30<=0.329999,"mV", IF(P30<=3.29999, "V1", IF(P30<=32.9999,"V2", IF(P30<=329.9999,"V3", IF(P30<=1020,"V4", "Number Out of Range" ))))) -> V1 | E30: 539.9 | G30: 539.9 | I30: 539.9 | K30: 539.9 | M30: 539.9 | P30: =IF(B27="mV",A27*0.9/1000) -> 0.54 | Q30: V
A31: 6 | B31: V
B32: =IF(P32<=0.1,(ABS(SUM(AVERAGE(E32:N32),A32)/2)), "Non EMF") -> Non EMF | C32: =0.1*A31 -> 0.6 | D32: =IF(P32<=0.329999,"mV", IF(P32<=3.29999, "V1", IF(P32<=32.9999,"V2", IF(P32<=329.9999,"V3", IF(P32<=1020,"V4", "Number Out of Range" ))))) -> V1 | E32: 0.6 | G32: 0.6 | I32: 0.6 | K32: 0.6 | M32: 0.6 | P32: =A31*0.1 -> 0.6 | Q32: V
B33: =IF(P33<=0.1,(ABS(SUM(AVERAGE(E33:N33),A33)/2)), "Non EMF") -> Non EMF | C33: =0.5*A31 -> 3 | D33: =IF(P33<=0.329999,"mV", IF(P33<=3.29999, "V1", IF(P33<=32.9999,"V2", IF(P33<=329.9999,"V3", IF(P33<=1020,"V4", "Number Out of Range" ))))) -> V1 | E33: 2.999 | G33: 2.999 | I33: 2.999 | K33: 2.999 | M33: 2.999 | P33: =0.5*A31 -> 3 | Q33: V
B34: =IF(P34<=0.1,(ABS(SUM(AVERAGE(E34:N34),A34)/2)), "Non EMF") -> Non EMF | C34: =0.9*A31 -> 5.4 | D34: =IF(P34<=0.329999,"mV", IF(P34<=3.29999, "V1", IF(P34<=32.9999,"V2", IF(P34<=329.9999,"V3", IF(P34<=1020,"V4", "Number Out of Range" ))))) -> V2 | E34: 5.399 | G34: 5.399 | I34: 5.399 | K34: 5.399 | M34: 5.399 | P34: =0.9*A31 -> 5.4 | Q34: V
A35: 60 | B35: V
B36: =IF(P36<=0.1,(ABS(SUM(AVERAGE(E36:N36),A36)/2)), "Non EMF") -> Non EMF | C36: =0.1*A35 -> 6 | D36: =IF(P36<=0.329999,"mV", IF(P36<=3.29999, "V1", IF(P36<=32.9999,"V2", IF(P36<=329.9999,"V3", IF(P36<=1020,"V4", "Number Out of Range" ))))) -> V2 | E36: 6 | G36: 6 | I36: 6 | K36: 6 | M36: 6 | P36: =0.1*A35 -> 6 | Q36: V
B37: =IF(P37<=0.1,(ABS(SUM(AVERAGE(E37:N37),A37)/2)), "Non EMF") -> Non EMF | C37: =0.5*A35 -> 30 | D37: =IF(P37<=0.329999,"mV", IF(P37<=3.29999, "V1", IF(P37<=32.9999,"V2", IF(P37<=329.9999,"V3", IF(P37<=1020,"V4", "Number Out of Range" ))))) -> V2 | E37: 30 | G37: 30 | I37: 30 | K37: 30 | M37: 30 | P37: =0.5*A35 -> 30 | Q37: V
B38: =IF(P38<=0.1,(ABS(SUM(AVERAGE(E38:N38),A38)/2)), "Non EMF") -> Non EMF | C38: =0.9*A35 -> 54 | D38: =IF(P38<=0.329999,"mV", IF(P38<=3.29999, "V1", IF(P38<=32.9999,"V2", IF(P38<=329.9999,"V3", IF(P38<=1020,"V4", "Number Out of Range" ))))) -> V3 | E38: 53.99 | G38: 53.99 | I38: 53.99 | K38: 53.99 | M38: 53.99 | P38: =0.9*A35 -> 54 | Q38: V
A39: 600 | B39: V
B40: =IF(P40<=0.1,(ABS(SUM(AVERAGE(E40:N40),A40)/2)), "Non EMF") -> Non EMF | C40: =0.1*A39 -> 60 | D40: =IF(P40<=0.329999,"mV", IF(P40<=3.29999, "V1", IF(P40<=32.9999,"V2", IF(P40<=329.9999,"V3", IF(P40<=1020,"V4", "Number Out of Range" ))))) -> V3 | E40: 60 | G40: 60 | I40: 60 | K40: 60 | M40: 60 | P40: =0.1*A39 -> 60 | Q40: V
B41: =IF(P41<=0.1,(ABS(SUM(AVERAGE(E41:N41),A41)/2)), "Non EMF") -> Non EMF | C41: =0.5*A39 -> 300 | D41: =IF(P41<=0.329999,"mV", IF(P41<=3.29999, "V1", IF(P41<=32.9999,"V2", IF(P41<=329.9999,"V3", IF(P41<=1020,"V4", "Number Out of Range" ))))) -> V3 | E41: 299.9 | G41: 299.9 | I41: 299.9 | K41: 299.9 | M41: 299.9 | P41: =0.5*A39 -> 300 | Q41: V
B42: =IF(P42<=0.1,(ABS(SUM(AVERAGE(E42:N42),A42)/2)), "Non EMF") -> Non EMF | C42: =0.9*A39 -> 540 | D42: =IF(P42<=0.329999,"mV", IF(P42<=3.29999, "V1", IF(P42<=32.9999,"V2", IF(P42<=329.9999,"V3", IF(P42<=1020,"V4", "Number Out of Range" ))))) -> V4 | E42: 539.9 | G42: 539.9 | I42: 539.9 | K42: 539.9 | M42: 539.9 | P42: =0.9*A39 -> 540 | Q42: V
A43: 1000 | B43: V
B44: =IF(P44<=0.1,(ABS(SUM(AVERAGE(E44:N44),A44)/2)), "Non EMF") -> Non EMF | C44: =0.1*A43 -> 100 | D44: =IF(P44<=0.329999,"mV", IF(P44<=3.29999, "V1", IF(P44<=32.9999,"V2", IF(P44<=329.9999,"V3", IF(P44<=1020,"V4", "Number Out of Range" ))))) -> V3 | E44: 100 | G44: 100 | I44: 100 | K44: 100 | M44: 100 | P44: =0.1*A43 -> 100 | Q44: V
B45: =IF(P45<=0.1,(ABS(SUM(AVERAGE(E45:N45),A45)/2)), "Non EMF") -> Non EMF | C45: =0.5*A43 -> 500 | D45: =IF(P45<=0.329999,"mV", IF(P45<=3.29999, "V1", IF(P45<=32.9999,"V2", IF(P45<=329.9999,"V3", IF(P45<=1020,"V4", "Number Out of Range" ))))) -> V4 | E45: 500 | G45: 500 | I45: 500 | K45: 500 | M45: 500 | P45: =0.5*A43 -> 500 | Q45: V
B46: =IF(P46<=0.1,(ABS(SUM(AVERAGE(E46:N46),A46)/2)), "Non EMF") -> Non EMF | C46: =0.9*A43 -> 900 | D46: =IF(P46<=0.329999,"mV", IF(P46<=3.29999, "V1", IF(P46<=32.9999,"V2", IF(P46<=329.9999,"V3", IF(P46<=1020,"V4", "Number Out of Range" ))))) -> V4 | E46: 900 | G46: 900 | I46: 900 | K46: 900 | M46: 900 | P46: =0.9*A43 -> 900 | Q46: V
A49: DATA VOLTAGE AC
...

Sheet Sheet1
A4: Range/Freq/ EMF/Shunt | C4: Pembacaan Standar/Alat | E4: Pembacaan Alat/Standar
E5: X1 | G5: X2 | I5: X3 | K5: X4 | M5: X5 | P5: Biarkan saja lur
A6: 600 | B6: mV | P6: Data Linear | Q6: Satuan
A7: -60 | B7: =IF(P7<=0.1,(ABS(SUM(AVERAGE(E7:N7),A7)/2)), "Non EMF") -> 0 | C7: =IF(0.1*A6 <329.9999, 0.1*A6,0.1*A6/1000) -> 60 | D7: =IF(P7<=0.329999,"mV", IF(P7<=3.29999, "V1", IF(P7<=32.9999,"V2", IF(P7<=329.9999,"V3", IF(P7<=1020,"V4", "Number Out of Range" ))))) -> mV | E7: 60 | G7: 60 | I7: 60 | K7: 60 | M7: 60 | P7: =IF(B6="mV",A6*0.1/1000) -> 0.06 | Q7: V
B8: =IF(P8<=0.1,(ABS(SUM(AVERAGE(E8:N8),A8)/2)), "Non EMF") -> Non EMF | C8: =IF(0.5*A6 <329.9999, 0.5*A6,0.1*A6/1000) -> 300 | D8: =IF(P8<=0.329999,"mV", IF(P8<=3.29999, "V1", IF(P8<=32.9999,"V2", IF(P8<=329.9999,"V3", IF(P8<=1020,"V4", "Number Out of Range" ))))) -> mV | E8: 299.9 | G8: 299.9 | I8: 299.9 | K8: 299.9 | M8: 299.9 | P8: =IF(B6="mV",A6*0.5/1000) -> 0.3 | Q8: V
B9: =IF(P9<=0.1,(ABS(SUM(AVERAGE(E9:N9),A9)/2)), "Non EMF") -> Non EMF | C9: =IF(0.9*A6<329.9999,0.9*A6,(0.9*A6)/1000) -> 0.54 | D9: =IF(P9<=0.329999,"mV", IF(P9<=3.29999, "V1", IF(P9<=32.9999,"V2", IF(P9<=329.9999,"V3", IF(P9<=1020,"V4", "Number Out of Range" ))))) -> V1 | E9: 539.9 | G9: 539.9 | I9: 539.9 | K9: 539.9 | M9: 539.9 | P9: =IF(B6="mV",A6*0.9/1000) -> 0.54 | Q9: V
A10: 6 | B10: V
B11: =IF(P11<=0.1,(ABS(SUM(AVERAGE(E11:N11),A11)/2)), "Non EMF") -> Non EMF | C11: =0.1*A10 -> 0.6 | D11: =IF(P11<=0.329999,"mV", IF(P11<=3.29999, "V1", IF(P11<=32.9999,"V2", IF(P11<=329.9999,"V3", IF(P11<=1020,"V4", "Number Out of Range" ))))) -> V1 | E11: 0.6 | G11: 0.6 | I11: 0.6 | K11: 0.6 | M11: 0.6 | P11: =A10*0.1 -> 0.6 | Q11: V
B12: =IF(P12<=0.1,(ABS(SUM(AVERAGE(E12:N12),A12)/2)), "Non EMF") -> Non EMF | C12: =0.5*A10 -> 3 | D12: =IF(P12<=0.329999,"mV", IF(P12<=3.29999, "V1", IF(P12<=32.9999,"V2", IF(P12<=329.9999,"V3", IF(P12<=1020,"V4", "Number Out of Range" ))))) -> V1 | E12: 2.999 | G12: 2.999 | I12: 2.999 | K12: 2.999 | M12: 2.999 | P12: =0.5*A10 -> 3 | Q12: V
B13: =IF(P13<=0.1,(ABS(SUM(AVERAGE(E13:N13),A13)/2)), "Non EMF") -> Non EMF | C13: =0.9*A10 -> 5.4 | D13: =IF(P13<=0.329999,"mV", IF(P13<=3.29999, "V1", IF(P13<=32.9999,"V2", IF(P13<=329.9999,"V3", IF(P13<=1020,"V4", "Number Out of Range" ))))) -> V2 | E13: 5.399 | G13: 5.399 | I13: 5.399 | K13: 5.399 | M13: 5.399 | P13: =0.9*A10 -> 5.4 | Q13: V
A14: 60 | B14: V
B15: =IF(P15<=0.1,(ABS(SUM(AVERAGE(E15:N15),A15)/2)), "Non EMF") -> Non EMF | C15: =0.1*A14 -> 6 | D15: =IF(P15<=0.329999,"mV", IF(P15<=3.29999, "V1", IF(P15<=32.9999,"V2", IF(P15<=329.9999,"V3", IF(P15<=1020,"V4", "Number Out of Range" ))))) -> V2 | E15: 6 | G15: 6 | I15: 6 | K15: 6 | M15: 6 | P15: =0.1*A14 -> 6 | Q15: V
B16: =IF(P16<=0.1,(ABS(SUM(AVERAGE(E16:N16),A16)/2)), "Non EMF") -> Non EMF | C16: =0.5*A14 -> 30 | D16: =IF(P16<=0.329999,"mV", IF(P16<=3.29999, "V1", IF(P16<=32.9999,"V2", IF(P16<=329.9999,"V3", IF(P16<=1020,"V4", "Number Out of Range" ))))) -> V2 | E16: 30 | G16: 30 | I16: 30 | K16: 30 | M16: 30 | P16: =0.5*A14 -> 30 | Q16: V
B17: =IF(P17<=0.1,(ABS(SUM(AVERAGE(E17:N17),A17)/2)), "Non EMF") -> Non EMF | C17: =0.9*A14 -> 54 | D17: =IF(P17<=0.329999,"mV", IF(P17<=3.29999, "V1", IF(P17<=32.9999,"V2", IF(P17<=329.9999,"V3", IF(P17<=1020,"V4", "Number Out of Range" ))))) -> V3 | E17: 53.99 | G17: 53.99 | I17: 53.99 | K17: 53.99 | M17: 53.99 | P17: =0.9*A14 -> 54 | Q17: V
A18: 600 | B18: V
B19: =IF(P19<=0.1,(ABS(SUM(AVERAGE(E19:N19),A19)/2)), "Non EMF") -> Non EMF | C19: =0.1*A18 -> 60 | D19: =IF(P19<=0.329999,"mV", IF(P19<=3.29999, "V1", IF(P19<=32.9999,"V2", IF(P19<=329.9999,"V3", IF(P19<=1020,"V4", "Number Out of Range" ))))) -> V3 | E19: 60 | G19: 60 | I19: 60 | K19: 60 | M19: 60 | P19: =0.1*A18 -> 60 | Q19: V
B20: =IF(P20<=0.1,(ABS(SUM(AVERAGE(E20:N20),A20)/2)), "Non EMF") -> Non EMF | C20: =0.5*A18 -> 300 | D20: =IF(P20<=0.329999,"mV", IF(P20<=3.29999, "V1", IF(P20<=32.9999,"V2", IF(P20<=329.9999,"V3", IF(P20<=1020,"V4", "Number Out of Range" ))))) -> V3 | E20: 299.9 | G20: 299.9 | I20: 299.9 | K20: 299.9 | M20: 299.9 | P20: =0.5*A18 -> 300 | Q20: V
B21: =IF(P21<=0.1,(ABS(SUM(AVERAGE(E21:N21),A21)/2)), "Non EMF") -> Non EMF | C21: =0.9*A18 -> 540 | D21: =IF(P21<=0.329999,"mV", IF(P21<=3.29999, "V1", IF(P21<=32.9999,"V2", IF(P21<=329.9999,"V3", IF(P21<=1020,"V4", "Number Out of Range" ))))) -> V4 | E21: 539.9 | G21: 539.9 | I21: 539.9 | K21: 539.9 | M21: 539.9 | P21: =0.9*A18 -> 540 | Q21: V
A22: 1000 | B22: V
B23: =IF(P23<=0.1,(ABS(SUM(AVERAGE(E23:N23),A23)/2)), "Non EMF") -> Non EMF | C23: =0.1*A22 -> 100 | D23: =IF(P23<=0.329999,"mV", IF(P23<=3.29999, "V1", IF(P23<=32.9999,"V2", IF(P23<=329.9999,"V3", IF(P23<=1020,"V4", "Number Out of Range" ))))) -> V3 | E23: 100 | G23: 100 | I23: 100 | K23: 100 | M23: 100 | P23: =0.1*A22 -> 100 | Q23: V
B24: =IF(P24<=0.1,(ABS(SUM(AVERAGE(E24:N24),A24)/2)), "Non EMF") -> Non EMF | C24: =0.5*A22 -> 500 | D24: =IF(P24<=0.329999,"mV", IF(P24<=3.29999, "V1", IF(P24<=32.9999,"V2", IF(P24<=329.9999,"V3", IF(P24<=1020,"V4", "Number Out of Range" ))))) -> V4 | E24: 500 | G24: 500 | I24: 500 | K24: 500 | M24: 500 | P24: =0.5*A22 -> 500 | Q24: V
B25: =IF(P25<=0.1,(ABS(SUM(AVERAGE(E25:N25),A25)/2)), "Non EMF") -> Non EMF | C25: =0.9*A22 -> 900 | D25: =IF(P25<=0.329999,"mV", IF(P25<=3.29999, "V1", IF(P25<=32.9999,"V2", IF(P25<=329.9999,"V3", IF(P25<=1020,"V4", "Number Out of Range" ))))) -> V4 | E25: 900 | G25: 900 | I25: 900 | K25: 900 | M25: 900 | P25: =0.9*A22 -> 900 | Q25: V
A29: Range/Freq/ EMF/Shunt | C29: Pembacaan Standar/Alat | E29: Pembacaan Alat/Standar
E30: X1 | G30: X2 | I30: X3 | K30: X4 | M30: X5
A31: 600 | B31: mV | P31: Data Linear | Q31: Satuan
A32: 50 | B32: Hz | C32: =IF(0.1*A31 <329.9999, 0.1*A31,0.1*A31/1000) -> 60 | D32: =IF(P32<=0.329999,"mV", IF(P32<=3.29999, "V1", IF(P32<=32.9999,"V2", IF(P32<=329.9999,"V3", IF(P32<=1020,"V4", "Number Out of Range" ))))) -> mV | E32: 60.3 | G32: 60.3 | I32: 60.3 | K32: 60.3 | M32: 60.3 | P32: =IF(B31="mV",A31*0.1/1000) -> 0.06 | Q32: V
C33: =IF(0.5*A31 <329.9999, 0.5*A31,0.1*A31/1000) -> 300 | D33: =IF(P33<=0.329999,"mV", IF(P33<=3.29999, "V1", IF(P33<=32.9999,"V2", IF(P33<=329.9999,"V3", IF(P33<=1020,"V4", "Number Out of Range" ))))) -> mV | E33: 300.1 | G33: 300.1 | I33: 300.1 | K33: 300.1 | M33: 300.1 | P33: =IF(B31="mV",A31*0.5/1000) -> 0.3 | Q33: V
C34: =IF(0.9*A31<329.9999,0.9*A31,(0.9*A31)/1000) -> 0.54 | D34: =IF(P34<=0.329999,"mV", IF(P34<=3.29999, "V1", IF(P34<=32.9999,"V2", IF(P34<=329.9999,"V3", IF(P34<=1020,"V4", "Number Out of Range" ))))) -> V1 | E34: 539.7 | G34: 539.8 | I34: 539.9 | K34: 540 | M34: 540.1 | P34: =IF(B31="mV",A31*0.9/1000) -> 0.54 | Q34: V
A35: 6 | B35: V
A36: 50 | B36: Hz | C36: =0.1*A35 -> 0.6 | D36: =IF(P36<=0.329999,"mV", IF(P36<=3.29999, "V1", IF(P36<=32.9999,"V2", IF(P36<=329.9999,"V3", IF(P36<=1020,"V4", "Number Out of Range" ))))) -> V1 | E36: 0.603 | G36: 0.603 | I36: 0.603 | K36: 0.603 | M36: 0.603 | P36: =A35*0.1 -> 0.6 | Q36: V
C37: =0.5*A35 -> 3 | D37: =IF(P37<=0.329999,"mV", IF(P37<=3.29999, "V1", IF(P37<=32.9999,"V2", IF(P37<=329.9999,"V3", IF(P37<=1020,"V4", "Number Out of Range" ))))) -> V1 | E37: 3.003 | G37: 3.003 | I37: 3.003 | K37: 3.003 | M37: 3.003 | P37: =0.5*A35 -> 3 | Q37: V
C38: =0.9*A35 -> 5.4 | D38: =IF(P38<=0.329999,"mV", IF(P38<=3.29999, "V1", IF(P38<=32.9999,"V2", IF(P38<=329.9999,"V3", IF(P38<=1020,"V4", "Number Out of Range" ))))) -> V2 | E38: 5.398 | G38: 5.398 | I38: 5.398 | K38: 5.398 | M38: 5.398 | P38: =0.9*A35 -> 5.4 | Q38: V
A39: 60 | B39: V
A40: 50 | B40: Hz | C40: =0.1*A39 -> 6 | D40: =IF(P40<=0.329999,"mV", IF(P40<=3.29999, "V1", IF(P40<=32.9999,"V2", IF(P40<=329.9999,"V3", IF(P40<=1020,"V4", "Number Out of Range" ))))) -> V2 | E40: 6.02 | G40: 6.02 | I40: 6.02 | K40: 6.02 | M40: 6.02 | P40: =0.1*A39 -> 6 | Q40: V
C41: =0.5*A39 -> 30 | D41: =IF(P41<=0.329999,"mV", IF(P41<=3.29999, "V1", IF(P41<=32.9999,"V2", IF(P41<=329.9999,"V3", IF(P41<=1020,"V4", "Number Out of Range" ))))) -> V2 | E41: 30.03 | G41: 30.03 | I41: 30.03 | K41: 30.03 | M41: 30.03 | P41: =0.5*A39 -> 30 | Q41: V
C42: =0.9*A39 -> 54 | D42: =IF(P42<=0.329999,"mV", IF(P42<=3.29999, "V1", IF(P42<=32.9999,"V2", IF(P42<=329.9999,"V3", IF(P42<=1020,"V4", "Number Out of Range" ))))) -> V3 | E42: 53.98 | G42: 53.98 | I42: 53.98 | K42: 53.98 | M42: 53.98 | P42: =0.9*A39 -> 54 | Q42: V
A43: 600 | B43: V
A44: 50 | B44: Hz | C44: =0.1*A43 -> 60 | D44: =IF(P44<=0.329999,"mV", IF(P44<=3.29999, "V1", IF(P44<=32.9999,"V2", IF(P44<=329.9999,"V3", IF(P44<=1020,"V4", "Number Out of Range" ))))) -> V3 | E44: 60.2 | G44: 60.2 | I44: 60.2 | K44: 60.2 | M44: 60.2 | P44: =0.1*A43 -> 60 | Q44: V
C45: =0.5*A43 -> 300 | D45: =IF(P45<=0.329999,"mV", IF(P45<=3.29999, "V1", IF(P45<=32.9999,"V2", IF(P45<=329.9999,"V3", IF(P45<=1020,"V4", "Number Out of Range" ))))) -> V3 | E45: 300.1 | G45: 300.1 | I45: 300.1 | K45: 300.1 | M45: 300.1 | P45: =0.5*A43 -> 300 | Q45: V
C46: =0.9*A43 -> 540 | D46: =IF(P46<=0.329999,"mV", IF(P46<=3.29999, "V1", IF(P46<=32.9999,"V2", IF(P46<=329.9999,"V3", IF(P46<=1020,"V4", "Number Out of Range" ))))) -> V4 | E46: 539.9 | G46: 539.9 | I46: 539.9 | K46: 539.9 | M46: 539.9 | P46: =0.9*A43 -> 540 | Q46: V
...

Sheet Kor&U95% VAC
A1: Range | C1: Frequency | E1: P Standar | G1: Kor Std | H1: P Alat | J1: Kor Alat | K1: U95% | L1: k | M1: CMC
A2: =Data!A52 -> 600 | B2: =Data!B52 -> mV | C2: =Data!A53 -> 50 | D2: =Data!B57 -> Hz | E2: =Data!C53 -> 60 | F2: =Data!D53 -> mV | G2: =T25 -> -0.011533354 | H2: =AVERAGE(Data!E53:N53) -> 60.3 | I2: mV | J2: =(E2+G2)-H2 -> -0.31153335 | K2: =N46 -> 0.065128253 | L2: =M45 -> 1.9908145 | M2: =E2/10^3*1.2 -> 0.072 | N2: =I2 -> mV
C3: =Data!A53 -> 50 | D3: =Data!B57 -> Hz | E3: =Data!C54 -> 300 | F3: =Data!D54 -> mV | G3: =T26 -> 0.0022128794 | H3: =AVERAGE(Data!G54:N54) -> 300.1 | I3: mV | J3: =(E3+G3)-H3 -> -0.097787121 | K3: =N60 -> 0.08963047 | L3: =M59 -> 1.9778882 | M3: =E3/10^3*1.2 -> 0.36 | N3: =I3 -> mV
C4: =Data!A53 -> 50 | D4: =Data!B57 -> Hz | E4: =Data!C55 -> 0.54 | F4: =Data!D55 -> V1 | G4: =T27 -> 0.0058650746 | H4: =AVERAGE(Data!E55:N55) -> 539.9 | I4: mV | J4: =(E4*10^3+G84)-H4 -> 0.1 | K4: =N74 -> 113.7667 | L4: =M73 -> 1.9863726 | M4: =E4/10^0*0.59 -> 0.3186 | N4: =I4 -> mV
A5: =Data!A56 -> 6 | B5: =Data!B56 -> V | C5: =Data!A57 -> 50 | D5: =Data!B57 -> Hz | E5: =Data!C57 -> 0.6 | F5: =Data!D57 -> V1 | G5: =T28 -> 0.0058722388 | H5: =AVERAGE(Data!E57:N57) -> 0.603 | I5: V | J5: =(E5+G5)-H5 -> 0.0028722388 | K5: =N88 -> 0.047445186 | L5: =M87 -> 2.0085632 | M5: =E5/10^3*0.59 -> 0.000354 | N5: =I5 -> V
C6: =Data!A57 -> 50 | D6: =Data!B61 -> Hz | E6: =Data!C58 -> 3 | F6: =Data!D58 -> V1 | G6: =T29 -> 0.00076967381 | H6: =AVERAGE(Data!E58:N58) -> 3.003 | I6: V | J6: =(E6+G6)-H6 -> -0.0022303262 | K6: =N102 -> 0.0013738603 | L6: =M101 -> 1.984947 | M6: =E6/10^3*0.59 -> 0.00177 | N6: =I6 -> V
C7: =Data!A57 -> 50 | D7: =Data!B57 -> Hz | E7: =Data!C59 -> 5.4 | F7: =Data!D59 -> V2 | G7: =T30 -> -0.0013608955 | H7: =AVERAGE(Data!E59:N59) -> 5.398 | I7: V | J7: =(E7+G7)-H7 -> 0.00063910448 | K7: =N116 -> 0.0014317598 | L7: =M115 -> 1.9764935 | M7: =E7/10^3*0.76 -> 0.004104 | N7: =I7 -> V
A8: =Data!A60 -> 60 | B8: =Data!B60 -> V | C8: =Data!A61 -> 50 | D8: =Data!B61 -> Hz | E8: =Data!C61 -> 6 | F8: =Data!D61 -> V2 | G8: =T31 -> -0.0013268657 | H8: =AVERAGE(Data!E61:N61) -> 6.02 | I8: V | J8: =(E8+G8)-H8 -> -0.021326866 | K8: =N130 -> 0.0061061546 | L8: =M129 -> 1.9989608 | M8: =E8/10^3*0.76 -> 0.00456 | N8: =I8 -> V
C9: =Data!A61 -> 50 | D9: =Data!B61 -> Hz | E9: =Data!C62 -> 30 | F9: =Data!D62 -> V2 | G9: =T32 -> -9.7451537e-05 | H9: =AVERAGE(Data!E62:N62) -> 30.03 | I9: V | J9: =(E9+G9)-H9 -> -0.030097452 | K9: =N144 -> 0.013351275 | L9: =M143 -> 1.9878186 | M9: =E9/10^3*0.76 -> 0.0228 | N9: =I9 -> V
C10: =Data!A61 -> 50 | D10: =Data!B61 -> Hz | E10: =Data!C63 -> 54 | F10: =Data!D63 -> V3 | G10: =T33 -> -0.016167164 | H10: =AVERAGE(Data!E63:N63) -> 53.98 | I10: V | J10: =(E10+G10)-H10 -> 0.0038328358 | K10: =N158 -> 0.013969788 | L10: =M157 -> 1.9764539 | M10: =E10/10^3*0.85 -> 0.0459 | N10: =I10 -> V
A11: =Data!A64 -> 600 | B11: =Data!B64 -> V | C11: =Data!A65 -> 50 | D11: =Data!B65 -> Hz | E11: =Data!C65 -> 60 | F11: =Data!D65 -> V3 | G11: =T34 -> -0.016014925 | H11: =AVERAGE(Data!E65:N65) -> 60.2 | I11: V | J11: =(E11+G11)-H11 -> -0.21601493 | K11: =N172 -> 0.061010325 | L11: =M171 -> 1.9990914 | M11: =E11/10^3*0.85 -> 0.051 | N11: =I11 -> V
C12: =Data!A65 -> 50 | D12: =D11 -> Hz | E12: =Data!C66 -> 300 | F12: =Data!D66 -> V3 | G12: =T35 -> -0.0015260687 | H12: =AVERAGE(Data!E66:N66) -> 300.1 | I12: V | J12: =(E12+G12)-H12 -> -0.10152607 | K12: =N186 -> 0.071526271 | L12: =M185 -> 1.9843349 | M12: =E12/10^3*0.85 -> 0.255 | N12: =I12 -> V
C13: =Data!A65 -> 50 | D13: =D11 -> Hz | E13: =Data!C67 -> 540 | F13: =Data!D67 -> V4 | G13: =T36 -> -0.03119403 | H13: =AVERAGE(Data!E67:N67) -> 539.9 | I13: V | J13: =(E13+G13)-H13 -> 0.06880597 | K13: =N200 -> 0.12142351 | L13: =M199 -> 1.9768611 | M13: =E13/10^3*0.81 -> 0.4374 | N13: =I13 -> V
A14: =Data!A68 -> 1000 | B14: =Data!B68 -> V | C14: =Data!A69 -> 50 | D14: =Data!B69 -> Hz | E14: =Data!C69 -> 100 | F14: =Data!D69 -> V3 | G14: =T37 -> -0.015 | H14: =AVERAGE(Data!E69:N69) -> 101 | I14: V | J14: =(E14+G14)-H14 -> -1.015 | K14: =N214 -> 0.57768218 | L14: =M213 -> 2.0084651 | M14: =E14/10^3*0.85 -> 0.085 | N14: =I14 -> V
C15: =Data!A69 -> 50 | D15: =Data!B69 -> Hz | E15: =Data!C70 -> 500 | F15: =Data!D70 -> V4 | G15: =T38 -> -0.034776119 | H15: =AVERAGE(Data!E70:N70) -> 500 | I15: V | J15: =(E15+G15)-H15 -> -0.034776119 | K15: =N228 -> 0.58726762 | L15: =M227 -> 2.0053334 | M15: =E15/10^3*0.81 -> 0.405 | N15: =I15 -> V
C16: =Data!A69 -> 50 | D16: =Data!B69 -> Hz | E16: =Data!C71 -> 900 | F16: =Data!D71 -> V4 | G16: =T39 -> 0.0010447761 | H16: =AVERAGE(Data!E71:N71) -> 899 | I16: V | J16: =(E16+G16)-H16 -> 1.0010448 | K16: =N242 -> 0.60372431 | L16: =M241 -> 2.0007254 | M16: =E16/10^3*0.81 -> 0.729 | N16: =I16 -> V
C19: Uncertainty Budget sebagai Pendukung Kemampuan Kalibrasi dan Pengukuran (CMC)
C21: Nama Laboratorium | E21: : | F21: BALAI BESAR STANDARDISASI DAN PELAYANAN JASA INDUSTRI LOGAM DAN MESIN
C22: Alamat | E22: : | F22: Jl. Sangkuriang No. 12 Bandung 40135
Q23: 50 hz
C24: Besaran yang diukur | G24: Kelistrikan | O24: IK-K-04-UL-01 | Q24: Titik Ukur | S24: Freq (Hz) | T24: 45506 | U24: 44655 | V24: 43854 | W24: 43283 | X24: Drift | Y24: U24 | AA24: Range | AC24: Freq | AE24: Alat Stan | AF24: KorStan24 | AG24: KorStan22 | AH24: KorStan20 | AI24: KorStan18 | AJ24: Un24
C25: Jenis alat yang dikalibrasi | G25: Digital Multimeter | Q25: =E2 -> 60 | R25: =F2 -> mV | S25: =C2 -> 50 | T25: {=IFERROR( _xlfn.FORECAST.LINEAR( Q25, INDEX($AF$25:$AF$66, MATCH(1, ($AE$25:$AE$66<=Q25)*($AF$25:$AF$66<>"x")*($AB$25:$AB$66=R25)*($AC$25:$AC$66=S25), 0) ): INDEX($AF$25:$AF$66, MATCH(1, ($AE$25:$AE$66>=Q25)*($AF$25:$AF$66<>"x")*($AB$25:$AB$66=R25)*($AC$25:$AC$66=S25), 0) ), INDEX($AE$25:$AE$66, MATCH(1, ($AE$25:$AE$66<=Q25)*($AF$25:$AF$66<>"x")*($AB$25:$AB$66=R25)*($AC$25:$AC$66=S25), 0) ): INDEX($AE$25:$AE$66, MATCH(1, ($AE$25:$AE$66>=Q25)*($AF$25:$AF$66<>"x")*($AB$25:$AB$66=R25)*($AC$25:$AC$66=S25), 0) ) ),INDEX($AF$25:$AF$66, MATCH( MIN(IF(($AF$25:$AF$66<>"x")*($AB$25:$AB$66=R25)*($AC$25:$AC$66=S25),ABS($AE$25:$AE$66-Q25))), IF(($AF$25:$AF$66<>"x")*($AB$25:$AB$66=R25)*($AC$25:$AC$66=S25),ABS($AE$25:$AE$66-Q25)), 0 )))} -> -0.011533354 | U25: {=IFERROR( _xlfn.FORECAST.LINEAR( Q25, INDEX($AG$25:$AG$66, MATCH(1, ($AE$25:$AE$66<=Q25)*($AG$25:$AG$66<>"x")*($AB$25:$AB$66=R25)*($AC$25:$AC$66=S25), 0) ): INDEX($AG$25:$AG$66, MATCH(1, ($AE$25:$AE$66>=Q25)*($AG$25:$AG$66<>"x")*($AB$25:$AB$66=R25)*($AC$25:$AC$66=S25), 0) ), INDEX($AE$25:$AE$66, MATCH(1, ($AE$25:$AE$66<=Q25)*($AG$25:$AG$66<>"x")*($AB$25:$AB$66=R25)*($AC$25:$AC$66=S25), 0) ): INDEX($AE$25:$AE$66, MATCH(1, ($AE$25:$AE$66>=Q25)*($AG$25:$AG$66<>"x")*($AB$25:$AB$66=R25)*($AC$25:$AC$66=S25), 0) ) ),INDEX($AG$25:$AG$66, MATCH( MIN(IF(($AG$25:$AG$66<>"x")*($AB$25:$AB$66=R25)*($AC$25:$AC$66=S25),ABS($AE$25:$AE$66-Q25))), IF(($AG$25:$AG$66<>"x")*($AB$25:$AB$66=R25)*($AC$25:$AC$66=S25),ABS($AE$25:$AE$66-Q25)), 0 )))} -> -0.0017732268 | V25: {=IFERROR( _xlfn.FORECAST.LINEAR( Q25, INDEX($AH$25:$AH$66, MATCH(1, ($AE$25:$AE$66<=Q25)*($AH$25:$AH$66<>"x")*($AB$25:$AB$66=R25)*($AC$25:$AC$66=S25), 0) ): INDEX($AH$25:$AH$66, MATCH(1, ($AE$25:$AE$66>=Q25)*($AH$25:$AH$66<>"x")*($AB$25:$AB$66=R25)*($AC$25:$AC$66=S25), 0) ), INDEX($AE$25:$AE$66, MATCH(1, ($AE$25:$AE$66<=Q25)*($AH$25:$AH$66<>"x")*($AB$25:$AB$66=R25)*($AC$25:$AC$66=S25), 0) ): INDEX($AE$25:$AE$66, MATCH(1, ($AE$25:$AE$66>=Q25)*($AH$25:$AH$66<>"x")*($AB$25:$AB$66=R25)*($AC$25:$AC$66=S25), 0) ) ),INDEX($AH$25:$AH$66, MATCH( MIN(IF(($AH$25:$AH$66<>"x")*($AB$25:$AB$66=R25)*($AC$25:$AC$66=S25),ABS($AE$25:$AE$66-Q25))), IF(($AH$25:$AH$66<>"x")*($AB$25:$AB$66=R25)*($AC$25:$AC$66=S25),ABS($AE$25:$AE$66-Q25)), 0 )))} -> -0.009 | W25: {=IFERROR( _xlfn.FORECAST.LINEAR( Q25, INDEX($AI$25:$AI$66, MATCH(1, ($AE$25:$AE$66<=Q25)*($AI$25:$AI$66<>"x")*($AB$25:$AB$66=R25)*($AC$25:$AC$66=S25), 0) ): INDEX($AI$25:$AI$66, MATCH(1, ($AE$25:$AE$66>=Q25)*($AI$25:$AI$66<>"x")*($AB$25:$AB$66=R25)*($AC$25:$AC$66=S25), 0) ), INDEX($AE$25:$AE$66, MATCH(1, ($AE$25:$AE$66<=Q25)*($AI$25:$AI$66<>"x")*($AB$25:$AB$66=R25)*($AC$25:$AC$66=S25), 0) ): INDEX($AE$25:$AE$66, MATCH(1, ($AE$25:$AE$66>=Q25)*($AI$25:$AI$66<>"x")*($AB$25:$AB$66=R25)*($AC$25:$AC$66=S25), 0) ) ),INDEX($AI$25:$AI$66, MATCH( MIN(IF(($AI$25:$AI$66<>"x")*($AB$25:$AB$66=R25)*($AC$25:$AC$66=S25),ABS($AE$25:$AE$66-Q25))), IF(($AI$25:$AI$66<>"x")*($AB$25:$AB$66=R25)*($AC$25:$AC$66=S25),ABS($AE$25:$AE$66-Q25)), 0 )))} -> 0.013 | X25: =((((ABS(T25-U25)/(T$24-U$24))+(ABS(U25-V25)/(U$24-V$24))+(ABS(V25-W25)/(V$24-W$24)))/3)*(((T$24-U$24)+(U$24-V$24)+(V$24-W$24))/3)) -> 0.014577964 | Y25: =AJ30 -> 0.025 | AA25: 329.999 | AB25: mV | AC25: 40 | AD25: Hz | AE25: 100 | AF25: -0.015 | AG25: -0.007 | AH25: -0.009 | AI25: 0.013 | AJ25: 0.025
C26: Standar yang digunakan | G26: Multiproduct Calibrator Fluke 5500A | Q26: =E3 -> 300 | R26: =F3 -> mV | S26: =C3 -> 50 | T26: {=IFERROR( _xlfn.FORECAST.LINEAR( Q26, INDEX($AF$25:$AF$66, MATCH(1, ($AE$25:$AE$66<=Q26)*($AF$25:$AF$66<>"x")*($AB$25:$AB$66=R26)*($AC$25:$AC$66=S26), 0) ): INDEX($AF$25:$AF$66, MATCH(1, ($AE$25:$AE$66>=Q26)*($AF$25:$AF$66<>"x")*($AB$25:$AB$66=R26)*($AC$25:$AC$66=S26), 0) ), INDEX($AE$25:$AE$66, MATCH(1, ($AE$25:$AE$66<=Q26)*($AF$25:$AF$66<>"x")*($AB$25:$AB$66=R26)*($AC$25:$AC$66=S26), 0) ): INDEX($AE$25:$AE$66, MATCH(1, ($AE$25:$AE$66>=Q26)*($AF$25:$AF$66<>"x")*($AB$25:$AB$66=R26)*($AC$25:$AC$66=S26), 0) ) ),INDEX($AF$25:$AF$66, MATCH( MIN(IF(($AF$25:$AF$66<>"x")*($AB$25:$AB$66=R26)*($AC$25:$AC$66=S26),ABS($AE$25:$AE$66-Q26))), IF(($AF$25:$AF$66<>"x")*($AB$25:$AB$66=R26)*($AC$25:$AC$66=S26),ABS($AE$25:$AE$66-Q26)), 0 )))} -> 0.0022128794 | U26: {=IFERROR( _xlfn.FORECAST.LINEAR( Q26, INDEX($AG$25:$AG$66, MATCH(1, ($AE$25:$AE$66<=Q26)*($AG$25:$AG$66<>"x")*($AB$25:$AB$66=R26)*($AC$25:$AC$66=S26), 0) ): INDEX($AG$25:$AG$66, MATCH(1, ($AE$25:$AE$66>=Q26)*($AG$25:$AG$66<>"x")*($AB$25:$AB$66=R26)*($AC$25:$AC$66=S26), 0) ), INDEX($AE$25:$AE$66, MATCH(1, ($AE$25:$AE$66<=Q26)*($AG$25:$AG$66<>"x")*($AB$25:$AB$66=R26)*($AC$25:$AC$66=S26), 0) ): INDEX($AE$25:$AE$66, MATCH(1, ($AE$25:$AE$66>=Q26)*($AG$25:$AG$66<>"x")*($AB$25:$AB$66=R26)*($AC$25:$AC$66=S26), 0) ) ),INDEX($AG$25:$AG$66, MATCH( MIN(IF(($AG$25:$AG$66<>"x")*($AB$25:$AB$66=R26)*($AC$25:$AC$66=S26),ABS($AE$25:$AE$66-Q26))), IF(($AG$25:$AG$66<>"x")*($AB$25:$AB$66=R26)*($AC$25:$AC$66=S26),ABS($AE$25:$AE$66-Q26)), 0 )))} -> -0.03 | V26: {=IFERROR( _xlfn.FORECAST.LINEAR( Q26, INDEX($AH$25:$AH$66, MATCH(1, ($AE$25:$AE$66<=Q26)*($AH$25:$AH$66<>"x")*($AB$25:$AB$66=R26)*($AC$25:$AC$66=S26), 0) ): INDEX($AH$25:$AH$66, MATCH(1, ($AE$25:$AE$66>=Q26)*($AH$25:$AH$66<>"x")*($AB$25:$AB$66=R26)*($AC$25:$AC$66=S26), 0) ), INDEX($AE$25:$AE$66, MATCH(1, ($AE$25:$AE$66<=Q26)*($AH$25:$AH$66<>"x")*($AB$25:$AB$66=R26)*($AC$25:$AC$66=S26), 0) ): INDEX($AE$25:$AE$66, MATCH(1, ($AE$25:$AE$66>=Q26)*($AH$25:$AH$66<>"x")*($AB$25:$AB$66=R26)*($AC$25:$AC$66=S26), 0) ) ),INDEX($AH$25:$AH$66, MATCH( MIN(IF(($AH$25:$AH$66<>"x")*($AB$25:$AB$66=R26)*($AC$25:$AC$66=S26),ABS($AE$25:$AE$66-Q26))), IF(($AH$25:$AH$66<>"x")*($AB$25:$AB$66=R26)*($AC$25:$AC$66=S26),ABS($AE$25:$AE$66-Q26)), 0 )))} -> -0.009 | W26: {=IFERROR( _xlfn.FORECAST.LINEAR( Q26, INDEX($AI$25:$AI$66, MATCH(1, ($AE$25:$AE$66<=Q26)*($AI$25:$AI$66<>"x")*($AB$25:$AB$66=R26)*($AC$25:$AC$66=S26), 0) ): INDEX($AI$25:$AI$66, MATCH(1, ($AE$25:$AE$66>=Q26)*($AI$25:$AI$66<>"x")*($AB$25:$AB$66=R26)*($AC$25:$AC$66=S26), 0) ), INDEX($AE$25:$AE$66, MATCH(1, ($AE$25:$AE$66<=Q26)*($AI$25:$AI$66<>"x")*($AB$25:$AB$66=R26)*($AC$25:$AC$66=S26), 0) ): INDEX($AE$25:$AE$66, MATCH(1, ($AE$25:$AE$66>=Q26)*($AI$25:$AI$66<>"x")*($AB$25:$AB$66=R26)*($AC$25:$AC$66=S26), 0) ) ),INDEX($AI$25:$AI$66, MATCH( MIN(IF(($AI$25:$AI$66<>"x")*($AB$25:$AB$66=R26)*($AC$25:$AC$66=S26),ABS($AE$25:$AE$66-Q26))), IF(($AI$25:$AI$66<>"x")*($AB$25:$AB$66=R26)*($AC$25:$AC$66=S26),ABS($AE$25:$AE$66-Q26)), 0 )))} -> 0.013 | X26: =((((ABS(T26-U26)/(T$24-U$24))+(ABS(U26-V26)/(U$24-V$24))+(ABS(V26-W26)/(V$24-W$24)))/3)*(((T$24-U$24)+(U$24-V$24)+(V$24-W$24))/3)) -> 0.025341977 | Y26: =AJ35 -> 0.062 | AB26: mV | AC26: 50 | AD26: Hz | AE26: 1 | AF26: -0.0015 | AG26: 0.01 | AH26: x | AI26: x | AJ26: 0.0094
C27: Model matematis Pengukuran | F27: : | G27: C = Vs - VUUT | I27: Model dengan memperhitungkan faktor-faktor lain yang berpengaruh | Q27: =E4 -> 0.54 | R27: =F4 -> V1 | S27: =C4 -> 50 | T27: {=IFERROR( _xlfn.FORECAST.LINEAR( Q27, INDEX($AF$25:$AF$66, MATCH(1, ($AE$25:$AE$66<=Q27)*($AF$25:$AF$66<>"x")*($AB$25:$AB$66=R27)*($AC$25:$AC$66=S27), 0) ): INDEX($AF$25:$AF$66, MATCH(1, ($AE$25:$AE$66>=Q27)*($AF$25:$AF$66<>"x")*($AB$25:$AB$66=R27)*($AC$25:$AC$66=S27), 0) ), INDEX($AE$25:$AE$66, MATCH(1, ($AE$25:$AE$66<=Q27)*($AF$25:$AF$66<>"x")*($AB$25:$AB$66=R27)*($AC$25:$AC$66=S27), 0) ): INDEX($AE$25:$AE$66, MATCH(1, ($AE$25:$AE$66>=Q27)*($AF$25:$AF$66<>"x")*($AB$25:$AB$66=R27)*($AC$25:$AC$66=S27), 0) ) ),INDEX($AF$25:$AF$66, MATCH( MIN(IF(($AF$25:$AF$66<>"x")*($AB$25:$AB$66=R27)*($AC$25:$AC$66=S27),ABS($AE$25:$AE$66-Q27))), IF(($AF$25:$AF$66<>"x")*($AB$25:$AB$66=R27)*($AC$25:$AC$66=S27),ABS($AE$25:$AE$66-Q27)), 0 )))} -> 0.0058650746 | U27: {=IFERROR( _xlfn.FORECAST.LINEAR( Q27, INDEX($AG$25:$AG$66, MATCH(1, ($AE$25:$AE$66<=Q27)*($AG$25:$AG$66<>"x")*($AB$25:$AB$66=R27)*($AC$25:$AC$66=S27), 0) ): INDEX($AG$25:$AG$66, MATCH(1, ($AE$25:$AE$66>=Q27)*($AG$25:$AG$66<>"x")*($AB$25:$AB$66=R27)*($AC$25:$AC$66=S27), 0) ), INDEX($AE$25:$AE$66, MATCH(1, ($AE$25:$AE$66<=Q27)*($AG$25:$AG$66<>"x")*($AB$25:$AB$66=R27)*($AC$25:$AC$66=S27), 0) ): INDEX($AE$25:$AE$66, MATCH(1, ($AE$25:$AE$66>=Q27)*($AG$25:$AG$66<>"x")*($AB$25:$AB$66=R27)*($AC$25:$AC$66=S27), 0) ) ),INDEX($AG$25:$AG$66, MATCH( MIN(IF(($AG$25:$AG$66<>"x")*($AB$25:$AB$66=R27)*($AC$25:$AC$66=S27),ABS($AE$25:$AE$66-Q27))), IF(($AG$25:$AG$66<>"x")*($AB$25:$AB$66=R27)*($AC$25:$AC$66=S27),ABS($AE$25:$AE$66-Q27)), 0 )))} -> -0.075522388 | V27: {=IFERROR( _xlfn.FORECAST.LINEAR( Q27, INDEX($AH$25:$AH$66, MATCH(1, ($AE$25:$AE$66<=Q27)*($AH$25:$AH$66<>"x")*($AB$25:$AB$66=R27)*($AC$25:$AC$66=S27), 0) ): INDEX($AH$25:$AH$66, MATCH(1, ($AE$25:$AE$66>=Q27)*($AH$25:$AH$66<>"x")*($AB$25:$AB$66=R27)*($AC$25:$AC$66=S27), 0) ), INDEX($AE$25:$AE$66, MATCH(1, ($AE$25:$AE$66<=Q27)*($AH$25:$AH$66<>"x")*($AB$25:$AB$66=R27)*($AC$25:$AC$66=S27), 0) ): INDEX($AE$25:$AE$66, MATCH(1, ($AE$25:$AE$66>=Q27)*($AH$25:$AH$66<>"x")*($AB$25:$AB$66=R27)*($AC$25:$AC$66=S27), 0) ) ),INDEX($AH$25:$AH$66, MATCH( MIN(IF(($AH$25:$AH$66<>"x")*($AB$25:$AB$66=R27)*($AC$25:$AC$66=S27),ABS($AE$25:$AE$66-Q27))), IF(($AH$25:$AH$66<>"x")*($AB$25:$AB$66=R27)*($AC$25:$AC$66=S27),ABS($AE$25:$AE$66-Q27)), 0 )))} -> 0 | W27: {=IFERROR( _xlfn.FORECAST.LINEAR( Q27, INDEX($AI$25:$AI$66, MATCH(1, ($AE$25:$AE$66<=Q27)*($AI$25:$AI$66<>"x")*($AB$25:$AB$66=R27)*($AC$25:$AC$66=S27), 0) ): INDEX($AI$25:$AI$66, MATCH(1, ($AE$25:$AE$66>=Q27)*($AI$25:$AI$66<>"x")*($AB$25:$AB$66=R27)*($AC$25:$AC$66=S27), 0) ), INDEX($AE$25:$AE$66, MATCH(1, ($AE$25:$AE$66<=Q27)*($AI$25:$AI$66<>"x")*($AB$25:$AB$66=R27)*($AC$25:$AC$66=S27), 0) ): INDEX($AE$25:$AE$66, MATCH(1, ($AE$25:$AE$66>=Q27)*($AI$25:$AI$66<>"x")*($AB$25:$AB$66=R27)*($AC$25:$AC$66=S27), 0) ) ),INDEX($AI$25:$AI$66, MATCH( MIN(IF(($AI$25:$AI$66<>"x")*($AB$25:$AB$66=R27)*($AC$25:$AC$66=S27),ABS($AE$25:$AE$66-Q27))), IF(($AI$25:$AI$66<>"x")*($AB$25:$AB$66=R27)*($AC$25:$AC$66=S27),ABS($AE$25:$AE$66-Q27)), 0 )))} -> 0.00016 | X27: =((((ABS(T27-U27)/(T$24-U$24))+(ABS(U27-V27)/(U$24-V$24))+(ABS(V27-W27)/(V$24-W$24)))/3)*(((T$24-U$24)+(U$24-V$24)+(V$24-W$24))/3)) -> 0.046980087 | Y27: =AJ37 -> 0.1 | AB27: mV | AC27: 50 | AD27: Hz | AE27: 3.3 | AF27: -0.0011 | AG27: 0.122 | AH27: x | AI27: x | AJ27: 0.0096
F28: : | G28: C = Vs + δVs - VUUT | Q28: =E5 -> 0.6 | R28: =F5 -> V1 | S28: =C5 -> 50 | T28: {=IFERROR( _xlfn.FORECAST.LINEAR( Q28, INDEX($AF$25:$AF$66, MATCH(1, ($AE$25:$AE$66<=Q28)*($AF$25:$AF$66<>"x")*($AB$25:$AB$66=R28)*($AC$25:$AC$66=S28), 0) ): INDEX($AF$25:$AF$66, MATCH(1, ($AE$25:$AE$66>=Q28)*($AF$25:$AF$66<>"x")*($AB$25:$AB$66=R28)*($AC$25:$AC$66=S28), 0) ), INDEX($AE$25:$AE$66, MATCH(1, ($AE$25:$AE$66<=Q28)*($AF$25:$AF$66<>"x")*($AB$25:$AB$66=R28)*($AC$25:$AC$66=S28), 0) ): INDEX($AE$25:$AE$66, MATCH(1, ($AE$25:$AE$66>=Q28)*($AF$25:$AF$66<>"x")*($AB$25:$AB$66=R28)*($AC$25:$AC$66=S28), 0) ) ),INDEX($AF$25:$AF$66, MATCH( MIN(IF(($AF$25:$AF$66<>"x")*($AB$25:$AB$66=R28)*($AC$25:$AC$66=S28),ABS($AE$25:$AE$66-Q28))), IF(($AF$25:$AF$66<>"x")*($AB$25:$AB$66=R28)*($AC$25:$AC$66=S28),ABS($AE$25:$AE$66-Q28)), 0 )))} -> 0.0058722388 | U28: {=IFERROR( _xlfn.FORECAST.LINEAR( Q28, INDEX($AG$25:$AG$66, MATCH(1, ($AE$25:$AE$66<=Q28)*($AG$25:$AG$66<>"x")*($AB$25:$AB$66=R28)*($AC$25:$AC$66=S28), 0) ): INDEX($AG$25:$AG$66, MATCH(1, ($AE$25:$AE$66>=Q28)*($AG$25:$AG$66<>"x")*($AB$25:$AB$66=R28)*($AC$25:$AC$66=S28), 0) ), INDEX($AE$25:$AE$66, MATCH(1, ($AE$25:$AE$66<=Q28)*($AG$25:$AG$66<>"x")*($AB$25:$AB$66=R28)*($AC$25:$AC$66=S28), 0) ): INDEX($AE$25:$AE$66, MATCH(1, ($AE$25:$AE$66>=Q28)*($AG$25:$AG$66<>"x")*($AB$25:$AB$66=R28)*($AC$25:$AC$66=S28), 0) ) ),INDEX($AG$25:$AG$66, MATCH( MIN(IF(($AG$25:$AG$66<>"x")*($AB$25:$AB$66=R28)*($AC$25:$AC$66=S28),ABS($AE$25:$AE$66-Q28))), IF(($AG$25:$AG$66<>"x")*($AB$25:$AB$66=R28)*($AC$25:$AC$66=S28),ABS($AE$25:$AE$66-Q28)), 0 )))} -> -0.065671642 | V28: {=IFERROR( _xlfn.FORECAST.LINEAR( Q28, INDEX($AH$25:$AH$66, MATCH(1, ($AE$25:$AE$66<=Q28)*($AH$25:$AH$66<>"x")*($AB$25:$AB$66=R28)*($AC$25:$AC$66=S28), 0) ): INDEX($AH$25:$AH$66, MATCH(1, ($AE$25:$AE$66>=Q28)*($AH$25:$AH$66<>"x")*($AB$25:$AB$66=R28)*($AC$25:$AC$66=S28), 0) ), INDEX($AE$25:$AE$66, MATCH(1, ($AE$25:$AE$66<=Q28)*($AH$25:$AH$66<>"x")*($AB$25:$AB$66=R28)*($AC$25:$AC$66=S28), 0) ): INDEX($AE$25:$AE$66, MATCH(1, ($AE$25:$AE$66>=Q28)*($AH$25:$AH$66<>"x")*($AB$25:$AB$66=R28)*($AC$25:$AC$66=S28), 0) ) ),INDEX($AH$25:$AH$66, MATCH( MIN(IF(($AH$25:$AH$66<>"x")*($AB$25:$AB$66=R28)*($AC$25:$AC$66=S28),ABS($AE$25:$AE$66-Q28))), IF(($AH$25:$AH$66<>"x")*($AB$25:$AB$66=R28)*($AC$25:$AC$66=S28),ABS($AE$25:$AE$66-Q28)), 0 )))} -> 0 | W28: {=IFERROR( _xlfn.FORECAST.LINEAR( Q28, INDEX($AI$25:$AI$66, MATCH(1, ($AE$25:$AE$66<=Q28)*($AI$25:$AI$66<>"x")*($AB$25:$AB$66=R28)*($AC$25:$AC$66=S28), 0) ): INDEX($AI$25:$AI$66, MATCH(1, ($AE$25:$AE$66>=Q28)*($AI$25:$AI$66<>"x")*($AB$25:$AB$66=R28)*($AC$25:$AC$66=S28), 0) ), INDEX($AE$25:$AE$66, MATCH(1, ($AE$25:$AE$66<=Q28)*($AI$25:$AI$66<>"x")*($AB$25:$AB$66=R28)*($AC$25:$AC$66=S28), 0) ): INDEX($AE$25:$AE$66, MATCH(1, ($AE$25:$AE$66>=Q28)*($AI$25:$AI$66<>"x")*($AB$25:$AB$66=R28)*($AC$25:$AC$66=S28), 0) ) ),INDEX($AI$25:$AI$66, MATCH( MIN(IF(($AI$25:$AI$66<>"x")*($AB$25:$AB$66=R28)*($AC$25:$AC$66=S28),ABS($AE$25:$AE$66-Q28))), IF(($AI$25:$AI$66<>"x")*($AB$25:$AB$66=R28)*($AC$25:$AC$66=S28),ABS($AE$25:$AE$66-Q28)), 0 )))} -> 0.00016 | X28: =((((ABS(T28-U28)/(T$24-U$24))+(ABS(U28-V28)/(U$24-V$24))+(ABS(V28-W28)/(V$24-W$24)))/3)*(((T$24-U$24)+(U$24-V$24)+(V$24-W$24))/3)) -> 0.041085398 | Y28: =AJ38 -> 0.00018 | AB28: mV | AC28: 50 | AD28: Hz | AE28: 29.699 | AF28: -0.003 | AG28: 0.004 | AH28: x | AI28: x | AJ28: 0.015
G29: C | H29: : koreksi tegangan dari UUT | Q29: =E6 -> 3 | R29: =F6 -> V1 | S29: =C6 -> 50 | T29: {=IFERROR( _xlfn.FORECAST.LINEAR( Q29, INDEX($AF$25:$AF$66, MATCH(1, ($AE$25:$AE$66<=Q29)*($AF$25:$AF$66<>"x")*($AB$25:$AB$66=R29)*($AC$25:$AC$66=S29), 0) ): INDEX($AF$25:$AF$66, MATCH(1, ($AE$25:$AE$66>=Q29)*($AF$25:$AF$66<>"x")*($AB$25:$AB$66=R29)*($AC$25:$AC$66=S29), 0) ), INDEX($AE$25:$AE$66, MATCH(1, ($AE$25:$AE$66<=Q29)*($AF$25:$AF$66<>"x")*($AB$25:$AB$66=R29)*($AC$25:$AC$66=S29), 0) ): INDEX($AE$25:$AE$66, MATCH(1, ($AE$25:$AE$66>=Q29)*($AF$25:$AF$66<>"x")*($AB$25:$AB$66=R29)*($AC$25:$AC$66=S29), 0) ) ),INDEX($AF$25:$AF$66, MATCH( MIN(IF(($AF$25:$AF$66<>"x")*($AB$25:$AB$66=R29)*($AC$25:$AC$66=S29),ABS($AE$25:$AE$66-Q29))), IF(($AF$25:$AF$66<>"x")*($AB$25:$AB$66=R29)*($AC$25:$AC$66=S29),ABS($AE$25:$AE$66-Q29)), 0 )))} -> 0.00076967381 | U29: {=IFERROR( _xlfn.FORECAST.LINEAR( Q29, INDEX($AG$25:$AG$66, MATCH(1, ($AE$25:$AE$66<=Q29)*($AG$25:$AG$66<>"x")*($AB$25:$AB$66=R29)*($AC$25:$AC$66=S29), 0) ): INDEX($AG$25:$AG$66, MATCH(1, ($AE$25:$AE$66>=Q29)*($AG$25:$AG$66<>"x")*($AB$25:$AB$66=R29)*($AC$25:$AC$66=S29), 0) ), INDEX($AE$25:$AE$66, MATCH(1, ($AE$25:$AE$66<=Q29)*($AG$25:$AG$66<>"x")*($AB$25:$AB$66=R29)*($AC$25:$AC$66=S29), 0) ): INDEX($AE$25:$AE$66, MATCH(1, ($AE$25:$AE$66>=Q29)*($AG$25:$AG$66<>"x")*($AB$25:$AB$66=R29)*($AC$25:$AC$66=S29), 0) ) ),INDEX($AG$25:$AG$66, MATCH( MIN(IF(($AG$25:$AG$66<>"x")*($AB$25:$AB$66=R29)*($AC$25:$AC$66=S29),ABS($AE$25:$AE$66-Q29))), IF(($AG$25:$AG$66<>"x")*($AB$25:$AB$66=R29)*($AC$25:$AC$66=S29),ABS($AE$25:$AE$66-Q29)), 0 )))} -> 0 | V29: {=IFERROR( _xlfn.FORECAST.LINEAR( Q29, INDEX($AH$25:$AH$66, MATCH(1, ($AE$25:$AE$66<=Q29)*($AH$25:$AH$66<>"x")*($AB$25:$AB$66=R29)*($AC$25:$AC$66=S29), 0) ): INDEX($AH$25:$AH$66, MATCH(1, ($AE$25:$AE$66>=Q29)*($AH$25:$AH$66<>"x")*($AB$25:$AB$66=R29)*($AC$25:$AC$66=S29), 0) ), INDEX($AE$25:$AE$66, MATCH(1, ($AE$25:$AE$66<=Q29)*($AH$25:$AH$66<>"x")*($AB$25:$AB$66=R29)*($AC$25:$AC$66=S29), 0) ): INDEX($AE$25:$AE$66, MATCH(1, ($AE$25:$AE$66>=Q29)*($AH$25:$AH$66<>"x")*($AB$25:$AB$66=R29)*($AC$25:$AC$66=S29), 0) ) ),INDEX($AH$25:$AH$66, MATCH( MIN(IF(($AH$25:$AH$66<>"x")*($AB$25:$AB$66=R29)*($AC$25:$AC$66=S29),ABS($AE$25:$AE$66-Q29))), IF(($AH$25:$AH$66<>"x")*($AB$25:$AB$66=R29)*($AC$25:$AC$66=S29),ABS($AE$25:$AE$66-Q29)), 0 )))} -> 0 | W29: {=IFERROR( _xlfn.FORECAST.LINEAR( Q29, INDEX($AI$25:$AI$66, MATCH(1, ($AE$25:$AE$66<=Q29)*($AI$25:$AI$66<>"x")*($AB$25:$AB$66=R29)*($AC$25:$AC$66=S29), 0) ): INDEX($AI$25:$AI$66, MATCH(1, ($AE$25:$AE$66>=Q29)*($AI$25:$AI$66<>"x")*($AB$25:$AB$66=R29)*($AC$25:$AC$66=S29), 0) ), INDEX($AE$25:$AE$66, MATCH(1, ($AE$25:$AE$66<=Q29)*($AI$25:$AI$66<>"x")*($AB$25:$AB$66=R29)*($AC$25:$AC$66=S29), 0) ): INDEX($AE$25:$AE$66, MATCH(1, ($AE$25:$AE$66>=Q29)*($AI$25:$AI$66<>"x")*($AB$25:$AB$66=R29)*($AC$25:$AC$66=S29), 0) ) ),INDEX($AI$25:$AI$66, MATCH( MIN(IF(($AI$25:$AI$66<>"x")*($AB$25:$AB$66=R29)*($AC$25:$AC$66=S29),ABS($AE$25:$AE$66-Q29))), IF(($AI$25:$AI$66<>"x")*($AB$25:$AB$66=R29)*($AC$25:$AC$66=S29),ABS($AE$25:$AE$66-Q29)), 0 )))} -> 0.00016 | X29: =((((ABS(T29-U29)/(T$24-U$24))+(ABS(U29-V29)/(U$24-V$24))+(ABS(V29-W29)/(V$24-W$24)))/3)*(((T$24-U$24)+(U$24-V$24)+(V$24-W$24))/3)) -> 0.00029260724 | Y29: =AJ45 -> 0.0012 | AB29: mV | AC29: 50 | AD29: Hz | AE29: 33 | AF29: -0.016 | AG29: -0.126 | AH29: x | AI29: x | AJ29: 0.015
G30: Vs | H30: : tegangan standar | Q30: =E7 -> 5.4 | R30: =F7 -> V2 | S30: =C7 -> 50 | T30: {=IFERROR( _xlfn.FORECAST.LINEAR( Q30, INDEX($AF$25:$AF$66, MATCH(1, ($AE$25:$AE$66<=Q30)*($AF$25:$AF$66<>"x")*($AB$25:$AB$66=R30)*($AC$25:$AC$66=S30), 0) ): INDEX($AF$25:$AF$66, MATCH(1, ($AE$25:$AE$66>=Q30)*($AF$25:$AF$66<>"x")*($AB$25:$AB$66=R30)*($AC$25:$AC$66=S30), 0) ), INDEX($AE$25:$AE$66, MATCH(1, ($AE$25:$AE$66<=Q30)*($AF$25:$AF$66<>"x")*($AB$25:$AB$66=R30)*($AC$25:$AC$66=S30), 0) ): INDEX($AE$25:$AE$66, MATCH(1, ($AE$25:$AE$66>=Q30)*($AF$25:$AF$66<>"x")*($AB$25:$AB$66=R30)*($AC$25:$AC$66=S30), 0) ) ),INDEX($AF$25:$AF$66, MATCH( MIN(IF(($AF$25:$AF$66<>"x")*($AB$25:$AB$66=R30)*($AC$25:$AC$66=S30),ABS($AE$25:$AE$66-Q30))), IF(($AF$25:$AF$66<>"x")*($AB$25:$AB$66=R30)*($AC$25:$AC$66=S30),ABS($AE$25:$AE$66-Q30)), 0 )))} -> -0.0013608955 | U30: {=IFERROR( _xlfn.FORECAST.LINEAR( Q30, INDEX($AG$25:$AG$66, MATCH(1, ($AE$25:$AE$66<=Q30)*($AG$25:$AG$66<>"x")*($AB$25:$AB$66=R30)*($AC$25:$AC$66=S30), 0) ): INDEX($AG$25:$AG$66, MATCH(1, ($AE$25:$AE$66>=Q30)*($AG$25:$AG$66<>"x")*($AB$25:$AB$66=R30)*($AC$25:$AC$66=S30), 0) ), INDEX($AE$25:$AE$66, MATCH(1, ($AE$25:$AE$66<=Q30)*($AG$25:$AG$66<>"x")*($AB$25:$AB$66=R30)*($AC$25:$AC$66=S30), 0) ): INDEX($AE$25:$AE$66, MATCH(1, ($AE$25:$AE$66>=Q30)*($AG$25:$AG$66<>"x")*($AB$25:$AB$66=R30)*($AC$25:$AC$66=S30), 0) ) ),INDEX($AG$25:$AG$66, MATCH( MIN(IF(($AG$25:$AG$66<>"x")*($AB$25:$AB$66=R30)*($AC$25:$AC$66=S30),ABS($AE$25:$AE$66-Q30))), IF(($AG$25:$AG$66<>"x")*($AB$25:$AB$66=R30)*($AC$25:$AC$66=S30),ABS($AE$25:$AE$66-Q30)), 0 )))} -> -0.001380597 | V30: {=IFERROR( _xlfn.FORECAST.LINEAR( Q30, INDEX($AH$25:$AH$66, MATCH(1, ($AE$25:$AE$66<=Q30)*($AH$25:$AH$66<>"x")*($AB$25:$AB$66=R30)*($AC$25:$AC$66=S30), 0) ): INDEX($AH$25:$AH$66, MATCH(1, ($AE$25:$AE$66>=Q30)*($AH$25:$AH$66<>"x")*($AB$25:$AB$66=R30)*($AC$25:$AC$66=S30), 0) ), INDEX($AE$25:$AE$66, MATCH(1, ($AE$25:$AE$66<=Q30)*($AH$25:$AH$66<>"x")*($AB$25:$AB$66=R30)*($AC$25:$AC$66=S30), 0) ): INDEX($AE$25:$AE$66, MATCH(1, ($AE$25:$AE$66>=Q30)*($AH$25:$AH$66<>"x")*($AB$25:$AB$66=R30)*($AC$25:$AC$66=S30), 0) ) ),INDEX($AH$25:$AH$66, MATCH( MIN(IF(($AH$25:$AH$66<>"x")*($AB$25:$AB$66=R30)*($AC$25:$AC$66=S30),ABS($AE$25:$AE$66-Q30))), IF(($AH$25:$AH$66<>"x")*($AB$25:$AB$66=R30)*($AC$25:$AC$66=S30),ABS($AE$25:$AE$66-Q30)), 0 )))} -> -0.0005 | W30: {=IFERROR( _xlfn.FORECAST.LINEAR( Q30, INDEX($AI$25:$AI$66, MATCH(1, ($AE$25:$AE$66<=Q30)*($AI$25:$AI$66<>"x")*($AB$25:$AB$66=R30)*($AC$25:$AC$66=S30), 0) ): INDEX($AI$25:$AI$66, MATCH(1, ($AE$25:$AE$66>=Q30)*($AI$25:$AI$66<>"x")*($AB$25:$AB$66=R30)*($AC$25:$AC$66=S30), 0) ), INDEX($AE$25:$AE$66, MATCH(1, ($AE$25:$AE$66<=Q30)*($AI$25:$AI$66<>"x")*($AB$25:$AB$66=R30)*($AC$25:$AC$66=S30), 0) ): INDEX($AE$25:$AE$66, MATCH(1, ($AE$25:$AE$66>=Q30)*($AI$25:$AI$66<>"x")*($AB$25:$AB$66=R30)*($AC$25:$AC$66=S30), 0) ) ),INDEX($AI$25:$AI$66, MATCH( MIN(IF(($AI$25:$AI$66<>"x")*($AB$25:$AB$66=R30)*($AC$25:$AC$66=S30),ABS($AE$25:$AE$66-Q30))), IF(($AI$25:$AI$66<>"x")*($AB$25:$AB$66=R30)*($AC$25:$AC$66=S30),ABS($AE$25:$AE$66-Q30)), 0 )))} -> 0.0006 | X30: =((((ABS(T30-U30)/(T$24-U$24))+(ABS(U30-V30)/(U$24-V$24))+(ABS(V30-W30)/(V$24-W$24)))/3)*(((T$24-U$24)+(U$24-V$24)+(V$24-W$24))/3)) -> 0.00075309507 | Y30: =AJ47 -> 0.00098 | AB30: mV | AC30: 50 | AD30: Hz | AE30: 100 | AF30: -0.016 | AG30: x | AH30: -0.009 | AI30: 0.013 | AJ30: 0.025
G31: δVs | H31: : koreksi tegangan standar | Q31: =E8 -> 6 | R31: =F8 -> V2 | S31: =C8 -> 50 | T31: {=IFERROR( _xlfn.FORECAST.LINEAR( Q31, INDEX($AF$25:$AF$66, MATCH(1, ($AE$25:$AE$66<=Q31)*($AF$25:$AF$66<>"x")*($AB$25:$AB$66=R31)*($AC$25:$AC$66=S31), 0) ): INDEX($AF$25:$AF$66, MATCH(1, ($AE$25:$AE$66>=Q31)*($AF$25:$AF$66<>"x")*($AB$25:$AB$66=R31)*($AC$25:$AC$66=S31), 0) ), INDEX($AE$25:$AE$66, MATCH(1, ($AE$25:$AE$66<=Q31)*($AF$25:$AF$66<>"x")*($AB$25:$AB$66=R31)*($AC$25:$AC$66=S31), 0) ): INDEX($AE$25:$AE$66, MATCH(1, ($AE$25:$AE$66>=Q31)*($AF$25:$AF$66<>"x")*($AB$25:$AB$66=R31)*($AC$25:$AC$66=S31), 0) ) ),INDEX($AF$25:$AF$66, MATCH( MIN(IF(($AF$25:$AF$66<>"x")*($AB$25:$AB$66=R31)*($AC$25:$AC$66=S31),ABS($AE$25:$AE$66-Q31))), IF(($AF$25:$AF$66<>"x")*($AB$25:$AB$66=R31)*($AC$25:$AC$66=S31),ABS($AE$25:$AE$66-Q31)), 0 )))} -> -0.0013268657 | U31: {=IFERROR( _xlfn.FORECAST.LINEAR( Q31, INDEX($AG$25:$AG$66, MATCH(1, ($AE$25:$AE$66<=Q31)*($AG$25:$AG$66<>"x")*($AB$25:$AB$66=R31)*($AC$25:$AC$66=S31), 0) ): INDEX($AG$25:$AG$66, MATCH(1, ($AE$25:$AE$66>=Q31)*($AG$25:$AG$66<>"x")*($AB$25:$AB$66=R31)*($AC$25:$AC$66=S31), 0) ), INDEX($AE$25:$AE$66, MATCH(1, ($AE$25:$AE$66<=Q31)*($AG$25:$AG$66<>"x")*($AB$25:$AB$66=R31)*($AC$25:$AC$66=S31), 0) ): INDEX($AE$25:$AE$66, MATCH(1, ($AE$25:$AE$66>=Q31)*($AG$25:$AG$66<>"x")*($AB$25:$AB$66=R31)*($AC$25:$AC$66=S31), 0) ) ),INDEX($AG$25:$AG$66, MATCH( MIN(IF(($AG$25:$AG$66<>"x")*($AB$25:$AB$66=R31)*($AC$25:$AC$66=S31),ABS($AE$25:$AE$66-Q31))), IF(($AG$25:$AG$66<>"x")*($AB$25:$AB$66=R31)*($AC$25:$AC$66=S31),ABS($AE$25:$AE$66-Q31)), 0 )))} -> -0.0013179104 | V31: {=IFERROR( _xlfn.FORECAST.LINEAR( Q31, INDEX($AH$25:$AH$66, MATCH(1, ($AE$25:$AE$66<=Q31)*($AH$25:$AH$66<>"x")*($AB$25:$AB$66=R31)*($AC$25:$AC$66=S31), 0) ): INDEX($AH$25:$AH$66, MATCH(1, ($AE$25:$AE$66>=Q31)*($AH$25:$AH$66<>"x")*($AB$25:$AB$66=R31)*($AC$25:$AC$66=S31), 0) ), INDEX($AE$25:$AE$66, MATCH(1, ($AE$25:$AE$66<=Q31)*($AH$25:$AH$66<>"x")*($AB$25:$AB$66=R31)*($AC$25:$AC$66=S31), 0) ): INDEX($AE$25:$AE$66, MATCH(1, ($AE$25:$AE$66>=Q31)*($AH$25:$AH$66<>"x")*($AB$25:$AB$66=R31)*($AC$25:$AC$66=S31), 0) ) ),INDEX($AH$25:$AH$66, MATCH( MIN(IF(($AH$25:$AH$66<>"x")*($AB$25:$AB$66=R31)*($AC$25:$AC$66=S31),ABS($AE$25:$AE$66-Q31))), IF(($AH$25:$AH$66<>"x")*($AB$25:$AB$66=R31)*($AC$25:$AC$66=S31),ABS($AE$25:$AE$66-Q31)), 0 )))} -> -0.0005 | W31: {=IFERROR( _xlfn.FORECAST.LINEAR( Q31, INDEX($AI$25:$AI$66, MATCH(1, ($AE$25:$AE$66<=Q31)*($AI$25:$AI$66<>"x")*($AB$25:$AB$66=R31)*($AC$25:$AC$66=S31), 0) ): INDEX($AI$25:$AI$66, MATCH(1, ($AE$25:$AE$66>=Q31)*($AI$25:$AI$66<>"x")*($AB$25:$AB$66=R31)*($AC$25:$AC$66=S31), 0) ), INDEX($AE$25:$AE$66, MATCH(1, ($AE$25:$AE$66<=Q31)*($AI$25:$AI$66<>"x")*($AB$25:$AB$66=R31)*($AC$25:$AC$66=S31), 0) ): INDEX($AE$25:$AE$66, MATCH(1, ($AE$25:$AE$66>=Q31)*($AI$25:$AI$66<>"x")*($AB$25:$AB$66=R31)*($AC$25:$AC$66=S31), 0) ) ),INDEX($AI$25:$AI$66, MATCH( MIN(IF(($AI$25:$AI$66<>"x")*($AB$25:$AB$66=R31)*($AC$25:$AC$66=S31),ABS($AE$25:$AE$66-Q31))), IF(($AI$25:$AI$66<>"x")*($AB$25:$AB$66=R31)*($AC$25:$AC$66=S31),ABS($AE$25:$AE$66-Q31)), 0 )))} -> 0.0006 | X31: =((((ABS(T31-U31)/(T$24-U$24))+(ABS(U31-V31)/(U$24-V$24))+(ABS(V31-W31)/(V$24-W$24)))/3)*(((T$24-U$24)+(U$24-V$24)+(V$24-W$24))/3)) -> 0.00073064568 | Y31: =AJ48 -> 0.0018 | AB31: mV | AC31: 50 | AD31: Hz | AE31: 297 | AF31: x | AG31: -0.03 | AH31: x | AI31: x | AJ31: x
G32: VUUT | H32: : tegangan UUT | Q32: =E9 -> 30 | R32: =F9 -> V2 | S32: =C9 -> 50 | T32: {=IFERROR( _xlfn.FORECAST.LINEAR( Q32, INDEX($AF$25:$AF$66, MATCH(1, ($AE$25:$AE$66<=Q32)*($AF$25:$AF$66<>"x")*($AB$25:$AB$66=R32)*($AC$25:$AC$66=S32), 0) ): INDEX($AF$25:$AF$66, MATCH(1, ($AE$25:$AE$66>=Q32)*($AF$25:$AF$66<>"x")*($AB$25:$AB$66=R32)*($AC$25:$AC$66=S32), 0) ), INDEX($AE$25:$AE$66, MATCH(1, ($AE$25:$AE$66<=Q32)*($AF$25:$AF$66<>"x")*($AB$25:$AB$66=R32)*($AC$25:$AC$66=S32), 0) ): INDEX($AE$25:$AE$66, MATCH(1, ($AE$25:$AE$66>=Q32)*($AF$25:$AF$66<>"x")*($AB$25:$AB$66=R32)*($AC$25:$AC$66=S32), 0) ) ),INDEX($AF$25:$AF$66, MATCH( MIN(IF(($AF$25:$AF$66<>"x")*($AB$25:$AB$66=R32)*($AC$25:$AC$66=S32),ABS($AE$25:$AE$66-Q32))), IF(($AF$25:$AF$66<>"x")*($AB$25:$AB$66=R32)*($AC$25:$AC$66=S32),ABS($AE$25:$AE$66-Q32)), 0 )))} -> -9.7451537e-05 | U32: {=IFERROR( _xlfn.FORECAST.LINEAR( Q32, INDEX($AG$25:$AG$66, MATCH(1, ($AE$25:$AE$66<=Q32)*($AG$25:$AG$66<>"x")*($AB$25:$AB$66=R32)*($AC$25:$AC$66=S32), 0) ): INDEX($AG$25:$AG$66, MATCH(1, ($AE$25:$AE$66>=Q32)*($AG$25:$AG$66<>"x")*($AB$25:$AB$66=R32)*($AC$25:$AC$66=S32), 0) ), INDEX($AE$25:$AE$66, MATCH(1, ($AE$25:$AE$66<=Q32)*($AG$25:$AG$66<>"x")*($AB$25:$AB$66=R32)*($AC$25:$AC$66=S32), 0) ): INDEX($AE$25:$AE$66, MATCH(1, ($AE$25:$AE$66>=Q32)*($AG$25:$AG$66<>"x")*($AB$25:$AB$66=R32)*($AC$25:$AC$66=S32), 0) ) ),INDEX($AG$25:$AG$66, MATCH( MIN(IF(($AG$25:$AG$66<>"x")*($AB$25:$AB$66=R32)*($AC$25:$AC$66=S32),ABS($AE$25:$AE$66-Q32))), IF(($AG$25:$AG$66<>"x")*($AB$25:$AB$66=R32)*($AC$25:$AC$66=S32),ABS($AE$25:$AE$66-Q32)), 0 )))} -> -0.0009 | V32: {=IFERROR( _xlfn.FORECAST.LINEAR( Q32, INDEX($AH$25:$AH$66, MATCH(1, ($AE$25:$AE$66<=Q32)*($AH$25:$AH$66<>"x")*($AB$25:$AB$66=R32)*($AC$25:$AC$66=S32), 0) ): INDEX($AH$25:$AH$66, MATCH(1, ($AE$25:$AE$66>=Q32)*($AH$25:$AH$66<>"x")*($AB$25:$AB$66=R32)*($AC$25:$AC$66=S32), 0) ), INDEX($AE$25:$AE$66, MATCH(1, ($AE$25:$AE$66<=Q32)*($AH$25:$AH$66<>"x")*($AB$25:$AB$66=R32)*($AC$25:$AC$66=S32), 0) ): INDEX($AE$25:$AE$66, MATCH(1, ($AE$25:$AE$66>=Q32)*($AH$25:$AH$66<>"x")*($AB$25:$AB$66=R32)*($AC$25:$AC$66=S32), 0) ) ),INDEX($AH$25:$AH$66, MATCH( MIN(IF(($AH$25:$AH$66<>"x")*($AB$25:$AB$66=R32)*($AC$25:$AC$66=S32),ABS($AE$25:$AE$66-Q32))), IF(($AH$25:$AH$66<>"x")*($AB$25:$AB$66=R32)*($AC$25:$AC$66=S32),ABS($AE$25:$AE$66-Q32)), 0 )))} -> -0.0005 | W32: {=IFERROR( _xlfn.FORECAST.LINEAR( Q32, INDEX($AI$25:$AI$66, MATCH(1, ($AE$25:$AE$66<=Q32)*($AI$25:$AI$66<>"x")*($AB$25:$AB$66=R32)*($AC$25:$AC$66=S32), 0) ): INDEX($AI$25:$AI$66, MATCH(1, ($AE$25:$AE$66>=Q32)*($AI$25:$AI$66<>"x")*($AB$25:$AB$66=R32)*($AC$25:$AC$66=S32), 0) ), INDEX($AE$25:$AE$66, MATCH(1, ($AE$25:$AE$66<=Q32)*($AI$25:$AI$66<>"x")*($AB$25:$AB$66=R32)*($AC$25:$AC$66=S32), 0) ): INDEX($AE$25:$AE$66, MATCH(1, ($AE$25:$AE$66>=Q32)*($AI$25:$AI$66<>"x")*($AB$25:$AB$66=R32)*($AC$25:$AC$66=S32), 0) ) ),INDEX($AI$25:$AI$66, MATCH( MIN(IF(($AI$25:$AI$66<>"x")*($AB$25:$AB$66=R32)*($AC$25:$AC$66=S32),ABS($AE$25:$AE$66-Q32))), IF(($AI$25:$AI$66<>"x")*($AB$25:$AB$66=R32)*($AC$25:$AC$66=S32),ABS($AE$25:$AE$66-Q32)), 0 )))} -> 0.0006 | X32: =((((ABS(T32-U32)/(T$24-U$24))+(ABS(U32-V32)/(U$24-V$24))+(ABS(V32-W32)/(V$24-W$24)))/3)*(((T$24-U$24)+(U$24-V$24)+(V$24-W$24))/3)) -> 0.00083211479 | Y32: =AJ54 -> 0.012 | AB32: mV | AC32: 50 | AD32: Hz | AE32: 320 | AF32: 0.007 | AG32: x | AH32: x | AI32: x | AJ32: 0.098
Q33: =E10 -> 54 | R33: =F10 -> V3 | S33: =C10 -> 50 | T33: {=IFERROR( _xlfn.FORECAST.LINEAR( Q33, INDEX($AF$25:$AF$66, MATCH(1, ($AE$25:$AE$66<=Q33)*($AF$25:$AF$66<>"x")*($AB$25:$AB$66=R33)*($AC$25:$AC$66=S33), 0) ): INDEX($AF$25:$AF$66, MATCH(1, ($AE$25:$AE$66>=Q33)*($AF$25:$AF$66<>"x")*($AB$25:$AB$66=R33)*($AC$25:$AC$66=S33), 0) ), INDEX($AE$25:$AE$66, MATCH(1, ($AE$25:$AE$66<=Q33)*($AF$25:$AF$66<>"x")*($AB$25:$AB$66=R33)*($AC$25:$AC$66=S33), 0) ): INDEX($AE$25:$AE$66, MATCH(1, ($AE$25:$AE$66>=Q33)*($AF$25:$AF$66<>"x")*($AB$25:$AB$66=R33)*($AC$25:$AC$66=S33), 0) ) ),INDEX($AF$25:$AF$66, MATCH( MIN(IF(($AF$25:$AF$66<>"x")*($AB$25:$AB$66=R33)*($AC$25:$AC$66=S33),ABS($AE$25:$AE$66-Q33))), IF(($AF$25:$AF$66<>"x")*($AB$25:$AB$66=R33)*($AC$25:$AC$66=S33),ABS($AE$25:$AE$66-Q33)), 0 )))} -> -0.016167164 | U33: {=IFERROR( _xlfn.FORECAST.LINEAR( Q33, INDEX($AG$25:$AG$66, MATCH(1, ($AE$25:$AE$66<=Q33)*($AG$25:$AG$66<>"x")*($AB$25:$AB$66=R33)*($AC$25:$AC$66=S33), 0) ): INDEX($AG$25:$AG$66, MATCH(1, ($AE$25:$AE$66>=Q33)*($AG$25:$AG$66<>"x")*($AB$25:$AB$66=R33)*($AC$25:$AC$66=S33), 0) ), INDEX($AE$25:$AE$66, MATCH(1, ($AE$25:$AE$66<=Q33)*($AG$25:$AG$66<>"x")*($AB$25:$AB$66=R33)*($AC$25:$AC$66=S33), 0) ): INDEX($AE$25:$AE$66, MATCH(1, ($AE$25:$AE$66>=Q33)*($AG$25:$AG$66<>"x")*($AB$25:$AB$66=R33)*($AC$25:$AC$66=S33), 0) ) ),INDEX($AG$25:$AG$66, MATCH( MIN(IF(($AG$25:$AG$66<>"x")*($AB$25:$AB$66=R33)*($AC$25:$AC$66=S33),ABS($AE$25:$AE$66-Q33))), IF(($AG$25:$AG$66<>"x")*($AB$25:$AB$66=R33)*($AC$25:$AC$66=S33),ABS($AE$25:$AE$66-Q33)), 0 )))} -> -0.015686567 | V33: {=IFERROR( _xlfn.FORECAST.LINEAR( Q33, INDEX($AH$25:$AH$66, MATCH(1, ($AE$25:$AE$66<=Q33)*($AH$25:$AH$66<>"x")*($AB$25:$AB$66=R33)*($AC$25:$AC$66=S33), 0) ): INDEX($AH$25:$AH$66, MATCH(1, ($AE$25:$AE$66>=Q33)*($AH$25:$AH$66<>"x")*($AB$25:$AB$66=R33)*($AC$25:$AC$66=S33), 0) ), INDEX($AE$25:$AE$66, MATCH(1, ($AE$25:$AE$66<=Q33)*($AH$25:$AH$66<>"x")*($AB$25:$AB$66=R33)*($AC$25:$AC$66=S33), 0) ): INDEX($AE$25:$AE$66, MATCH(1, ($AE$25:$AE$66>=Q33)*($AH$25:$AH$66<>"x")*($AB$25:$AB$66=R33)*($AC$25:$AC$66=S33), 0) ) ),INDEX($AH$25:$AH$66, MATCH( MIN(IF(($AH$25:$AH$66<>"x")*($AB$25:$AB$66=R33)*($AC$25:$AC$66=S33),ABS($AE$25:$AE$66-Q33))), IF(($AH$25:$AH$66<>"x")*($AB$25:$AB$66=R33)*($AC$25:$AC$66=S33),ABS($AE$25:$AE$66-Q33)), 0 )))} -> -0.013 | W33: {=IFERROR( _xlfn.FORECAST.LINEAR( Q33, INDEX($AI$25:$AI$66, MATCH(1, ($AE$25:$AE$66<=Q33)*($AI$25:$AI$66<>"x")*($AB$25:$AB$66=R33)*($AC$25:$AC$66=S33), 0) ): INDEX($AI$25:$AI$66, MATCH(1, ($AE$25:$AE$66>=Q33)*($AI$25:$AI$66<>"x")*($AB$25:$AB$66=R33)*($AC$25:$AC$66=S33), 0) ), INDEX($AE$25:$AE$66, MATCH(1, ($AE$25:$AE$66<=Q33)*($AI$25:$AI$66<>"x")*($AB$25:$AB$66=R33)*($AC$25:$AC$66=S33), 0) ): INDEX($AE$25:$AE$66, MATCH(1, ($AE$25:$AE$66>=Q33)*($AI$25:$AI$66<>"x")*($AB$25:$AB$66=R33)*($AC$25:$AC$66=S33), 0) ) ),INDEX($AI$25:$AI$66, MATCH( MIN(IF(($AI$25:$AI$66<>"x")*($AB$25:$AB$66=R33)*($AC$25:$AC$66=S33),ABS($AE$25:$AE$66-Q33))), IF(($AI$25:$AI$66<>"x")*($AB$25:$AB$66=R33)*($AC$25:$AC$66=S33),ABS($AE$25:$AE$66-Q33)), 0 )))} -> 0.001 | X33: =((((ABS(T33-U33)/(T$24-U$24))+(ABS(U33-V33)/(U$24-V$24))+(ABS(V33-W33)/(V$24-W$24)))/3)*(((T$24-U$24)+(U$24-V$24)+(V$24-W$24))/3)) -> 0.0070239758 | Y33: =AJ56 -> 0.0098 | AB33: mV | AC33: 1000 | AD33: Hz | AE33: 100 | AF33: -0.016 | AG33: -0.007 | AH33: -0.014 | AI33: 0.014 | AJ33: 0.02
C34: Rentang ukur | F34: =C$2 -> 50 | G34: =D$2 -> Hz | H34: =C$3 -> 50 | I34: =D$3 -> Hz | O34: AC Voltage-Measure | Q34: =E11 -> 60 | R34: =F11 -> V3 | S34: =C11 -> 50 | T34: {=IFERROR( _xlfn.FORECAST.LINEAR( Q34, INDEX($AF$25:$AF$66, MATCH(1, ($AE$25:$AE$66<=Q34)*($AF$25:$AF$66<>"x")*($AB$25:$AB$66=R34)*($AC$25:$AC$66=S34), 0) ): INDEX($AF$25:$AF$66, MATCH(1, ($AE$25:$AE$66>=Q34)*($AF$25:$AF$66<>"x")*($AB$25:$AB$66=R34)*($AC$25:$AC$66=S34), 0) ), INDEX($AE$25:$AE$66, MATCH(1, ($AE$25:$AE$66<=Q34)*($AF$25:$AF$66<>"x")*($AB$25:$AB$66=R34)*($AC$25:$AC$66=S34), 0) ): INDEX($AE$25:$AE$66, MATCH(1, ($AE$25:$AE$66>=Q34)*($AF$25:$AF$66<>"x")*($AB$25:$AB$66=R34)*($AC$25:$AC$66=S34), 0) ) ),INDEX($AF$25:$AF$66, MATCH( MIN(IF(($AF$25:$AF$66<>"x")*($AB$25:$AB$66=R34)*($AC$25:$AC$66=S34),ABS($AE$25:$AE$66-Q34))), IF(($AF$25:$AF$66<>"x")*($AB$25:$AB$66=R34)*($AC$25:$AC$66=S34),ABS($AE$25:$AE$66-Q34)), 0 )))} -> -0.016014925 | U34: {=IFERROR( _xlfn.FORECAST.LINEAR( Q34, INDEX($AG$25:$AG$66, MATCH(1, ($AE$25:$AE$66<=Q34)*($AG$25:$AG$66<>"x")*($AB$25:$AB$66=R34)*($AC$25:$AC$66=S34), 0) ): INDEX($AG$25:$AG$66, MATCH(1, ($AE$25:$AE$66>=Q34)*($AG$25:$AG$66<>"x")*($AB$25:$AB$66=R34)*($AC$25:$AC$66=S34), 0) ), INDEX($AE$25:$AE$66, MATCH(1, ($AE$25:$AE$66<=Q34)*($AG$25:$AG$66<>"x")*($AB$25:$AB$66=R34)*($AC$25:$AC$66=S34), 0) ): INDEX($AE$25:$AE$66, MATCH(1, ($AE$25:$AE$66>=Q34)*($AG$25:$AG$66<>"x")*($AB$25:$AB$66=R34)*($AC$25:$AC$66=S34), 0) ) ),INDEX($AG$25:$AG$66, MATCH( MIN(IF(($AG$25:$AG$66<>"x")*($AB$25:$AB$66=R34)*($AC$25:$AC$66=S34),ABS($AE$25:$AE$66-Q34))), IF(($AG$25:$AG$66<>"x")*($AB$25:$AB$66=R34)*($AC$25:$AC$66=S34),ABS($AE$25:$AE$66-Q34)), 0 )))} -> -0.015597015 | V34: {=IFERROR( _xlfn.FORECAST.LINEAR( Q34, INDEX($AH$25:$AH$66, MATCH(1, ($AE$25:$AE$66<=Q34)*($AH$25:$AH$66<>"x")*($AB$25:$AB$66=R34)*($AC$25:$AC$66=S34), 0) ): INDEX($AH$25:$AH$66, MATCH(1, ($AE$25:$AE$66>=Q34)*($AH$25:$AH$66<>"x")*($AB$25:$AB$66=R34)*($AC$25:$AC$66=S34), 0) ), INDEX($AE$25:$AE$66, MATCH(1, ($AE$25:$AE$66<=Q34)*($AH$25:$AH$66<>"x")*($AB$25:$AB$66=R34)*($AC$25:$AC$66=S34), 0) ): INDEX($AE$25:$AE$66, MATCH(1, ($AE$25:$AE$66>=Q34)*($AH$25:$AH$66<>"x")*($AB$25:$AB$66=R34)*($AC$25:$AC$66=S34), 0) ) ),INDEX($AH$25:$AH$66, MATCH( MIN(IF(($AH$25:$AH$66<>"x")*($AB$25:$AB$66=R34)*($AC$25:$AC$66=S34),ABS($AE$25:$AE$66-Q34))), IF(($AH$25:$AH$66<>"x")*($AB$25:$AB$66=R34)*($AC$25:$AC$66=S34),ABS($AE$25:$AE$66-Q34)), 0 )))} -> -0.013 | W34: {=IFERROR( _xlfn.FORECAST.LINEAR( Q34, INDEX($AI$25:$AI$66, MATCH(1, ($AE$25:$AE$66<=Q34)*($AI$25:$AI$66<>"x")*($AB$25:$AB$66=R34)*($AC$25:$AC$66=S34), 0) ): INDEX($AI$25:$AI$66, MATCH(1, ($AE$25:$AE$66>=Q34)*($AI$25:$AI$66<>"x")*($AB$25:$AB$66=R34)*($AC$25:$AC$66=S34), 0) ), INDEX($AE$25:$AE$66, MATCH(1, ($AE$25:$AE$66<=Q34)*($AI$25:$AI$66<>"x")*($AB$25:$AB$66=R34)*($AC$25:$AC$66=S34), 0) ): INDEX($AE$25:$AE$66, MATCH(1, ($AE$25:$AE$66>=Q34)*($AI$25:$AI$66<>"x")*($AB$25:$AB$66=R34)*($AC$25:$AC$66=S34), 0) ) ),INDEX($AI$25:$AI$66, MATCH( MIN(IF(($AI$25:$AI$66<>"x")*($AB$25:$AB$66=R34)*($AC$25:$AC$66=S34),ABS($AE$25:$AE$66-Q34))), IF(($AI$25:$AI$66<>"x")*($AB$25:$AB$66=R34)*($AC$25:$AC$66=S34),ABS($AE$25:$AE$66-Q34)), 0 )))} -> 0.001 | X34: =((((ABS(T34-U34)/(T$24-U$24))+(ABS(U34-V34)/(U$24-V$24))+(ABS(V34-W34)/(V$24-W$24)))/3)*(((T$24-U$24)+(U$24-V$24)+(V$24-W$24))/3)) -> 0.0069781665 | Y34: =AJ57 -> 0.018 | AB34: mV | AC34: 10000 | AD34: Hz | AE34: 100 | AF34: -0.028 | AG34: -0.008 | AH34: -0.014 | AI34: 0.006 | AJ34: 0.024
