Workbook
Name sert: #REF!

Sheet Sertifikat
A7: S E R T I F I K A T K A L I B R A S I
A8: C A L I B R A T I O N C E R T I F I C A T E
A9: Nomor / Number :
B14: IDENTITAS ALAT
B15: INSTRUMENT DETAILS
B17: Nama Alat | E17: : Disolve oxygen meter
B18: Instrument Name
B19: Merek | E19: =CONCATENATE(":"," ",'Budget DO meter'!B7) -> : YSI
B20: Brand
B21: Tipe | E21: =CONCATENATE(":"," ",'Budget DO meter'!B8) -> : Pro 20i
B22: Type
B23: Nomor Identifikasi | E23: : -
B24: Identification Number
B25: Nomor Seri | E25: =CONCATENATE(":"," ",'Budget DO meter'!B9) -> : JC042923
B26: Serial Number
B27: Lain-lain | E27: : Kapasitas | G27: =CONCATENATE(":"," ",'Budget DO meter'!B10," ",'Budget DO meter'!E10) -> : 0 s.d. 20 mg/L
B28: Others | E28: Kecermatan | G28: =CONCATENATE(":"," ",'Budget DO meter'!D10," ",'Budget DO meter'!E10) -> : 0,01 mg/L
B30: IDENTITAS PEMILIK
B31: Owner’s Identification
B33: Nama | C33: =CONCATENATE(":"," ",'Budget DO meter'!B6) -> :
B34: Designation
B35: Alamat | C35: =CONCATENATE(":"," ",'Budget DO meter'!B2) -> :
B36: Address
G40: Halaman 1 dari 2 halaman
G41: Page of page
G43: Diterbitkan Tanggal 2 September 2025
G44: Date of Issue
E45: Penguji Mutu Barang Ahli Madya
E46: Elis Sofianti
E47: NIP. 197109301994032002
E68: Nomor | F68: =CONCATENATE(":"," ",MID(A9,18,100)) -> :
E69: No. Order | F69: =": " &'Budget DO meter'!B3 -> :
E70: Halaman | F70: : 2 dari 2
B72: SPESIFIKASI ALAT
B73: Nama | D73: =E17 -> : Disolve oxygen meter
B74: Merk / Tipe | D74: =CONCATENATE(":"," ",'Budget DO meter'!B7," ","/"," ",'Budget DO meter'!B8) -> : YSI / Pro 20i
B75: No. Identifikasi | D75: =E23 -> : -
B76: No. Seri | D76: =E25 -> : JC042923
B77: Kapasitas | D77: =G27 -> : 0 s.d. 20 mg/L
B78: Kecermatan | D78: =G28 -> : 0,01 mg/L | G78: Kondisi ruang
...

Sheet Budget DO meter
A1: data kalibrasi
A2: Alamat | K2: Thermohygro Beureur data 2025
A3: no. order | G3: Suhu (°C) | H3: %RH | K3: Koreksi suhu | N3: Koreksi RH
A4: tanggal terima | F4: Awal | G4: 21.1 | H4: 72.8 | K4: T (°C) | L4: Koreksi | M4: U95 | N4: RH (%) | O4: Koreksi | P4: U95
A5: tanggal kalibrasi | F5: Akhir | G5: 21.2 | H5: 72.6 | K5: 20.01 | L5: 0.3 | M5: 2 | N5: 40.01 | O5: -2 | P5: 3
A6: Pemilik | F6: Rata2 | G6: =AVERAGE(G4:G5) -> 21.15 | H6: =AVERAGE(H4:H5) -> 72.7 | K6: 25 | L6: 0.4 | M6: 2 | N6: 50.01 | O6: -3 | P6: 3
A7: merk | B7: YSI | F7: Terkoreksi | G7: =G6+FORECAST(G6,L5:L9,K5:K9) -> 21.33233 | H7: =H6+FORECAST(H6,O5:O9,N5:N9) -> 71.431483 | K7: 30 | L7: 0.5 | M7: 2 | N7: 60.02 | O7: -1 | P7: 3
A8: Tipe | B8: Pro 20i | F8: U95 | G8: 2 | H8: =FORECAST(H7,P5:P9,N5:N9) -> 2.7023274 | K8: 35 | L8: 1.2 | M8: 2 | N8: 70 | O8: 0 | P8: 2
A9: no seri | B9: JC042923 | F9: Fluktuasi suhu | G9: =(MAX(G4:G5)-G6+G6-MIN(G4:G5))/2 -> 0.05 | H9: =(MAX(H4:H5)-H6+H6-MIN(H4:H5))/2 -> 0.1 | K9: 40 | L9: 1.7 | M9: 2 | N9: 82 | O9: -2 | P9: 3
A10: kapasitas/resolusi | B10: 0 s.d. 20 | C10: / | D10: 0.01 | E10: mg/L | F10: Flu+U95 | G10: =G8+G9 -> 2.05 | H10: =H8+H9 -> 2.8023274
F11: Kondisi Ruang | G11: =FIXED(G7,2) & " ± "&FIXED(G10,2) -> 21,33 ± 2,05 | H11: =FIXED(H7,2) & " ± "&FIXED(H10,2) -> 71,43 ± 2,80
G14: Suhu awal | H14: Suhu Akhir
A15: DO 5,5 mg/L | F15: Suhu Buffer | G15: 19.9 | H15: =19.8 -> 19.8 | I15: °C | N15: koreksi temperatur | Q15: Nilai koreksi termometer digital tahun 2025
A16: buffer standar | B16: suhu °C | C16: pembacaan alat | I16: stdev | J16: standar terkoreksi | K16: =Q18 -> 19.3 | L16: =S18 -> 19.1 | Q16: pembacaan alat | R16: koreksi | S16: pembacaan alat terkoreksi
C17: X1 | D17: X2 | E17: X3 | F17: X4 | G17: X5 | H17: X rata | K17: =AVERAGE(G15,H15) -> 19.85 | L17: =(K17-K16)*(L18-L16)/(K18-K16)+L16 -> 19.680556 | N17: =L17-K17 -> -0.16944444 | Q17: °C | R17: °C | S17: °C
A18: 5.5 | B18: =L17 -> 19.680556 | C18: 5.58 | D18: 5.55 | E18: 5.5 | F18: 5.62 | G18: 5.66 | H18: =AVERAGE(C18:G18) -> 5.582 | I18: =STDEV(C18:G18) -> 0.061806149 | J18: =A18-H33 -> 5.5292464 | K18: =Q20 -> 21.1 | L18: =S20 -> 21 | Q18: 19.3 | R18: -0.2 | S18: =Q18+R18 -> 19.1
Q19: 20.1 | R19: -0.2 | S19: =Q19+R19 -> 19.9
G20: suhu buffer | H20: =AVERAGE(19.9,19.9) -> 19.9 | I20: °C | Q20: 21.1 | R20: -0.1 | S20: =Q20+R20 -> 21
A21: buffer standar | B21: suhu °C | C21: pembacaan alat | I21: stdev | J21: standar terkoreksi | K21: =Q18 -> 19.3 | L21: =S18 -> 19.1 | Q21: 24.2 | R21: -0.2 | S21: =Q21+R21 -> 24
C22: X1 | D22: X2 | E22: X3 | F22: X4 | G22: X5 | H22: X rata | K22: =H20 -> 19.9 | L22: =(K22-K21)*(L23-L21)/(K23-K21)+L21 -> 19.733333 | N22: =L22-K22 -> -0.16666667 | Q22: 25.1 | R22: -0.1 | S22: =Q22+R22 -> 25
B23: =L22 -> 19.733333 | H23: =AVERAGE(C23:G23) -> #DIV/0! | I23: =STDEV(C23:G23) -> #DIV/0! | J23: =A23+R57 -> 0.0010666667 | K23: =Q20 -> 21.1 | L23: =S20 -> 21 | Q23: 26.1 | R23: -0.1 | S23: =Q23+R23 -> 26
Q24: 30.1 | R24: -0.1 | S24: =Q24+R24 -> 30
G25: suhu buffer | H25: =AVERAGE(19.9,19.8) -> 19.85 | I25: °C
A26: buffer standar | B26: suhu °C | C26: pembacaan alat | I26: stdev | J26: standar terkoreksi | K26: =Q18 -> 19.3 | L26: =S18 -> 19.1
C27: X1 | D27: X2 | E27: X3 | F27: X4 | G27: X5 | H27: X rata | K27: =H25 -> 19.85 | L27: =(K27-K26)*(L28-L26)/(K28-K26)+L26 -> 19.680556 | N27: =L27-K27 -> -0.16944444
B28: =L27 -> 19.680556 | H28: =AVERAGE(C28:G28) -> #DIV/0! | I28: =STDEV(C28:G28) -> #DIV/0! | J28: =A28+R75 -> 0.0031944444 | K28: =Q20 -> 21.1 | L28: =S20 -> 21
A33: St. deviasi | D33: U sertifikat | E33: 0.08 | G33: Koreksi | H33: =5.51-((R39/O39)*5.51) -> -0.029246443 | N33: temperatur °C | O33: DO mg/L | Q33: temperatur °C | R33: ΔPH
D34: U sertifikat thermometer | E34: =0.4 -> 0.4 | N34: 15 | O34: 10.083
A35: Skala terkecil alat | B35: =D10 -> 0.01 | N35: 16 | O35: 9.885
N36: 17 | O36: 9.699
A37: DO 5,5 mg/L | N37: 18 | O37: 9.525 | Q37: Koreksi temperatur
A38: Komponen | B38: Satuan | C38: Distribusi | D38: U | E38: Pembagi | F38: vi | G38: ui | H38: ci | I38: uici | J38: (uici)2 | K38: (uici)4/vi | N38: 19 | O38: 9.361 | Q38: =IF(Q39<=20,N38,IF(Q39>=20,N39,0)) -> 19 | R38: =VLOOKUP(Q38,$N$34:$O$49,2,FALSE) -> 9.361
A39: Repeatability | B39: pH | C39: Normal | D39: =I18 -> 0.061806149 | E39: =SQRT(5) -> 2.236068 | F39: 4 | G39: =D39/E39 -> 0.02764055 | H39: 1 | I39: =G39*H39 -> 0.02764055 | J39: =I39^2 -> 0.000764 | K39: =I39^4/F39 -> 1.45924e-07 | N39: 20 | O39: 9.208 | Q39: =B18 -> 19.680556 | R39: =(Q39-Q38)*(R40-R38)/(Q40-Q38)+R38 -> 9.256875
A40: Larutan Buffer | B40: pH | C40: t-student | D40: =E33 -> 0.08 | E40: 2 | F40: 60 | G40: =D40/E40 -> 0.04 | H40: 1 | I40: =G40*H40 -> 0.04 | J40: =I40^2 -> 0.0016 | K40: =I40^4/F40 -> 4.2666667e-08 | N40: 21 | O40: 9.065 | Q40: =IF(Q39<=20,N39,IF(Q39>=20,N40,0)) -> 20 | R40: =VLOOKUP(Q40,$N$34:$O$49,2,FALSE) -> 9.208
A41: Koreksi pengaruh ΔT | B41: pH | C41: Rect | D41: =H33 -> -0.029246443 | E41: =SQRT(3) -> 1.7320508 | F41: 50 | G41: =D41/E41 -> -0.016885442 | H41: 1 | I41: =G41*H41 -> -0.016885442 | J41: =I41^2 -> 0.00028511815 | K41: =I41^4/F41 -> 1.6258472e-09 | N41: 22 | O41: 8.931 | Q41: =A81 -> Pengaruh ketidakpastian Termometer digital
A42: Readability | B42: pH | C42: Rect | D42: =B35/2 -> 0.005 | E42: =SQRT(3) -> 1.7320508 | F42: 50 | G42: =D42/E42 -> 0.0028867513 | H42: 1 | I42: =G42*H42 -> 0.0028867513 | J42: =I42^2 -> 8.3333333e-06 | K42: =I42^4/F42 -> 1.3888889e-12 | N42: 23 | O42: 8.806 | Q42: 15 | R42: =O38 -> 9.361
A43: Pengaruh ketidakpastian Termometer digital | B43: oC | C43: Normal | D43: =E34 -> 0.4 | E43: 2 | F43: 60 | G43: =D43/E43 -> 0.2 | H43: =0.01/5 -> 0.002 | I43: =G43*H43 -> 0.0004 | J43: =I43^2 -> 1.6e-07 | K43: =I43^4/F43 -> 4.2666667e-16 | N43: 24 | O43: 8.69 | Q43: =E34+B18 -> 20.080556 | R43: =(Q43-Q42)*(R44-R42)/(Q44-Q42)+R42 -> 4.6101725
A44: Sums | J44: =SUM(J39:J42) -> 0.0026574515 | K44: =SUM(K39:K42) -> 1.902179e-07 | N44: 25 | O44: 8.581 | Q44: 25 | R44: 0.01
A45: Ketidakpastian baku gabungan, uc, Unit | J45: =SQRT(J44) -> 0.051550475 | N45: 26 | O45: 8.481
A46: Dearajat kebebasan efektif, veff | J46: =J45^4/K44 -> 37.126097 | N46: 27 | O46: 8.388
...

Sheet Sheet1
D4: temperatur °C | E4: DO mg/L
D5: 15 | E5: 10.083 | F5: =E5-9.208 -> 0.875
D6: 16 | E6: 9.885 | F6: =E6-9.208 -> 0.677
D7: 17 | E7: 9.699 | F7: =E7-9.208 -> 0.491
D8: 18 | E8: 9.525 | F8: =E8-9.208 -> 0.317
D9: 19 | E9: 9.361 | F9: =E9-9.208 -> 0.153
D10: 20 | E10: 9.208 | F10: =E10-9.208 -> 0
D11: 21 | E11: 9.065 | F11: =E11-9.208 -> -0.143
D12: 22 | E12: 8.931 | F12: =E12-9.208 -> -0.277
D13: 23 | E13: 8.806 | F13: =E13-9.208 -> -0.402
D14: 24 | E14: 8.69 | F14: =E14-9.208 -> -0.518
D15: 25 | E15: 8.581 | F15: =E15-9.208 -> -0.627
D16: 26 | E16: 8.481 | F16: =E16-9.208 -> -0.727
... D20: 30 | E20: 8.152 | F20: =E20-9.208 -> -1.056
