Workbook
Name m: #REF!

Sheet Termohygro
A2: Temperatur (°C) | E2: Kelembaban Relatif(%RH)
A3: Alat | B3: Koreksi | C3: U95% | E3: Alat | F3: Koreksi | G3: U95%
A4: 19.3 | B4: 0.7 | C4: 2 | E4: 81.2 | F4: -1.2 | G4: 2.3
A5: 25.1 | B5: -0.1 | C5: 2 | E5: 70.6 | F5: -0.7 | G5: 2
A6: 30 | B6: 0.1 | C6: 2 | E6: 58.4 | F6: 1.6 | G6: 2.9
A7: 34.8 | B7: 0.4 | C7: 2 | E7: 45.7 | F7: 4.4 | G7: 2.5
A8: 41.1 | B8: -0.9 | C8: 2 | E8: 39.3 | F8: 0.9 | G8: 2.3
A10: 2024 | B10: Testo
A11: Suhu (°C) | E11: Kelembapan Relatif (%RH)
A12: Alat rata-rata | B12: Koreksi Alat | C12: U95% (k=2) | E12: Alat rata-rata | F12: Koreksi Alat | G12: U95% (k=2)
A13: 19.1 | B13: 0.9 | C13: 2 | E13: 42 | F13: -2 | G13: 3
A14: 24.5 | B14: 0.5 | C14: 2 | E14: 50.5 | F14: -0.5 | G14: 3
A15: 30.3 | B15: -0.3 | C15: 2 | E15: 61.4 | F15: -1.4 | G15: 3
A16: 35.6 | B16: -0.6 | C16: 2 | E16: 69.2 | F16: 0.8 | G16: 2
A17: 41 | B17: -1 | C17: 2 | E17: 78.4 | F17: 1.6 | G17: 3
A19: 2024 Suhu Rotronic | E19: %RH
A20: Alat rata-rata | B20: Koreksi Alat | C20: U95% (k=2) | E20: Alat rata-rata | F20: Koreksi Alat | G20: U95% (k=2)
A21: 19.7 | B21: 0.3 | C21: 2 | E21: 40.4 | F21: -0.4 | G21: 2.5
A22: 25 | B22: 0 | C22: 2 | E22: 49.7 | F22: 0.3 | G22: 2.8
A23: 30.4 | B23: -0.4 | C23: 2 | E23: 59.9 | F23: 0.1 | G23: 3.2
A24: 35.1 | B24: -0.1 | C24: 2 | E24: 69.7 | F24: 0.3 | G24: 2
A25: 40.6 | B25: -0.6 | C25: 2 | E25: 78.8 | F25: 1.2 | G25: 2.6

Sheet Data Pembacaan Alt
C2: KALIBRASI OVEN
C3: LABORATORIUM KALIBRASI DAN PENGUJI
C4: BALAI BESAR LOGAM DAN MESIN
C5: BANDUNG
A7: Merk | C7: Memmert | F7: Tipe | G7: B 40
A8: Kapasitas/Graduasi | C8: (30 ~ 120) | D8: °C / | F8: 0.5 | H8: °C
A9: No. Seri | C9: 801356 | F9: No. ID | G9: -
A10: Standar Acuan | C10: IK-K-KT-02 (KAN Pd-02.04)
A11: Temperatur Ruangan (T) | C11: Tawal : | D11: 25.2 | F11: Koreksi | G11: =FORECAST(D11,Termohygro!B14:B15,Termohygro!A14:A15) -> 0.40344828
C12: Takhir : | D12: 26.2 | F12: Koreksi | G12: =FORECAST(D12,Termohygro!B14:B15,Termohygro!A14:A15) -> 0.26551724
B13: Trata-rata terkoreksi : | D13: =(D11+D12+G11+G12+E11+H11+E12+H12)/2 -> 26.034483 | E13: °C ± | F13: =MAX(MAX(D11+G11,D12+G12)-D13,D13-MIN(D11+G11,D12+G12)) -> 0.43103448 | G13: °C
A14: Kelembapan ruangan (RH) | C14: RHawal : | D14: 73.7 | F14: Koreksi | G14: =FORECAST(D14,Termohygro!F16:F17,Termohygro!E16:E17) -> 1.1913043
C15: RHakhir : | D15: 64.5 | F15: Koreksi | G15: =FORECAST(D15,Termohygro!F15:F16,Termohygro!E15:E16) -> -0.52564103
B16: RHrata-rata terkoreksi : | D16: =(D14+D15+G14+G15+E14+H14+E15+H15)/2 -> 69.432832 | E16: % RH ± | F16: =MAX(MAX(D14+G14,D15+G15)-D16,D16-MIN(D14+G14,D15+G15)) -> 5.4584727 | G16: % RH
A17: Lokasi Kalibrasi | C17: Lab. Teknik Struktur
A41: No. Order | B41: K671-2 | D41: Dikalibrasi | E41: Firman/Nikita
A42: Tgl terima | B42: 45994 | D42: Diperiksa | E42: Nur ID | G42: Paraf
A43: Tgl kalibrasi | B43: 45994 | D43: Disetujui | E43: Elis S
A44: Kalibrator yang digunakan :
B45: Data Acquisition Hewlett Packard 34970A No. Seri US37020738
B46: dengan Termokopel Tipe T (IEC) yang tertelusur ke SI melalui LK-001-IDN.
I48: F-IK-K-04-KT-02
A51: No. Order | B51: =B$41 -> K671-2 | H51: Halaman | I51: 2
A53: Spesifikasi Dimensi Enclosure
A54: Panjang | C54: : | D54: 600 | F54: mm
A55: Lebar | C55: : | D55: 400 | F55: mm
A56: Tinggi | C56: : | D56: 480 | F56: mm
A57: Volume | C57: : | D57: =D56*D55*D54/10^9 -> 0.1152 | F57: m3
A59: Setting Alat | B59: 60 | C59: °C | D59: Setting Alat | E59: 100 | F59: °C | G59: Setting Alat | H59: 110 | I59: °C
A60: Pembacaan Indikator Enclosure | B60: Data ke- | C60: °C | D60: Pembacaan Indikator Enclosure | E60: Data ke- | F60: °C | G60: Pembacaan Indikator Enclosure | H60: Data ke- | I60: °C
A61: Menit ke-n | D61: Menit ke-n | G61: Menit ke-n
A62: 1 | B62: 61 | C62: 63.5 | D62: 1 | E62: 151 | F62: 105 | G62: 1 | H62: 241 | I62: 118
A63: 2 | B63: 62 | C63: 63.5 | D63: 2 | E63: 152 | F63: 105 | G63: 2 | H63: 242 | I63: 118
A64: 3 | B64: 63 | C64: 64 | D64: 3 | E64: 153 | F64: 105.5 | G64: 3 | H64: 243 | I64: 118
A65: 4 | B65: 64 | C65: 64 | D65: 4 | E65: 154 | F65: 105.5 | G65: 4 | H65: 244 | I65: 118
A66: 5 | B66: 65 | C66: 64 | D66: 5 | E66: 155 | F66: 105.5 | G66: 5 | H66: 245 | I66: 118
A67: 6 | B67: 66 | C67: 64 | D67: 6 | E67: 156 | F67: 106 | G67: 6 | H67: 246 | I67: 118
A68: 7 | B68: 67 | C68: 64 | D68: 7 | E68: 157 | F68: 106 | G68: 7 | H68: 247 | I68: 118
A69: 8 | B69: 68 | C69: 64 | D69: 8 | E69: 158 | F69: 106 | G69: 8 | H69: 248 | I69: 118
A70: 9 | B70: 69 | C70: 64 | D70: 9 | E70: 159 | F70: 106 | G70: 9 | H70: 249 | I70: 118
...

Sheet DATA REKAMAN
A1: Name: | B1: Data Instr INSTR 12/3/2025 09:23:47
A2: Owner: | B2: Admin
A3: Comments:
A4: Acquisition Date: | B4: 03/12/2025 09.23.47
A5: &Instrument: | B5: 34970A | C5: Address: | D5: ASRL3::INSTR | E5: Modules: | F5: 1 | G5: Slot1: | H5: 34901A
A6: Total Channels: | B6: 20
A7: Channel | B7: Name | C7: Function | D7: Range | E7: Resolution | F7: AdvSettings | G7: Scale | H7: Gain | I7: Offset | J7: Label | K7: Test | L7: Low | M7: High | N7: HWAlarm
A8: 101 | C8: Temp (Type T) | D8: None | E8: C | F8: Temp (Type T)#1#0,016#Auto#0,001#C#Internal#0#false | G8: FALSE | H8: 1 | I8: 0 | J8: C | K8: Off | L8: 0 | M8: 1 | N8: Alarm 1
A9: 102 | C9: Temp (Type T) | D9: None | E9: C | F9: Temp (Type T)#1#0,016#Auto#0,001#C#Internal#0#false | G9: FALSE | H9: 1 | I9: 0 | J9: C | K9: Off | L9: 0 | M9: 1 | N9: Alarm 1
A10: 103 | C10: Temp (Type T) | D10: None | E10: C | F10: Temp (Type T)#1#0,016#Auto#0,001#C#Internal#0#false | G10: FALSE | H10: 1 | I10: 0 | J10: C | K10: Off | L10: 0 | M10: 1 | N10: Alarm 1
A11: 104 | C11: Temp (Type T) | D11: None | E11: C | F11: Temp (Type T)#1#0,016#Auto#0,001#C#Internal#0#false | G11: FALSE | H11: 1 | I11: 0 | J11: C | K11: Off | L11: 0 | M11: 1 | N11: Alarm 1
A12: 105 | C12: Temp (Type T) | D12: None | E12: C | F12: Temp (Type T)#1#0,016#Auto#0,001#C#Internal#0#false | G12: FALSE | H12: 1 | I12: 0 | J12: C | K12: Off | L12: 0 | M12: 1 | N12: Alarm 1
A13: 106 | C13: Temp (Type T) | D13: None | E13: C | F13: Temp (Type T)#1#0,016#Auto#0,001#C#Internal#0#false | G13: FALSE | H13: 1 | I13: 0 | J13: C | K13: Off | L13: 0 | M13: 1 | N13: Alarm 1
A14: 107 | C14: Temp (Type T) | D14: None | E14: C | F14: Temp (Type T)#1#0,016#Auto#0,001#C#Internal#0#false | G14: FALSE | H14: 1 | I14: 0 | J14: C | K14: Off | L14: 0 | M14: 1 | N14: Alarm 1
A15: 108 | C15: Temp (Type T) | D15: None | E15: C | F15: Temp (Type T)#1#0,016#Auto#0,001#C#Internal#0#false | G15: FALSE | H15: 1 | I15: 0 | J15: C | K15: Off | L15: 0 | M15: 1 | N15: Alarm 1
A16: 109 | C16: Temp (Type T) | D16: None | E16: C | F16: Temp (Type T)#1#0,016#Auto#0,001#C#Internal#0#false | G16: FALSE | H16: 1 | I16: 0 | J16: C | K16: Off | L16: 0 | M16: 1 | N16: Alarm 1
A17: 110 | C17: Temp (Type T) | D17: None | E17: C | F17: Temp (Type T)#1#0,016#Auto#0,001#C#Internal#0#false | G17: FALSE | H17: 1 | I17: 0 | J17: C | K17: Off | L17: 0 | M17: 1 | N17: Alarm 1
A18: 111 | C18: Temp (Type T) | D18: None | E18: C | F18: Temp (Type T)#1#0,016#Auto#0,001#C#Internal#0#false | G18: FALSE | H18: 1 | I18: 0 | J18: C | K18: Off | L18: 0 | M18: 1 | N18: Alarm 1
A19: 112 | C19: Temp (Type T) | D19: None | E19: C | F19: Temp (Type T)#1#0,016#Auto#0,001#C#Internal#0#false | G19: FALSE | H19: 1 | I19: 0 | J19: C | K19: Off | L19: 0 | M19: 1 | N19: Alarm 1
... A27: 120 | C27: Temp (Type T) | D27: None | E27: C | F27: Temp (Type T)#1#0,016#Auto#0,001#C#Internal#0#false | G27: FALSE | H27: 1 | I27: 0 | J27: C | K27: Off | L27: 0 | M27: 1 | N27: Alarm 1
A28: Scan Control: | B28: Start Action: | C28: Immediately | D28: Stop Action: | E28: User Terminated
A29: Scan | B29: Time | C29: 101 (C) | D29: 102 (C) | E29: 103 (C) | F29: 104 (C) | G29: 105 (C) | H29: 106 (C) | I29: 107 (C) | J29: 108 (C) | K29: 109 (C) | L29: 110 (C) | M29: 111 (C) | N29: 112 (C) | O29: 113 (C) | P29: 114 (C) | Q29: 115 (C) | R29: 116 (C) | S29: 117 (C) | T29: 118 (C) | U29: 119 (C) | V29: 120 (C)
A30: 1 | B30: 03/12/2025 09:23:47:735 | C30: 25.45 | D30: 25.274 | E30: 25.349 | F30: 25.389 | G30: -9.9e+37 | H30: 25.154 | I30: 25.158 | J30: 25.242 | K30: 25.206 | L30: -17.794 | M30: 39.843 | N30: 40.581 | O30: 39.927 | P30: 39.756 | Q30: 48.42 | R30: 51.082 | S30: 44.693 | T30: 46.78 | U30: 39.625 | V30: -2.867
A31: 2 | B31: 03/12/2025 09:24:47:719 | C31: 25.481 | D31: 25.326 | E31: 25.403 | F31: 25.395 | G31: 25.227 | H31: 25.252 | I31: 25.186 | J31: 25.195 | K31: 25.205 | L31: -89.64 | M31: 41.354 | N31: 42.144 | O31: 41.452 | P31: 41.306 | Q31: 49.384 | R31: 52.123 | S31: 46.199 | T31: 48.057 | U31: 41.381 | V31: -62.979
A32: 3 | B32: 03/12/2025 09:25:47:719 | C32: 25.706 | D32: 25.577 | E32: 25.57 | F32: 25.584 | G32: 25.365 | H32: 25.396 | I32: 25.379 | J32: 25.405 | K32: 26.431 | L32: 27.208 | M32: 42.279 | N32: 43.244 | O32: 42.464 | P32: 42.247 | Q32: 50.759 | R32: 53.411 | S32: 47.6 | T32: 49.42 | U32: 42.723 | V32: -72.49
A33: 4 | B33: 03/12/2025 09:26:47:719 | C33: 25.66 | D33: 25.526 | E33: 25.574 | F33: 25.585 | G33: 25.48 | H33: 25.455 | I33: 25.462 | J33: 25.461 | K33: 25.526 | L33: 25.707 | M33: 43.778 | N33: 44.506 | O33: 43.749 | P33: 43.64 | Q33: 51.356 | R33: 53.733 | S33: 48.806 | T33: 50.192 | U33: 44.253 | V33: -11.124
A34: 5 | B34: 03/12/2025 09:27:47:719 | C34: 27.705 | D34: 27.422 | E34: 27.817 | F34: 27.487 | G34: 27.506 | H34: 27.27 | I34: 27.604 | J34: 27.256 | K34: 26.989 | L34: 27.126 | M34: 44.447 | N34: 45.627 | O34: 44.672 | P34: 44.679 | Q34: 52.153 | R34: 54.459 | S34: 49.545 | T34: 51.357 | U34: 45.443 | V34: -58.722
A35: 6 | B35: 03/12/2025 09:28:47:719 | C35: 31.656 | D35: 31.269 | E35: 31.776 | F35: 31.301 | G35: 31.342 | H35: 30.547 | I35: 31.231 | J35: 30.532 | K35: 30.354 | L35: 30.503 | M35: 45.851 | N35: 46.989 | O35: 45.911 | P35: 45.842 | Q35: 52.992 | R35: 55.245 | S35: 50.829 | T35: 52.048 | U35: 46.655 | V35: -77.785
A36: 7 | B36: 03/12/2025 09:29:47:719 | C36: 36.605 | D36: 35.881 | E36: 36.715 | F36: 36.093 | G36: 36.709 | H36: 35.075 | I36: 36.431 | J36: 35.146 | K36: 34.973 | L36: 35.165 | M36: 46.736 | N36: 47.825 | O36: 46.628 | P36: 46.677 | Q36: 53.338 | R36: 55.676 | S36: 51.117 | T36: 52.457 | U36: 47.619 | V36: 16.527
A37: 8 | B37: 03/12/2025 09:30:47:719 | C37: 42.143 | D37: 41.222 | E37: 42.009 | F37: 41.425 | G37: 42.469 | H37: 40.604 | I37: 41.999 | J37: 40.46 | K37: 39.944 | L37: 40.084 | M37: 47.893 | N37: 49.003 | O37: 47.86 | P37: 47.924 | Q37: 54.515 | R37: 56.899 | S37: 52.209 | T37: 53.644 | U37: 48.851 | V37: 10.018
A38: 9 | B38: 03/12/2025 09:31:47:719 | C38: 47.966 | D38: 46.955 | E38: 47.848 | F38: 47.349 | G38: 49.528 | H38: 46.192 | I38: 48.048 | J38: 46.373 | K38: 46.024 | L38: 46.19 | M38: 48.597 | N38: 49.717 | O38: 48.623 | P38: 48.62 | Q38: 54.162 | R38: 56.116 | S38: 52.517 | T38: 53.459 | U38: 49.544 | V38: 3.421
A39: 10 | B39: 03/12/2025 09:32:47:719 | C39: 52.442 | D39: 51.415 | E39: 52.156 | F39: 51.643 | G39: 53.29 | H39: 51.782 | I39: 52.557 | J39: 51.289 | K39: 50.845 | L39: 50.988 | M39: 49.768 | N39: 50.849 | O39: 49.63 | P39: 49.739 | Q39: 55.859 | R39: 57.814 | S39: 53.856 | T39: 55.022 | U39: 50.644 | V39: -38.193
A40: 11 | B40: 03/12/2025 09:33:47:719 | C40: 54.605 | D40: 53.419 | E40: 54.915 | F40: 53.769 | G40: 55.027 | H40: 55.623 | I40: 54.841 | J40: 57.737 | K40: 53.76 | L40: 53.841 | M40: 50.222 | N40: 51.562 | O40: 50.414 | P40: 50.346 | Q40: 55.145 | R40: 57.024 | S40: 53.701 | T40: 54.704 | U40: 51.253 | V40: -69.005
A41: 12 | B41: 03/12/2025 09:34:47:719 | C41: 57.297 | D41: 55.774 | E41: 57.255 | F41: 56.084 | G41: 56.696 | H41: 58.664 | I41: 56.415 | J41: 59.164 | K41: 55.775 | L41: 55.829 | M41: 51.25 | N41: 52.334 | O41: 51.118 | P41: 51.299 | Q41: 56.671 | R41: 58.509 | S41: 54.867 | T41: 55.749 | U41: 51.99 | V41: 7.018
... A300: 271 | B300: 03/12/2025 13:53:47:719 | C300: 124.502 | D300: 124.731 | E300: 124.323 | F300: 124.629 | G300: 119.783 | H300: 118.918 | I300: 119.546 | J300: 117.969 | K300: 122.963 | L300: 122.666 | M300: 120.136 | N300: 121.275 | O300: 119.75 | P300: 120.321 | Q300: 118.17 | R300: 119.86 | S300: 117.494 | T300: 118.601 | U300: 120.22 | V300: -85.682

Sheet DS2025
A1: 2025
A2: ch101 | D2: ch102 | G2: ch103 | J2: ch104 | M2: ch105 | P2: ch106 | S2: ch107 | V2: ch108 | Y2: ch109
A3: Rata-rata Alat (°C) | B3: Koreksi Alat (°C) | C3: U95% °C (k=2) | D3: Rata-rata Alat (°C) | E3: Koreksi Alat (°C) | F3: U95% °C (k=2) | G3: Rata-rata Alat (°C) | H3: Koreksi Alat (°C) | I3: U95% °C (k=2) | J3: Rata-rata Alat (°C) | K3: Koreksi Alat (°C) | L3: U95% °C (k=2) | M3: Rata-rata Alat (°C) | N3: Koreksi Alat (°C) | O3: U95% °C (k=2) | P3: Rata-rata Alat (°C) | Q3: Koreksi Alat (°C) | R3: U95% °C (k=2) | S3: Rata-rata Alat (°C) | T3: Koreksi Alat (°C) | U3: U95% °C (k=2) | V3: Rata-rata Alat (°C) | W3: Koreksi Alat (°C) | X3: U95% °C (k=2) | Y3: Rata-rata Alat (°C) | Z3: Koreksi Alat (°C) | AA3: U95% °C (k=2)
A5: -0.1354 | B5: 0.13681423 | C5: 0.23938625 | D5: -0.2022 | E5: 0.20361423 | F5: 0.23909407 | G5: -0.1466 | H5: 0.14801423 | I5: 0.23986664 | J5: -0.1362 | K5: 0.13761423 | L5: 0.23872365 | M5: -0.2114 | N5: 0.21281423 | O5: 0.23878841 | P5: -0.1818 | Q5: 0.18321423 | R5: 0.23830564 | S5: -0.314 | T5: 0.31541423 | U5: 0.23873609 | V5: -0.2882 | W5: 0.28961423 | X5: 0.23827623 | Y5: -0.2304 | Z5: 0.23181423 | AA5: 0.23842432
A6: 25.2812 | B6: -0.27588399 | C6: 0.34286659 | D6: 25.2266 | E6: -0.22128399 | F6: 0.3434192 | G6: 25.2478 | H6: -0.24248399 | I6: 0.34302881 | J6: 25.0876 | K6: -0.082283991 | L6: 0.34306825 | M6: 25.1754 | N6: -0.17008399 | O6: 0.34309816 | P6: 25.1576 | Q6: -0.15228399 | R6: 0.3430472 | S6: 24.9092 | T6: 0.096116009 | U6: 0.34317841 | V6: 24.9828 | W6: 0.022516009 | X6: 0.34309418 | Y6: 25.069 | Z6: -0.063683991 | AA6: 0.34302416
A7: 50.234 | B7: -0.22918635 | C7: 0.35116603 | D7: 50.2138 | E7: -0.20898635 | F7: 0.35151421 | G7: 50.1472 | H7: -0.14238635 | I7: 0.35116137 | J7: 50.0814 | K7: -0.076586351 | L7: 0.3514834 | M7: 50.29 | N7: -0.28518635 | O7: 0.35120557 | P7: 50.2844 | Q7: -0.27958635 | R7: 0.35133539 | S7: 50.043 | T7: -0.038186351 | U7: 0.35147115 | V7: 50.0878 | W7: -0.082986351 | X7: 0.35135425 | Y7: 50.1848 | Z7: -0.17998635 | AA7: 0.35136022
A8: 75.2096 | B8: -0.21076479 | C8: 0.37272552 | D8: 75.1282 | E8: -0.12936479 | F8: 0.37158065 | G8: 74.933 | H8: 0.065835206 | I8: 0.37178567 | J8: 75.1098 | K8: -0.11096479 | L8: 0.37226883 | M8: 75.202 | N8: -0.20316479 | O8: 0.37147483 | P8: 75.3538 | Q8: -0.35496479 | R8: 0.37150631 | S8: 74.9894 | T8: 0.0094352055 | U8: 0.3715705 | V8: 75.1054 | W8: -0.10656479 | X8: 0.37218769 | Y8: 75.2954 | Z8: -0.29656479 | AA8: 0.3713629
A9: 100.1518 | B9: -0.15086581 | C9: 0.46144811 | D9: 100.0102 | E9: -0.0092658067 | F9: 0.46142751 | G9: 99.7526 | H9: 0.24833419 | I9: 0.46160976 | J9: 99.966 | K9: 0.034934193 | L9: 0.4616025 | M9: 100.1694 | N9: -0.16846581 | O9: 0.46261246 | P9: 100.301 | Q9: -0.30006581 | R9: 0.46169528 | S9: 99.8138 | T9: 0.18713419 | U9: 0.4614168 | V9: 99.9844 | W9: 0.016534193 | X9: 0.46182752 | Y9: 100.26 | Z9: -0.25906581 | AA9: 0.46178767
A10: 125.1506 | B10: -0.14730144 | C10: 0.51824805 | D10: 124.9398 | E10: 0.063498558 | F10: 0.51858601 | G10: 124.6086 | H10: 0.39469856 | I10: 0.51823517 | J10: 124.862 | K10: 0.14129856 | L10: 0.51824747 | M10: 125.1248 | N10: -0.12150144 | O10: 0.51971743 | P10: 125.292 | Q10: -0.28870144 | R10: 0.51797523 | S10: 124.708 | T10: 0.29529856 | U10: 0.51859139 | V10: 124.8914 | W10: 0.11189856 | X10: 0.51874823 | Y10: 125.2348 | Z10: -0.23150144 | AA10: 0.51848987
A11: 150.0946 | B11: -0.094015831 | C11: 0.53210777 | D11: 149.8788 | E11: 0.12178417 | F11: 0.53073855 | G11: 149.5892 | H11: 0.41138417 | I11: 0.531173 | J11: 149.7876 | K11: 0.21298417 | L11: 0.53153931 | M11: 150.0566 | N11: -0.056015831 | O11: 0.53272227 | P11: 150.2522 | Q11: -0.25161583 | R11: 0.53034878 | S11: 149.6728 | T11: 0.32778417 | U11: 0.53141364 | V11: 149.7786 | W11: 0.22198417 | X11: 0.53235698 | Y11: 150.1322 | Z11: -0.13161583 | AA11: 0.53031004
A12: 174.9244 | B12: 0.043777345 | C12: 0.55905136 | D12: 174.7936 | E12: 0.17457734 | F12: 0.55665965 | G12: 174.5202 | H12: 0.44797734 | I12: 0.55649426 | J12: 174.6274 | K12: 0.34077734 | L12: 0.55853517 | M12: 174.8704 | N12: 0.097777345 | O12: 0.55915785 | P12: 175.1442 | Q12: -0.17602266 | R12: 0.55604898 | S12: 174.5284 | T12: 0.43977734 | U12: 0.55867732 | V12: 174.6274 | W12: 0.34077734 | X12: 0.56052693 | Y12: 175.2978 | Z12: -0.32962266 | AA12: 0.55635843
A13: 199.686 | B13: 0.25224003 | C13: 0.56362329 | D13: 199.5582 | E13: 0.38004003 | F13: 0.56274662 | G13: 199.3392 | H13: 0.59904003 | I13: 0.56293918 | J13: 199.4464 | K13: 0.49184003 | L13: 0.56301292 | M13: 199.79 | N13: 0.14824003 | O13: 0.56422336 | P13: 199.9618 | Q13: -0.023559968 | R13: 0.56276013 | S13: 199.2986 | T13: 0.63964003 | U13: 0.56307477 | V13: 199.431 | W13: 0.50724003 | X13: 0.5633742 | Y13: 200.167 | Z13: -0.22875997 | AA13: 0.56266713
A14: 224.5564 | B14: 0.4293585 | C14: 0.58 | D14: 224.4394 | E14: 0.5463585 | F14: 0.58 | G14: 224.1956 | H14: 0.7901585 | I14: 0.58 | J14: 224.34 | K14: 0.6457585 | L14: 0.58 | M14: 224.6768 | N14: 0.3089585 | O14: 0.58 | P14: 224.9494 | Q14: 0.036358498 | R14: 0.58 | S14: 224.1736 | T14: 0.8121585 | U14: 0.58 | V14: 224.3282 | W14: 0.6575585 | X14: 0.58 | Y14: 225.1888 | Z14: -0.2030415 | AA14: 0.58
A15: 250.1786 | B15: -0.14554413 | C15: 0.58 | D15: 250.0146 | E15: 0.01845587 | F15: 0.58 | G15: 249.737 | H15: 0.29605587 | I15: 0.58 | J15: 249.836 | K15: 0.19705587 | L15: 0.58 | M15: 250.1444 | N15: -0.11134413 | O15: 0.58 | P15: 250.3834 | Q15: -0.35034413 | R15: 0.58 | S15: 249.626 | T15: 0.40705587 | U15: 0.58 | V15: 249.866 | W15: 0.16705587 | X15: 0.58 | Y15: 250.6834 | Z15: -0.65034413 | AA15: 0.58
A18: ch111 | D18: ch112 | G18: ch113 | J18: ch114 | M18: ch115 | P18: ch116 | S18: ch117 | V18: ch118 | Y18: ch119 | AB18: ch120
A19: rata rata | B19: Koreksi | C19: U95% | D19: rata rata | E19: Koreksi | F19: U95% | G19: rata rata | H19: Koreksi | I19: U95% | J19: rata rata | K19: Koreksi | L19: U95% | M19: rata rata | N19: Koreksi | O19: U95% | P19: rata rata | Q19: Koreksi | R19: U95% | S19: rata rata | T19: Koreksi | U19: U95% | V19: rata rata | W19: Koreksi | X19: U95% | Y19: rata rata | Z19: Koreksi | AA19: U95% | AB19: rata rata | AC19: Koreksi | AD19: U95%
A20: Alat | B20: Alat °C | C20: °C (k=2) | D20: Alat | E20: Alat °C | F20: °C (k=2) | G20: Alat | H20: Alat °C | I20: °C (k=2) | J20: Alat | K20: Alat °C | L20: °C (k=2) | M20: Alat | N20: Alat °C | O20: °C (k=2) | P20: Alat | Q20: Alat °C | R20: °C (k=2) | S20: Alat | T20: Alat °C | U20: °C (k=2) | V20: Alat | W20: Alat °C | X20: °C (k=2) | Y20: Alat | Z20: Alat °C | AA20: °C (k=2) | AB20: Alat | AC20: Alat °C | AD20: °C (k=2)
A21: -0.131 | B21: 0.133 | C21: 0.238 | D21: -0.409 | E21: 0.411 | F21: 0.239 | G21: -0.486 | H21: 0.487 | I21: 0.239 | J21: -0.449 | K21: 0.45 | L21: 0.238 | M21: -0.509 | N21: 0.511 | O21: 0.239 | P21: -0.502 | Q21: 0.503 | R21: 0.238 | S21: -0.563 | T21: 0.564 | U21: 0.239 | V21: -0.469 | W21: 0.47 | X21: 0.239 | Y21: -0.476 | Z21: 0.478 | AA21: 0.239 | AB21: -0.642 | AC21: 0.644 | AD21: 0.238
A22: 25.118 | B22: -0.113 | C22: 0.343 | D22: 25.064 | E22: -0.059 | F22: 0.346 | G22: 25.021 | H22: -0.015 | I22: 0.343 | J22: 24.982 | K22: 0.024 | L22: 0.343 | M22: 25.082 | N22: -0.076 | O22: 0.345 | P22: 24.965 | Q22: 0.04 | R22: 0.343 | S22: 24.927 | T22: 0.079 | U22: 0.343 | V22: 25.148 | W22: -0.143 | X22: 0.343 | Y22: 25.058 | Z22: -0.052 | AA22: 0.343 | AB22: 24.788 | AC22: 0.217 | AD22: 0.343
A23: 50.296 | B23: -0.291 | C23: 0.352 | D23: 50.34 | E23: -0.335 | F23: 0.352 | G23: 50.22 | H23: -0.215 | I23: 0.352 | J23: 50.199 | K23: -0.194 | L23: 0.351 | M23: 50.375 | N23: -0.37 | O23: 0.352 | P23: 50.131 | Q23: -0.126 | R23: 0.351 | S23: 50.071 | T23: -0.066 | U23: 0.352 | V23: 50.371 | W23: -0.366 | X23: 0.351 | Y23: 50.228 | Z23: -0.223 | AA23: 0.351 | AB23: 49.878 | AC23: 0.127 | AD23: 0.351
A24: 75.364 | B24: -0.365 | C24: 0.372 | D24: 75.27 | E24: -0.272 | F24: 0.372 | G24: 75.14 | H24: -0.141 | I24: 0.372 | J24: 75.2 | K24: -0.201 | L24: 0.371 | M24: 75.264 | N24: -0.265 | O24: 0.371 | P24: 75.111 | Q24: -0.113 | R24: 0.371 | S24: 75.225 | T24: -0.227 | U24: 0.371 | V24: 75.215 | W24: -0.217 | X24: 0.371 | Y24: 75.149 | Z24: -0.15 | AA24: 0.372 | AB24: 75.061 | AC24: -0.062 | AD24: 0.371
A25: 100.36 | B25: -0.359 | C25: 0.461 | D25: 100.21 | E25: -0.209 | F25: 0.462 | G25: 100.065 | H25: -0.064 | I25: 0.462 | J25: 100.165 | K25: -0.164 | L25: 0.462 | M25: 100.254 | N25: -0.253 | O25: 0.462 | P25: 100.009 | Q25: -0.008 | R25: 0.461 | S25: 100.165 | T25: -0.164 | U25: 0.462 | V25: 100.221 | W25: -0.22 | X25: 0.462 | Y25: 100.065 | Z25: -0.064 | AA25: 0.462 | AB25: 99.98 | AC25: 0.021 | AD25: 0.461
A26: 125.365 | B26: -0.362 | C26: 0.518 | D26: 125.281 | E26: -0.278 | F26: 0.518 | G26: 125.066 | H26: -0.063 | I26: 0.52 | J26: 125.168 | K26: -0.164 | L26: 0.518 | M26: 125.31 | N26: -0.306 | O26: 0.518 | P26: 125.041 | Q26: -0.038 | R26: 0.519 | S26: 125.23 | T26: -0.227 | U26: 0.518 | V26: 125.274 | W26: -0.271 | X26: 0.518 | Y26: 125.137 | Z26: -0.134 | AA26: 0.518 | AB26: 125.055 | AC26: -0.052 | AD26: 0.518
A27: 150.309 | B27: -0.308 | C27: 0.531 | D27: 150.28 | E27: -0.28 | F27: 0.531 | G27: 150.06 | H27: -0.059 | I27: 0.53 | J27: 150.182 | K27: -0.181 | L27: 0.531 | M27: 150.289 | N27: -0.288 | O27: 0.531 | P27: 150 | Q27: 0.001 | R27: 0.531 | S27: 150.242 | T27: -0.241 | U27: 0.53 | V27: 150.301 | W27: -0.3 | X27: 0.531 | Y27: 150.136 | Z27: -0.135 | AA27: 0.531 | AB27: 150.045 | AC27: -0.044 | AD27: 0.53
A28: 175.267 | B28: -0.299 | C28: 0.558 | D28: 175.208 | E28: -0.24 | F28: 0.557 | G28: 174.926 | H28: 0.042 | I28: 0.557 | J28: 175.08 | K28: -0.112 | L28: 0.559 | M28: 175.185 | N28: -0.217 | O28: 0.558 | P28: 174.939 | Q28: 0.029 | R28: 0.557 | S28: 175.209 | T28: -0.241 | U28: 0.556 | V28: 175.228 | W28: -0.26 | X28: 0.557 | Y28: 174.982 | Z28: -0.013 | AA28: 0.558 | AB28: 174.96 | AC28: 0.008 | AD28: 0.556
A29: 200.14 | B29: -0.202 | C29: 0.563 | D29: 200.138 | E29: -0.2 | F29: 0.563 | G29: 199.946 | H29: -0.007 | I29: 0.563 | J29: 199.994 | K29: -0.055 | L29: 0.563 | M29: 200.08 | N29: -0.142 | O29: 0.563 | P29: 199.81 | Q29: 0.128 | R29: 0.563 | S29: 200.136 | T29: -0.198 | U29: 0.563 | V29: 200.155 | W29: -0.217 | X29: 0.563 | Y29: 199.929 | Z29: 0.009 | AA29: 0.563 | AB29: 199.835 | AC29: 0.103 | AD29: 0.563
A30: 225.137 | B30: -0.151 | C30: 0.58 | D30: 225.09 | E30: -0.104 | F30: 0.58 | G30: 224.801 | H30: 0.185 | I30: 0.58 | J30: 224.979 | K30: 0.007 | L30: 0.58 | M30: 225.042 | N30: -0.056 | O30: 0.58 | P30: 224.746 | Q30: 0.24 | R30: 0.58 | S30: 225.133 | T30: -0.148 | U30: 0.58 | V30: 225.13 | W30: -0.144 | X30: 0.58 | Y30: 224.857 | Z30: 0.129 | AA30: 0.58 | AB30: 224.767 | AC30: 0.219 | AD30: 0.58
A31: 250.618 | B31: -0.585 | C31: 0.58 | D31: 250.528 | E31: -0.495 | F31: 0.58 | G31: 250.288 | H31: -0.255 | I31: 0.58 | J31: 250.418 | K31: -0.385 | L31: 0.58 | M31: 250.507 | N31: -0.474 | O31: 0.58 | P31: 250.239 | Q31: -0.206 | R31: 0.58 | S31: 250.62 | T31: -0.587 | U31: 0.58 | V31: 250.594 | W31: -0.561 | X31: 0.58 | Y31: 250.358 | Z31: -0.325 | AA31: 0.58 | AB31: 250.23 | AC31: -0.197 | AD31: 0.58
A32: 275.594 | B32: -0.54 | C32: 0.58 | D32: 275.643 | E32: -0.588 | F32: 0.58 | G32: 275.455 | H32: -0.4 | I32: 0.58 | J32: 275.412 | K32: -0.357 | L32: 0.58 | M32: 275.42 | N32: -0.365 | O32: 0.58 | P32: 275.28 | Q32: -0.225 | R32: 0.58 | S32: 275.475 | T32: -0.421 | U32: 0.58 | V32: 275.554 | W32: -0.499 | X32: 0.58 | Y32: 275.515 | Z32: -0.461 | AA32: 0.58 | AB32: 275.477 | AC32: -0.423 | AD32: 0.58
... A35: 349.536 | B35: 1.25 | C35: 0.915 | D35: 350.313 | E35: 0.474 | F35: 0.915 | G35: 348.738 | H35: 2.048 | I35: 0.915 | J35: 348.783 | K35: 2.003 | L35: 0.915 | M35: 349.722 | N35: 1.065 | O35: 0.915 | P35: 349.539 | Q35: 0.844 | R35: 1.243 | S35: 349.08 | T35: 1.303 | U35: 1.243 | V35: 349.551 | W35: 0.832 | X35: 1.243 | Y35: 349.167 | Z35: 1.216 | AA35: 1.243 | AB35: 348.662 | AC35: 1.721 | AD35: 1.243

Sheet DS2024
A1: 2024
A2: ch101 | D2: ch102 | G2: ch103 | J2: C104 | M2: ch105 | P2: ch106 | S2: ch107 | V2: ch108 | Y2: ch109 | AB2: CH110
A3: Rata-rata Alat (°C) | B3: Koreksi Alat (°C) | C3: U95% °C (k=2) | D3: Rata-rata Alat (°C) | E3: Koreksi Alat (°C) | F3: U95% °C (k=2) | G3: Rata-rata Alat (°C) | H3: Koreksi Alat (°C) | I3: U95% °C (k=2) | J3: Rata-rata Alat (°C) | K3: Koreksi Alat (°C) | L3: U95% °C (k=2) | M3: Rata-rata Alat (°C) | N3: Koreksi Alat (°C) | O3: U95% °C (k=2) | P3: Rata-rata Alat (°C) | Q3: Koreksi Alat (°C) | R3: U95% °C (k=2) | S3: Rata-rata Alat (°C) | T3: Koreksi Alat (°C) | U3: U95% °C (k=2) | V3: Rata-rata Alat (°C) | W3: Koreksi Alat (°C) | X3: U95% °C (k=2) | Y3: Rata-rata Alat (°C) | Z3: Koreksi Alat (°C) | AA3: U95% °C (k=2) | AB3: Rata-rata Alat (°C) | AC3: Koreksi Alat (°C) | AD3: U95% °C (k=2)
A5: -0.291 | B5: 0.231 | C5: 0.22 | D5: -0.323 | E5: 0.262 | F5: 0.22 | G5: -0.321 | H5: 0.26 | I5: 0.22 | J5: -0.323 | K5: 0.263 | L5: 0.22 | M5: -0.348 | N5: 0.288 | O5: 0.22 | P5: -0.327 | Q5: 0.266 | R5: 0.22 | S5: -0.374 | T5: 0.314 | U5: 0.22 | V5: -0.383 | W5: 0.322 | X5: 0.22 | Y5: -0.428 | Z5: 0.367 | AA5: 0.22 | AB5: -0.39 | AC5: 0.33 | AD5: 0.22
A6: 24.372 | B6: 0.389 | C6: 0.327 | D6: 24.388 | E6: 0.372 | F6: 0.328 | G6: 24.376 | H6: 0.385 | I6: 0.333 | J6: 24.345 | K6: 0.415 | L6: 0.328 | M6: 24.346 | N6: 0.414 | O6: 0.326 | P6: 24.353 | Q6: 0.408 | R6: 0.329 | S6: 24.294 | T6: 0.467 | U6: 0.328 | V6: 24.265 | W6: 0.496 | X6: 0.327 | Y6: 24.285 | Z6: 0.476 | AA6: 0.327 | AB6: 24.255 | AC6: 0.505 | AD6: 0.332
A7: 49.768 | B7: 0.079 | C7: 0.361 | D7: 49.742 | E7: 0.105 | F7: 0.362 | G7: 49.691 | H7: 0.156 | I7: 0.361 | J7: 49.725 | K7: 0.122 | L7: 0.36 | M7: 49.702 | N7: 0.145 | O7: 0.361 | P7: 49.697 | Q7: 0.15 | R7: 0.361 | S7: 49.628 | T7: 0.219 | U7: 0.36 | V7: 49.684 | W7: 0.163 | X7: 0.372 | Y7: 49.645 | Z7: 0.202 | AA7: 0.36 | AB7: 49.591 | AC7: 0.256 | AD7: 0.36
A8: 74.788 | B8: 0.099 | C8: 0.393 | D8: 74.765 | E8: 0.122 | F8: 0.393 | G8: 74.703 | H8: 0.184 | I8: 0.393 | J8: 74.719 | K8: 0.167 | L8: 0.392 | M8: 74.742 | N8: 0.144 | O8: 0.392 | P8: 74.735 | Q8: 0.151 | R8: 0.392 | S8: 74.655 | T8: 0.231 | U8: 0.391 | V8: 74.669 | W8: 0.217 | X8: 0.392 | Y8: 74.718 | Z8: 0.169 | AA8: 0.391 | AB8: 74.596 | AC8: 0.29 | AD8: 0.391
A9: 99.795 | B9: 0.096 | C9: 0.471 | D9: 99.794 | E9: 0.097 | F9: 0.471 | G9: 99.709 | H9: 0.182 | I9: 0.471 | J9: 99.719 | K9: 0.172 | L9: 0.471 | M9: 99.753 | N9: 0.138 | O9: 0.471 | P9: 99.733 | Q9: 0.158 | R9: 0.472 | S9: 99.627 | T9: 0.264 | U9: 0.472 | V9: 99.665 | W9: 0.226 | X9: 0.472 | Y9: 99.711 | Z9: 0.18 | AA9: 0.472 | AB9: 99.556 | AC9: 0.335 | AD9: 0.472
A10: 124.768 | B10: 0.156 | C10: 0.437 | D10: 124.76 | E10: 0.164 | F10: 0.437 | G10: 124.647 | H10: 0.278 | I10: 0.438 | J10: 124.666 | K10: 0.258 | L10: 0.438 | M10: 124.702 | N10: 0.222 | O10: 0.437 | P10: 124.671 | Q10: 0.253 | R10: 0.437 | S10: 124.563 | T10: 0.361 | U10: 0.437 | V10: 124.598 | W10: 0.326 | X10: 0.436 | Y10: 124.671 | Z10: 0.253 | AA10: 0.437 | AB10: 124.475 | AC10: 0.449 | AD10: 0.436
A11: 149.71 | B11: 0.24 | C11: 0.451 | D11: 149.716 | E11: 0.234 | F11: 0.45 | G11: 149.597 | H11: 0.354 | I11: 0.449 | J11: 149.638 | K11: 0.312 | L11: 0.449 | M11: 149.695 | N11: 0.255 | O11: 0.448 | P11: 149.673 | Q11: 0.277 | R11: 0.449 | S11: 149.557 | T11: 0.393 | U11: 0.448 | V11: 149.62 | W11: 0.33 | X11: 0.448 | Y11: 149.707 | Z11: 0.243 | AA11: 0.448 | AB11: 149.486 | AC11: 0.464 | AD11: 0.448
A12: 174.602 | B12: 0.355 | C12: 0.43 | D12: 174.578 | E12: 0.378 | F12: 0.43 | G12: 174.44 | H12: 0.516 | I12: 0.43 | J12: 174.483 | K12: 0.474 | L12: 0.43 | M12: 174.544 | N12: 0.412 | O12: 0.43 | P12: 174.492 | Q12: 0.464 | R12: 0.43 | S12: 174.393 | T12: 0.564 | U12: 0.43 | V12: 174.439 | W12: 0.517 | X12: 0.43 | Y12: 174.542 | Z12: 0.415 | AA12: 0.43 | AB12: 174.288 | AC12: 0.669 | AD12: 0.43
A13: 199.485 | B13: 0.447 | C13: 0.562 | D13: 199.477 | E13: 0.455 | F13: 0.563 | G13: 199.335 | H13: 0.598 | I13: 0.563 | J13: 199.366 | K13: 0.567 | L13: 0.562 | M13: 199.441 | N13: 0.492 | O13: 0.562 | P13: 199.394 | Q13: 0.539 | R13: 0.563 | S13: 199.27 | T13: 0.662 | U13: 0.562 | V13: 199.313 | W13: 0.62 | X13: 0.562 | Y13: 199.449 | Z13: 0.483 | AA13: 0.562 | AB13: 199.184 | AC13: 0.749 | AD13: 0.562
A14: 224.463 | B14: 0.46 | C14: 0.58 | D14: 224.455 | E14: 0.468 | F14: 0.58 | G14: 224.293 | H14: 0.63 | I14: 0.58 | J14: 224.31 | K14: 0.613 | L14: 0.58 | M14: 224.412 | N14: 0.511 | O14: 0.58 | P14: 224.362 | Q14: 0.561 | R14: 0.58 | S14: 224.226 | T14: 0.697 | U14: 0.58 | V14: 224.314 | W14: 0.609 | X14: 0.58 | Y14: 224.437 | Z14: 0.486 | AA14: 0.58 | AB14: 224.134 | AC14: 0.789 | AD14: 0.58
A15: 249.447 | B15: 0.412 | C15: 0.712 | D15: 249.481 | E15: 0.378 | F15: 0.714 | G15: 249.284 | H15: 0.575 | I15: 0.712 | J15: 249.274 | K15: 0.585 | L15: 0.712 | M15: 249.401 | N15: 0.459 | O15: 0.712 | P15: 249.382 | Q15: 0.478 | R15: 0.712 | S15: 249.23 | T15: 0.629 | U15: 0.712 | V15: 249.365 | W15: 0.494 | X15: 0.712 | Y15: 249.489 | Z15: 0.371 | AA15: 0.712 | AB15: 249.145 | AC15: 0.714 | AD15: 0.712
A17: ch111 | D17: ch112 | G17: ch113 | J17: ch114 | M17: ch115 | P17: ch116 | S17: ch117 | V17: ch118 | Y17: ch119 | AB17: ch120
A18: Rata-rata Alat (°C) | B18: Koreksi Alat (°C) | C18: U95% °C (k=2) | D18: Rata-rata Alat (°C) | E18: Koreksi Alat (°C) | F18: U95% °C (k=2) | G18: Rata-rata Alat (°C) | H18: Koreksi Alat (°C) | I18: U95% °C (k=2) | J18: Rata-rata Alat (°C) | K18: Koreksi Alat (°C) | L18: U95% °C (k=2) | M18: Rata-rata Alat (°C) | N18: Koreksi Alat (°C) | O18: U95% °C (k=2) | P18: Rata-rata Alat (°C) | Q18: Koreksi Alat (°C) | R18: U95% °C (k=2) | S18: Rata-rata Alat (°C) | T18: Koreksi Alat (°C) | U18: U95% °C (k=2) | V18: Rata-rata Alat (°C) | W18: Koreksi Alat (°C) | X18: U95% °C (k=2) | Y18: Rata-rata Alat (°C) | Z18: Koreksi Alat (°C) | AA18: U95% °C (k=2) | AB18: Rata-rata Alat (°C) | AC18: Koreksi Alat (°C) | AD18: U95% °C (k=2)
A20: -0.499 | B20: 0.439 | C20: 0.22 | D20: -0.535 | E20: 0.475 | F20: 0.22 | G20: -0.513 | H20: 0.453 | I20: 0.22 | J20: -0.534 | K20: 0.474 | L20: 0.22 | M20: -0.556 | N20: 0.496 | O20: 0.22 | P20: -0.524 | Q20: 0.463 | R20: 0.22 | S20: -0.523 | T20: 0.463 | U20: 0.22 | V20: -0.502 | W20: 0.441 | X20: 0.22 | Y20: -0.447 | Z20: 0.386 | AA20: 0.22 | AB20: -0.469 | AC20: 0.409 | AD20: 0.22
A21: 24.232 | B21: 0.528 | C21: 0.326 | D21: 24.211 | E21: 0.55 | F21: 0.326 | G21: 24.226 | H21: 0.534 | I21: 0.329 | J21: 24.17 | K21: 0.591 | L21: 0.327 | M21: 24.172 | N21: 0.588 | O21: 0.326 | P21: 24.23 | Q21: 0.531 | R21: 0.33 | S21: 24.167 | T21: 0.594 | U21: 0.328 | V21: 24.161 | W21: 0.6 | X21: 0.326 | Y21: 24.26 | Z21: 0.5 | AA21: 0.33 | AB21: 24.268 | AC21: 0.492 | AD21: 0.329
A22: 49.603 | B22: 0.244 | C22: 0.359 | D22: 49.606 | E22: 0.241 | F22: 0.36 | G22: 49.582 | H22: 0.265 | I22: 0.36 | J22: 49.565 | K22: 0.282 | L22: 0.36 | M22: 49.587 | N22: 0.26 | O22: 0.36 | P22: 49.568 | Q22: 0.279 | R22: 0.36 | S22: 49.6 | T22: 0.247 | U22: 0.36 | V22: 49.628 | W22: 0.219 | X22: 0.36 | Y22: 49.649 | Z22: 0.198 | AA22: 0.36 | AB22: 49.662 | AC22: 0.185 | AD22: 0.361
A23: 74.722 | B23: 0.164 | C23: 0.388 | D23: 74.756 | E23: 0.131 | F23: 0.391 | G23: 74.698 | H23: 0.188 | I23: 0.391 | J23: 74.696 | K23: 0.191 | L23: 0.389 | M23: 74.74 | N23: 0.146 | O23: 0.39 | P23: 74.672 | Q23: 0.215 | R23: 0.39 | S23: 74.729 | T23: 0.158 | U23: 0.389 | V23: 74.769 | W23: 0.118 | X23: 0.39 | Y23: 74.752 | Z23: 0.135 | AA23: 0.388 | AB23: 74.792 | AC23: 0.094 | AD23: 0.39
A24: 99.791 | B24: 0.1 | C24: 0.471 | D24: 99.793 | E24: 0.098 | F24: 0.472 | G24: 99.743 | H24: 0.148 | I24: 0.472 | J24: 99.727 | K24: 0.164 | L24: 0.471 | M24: 99.794 | N24: 0.097 | O24: 0.473 | P24: 99.716 | Q24: 0.175 | R24: 0.472 | S24: 99.784 | T24: 0.107 | U24: 0.471 | V24: 99.821 | W24: 0.07 | X24: 0.472 | Y24: 99.801 | Z24: 0.09 | AA24: 0.471 | AB24: 99.831 | AC24: 0.06 | AD24: 0.472
A25: 124.81 | B25: 0.114 | C25: 0.436 | D25: 124.805 | E25: 0.119 | F25: 0.436 | G25: 124.733 | H25: 0.191 | I25: 0.437 | J25: 124.733 | K25: 0.192 | L25: 0.437 | M25: 124.815 | N25: 0.109 | O25: 0.436 | P25: 124.723 | Q25: 0.201 | R25: 0.437 | S25: 124.786 | T25: 0.138 | U25: 0.436 | V25: 124.842 | W25: 0.082 | X25: 0.436 | Y25: 124.811 | Z25: 0.113 | AA25: 0.436 | AB25: 124.83 | AC25: 0.094 | AD25: 0.435
A26: 149.878 | B26: 0.072 | C26: 0.448 | D26: 149.876 | E26: 0.074 | F26: 0.448 | G26: 149.782 | H26: 0.168 | I26: 0.448 | J26: 149.772 | K26: 0.178 | L26: 0.448 | M26: 149.833 | N26: 0.117 | O26: 0.448 | P26: 149.749 | Q26: 0.202 | R26: 0.448 | S26: 149.833 | T26: 0.117 | U26: 0.447 | V26: 149.865 | W26: 0.085 | X26: 0.448 | Y26: 149.835 | Z26: 0.116 | AA26: 0.448 | AB26: 149.857 | AC26: 0.093 | AD26: 0.448
A27: 174.778 | B27: 0.178 | C27: 0.43 | D27: 174.765 | E27: 0.191 | F27: 0.43 | G27: 174.624 | H27: 0.332 | I27: 0.43 | J27: 174.658 | K27: 0.298 | L27: 0.43 | M27: 174.751 | N27: 0.205 | O27: 0.43 | P27: 174.6 | Q27: 0.356 | R27: 0.43 | S27: 174.706 | T27: 0.251 | U27: 0.43 | V27: 174.765 | W27: 0.191 | X27: 0.43 | Y27: 174.707 | Z27: 0.249 | AA27: 0.43 | AB27: 174.725 | AC27: 0.231 | AD27: 0.43
A28: 199.725 | B28: 0.207 | C28: 0.562 | D28: 199.703 | E28: 0.229 | F28: 0.562 | G28: 199.557 | H28: 0.375 | I28: 0.564 | J28: 199.612 | K28: 0.32 | L28: 0.562 | M28: 199.702 | N28: 0.231 | O28: 0.563 | P28: 199.535 | Q28: 0.398 | R28: 0.564 | S28: 199.673 | T28: 0.26 | U28: 0.563 | V28: 199.721 | W28: 0.211 | X28: 0.563 | Y28: 199.631 | Z28: 0.301 | AA28: 0.562 | AB28: 199.658 | AC28: 0.274 | AD28: 0.563
A29: 224.716 | B29: 0.207 | C29: 0.58 | D29: 224.722 | E29: 0.201 | F29: 0.58 | G29: 224.58 | H29: 0.343 | I29: 0.58 | J29: 224.596 | K29: 0.327 | L29: 0.58 | M29: 224.715 | N29: 0.208 | O29: 0.58 | P29: 224.553 | Q29: 0.37 | R29: 0.58 | S29: 224.654 | T29: 0.269 | U29: 0.58 | V29: 224.701 | W29: 0.222 | X29: 0.58 | Y29: 224.646 | Z29: 0.277 | AA29: 0.58 | AB29: 224.653 | AC29: 0.27 | AD29: 0.58
A30: 249.752 | B30: 0.107 | C30: 0.712 | D30: 249.816 | E30: 0.043 | F30: 0.712 | G30: 249.714 | H30: 0.145 | I30: 0.713 | J30: 249.673 | K30: 0.186 | L30: 0.712 | M30: 249.797 | N30: 0.062 | O30: 0.712 | P30: 249.655 | Q30: 0.204 | R30: 0.712 | S30: 249.722 | T30: 0.138 | U30: 0.712 | V30: 249.772 | W30: 0.087 | X30: 0.712 | Y30: 249.74 | Z30: 0.119 | AA30: 0.712 | AB30: 249.726 | AC30: 0.134 | AD30: 0.712
A31: 274.871 | B31: 0.125 | C31: 0.58 | D31: 274.86 | E31: 0.137 | F31: 0.58 | G31: 274.793 | H31: 0.203 | I31: 0.58 | J31: 274.783 | K31: 0.213 | L31: 0.58 | M31: 274.875 | N31: 0.121 | O31: 0.58 | P31: 274.728 | Q31: 0.268 | R31: 0.58 | S31: 274.802 | T31: 0.194 | U31: 0.58 | V31: 274.844 | W31: 0.153 | X31: 0.58 | Y31: 274.816 | Z31: 0.18 | AA31: 0.58 | AB31: 274.775 | AC31: 0.221 | AD31: 0.58
... A34: 350.254 | B34: 0.016 | C34: 1.251 | D34: 349.413 | E34: 0.857 | F34: 1.25 | G34: 349.359 | H34: 0.911 | I34: 1.25 | J34: 349.994 | K34: 0.276 | L34: 1.25 | M34: 350.193 | N34: 0.078 | O34: 1.25 | P34: 349.159 | Q34: 1.111 | R34: 1.038 | S34: 348.168 | T34: 2.102 | U34: 1.038 | V34: 347.857 | W34: 2.414 | X34: 1.038 | Y34: 348.702 | Z34: 1.568 | AA34: 1.038 | AB34: 348.696 | AC34: 1.574 | AD34: 1.038

Sheet Data 60 C
A1: Nama alat | C1: =PROPER(MID('Data Pembacaan Alt'!C2:I2,FIND(" ",'Data Pembacaan Alt'!C2:I2)+1,LEN('Data Pembacaan Alt'!C2:I2))) -> Oven | G1: Tanggal terima | I1: ='Data Pembacaan Alt'!B42 -> 45994
A2: Merek/Tipe | C2: ='Data Pembacaan Alt'!C7 -> Memmert | D2: / | E2: ='Data Pembacaan Alt'!G7 -> B 40 | G2: Tanggal kalibrasi | I2: ='Data Pembacaan Alt'!B43 -> 45994 | J2: ='Data Pembacaan Alt'!C43 -> 0
A3: Kapasitas | C3: ='Data Pembacaan Alt'!C8 -> (30 ~ 120) | D3: °C | G3: Prosedur | I3: ='Data Pembacaan Alt'!C10 -> IK-K-KT-02 (KAN Pd-02.04)
A4: Kecermatan | C4: ='Data Pembacaan Alt'!F8 -> 0.5 | D4: =D3 -> °C | G4: Temperatur | I4: ='Data Pembacaan Alt'!D13 -> 26.034483 | J4: °C ± | K4: ='Data Pembacaan Alt'!F13 -> 0.43103448
A5: No. Seri/No. ID | C5: ='Data Pembacaan Alt'!C9 -> 801356 | D5: / | E5: ='Data Pembacaan Alt'!G9 -> - | G5: Kelembaban relatif | I5: ='Data Pembacaan Alt'!D16 -> 69.432832 | J5: % RH ± | K5: ='Data Pembacaan Alt'!F16 -> 5.4584727
A6: Posisi Termokopel | B6: 1 | C6: 2 | D6: 3 | E6: 4 | F6: 5 | G6: 6 | H6: 7 | I6: 8 | J6: 9 | K6: Tind(°C)
A7: Menit Ke- | B7: CH111 | C7: CH112 | D7: CH113 | E7: CH114 | F7: CH115 | G7: CH116 | H7: CH117 | I7: CH118 | J7: CH119
A8: 1 | B8: ='DATA REKAMAN'!M90 -> 64.716 | C8: ='DATA REKAMAN'!N90 -> 65.29 | D8: ='DATA REKAMAN'!O90 -> 64.555 | E8: ='DATA REKAMAN'!P90 -> 64.639 | F8: ='DATA REKAMAN'!Q90 -> 65.074 | G8: ='DATA REKAMAN'!R90 -> 66.276 | H8: ='DATA REKAMAN'!S90 -> 64.437 | I8: ='DATA REKAMAN'!T90 -> 64.82 | J8: ='DATA REKAMAN'!U90 -> 64.594 | K8: ='Data Pembacaan Alt'!C62 -> 63.5
A9: 2 | B9: ='DATA REKAMAN'!M91 -> 64.668 | C9: ='DATA REKAMAN'!N91 -> 65.375 | D9: ='DATA REKAMAN'!O91 -> 64.682 | E9: ='DATA REKAMAN'!P91 -> 64.671 | F9: ='DATA REKAMAN'!Q91 -> 64.528 | G9: ='DATA REKAMAN'!R91 -> 65.249 | H9: ='DATA REKAMAN'!S91 -> 64.219 | I9: ='DATA REKAMAN'!T91 -> 64.403 | J9: ='DATA REKAMAN'!U91 -> 64.695 | K9: ='Data Pembacaan Alt'!C63 -> 63.5
A10: 3 | B10: ='DATA REKAMAN'!M92 -> 64.551 | C10: ='DATA REKAMAN'!N92 -> 65.172 | D10: ='DATA REKAMAN'!O92 -> 64.461 | E10: ='DATA REKAMAN'!P92 -> 64.529 | F10: ='DATA REKAMAN'!Q92 -> 63.782 | G10: ='DATA REKAMAN'!R92 -> 64.295 | H10: ='DATA REKAMAN'!S92 -> 63.536 | I10: ='DATA REKAMAN'!T92 -> 63.555 | J10: ='DATA REKAMAN'!U92 -> 64.593 | K10: ='Data Pembacaan Alt'!C64 -> 64
A11: 4 | B11: ='DATA REKAMAN'!M93 -> 64.742 | C11: ='DATA REKAMAN'!N93 -> 65.357 | D11: ='DATA REKAMAN'!O93 -> 64.657 | E11: ='DATA REKAMAN'!P93 -> 64.69 | F11: ='DATA REKAMAN'!Q93 -> 64.755 | G11: ='DATA REKAMAN'!R93 -> 65.806 | H11: ='DATA REKAMAN'!S93 -> 64.105 | I11: ='DATA REKAMAN'!T93 -> 64.533 | J11: ='DATA REKAMAN'!U93 -> 64.717 | K11: ='Data Pembacaan Alt'!C65 -> 64
A12: 5 | B12: ='DATA REKAMAN'!M94 -> 64.978 | C12: ='DATA REKAMAN'!N94 -> 65.594 | D12: ='DATA REKAMAN'!O94 -> 64.943 | E12: ='DATA REKAMAN'!P94 -> 65 | F12: ='DATA REKAMAN'!Q94 -> 65.106 | G12: ='DATA REKAMAN'!R94 -> 66.141 | H12: ='DATA REKAMAN'!S94 -> 64.713 | I12: ='DATA REKAMAN'!T94 -> 64.998 | J12: ='DATA REKAMAN'!U94 -> 64.956 | K12: ='Data Pembacaan Alt'!C66 -> 64
A13: 6 | B13: ='DATA REKAMAN'!M95 -> 64.936 | C13: ='DATA REKAMAN'!N95 -> 65.49 | D13: ='DATA REKAMAN'!O95 -> 64.834 | E13: ='DATA REKAMAN'!P95 -> 64.933 | F13: ='DATA REKAMAN'!Q95 -> 64.432 | G13: ='DATA REKAMAN'!R95 -> 64.968 | H13: ='DATA REKAMAN'!S95 -> 64.235 | I13: ='DATA REKAMAN'!T95 -> 64.329 | J13: ='DATA REKAMAN'!U95 -> 64.938 | K13: ='Data Pembacaan Alt'!C67 -> 64
A14: 7 | B14: ='DATA REKAMAN'!M96 -> 64.755 | C14: ='DATA REKAMAN'!N96 -> 65.355 | D14: ='DATA REKAMAN'!O96 -> 64.706 | E14: ='DATA REKAMAN'!P96 -> 64.757 | F14: ='DATA REKAMAN'!Q96 -> 63.917 | G14: ='DATA REKAMAN'!R96 -> 64.43 | H14: ='DATA REKAMAN'!S96 -> 63.628 | I14: ='DATA REKAMAN'!T96 -> 63.633 | J14: ='DATA REKAMAN'!U96 -> 64.833 | K14: ='Data Pembacaan Alt'!C68 -> 64
A15: 8 | B15: ='DATA REKAMAN'!M97 -> 65.199 | C15: ='DATA REKAMAN'!N97 -> 65.799 | D15: ='DATA REKAMAN'!O97 -> 65.062 | E15: ='DATA REKAMAN'!P97 -> 65.134 | F15: ='DATA REKAMAN'!Q97 -> 65.431 | G15: ='DATA REKAMAN'!R97 -> 66.447 | H15: ='DATA REKAMAN'!S97 -> 64.79 | I15: ='DATA REKAMAN'!T97 -> 65.247 | J15: ='DATA REKAMAN'!U97 -> 65.137 | K15: ='Data Pembacaan Alt'!C69 -> 64
A16: 9 | B16: ='DATA REKAMAN'!M98 -> 65.245 | C16: ='DATA REKAMAN'!N98 -> 65.814 | D16: ='DATA REKAMAN'!O98 -> 65.202 | E16: ='DATA REKAMAN'!P98 -> 65.248 | F16: ='DATA REKAMAN'!Q98 -> 65.066 | G16: ='DATA REKAMAN'!R98 -> 65.74 | H16: ='DATA REKAMAN'!S98 -> 64.835 | I16: ='DATA REKAMAN'!T98 -> 65.003 | J16: ='DATA REKAMAN'!U98 -> 65.224 | K16: ='Data Pembacaan Alt'!C70 -> 64
A17: 10 | B17: ='DATA REKAMAN'!M99 -> 65.105 | C17: ='DATA REKAMAN'!N99 -> 65.656 | D17: ='DATA REKAMAN'!O99 -> 64.967 | E17: ='DATA REKAMAN'!P99 -> 65.096 | F17: ='DATA REKAMAN'!Q99 -> 64.333 | G17: ='DATA REKAMAN'!R99 -> 64.848 | H17: ='DATA REKAMAN'!S99 -> 64.155 | I17: ='DATA REKAMAN'!T99 -> 64.192 | J17: ='DATA REKAMAN'!U99 -> 65.158 | K17: ='Data Pembacaan Alt'!C71 -> 64
A18: 11 | B18: ='DATA REKAMAN'!M100 -> 65.138 | C18: ='DATA REKAMAN'!N100 -> 65.763 | D18: ='DATA REKAMAN'!O100 -> 65.001 | E18: ='DATA REKAMAN'!P100 -> 65.056 | F18: ='DATA REKAMAN'!Q100 -> 64.748 | G18: ='DATA REKAMAN'!R100 -> 65.658 | H18: ='DATA REKAMAN'!S100 -> 64.105 | I18: ='DATA REKAMAN'!T100 -> 64.569 | J18: ='DATA REKAMAN'!U100 -> 65.159 | K18: ='Data Pembacaan Alt'!C72 -> 64.5
A19: 12 | B19: ='DATA REKAMAN'!M101 -> 65.532 | C19: ='DATA REKAMAN'!N101 -> 66.101 | D19: ='DATA REKAMAN'!O101 -> 65.391 | E19: ='DATA REKAMAN'!P101 -> 65.505 | F19: ='DATA REKAMAN'!Q101 -> 65.691 | G19: ='DATA REKAMAN'!R101 -> 66.683 | H19: ='DATA REKAMAN'!S101 -> 65.198 | I19: ='DATA REKAMAN'!T101 -> 65.52 | J19: ='DATA REKAMAN'!U101 -> 65.456 | K19: ='Data Pembacaan Alt'!C73 -> 64.5
... A37: 30 | B37: ='DATA REKAMAN'!M119 -> 66.271 | C37: ='DATA REKAMAN'!N119 -> 66.787 | D37: ='DATA REKAMAN'!O119 -> 66.064 | E37: ='DATA REKAMAN'!P119 -> 66.137 | F37: ='DATA REKAMAN'!Q119 -> 66.047 | G37: ='DATA REKAMAN'!R119 -> 66.904 | H37: ='DATA REKAMAN'!S119 -> 65.368 | I37: ='DATA REKAMAN'!T119 -> 65.839 | J37: ='DATA REKAMAN'!U119 -> 66.203 | K37: ='Data Pembacaan Alt'!C91 -> 65

Sheet Evaluasi 60 C
A2: Resolusi | B2: 0.1 | C2: °C
B4: Channel | C4: ch111 | F4: ch112 | I4: ch112 | L4: ch111 | O4: ch111 | R4: ch111 | U4: ch111 | X4: ch111 | AA4: ch111
B5: T1 | E5: T2 | H5: T3 | K5: T4 | N5: T5 | Q5: T6 | T5: T7 | W5: T8 | Z5: T9 | AC5: Indikator
B6: T | C6: Koreksi | D6: Terkoreksi | E6: T | F6: Koreksi | G6: Terkoreksi | H6: T | I6: Koreksi | J6: Terkoreksi | K6: T | L6: Koreksi | M6: Terkoreksi | N6: T | O6: Koreksi | P6: Terkoreksi | Q6: T | R6: Koreksi | S6: Terkoreksi | T6: T | U6: Koreksi | V6: Terkoreksi | W6: T | X6: Koreksi | Y6: Terkoreksi | Z6: T | AA6: Koreksi | AB6: Terkoreksi | AC6: Inkubator
