Workbook
Name sert: #REF!

Sheet Sertifikat
A7: S E R T I F I K A T K A L I B R A S I
A8: C A L I B R A T I O N C E R T I F I C A T E
A9: Nomor / Number : 0058-7.2/KALIBRASI BBLM/XII/2025
B14: IDENTITAS ALAT
B15: INSTRUMENT DETAILS
B17: Nama Alat | E17: : pH meter
B18: Instrument Name
B19: Merek | E19: =CONCATENATE(":"," ",'Budget pH meter'!B7) -> : Thermo Scientific
B20: Brand
B21: Tipe | E21: =CONCATENATE(":"," ",'Budget pH meter'!B8) -> : Orion Star A325
B22: Type
B23: Nomor Identifikasi | E23: =CONCATENATE(":"," ",'Budget pH meter'!B9) -> : -
B24: Identification Number
B25: Nomor Seri | E25: =CONCATENATE(":"," ",'Budget pH meter'!B10) -> : G13040
B26: Serial Number
B27: Lain-lain | E27: : Kapasitas | G27: =CONCATENATE(":"," ",'Budget pH meter'!B11," ",'Budget pH meter'!E11) -> : (-2,00) s.d. 20,00 pH
B28: Others | E28: Kecermatan | G28: =CONCATENATE(":"," ",'Budget pH meter'!D11," ",'Budget pH meter'!E11) -> : 0,01 pH
B30: IDENTITAS PEMILIK
B31: Owner’s Identification
B33: Nama | C33: =CONCATENATE(":"," ",'Budget pH meter'!B6) -> : UPTD. Laboratorium Lingkungan Hidup, DLH Jawa Barat
B34: Designation
B35: Alamat | C35: =CONCATENATE(":"," ",'Budget pH meter'!B2) -> : Jl. A. H. Nasution No. 117, Pasir Endah, Kec. ujung Berung, Bandung 40619
B36: Address
I38: Halaman 1 dari 2 halaman
I39: Page of page
I41: Diterbitkan Tanggal 15 Desember 2025
I42: Date of Issue
G44: Penguji Mutu Barang Ahli Madya
G45: Elis Sofianti
G46: NIP. 197109301994032002
G66: Nomor | H66: =CONCATENATE(":"," ",MID(A9,18,100)) -> : 0058-7.2/KALIBRASI BBLM/XII/2025
G67: No. Order | H67: =": " &'Budget pH meter'!B3 -> : K663-2
G68: Halaman | H68: : 2 dari 2
B70: SPESIFIKASI ALAT
B71: Nama | D71: =E17 -> : pH meter
B72: Merk / Tipe | D72: =CONCATENATE(":"," ",'Budget pH meter'!B7," ","/"," ",'Budget pH meter'!B8) -> : Thermo Scientific / Orion Star A325
B73: No. Identifikasi | D73: =E23 -> : -
B74: No. Seri | D74: =E25 -> : G13040
B75: Kapasitas | D75: =G27 -> : (-2,00) s.d. 20,00 pH
B76: Kecermatan | D76: =G28 -> : 0,01 pH | G76: Kondisi ruang
...

Sheet Budget pH meter
A1: data kalibrasi
A2: Alamat | B2: Jl. A. H. Nasution No. 117, Pasir Endah, Kec. ujung Berung, Bandung 40619
A3: no. order | B3: K663-2 | K3: Thermohygro Beureur data 2025
A4: tanggal terima | B4: 25 November 2025 | G4: Suhu (°C) | H4: %RH | K4: Koreksi suhu | N4: Koreksi RH
A5: tanggal kalibrasi | B5: 1 Desember 2025 | F5: Awal | G5: 19.5 | H5: 65 | K5: T (°C) | L5: Koreksi | M5: U95 | N5: RH (%) | O5: Koreksi | P5: U95
A6: Pemilik | B6: UPTD. Laboratorium Lingkungan Hidup, DLH Jawa Barat | F6: Akhir | G6: 19.5 | H6: 65 | K6: 20.01 | L6: 0.3 | M6: 2 | N6: 40.01 | O6: -2 | P6: 3
A7: merk | B7: Thermo Scientific | F7: Rata2 | G7: =AVERAGE(G5:G6) -> 19.5 | H7: =AVERAGE(H5:H6) -> 65 | K7: 25 | L7: 0.4 | M7: 2 | N7: 50.01 | O7: -3 | P7: 3
A8: Tipe | B8: Orion Star A325 | F8: Terkoreksi | G8: =G7+FORECAST(G7,L6:L10,K6:K10) -> 19.563469 | H8: =H7+FORECAST(H7,O6:O10,N6:N10) -> 63.523834 | K8: 30 | L8: 0.5 | M8: 2 | N8: 60.02 | O8: -1 | P8: 3
A9: No identifikasi | B9: - | F9: U95 | G9: 2 | H9: =FORECAST(H8,P6:P10,N6:N10) -> 2.7723924 | K9: 35 | L9: 1.2 | M9: 2 | N9: 70 | O9: 0 | P9: 2
A10: no seri | B10: G13040 | F10: Fluktuasi suhu | G10: =(MAX(G5:G6)-G7+G7-MIN(G5:G6))/2 -> 0 | H10: =(MAX(H5:H6)-H7+H7-MIN(H5:H6))/2 -> 0 | K10: 40 | L10: 1.7 | M10: 2 | N10: 82 | O10: -2 | P10: 3
A11: kapasitas/resolusi | B11: (-2,00) s.d. 20,00 | C11: / | D11: 0.01 | E11: pH | F11: Flu+U95 | G11: =G9+G10 -> 2 | H11: =H9+H10 -> 2.7723924
F12: Kondisi Ruang | G12: =FIXED(G8,1) & " ± "&FIXED(G11,1) -> 19,6 ± 2,0 | H12: =FIXED(H8,0) & " ± "&FIXED(H11,0) -> 64 ± 3
G14: Suhu Awal | H14: Suhu Akhir
A15: PH 4 | F15: Suhu buffer | G15: 19.7 | H15: 19.8 | I15: °C | N15: koreksi temperatur | Q15: Nilai koreksi termometer digital tahun 2025
A16: buffer standar | B16: suhu °C | C16: pembacaan alat | I16: stdev | J16: standar terkoreksi | K16: =Q18 -> 19.3 | L16: =S18 -> 19.1 | Q16: pembacaan alat | R16: koreksi | S16: pembacaan alat terkoreksi
C17: X1 | D17: X2 | E17: X3 | F17: X4 | G17: X5 | H17: X rata | K17: =AVERAGE(G15,H15) -> 19.75 | L17: =(K17-K16)*(L18-L16)/(K18-K16)+L16 -> 19.575 | N17: =L17-K17 -> -0.175 | Q17: °C | R17: °C | S17: °C
A18: 4 | B18: =L17 -> 19.575 | C18: 3.98 | D18: 3.98 | E18: 3.98 | F18: 3.98 | G18: 3.98 | H18: =AVERAGE(C18:G18) -> 3.98 | I18: =STDEV(C18:G18) -> 4.9650683e-16 | J18: =A18-R46 -> 3.99915 | K18: =Q20 -> 21.1 | L18: =S20 -> 21 | Q18: 19.3 | R18: -0.2 | S18: =Q18+R18 -> 19.1
B19: mV | C19: 175.8 | D19: 175.8 | E19: 175.8 | F19: 175.8 | G19: 175.8 | H19: =AVERAGE(C19:G19) -> 175.8 | Q19: 20.1 | R19: -0.2 | S19: =Q19+R19 -> 19.9
G20: Suhu Awal | H20: Suhu Akhir | Q20: 21.1 | R20: -0.1 | S20: =Q20+R20 -> 21
A21: PH 7 | F21: Suhu buffer | G21: 19.9 | H21: 19.9 | I21: °C
A22: buffer standar | B22: suhu °C | C22: pembacaan alat | I22: stdev | J22: standar terkoreksi | K22: =Q18 -> 19.3 | L22: =S18 -> 19.1
C23: X1 | D23: X2 | E23: X3 | F23: X4 | G23: X5 | H23: X rata | K23: =AVERAGE(G21,H21) -> 19.9 | L23: =(K23-K22)*(L24-L22)/(K24-K22)+L22 -> 19.733333 | N23: =L23-K23 -> -0.16666667
A24: 7 | B24: =L23 -> 19.733333 | C24: 6.99 | D24: 6.98 | E24: 6.98 | F24: 6.98 | G24: 6.98 | H24: =AVERAGE(C24:G24) -> 6.982 | I24: =STDEV(C24:G24) -> 0.004472136 | J24: =A24+R64 -> 7.0010667 | K24: =Q20 -> 21.1 | L24: =S20 -> 21
B25: mV | C25: 1.7 | D25: 1.8 | E25: 1.9 | F25: 1.9 | G25: 1.9 | H25: =AVERAGE(C25:G25) -> 1.84 | Q25: % Slope | R25: Standard | S25: 58.24 | T25: Delta ABS
G26: Suhu Awal | H26: Suhu Akhir | Q26: =(H19-H25)/(H24-H18) -> 57.948035 | R26: =Q26/S25 -> 0.99498686 | T26: =ABS(Q26-S25) -> 0.29196536
A27: PH 10 | F27: suhu buffer | G27: 19.9 | H27: 19.8 | I27: °C | Q27: =(H25-H31)/(H30-H24) -> 43.384813 | R27: =Q27/S25 -> 0.74493155 | T27: =ABS(Q27-S25) -> 14.855187
A28: buffer standar | B28: suhu °C | C28: pembacaan alat | I28: stdev | J28: standar terkoreksi | K28: =Q18 -> 19.3 | L28: =S18 -> 19.1
C29: X1 | D29: X2 | E29: X3 | F29: X4 | G29: X5 | H29: X rata | K29: =AVERAGE(G27,H27) -> 19.85 | L29: =(K29-K28)*(L30-L28)/(K30-K28)+L28 -> 19.680556 | N29: =L29-K29 -> -0.16944444
A30: 10 | B30: =L29 -> 19.680556 | C30: 10.09 | D30: 10.09 | E30: 10.09 | F30: 10.09 | G30: 10.09 | H30: =AVERAGE(C30:G30) -> 10.09 | I30: =STDEV(C30:G30) -> 0 | J30: =A30+R82 -> 10.003194 | K30: =Q20 -> 21.1 | L30: =S20 -> 21 | Q30: Hasil | R30: =IF(T26<T27,R26,IF(T27<T26,R27,0)) -> 0.99498686
B31: mV | C31: -133 | D31: -133 | E31: -133 | F31: -133 | G31: -133 | H31: =AVERAGE(C31:G31) -> -133
G32: Suhu Awal | H32: Suhu Akhir
A33: PH 2 | F33: suhu buffer | G33: 0 | H33: 0 | I33: °C
A34: buffer standar | B34: suhu °C | C34: pembacaan alat | I34: stdev | J34: standar terkoreksi | K34: =Q18 -> 19.3 | L34: =S18 -> 19.1
C35: X1 | D35: X2 | E35: X3 | F35: X4 | G35: X5 | H35: X rata | K35: =AVERAGE(G33,H33) -> 0 | L35: =(K35-K34)*(L36-L34)/(K36-K34)+L34 -> -1.2722222 | N35: =L35-K35 -> -1.2722222
A36: 2 | B36: =L35 -> -1.2722222 | C36: 0 | D36: 0 | E36: 0 | F36: 0 | G36: 0 | H36: =AVERAGE(C36:G36) -> 0 | I36: =STDEV(C36:G36) -> 0 | J36: =A36+R103 -> 2.7572911 | K36: =Q20 -> 21.1 | L36: =S20 -> 21
B37: mV | C37: 0 | D37: 0 | E37: 0 | F37: 0 | G37: 0 | H37: =AVERAGE(C37:G37) -> 0
A40: St. deviasi | B40: =I18 -> 4.9650683e-16 | D40: U sertifikat Buffer | E40: 0.02 | G40: Koreksi | H40: =R46 -> 0.00085 | N40: temperatur °C | O40: ΔPH
D41: U sertifikat thermometer | E41: =0.4 -> 0.4 | N41: 0 | O41: 0.05 | Q41: temperatur °C | R41: ΔPH
A42: Skala terkecil alat | B42: =D11 -> 0.01 | N42: 5 | O42: 0.04
N43: 10 | O43: 0.02
...
