Workbook

Sheet Sertifikat
B2: S E R T I F I K A T K A L I B R A S I
B3: C A L I B R A T I O N C E R T I F I C A T E
G4: Nomor / | H4: Number | K4: : | N4: 0174-1.2 | O4: =CONCATENATE("/KALIBRASI BBLM/",ROMAN(TEXT(T37,"m")),"/",TEXT(T37,"yyyy")) -> /KALIBRASI BBLM/XI/2025
B7: IDENTITAS ALAT
B8: INSTRUMENT DETAILS
B10: Nama Alat | H10: ='Data Mentah PT100'!F2 -> PT100
B11: Instrument Name
B12: Merek | H12: ='Data Mentah PT100'!C7 -> -
B13: Brand
B14: Tipe | H14: ='Data Mentah PT100'!G7 -> -
B15: Type
B16: Nomor Identitas | H16: ='Data Mentah PT100'!F9 -> 162/CBM/LABI/25
B17: Identity Number
B18: Nomor Seri | H18: ='Data Mentah PT100'!C9 -> -
B19: Serial Number
B20: Lain-lain | H20: Kapasitas | M20: =CONCATENATE('Data Mentah PT100'!C8," ",'Data Mentah PT100'!D8) -> 500 °C
B21: Others
B24: IDENTITAS PEMILIK
B25: OWNER'S IDENTIFICATION
B27: Nama | H27: PT Calfindo Berkah Mandiri
B28: Designation
B29: Alamat | H29: Grand Residence City, Cluster Senopati Park Blok CA 40 No. 8, Burangkeng, Kec. Setu, Kabupaten Bekasi, Jawa Barat 17320
B30: Address
P34: Halaman | Q34: 1 | R34: dari | T34: 2 | U34: halaman
P35: Page | R35: of | U35: pages
S37: Diterbitkan Tanggal | T37: 45988
S38: Date of Issue
N41: Penguji Mutu Barang Ahli Madya,
N42: Elis Sofianti
N43: NIP. 197109301994032002
M52: Nomor | Q52: =CONCATENATE($N$4,$O$4) -> 0174-1.2/KALIBRASI BBLM/XI/2025
M53: No. Order | Q53: ='Data Mentah PT100'!C32 -> K595
M54: Halaman | Q54: =CONCATENATE(INT(ROW()/50)+1, " dari ",$T$34) -> 2 dari 2
B56: SPESIFIKASI ALAT
B57: Nama | J57: ='Data Mentah PT100'!F2 -> PT100
B58: Merek / Tipe | J58: =CONCATENATE('Data Mentah PT100'!C7," / ",'Data Mentah PT100'!G7) -> - / -
B59: No. Identitas / No. Seri | J59: =CONCATENATE('Data Mentah PT100'!F9," / ",'Data Mentah PT100'!C9) -> 162/CBM/LABI/25 / -
B60: Kapasitas | J60: =CONCATENATE('Data Mentah PT100'!C8," ",'Data Mentah PT100'!D8) -> 500 °C
B61: Prosedur Kalibrasi | J61: ='Data Mentah PT100'!C10 -> IK-K-KT-04
B62: Tanggal Terima | J62: ='Data Mentah PT100'!C33 -> 45952 | R62: Kondisi ruang
...

Sheet Data Mentah PT100
D2: KALIBRASI | F2: PT100
A3: LABORATORIUM KALIBRASI DAN PENGUJIAN
A4: BALAI BESAR LOGAM DAN MESIN
A5: BANDUNG
A7: Merk | B7: : | C7: - | F7: Tipe | G7: -
A8: Kapasitas/Graduasi : | C8: 500 | D8: °C
A9: No. Seri | B9: : | C9: - | E9: No. ID : | F9: 162/CBM/LABI/25
A10: Standar Acuan : | C10: IK-K-KT-04
A11: Temperatur Ruangan (T) | F11: Kelembaban (RH)
A12: T awal | B12: 20.9 | C12: 19.9 | D12: 23.2 | E12: °C | F12: RH awal | G12: 60 | H12: 69.7 | I12: 58.5
A13: Takhir | B13: 27 | C13: 22.5 | D13: 23.8 | E13: °C | F13: RH akhir | G13: 60 | H13: 78.6 | I13: 55.5
B14: (Oakton) | C14: Rotronic | G14: (Oakton) | H14: Rotronic
A15: Pembacaan Standar (W) | F15: Pembacaan Alat (W)
A16: S1 | B16: S2 | C16: S3 | D16: S4 | E16: S5 | F16: X1 | G16: X2 | H16: X3 | I16: X4 | J16: X5
A17: 100.01 | B17: 100.01 | C17: 100.01 | D17: 100.01 | E17: 100.01 | F17: 100.15 | G17: 100.15 | H17: 100.15 | I17: 100.15 | J17: 100.15
A18: 109.93 | B18: 109.93 | C18: 109.93 | D18: 109.935 | E18: 109.935 | F18: 109.905 | G18: 109.905 | H18: 109.905 | I18: 109.9 | J18: 109.9
A19: 119.825 | B19: 119.825 | C19: 119.825 | D19: 119.82 | E19: 119.82 | F19: 119.46 | G19: 119.46 | H19: 119.455 | I19: 119.455 | J19: 119.45
A20: 129.575 | B20: 129.575 | C20: 129.58 | D20: 129.575 | E20: 129.58 | F20: 129.175 | G20: 129.175 | H20: 129.18 | I20: 129.175 | J20: 129.185
A21: 139.275 | B21: 139.275 | C21: 139.275 | D21: 139.275 | E21: 139.275 | F21: 138.71 | G21: 138.71 | H21: 138.7 | I21: 138.7 | J21: 138.71
A22: 148.905 | B22: 148.905 | C22: 148.905 | D22: 148.9 | E22: 148.905 | F22: 148.17 | G22: 148.17 | H22: 148.18 | I22: 148.18 | J22: 148.17
A23: 158.45 | B23: 158.45 | C23: 158.45 | D23: 158.46 | E23: 158.46 | F23: 157.58 | G23: 157.58 | H23: 157.575 | I23: 157.59 | J23: 157.59
A24: 167.92 | B24: 167.92 | C24: 167.92 | D24: 167.94 | E24: 167.94 | F24: 166.98 | G24: 166.98 | H24: 166.96 | I24: 166.96 | J24: 166.98
A25: 177.34 | B25: 177.34 | C25: 177.32 | D25: 177.32 | E25: 177.32 | F25: 176.16 | G25: 176.16 | H25: 176.16 | I25: 176.18 | J25: 176.18
A26: 186.66 | B26: 186.68 | C26: 186.68 | D26: 186.66 | E26: 186.66 | F26: 185.28 | G26: 185.28 | H26: 185.28 | I26: 185.28 | J26: 185.28
A27: 195.94 | B27: 195.94 | C27: 195.94 | D27: 195.94 | E27: 195.94 | F27: 194.48 | G27: 194.48 | H27: 194.48 | I27: 194.48 | J27: 194.48
A32: No. Order | C32: K595 | F32: Dikalibrasi | G32: Tris,Nikita | I32: Paraf
A33: Tgl.terima | C33: 45952 | F33: Dipertiksa | G33: Nur ID
A34: Tgl.kalibrasi | C34: 45959 | D34: s.d. | E34: 45961 | F34: Disetujui | G34: Yoyon S
A35: Kalibrator yang digunakan :
A36: Temperature Calibrator Beamex TC305 No. Seri 3209 dan IPRT Burns Engr 3925 No. Seri 490464 tertelusur ke SI melalui LK-001-IDN dan LK-304-IDN.
H40: F-IK-K-04-KT-04

Sheet Olahdata-PT100 C
A2: KALIBRASI PT100
A3: LABORATORIUM KALIBRASI DAN PENGUJIAN
A4: BALAI BESAR LOGAM DAN MESIN
A5: BANDUNG
A7: Merk | C7: ='Data Mentah PT100'!C7 -> - | G7: Type : | H7: ='Data Mentah PT100'!G7 -> -
A8: Kapasitas/Graduasi | C8: ='Data Mentah PT100'!C8 -> 500
A9: No. Seri | C9: ='Data Mentah PT100'!C9 -> -
A10: Standar Acuan | C10: ='Data Mentah PT100'!C10 -> IK-K-KT-04
A11: Temperatur Ruangan (T) | H11: Kelembaban (RH)
A12: T awal : | B12: ='Data Mentah PT100'!B12 -> 20.9 | C12: ='Data Mentah PT100'!C12 -> 19.9 | D12: ='Data Mentah PT100'!D12 -> 23.2 | E12: =FORECAST(B12,'THM A21011860&Oakton'!I4:I5,'THM A21011860&Oakton'!H4:H5) -> 0.56551724 | F12: =FORECAST(C12,'THM A21011860&Oakton'!B4:B5,'THM A21011860&Oakton'!A4:A5) -> 0.3149643 | G12: =FORECAST(D12,'THM A21011860&Oakton'!I4:I5,'THM A21011860&Oakton'!H4:H5) -> 0.24827586 | H12: RH awal | I12: ='Data Mentah PT100'!G12 -> 60 | J12: ='Data Mentah PT100'!H12 -> 69.7 | K12: ='Data Mentah PT100'!I12 -> 58.5 | L12: %RH | M12: Koreksi | N12: =FORECAST(I12,'THM A21011860&Oakton'!K5:K6,'THM A21011860&Oakton'!J5:J6) -> -1.0526316 | O12: =FORECAST(J12,'THM A21011860&Oakton'!D6:D7,'THM A21011860&Oakton'!C6:C7) -> -0.010961448 | P12: =FORECAST(K12,'THM A21011860&Oakton'!K5:K6,'THM A21011860&Oakton'!J5:J6) -> -1.1315789
A13: Takhir : | B13: ='Data Mentah PT100'!B13 -> 27 | C13: ='Data Mentah PT100'!C13 -> 22.5 | D13: ='Data Mentah PT100'!D13 -> 23.8 | E13: =FORECAST(B13,'THM A21011860&Oakton'!I5:I6,'THM A21011860&Oakton'!H5:H6) -> -0.27586207 | F13: =FORECAST(C13,'THM A21011860&Oakton'!B4:B5,'THM A21011860&Oakton'!A4:A5) -> 0.25387794 | G13: =FORECAST(D13,'THM A21011860&Oakton'!I4:I5,'THM A21011860&Oakton'!H4:H5) -> 0.16551724 | H13: RH akhir | I13: ='Data Mentah PT100'!G13 -> 60 | J13: ='Data Mentah PT100'!H13 -> 78.6 | K13: ='Data Mentah PT100'!I13 -> 55.5 | L13: %RH | M13: Koreksi | N13: =FORECAST(I13,'THM A21011860&Oakton'!K5:K6,'THM A21011860&Oakton'!J5:J6) -> -1.0526316 | O13: =FORECAST(J13,'THM A21011860&Oakton'!D7:D8,'THM A21011860&Oakton'!C7:C8) -> 0.26956026 | P13: =FORECAST(K13,'THM A21011860&Oakton'!K5:K6,'THM A21011860&Oakton'!J5:J6) -> -1.2894737
A14: Trata-rata terkoreksi ( | C14: =SUM(B12:G13)/6 -> 23.095382 | D14: =MAX(MAX(SUM(B12,E12),SUM(C12,F12),SUM(D12,G12),SUM(B13,E13),SUM(C13,F13),SUM(D13,G13))-C14,C14-MIN(SUM(B12,E12),SUM(C12,F12),SUM(D12,G12),SUM(B13,E13),SUM(C13,F13),SUM(D13,G13))) -> 3.6287562 | H14: RH rata-rata terkoreksi ( | J14: =SUM(I12:K13,N12:P13)/6 -> 63.005381 | K14: =MAX(MAX(SUM(I12,N12),SUM(J12,O12),SUM(K12,P12),SUM(I13,N13),SUM(J13,O13),SUM(K13,P13))-J14,J14-MIN(SUM(I12,N12),SUM(J12,O12),SUM(K12,P12),SUM(I13,N13),SUM(J13,O13),SUM(K13,P13))) -> 15.86418
B15: (Oakton) | C15: Rotronic | D15: (Oakton)
A16: Pembacaan Standar (W) | G16: Koreksi | H16: P.Standar | I16: P.Standar | J16: Pembacaan Alat (Ω) | O16: X | P16: Koreksi Beamex ohm | Q16: R alat terkoreksi | S16: ohm beamex
A17: S1 | B17: S2 | C17: S3 | D17: S4 | E17: S5 | F17: Srata-rata | G17: ohm | H17: Terkoreksi ohm | I17: Terkoreksi °C | J17: X1 | K17: X2 | L17: X3 | M17: X4 | N17: X5 | O17: rata-rata ohm | S17: 40.019 | T17: -0.018886517 | U17: 0.044
A18: ='Data Mentah PT100'!A17 -> 100.01 | B18: ='Data Mentah PT100'!B17 -> 100.01 | C18: ='Data Mentah PT100'!C17 -> 100.01 | D18: ='Data Mentah PT100'!D17 -> 100.01 | E18: ='Data Mentah PT100'!E17 -> 100.01 | F18: =AVERAGE(A18:E18) -> 100.01 | G18: =FORECAST(F18,T$18:T$19,S$18:S$19) -> -0.038937992 | H18: =F18+G18 -> 99.971062 | I18: =_xlfn.FORECAST.LINEAR(H18, INDEX(Table1[[Suhu ]],MATCH(H18,Table1[Resistansi 2024],1)): INDEX(Table1[[Suhu ]],MATCH(H18,Table1[Resistansi 2024],1)+1), INDEX(Table1[Resistansi 2024],MATCH(H18,Table1[Resistansi 2024],1)): INDEX(Table1[Resistansi 2024],MATCH(H18,Table1[Resistansi 2024],1)+1)) -> 0.0043935329 | J18: ='Data Mentah PT100'!F17 -> 100.15 | K18: ='Data Mentah PT100'!G17 -> 100.15 | L18: ='Data Mentah PT100'!H17 -> 100.15 | M18: ='Data Mentah PT100'!I17 -> 100.15 | N18: ='Data Mentah PT100'!J17 -> 100.15 | O18: =AVERAGE(J18:N18) -> 100.15 | P18: =FORECAST(O18,T$18:T$19,S$18:S$19) -> -0.039009761 | Q18: =O18+P18 -> 100.11099 | S18: 80.03 | T18: -0.028695506 | U18: 0.088
A19: ='Data Mentah PT100'!A18 -> 109.93 | B19: ='Data Mentah PT100'!B18 -> 109.93 | C19: ='Data Mentah PT100'!C18 -> 109.93 | D19: ='Data Mentah PT100'!D18 -> 109.935 | E19: ='Data Mentah PT100'!E18 -> 109.935 | F19: =AVERAGE(A19:E19) -> 109.932 | G19: =FORECAST(F19,T$18:T$19,S$18:S$19) -> -0.044024375 | H19: 108 | I19: =_xlfn.FORECAST.LINEAR(H19, INDEX(Table1[[Suhu ]],MATCH(H19,Table1[Resistansi 2024],1)): INDEX(Table1[[Suhu ]],MATCH(H19,Table1[Resistansi 2024],1)+1), INDEX(Table1[Resistansi 2024],MATCH(H19,Table1[Resistansi 2024],1)): INDEX(Table1[Resistansi 2024],MATCH(H19,Table1[Resistansi 2024],1)+1)) -> 20.230449 | J19: ='Data Mentah PT100'!F18 -> 109.905 | K19: ='Data Mentah PT100'!G18 -> 109.905 | L19: ='Data Mentah PT100'!H18 -> 109.905 | M19: ='Data Mentah PT100'!I18 -> 109.9 | N19: ='Data Mentah PT100'!J18 -> 109.9 | O19: =AVERAGE(J19:N19) -> 109.903 | P19: =FORECAST(O19,T$18:T$19,S$18:S$19) -> -0.044009509 | Q19: =O19+P19 -> 109.85899 | S19: 120.05 | T19: -0.049211236 | U19: 0.0336
A20: ='Data Mentah PT100'!A19 -> 119.825 | B20: ='Data Mentah PT100'!B19 -> 119.825 | C20: ='Data Mentah PT100'!C19 -> 119.825 | D20: ='Data Mentah PT100'!D19 -> 119.82 | E20: ='Data Mentah PT100'!E19 -> 119.82 | F20: =AVERAGE(A20:E20) -> 119.823 | G20: =FORECAST(F20,T$18:T$19,S$18:S$19) -> -0.049094867 | H20: =F20+G20 -> 119.77391 | I20: =_xlfn.FORECAST.LINEAR(H20, INDEX(Table1[[Suhu ]],MATCH(H20,Table1[Resistansi 2024],1)): INDEX(Table1[[Suhu ]],MATCH(H20,Table1[Resistansi 2024],1)+1), INDEX(Table1[Resistansi 2024],MATCH(H20,Table1[Resistansi 2024],1)): INDEX(Table1[Resistansi 2024],MATCH(H20,Table1[Resistansi 2024],1)+1)) -> 50.111172 | J20: ='Data Mentah PT100'!F19 -> 119.46 | K20: ='Data Mentah PT100'!G19 -> 119.46 | L20: ='Data Mentah PT100'!H19 -> 119.455 | M20: ='Data Mentah PT100'!I19 -> 119.455 | N20: ='Data Mentah PT100'!J19 -> 119.45 | O20: =AVERAGE(J20:N20) -> 119.456 | P20: =FORECAST(O20,T$18:T$19,S$18:S$19) -> -0.04890673 | Q20: =O20+P20 -> 119.40709 | S20: 160.06 | T20: -0.05965618 | U20: 0.0448
A21: ='Data Mentah PT100'!A20 -> 129.575 | B21: ='Data Mentah PT100'!B20 -> 129.575 | C21: ='Data Mentah PT100'!C20 -> 129.58 | D21: ='Data Mentah PT100'!D20 -> 129.575 | E21: ='Data Mentah PT100'!E20 -> 129.58 | F21: =AVERAGE(A21:E21) -> 129.577 | G21: =FORECAST(F21,T$19:T$20,S$19:S$20) -> -0.051698339 | H21: =F21+G21 -> 129.5253 | I21: =_xlfn.FORECAST.LINEAR(H21, INDEX(Table1[[Suhu ]],MATCH(H21,Table1[Resistansi 2024],1)): INDEX(Table1[[Suhu ]],MATCH(H21,Table1[Resistansi 2024],1)+1), INDEX(Table1[Resistansi 2024],MATCH(H21,Table1[Resistansi 2024],1)): INDEX(Table1[Resistansi 2024],MATCH(H21,Table1[Resistansi 2024],1)+1)) -> 75.06214 | J21: ='Data Mentah PT100'!F20 -> 129.175 | K21: ='Data Mentah PT100'!G20 -> 129.175 | L21: ='Data Mentah PT100'!H20 -> 129.18 | M21: ='Data Mentah PT100'!I20 -> 129.175 | N21: ='Data Mentah PT100'!J20 -> 129.185 | O21: =AVERAGE(J21:N21) -> 129.178 | P21: =FORECAST(O21,T$19:T$20,S$19:S$20) -> -0.051594176 | Q21: =O21+P21 -> 129.12641 | S21: 200.06 | T21: -0.060101124 | U21: 0.056
A22: ='Data Mentah PT100'!A21 -> 139.275 | B22: ='Data Mentah PT100'!B21 -> 139.275 | C22: ='Data Mentah PT100'!C21 -> 139.275 | D22: ='Data Mentah PT100'!D21 -> 139.275 | E22: ='Data Mentah PT100'!E21 -> 139.275 | F22: =AVERAGE(A22:E22) -> 139.275 | G22: =FORECAST(F22,T$19:T$20,S$19:S$20) -> -0.054230082 | H22: =F22+G22 -> 139.22077 | I22: =_xlfn.FORECAST.LINEAR(H22, INDEX(Table1[[Suhu ]],MATCH(H22,Table1[Resistansi 2024],1)): INDEX(Table1[[Suhu ]],MATCH(H22,Table1[Resistansi 2024],1)+1), INDEX(Table1[Resistansi 2024],MATCH(H22,Table1[Resistansi 2024],1)): INDEX(Table1[Resistansi 2024],MATCH(H22,Table1[Resistansi 2024],1)+1)) -> 100.05683 | J22: ='Data Mentah PT100'!F21 -> 138.71 | K22: ='Data Mentah PT100'!G21 -> 138.71 | L22: ='Data Mentah PT100'!H21 -> 138.7 | M22: ='Data Mentah PT100'!I21 -> 138.7 | N22: ='Data Mentah PT100'!J21 -> 138.71 | O22: =AVERAGE(J22:N22) -> 138.706 | P22: =FORECAST(O22,T$19:T$20,S$19:S$20) -> -0.05408154 | Q22: =O22+P22 -> 138.65192 | S22: 240.06 | T22: -0.060546067 | U22: 0.0672
A23: ='Data Mentah PT100'!A22 -> 148.905 | B23: ='Data Mentah PT100'!B22 -> 148.905 | C23: ='Data Mentah PT100'!C22 -> 148.905 | D23: ='Data Mentah PT100'!D22 -> 148.9 | E23: ='Data Mentah PT100'!E22 -> 148.905 | F23: =AVERAGE(A23:E23) -> 148.904 | G23: =FORECAST(F23,T$19:T$20,S$19:S$20) -> -0.056743813 | H23: =F23+G23 -> 148.84726 | I23: =_xlfn.FORECAST.LINEAR(H23, INDEX(Table1[[Suhu ]],MATCH(H23,Table1[Resistansi 2024],1)): INDEX(Table1[[Suhu ]],MATCH(H23,Table1[Resistansi 2024],1)+1), INDEX(Table1[Resistansi 2024],MATCH(H23,Table1[Resistansi 2024],1)): INDEX(Table1[Resistansi 2024],MATCH(H23,Table1[Resistansi 2024],1)+1)) -> 125.06224 | J23: ='Data Mentah PT100'!F22 -> 148.17 | K23: ='Data Mentah PT100'!G22 -> 148.17 | L23: ='Data Mentah PT100'!H22 -> 148.18 | M23: ='Data Mentah PT100'!I22 -> 148.18 | N23: ='Data Mentah PT100'!J22 -> 148.17 | O23: =AVERAGE(J23:N23) -> 148.174 | P23: =FORECAST(O23,T$19:T$20,S$19:S$20) -> -0.05655324 | Q23: =O23+P23 -> 148.11745 | S23: 280.068 | T23: -0.068991011 | U23: 0.0784
A24: ='Data Mentah PT100'!A23 -> 158.45 | B24: ='Data Mentah PT100'!B23 -> 158.45 | C24: ='Data Mentah PT100'!C23 -> 158.45 | D24: ='Data Mentah PT100'!D23 -> 158.46 | E24: ='Data Mentah PT100'!E23 -> 158.46 | F24: =AVERAGE(A24:E24) -> 158.454 | G24: =FORECAST(F24,T$19:T$20,S$19:S$20) -> -0.05923692 | H24: =F24+G24 -> 158.39476 | I24: =_xlfn.FORECAST.LINEAR(H24, INDEX(Table1[[Suhu ]],MATCH(H24,Table1[Resistansi 2024],1)): INDEX(Table1[[Suhu ]],MATCH(H24,Table1[Resistansi 2024],1)+1), INDEX(Table1[Resistansi 2024],MATCH(H24,Table1[Resistansi 2024],1)): INDEX(Table1[Resistansi 2024],MATCH(H24,Table1[Resistansi 2024],1)+1)) -> 150.05235 | J24: ='Data Mentah PT100'!F23 -> 157.58 | K24: ='Data Mentah PT100'!G23 -> 157.58 | L24: ='Data Mentah PT100'!H23 -> 157.575 | M24: ='Data Mentah PT100'!I23 -> 157.59 | N24: ='Data Mentah PT100'!J23 -> 157.59 | O24: =AVERAGE(J24:N24) -> 157.583 | P24: =FORECAST(O24,T$19:T$20,S$19:S$20) -> -0.059009538 | Q24: =O24+P24 -> 157.52399 | S24: 320.08 | T24: -0.081435955 | U24: 0.0896
A25: ='Data Mentah PT100'!A24 -> 167.92 | B25: ='Data Mentah PT100'!B24 -> 167.92 | C25: ='Data Mentah PT100'!C24 -> 167.92 | D25: ='Data Mentah PT100'!D24 -> 167.94 | E25: ='Data Mentah PT100'!E24 -> 167.94 | F25: =AVERAGE(A25:E25) -> 167.928 | G25: =FORECAST(F25,T$20:T$21,S$20:S$21) -> -0.0597437 | H25: =F25+G25 -> 167.86826 | I25: =_xlfn.FORECAST.LINEAR(H25, INDEX(Table1[[Suhu ]],MATCH(H25,Table1[Resistansi 2024],1)): INDEX(Table1[[Suhu ]],MATCH(H25,Table1[Resistansi 2024],1)+1), INDEX(Table1[Resistansi 2024],MATCH(H25,Table1[Resistansi 2024],1)): INDEX(Table1[Resistansi 2024],MATCH(H25,Table1[Resistansi 2024],1)+1)) -> 175.043 | J25: ='Data Mentah PT100'!F24 -> 166.98 | K25: ='Data Mentah PT100'!G24 -> 166.98 | L25: ='Data Mentah PT100'!H24 -> 166.96 | M25: ='Data Mentah PT100'!I24 -> 166.96 | N25: ='Data Mentah PT100'!J24 -> 166.98 | O25: =AVERAGE(J25:N25) -> 166.972 | P25: =FORECAST(O25,T$20:T$21,S$20:S$21) -> -0.059733066 | Q25: =O25+P25 -> 166.91227 | S25: 360.1 | T25: -0.11433725 | U25: 0.1008
A26: ='Data Mentah PT100'!A25 -> 177.34 | B26: ='Data Mentah PT100'!B25 -> 177.34 | C26: ='Data Mentah PT100'!C25 -> 177.32 | D26: ='Data Mentah PT100'!D25 -> 177.32 | E26: ='Data Mentah PT100'!E25 -> 177.32 | F26: =AVERAGE(A26:E26) -> 177.328 | G26: =FORECAST(F26,T$20:T$21,S$20:S$21) -> -0.059848262 | H26: =F26+G26 -> 177.26815 | I26: =_xlfn.FORECAST.LINEAR(H26, INDEX(Table1[[Suhu ]],MATCH(H26,Table1[Resistansi 2024],1)): INDEX(Table1[[Suhu ]],MATCH(H26,Table1[Resistansi 2024],1)+1), INDEX(Table1[Resistansi 2024],MATCH(H26,Table1[Resistansi 2024],1)): INDEX(Table1[Resistansi 2024],MATCH(H26,Table1[Resistansi 2024],1)+1)) -> 200.02603 | J26: ='Data Mentah PT100'!F25 -> 176.16 | K26: ='Data Mentah PT100'!G25 -> 176.16 | L26: ='Data Mentah PT100'!H25 -> 176.16 | M26: ='Data Mentah PT100'!I25 -> 176.18 | N26: ='Data Mentah PT100'!J25 -> 176.18 | O26: =AVERAGE(J26:N26) -> 176.168 | P26: =FORECAST(O26,T$20:T$21,S$20:S$21) -> -0.059835359 | Q26: =O26+P26 -> 176.10816 | S26: 400.1 | T26: -0.10232584 | U26: 0.112
A27: ='Data Mentah PT100'!A26 -> 186.66 | B27: ='Data Mentah PT100'!B26 -> 186.68 | C27: ='Data Mentah PT100'!C26 -> 186.68 | D27: ='Data Mentah PT100'!D26 -> 186.66 | E27: ='Data Mentah PT100'!E26 -> 186.66 | F27: =AVERAGE(A27:E27) -> 186.668 | G27: =FORECAST(F27,T$20:T$21,S$20:S$21) -> -0.059952156 | H27: =F27+G27 -> 186.60805 | I27: =_xlfn.FORECAST.LINEAR(H27, INDEX(Table1[[Suhu ]],MATCH(H27,Table1[Resistansi 2024],1)): INDEX(Table1[[Suhu ]],MATCH(H27,Table1[Resistansi 2024],1)+1), INDEX(Table1[Resistansi 2024],MATCH(H27,Table1[Resistansi 2024],1)): INDEX(Table1[Resistansi 2024],MATCH(H27,Table1[Resistansi 2024],1)+1)) -> 225.0472 | J27: ='Data Mentah PT100'!F26 -> 185.28 | K27: ='Data Mentah PT100'!G26 -> 185.28 | L27: ='Data Mentah PT100'!H26 -> 185.28 | M27: ='Data Mentah PT100'!I26 -> 185.28 | N27: ='Data Mentah PT100'!J26 -> 185.28 | O27: =AVERAGE(J27:N27) -> 185.28 | P27: =FORECAST(O27,T$20:T$21,S$20:S$21) -> -0.059936717 | Q27: =O27+P27 -> 185.22006
A28: ='Data Mentah PT100'!A27 -> 195.94 | B28: ='Data Mentah PT100'!B27 -> 195.94 | C28: ='Data Mentah PT100'!C27 -> 195.94 | D28: ='Data Mentah PT100'!D27 -> 195.94 | E28: ='Data Mentah PT100'!E27 -> 195.94 | F28: =AVERAGE(A28:E28) -> 195.94 | G28: =FORECAST(F28,T$20:T$21,S$20:S$21) -> -0.060055294 | H28: =F28+G28 -> 195.87994 | I28: =_xlfn.FORECAST.LINEAR(H28, INDEX(Table1[[Suhu ]],MATCH(H28,Table1[Resistansi 2024],1)): INDEX(Table1[[Suhu ]],MATCH(H28,Table1[Resistansi 2024],1)+1), INDEX(Table1[Resistansi 2024],MATCH(H28,Table1[Resistansi 2024],1)): INDEX(Table1[Resistansi 2024],MATCH(H28,Table1[Resistansi 2024],1)+1)) -> 250.04129 | J28: ='Data Mentah PT100'!F27 -> 194.48 | K28: ='Data Mentah PT100'!G27 -> 194.48 | L28: ='Data Mentah PT100'!H27 -> 194.48 | M28: ='Data Mentah PT100'!I27 -> 194.48 | N28: ='Data Mentah PT100'!J27 -> 194.48 | O28: =AVERAGE(J28:N28) -> 194.48 | P28: =FORECAST(O28,T$20:T$21,S$20:S$21) -> -0.060039054 | Q28: =O28+P28 -> 194.41996
A31: No. Order | C31: INT | H31: Dikalibrasi | K31: ='Data Mentah PT100'!G32 -> Tris,Nikita | P31: Paraf
A32: Tgl.terima | C32: 45958 | H32: Diperiksa | K32: ='Data Mentah PT100'!G33 -> Nur ID
A33: Tgl.kalibrasi | C33: ='Data Mentah PT100'!C34 -> 45959 | D33: sd | E33: ='Data Mentah PT100'!E34 -> 45961 | H33: Disetujui | K33: ='Data Mentah PT100'!G34 -> Yoyon S
A34: Kalibrator yang digunakan :
A35: ='Data Mentah PT100'!A36 -> Temperature Calibrator Beamex TC305 No. Seri 3209 dan IPRT Burns Engr 3925 No. Seri 490464 tertelusur ke SI melalui LK-001-IDN dan LK-304-IDN.
O38: F-IK-04-KT-04
Z79: y
X80: R | Y80: t | Z80: R-R0 | AA80: R0t | AB80: R0t^2
X81: =Q18 -> 100.11099 | Y81: =I18 -> 0.0043935329 | Z81: =X81-X$81 -> 0 | AA81: =X$81*Y81 -> 0.43984093 | AB81: =X$81*Y81^2 -> 0.0019324556
X82: =Q19 -> 109.85899 | Y82: =I19 -> 20.230449 | Z82: =X82-X$81 -> 9.7480003 | AA82: =X$81*Y82 -> 2025.2902 | AB82: =X$81*Y82^2 -> 40972.53
X83: =Q20 -> 119.40709 | Y83: =I20 -> 50.111172 | Z83: =X83-X$81 -> 19.296103 | AA83: =X$81*Y83 -> 5016.6791 | AB83: =X$81*Y83^2 -> 251391.67
X84: =Q21 -> 129.12641 | Y84: =I21 -> 75.06214 | Z84: =X84-X$81 -> 29.015416 | AA84: =X$81*Y84 -> 7514.5451 | AB84: =X$81*Y84^2 -> 564057.84
X85: =Q22 -> 138.65192 | Y85: =I22 -> 100.05683 | Z85: =X85-X$81 -> 38.540928 | AA85: =X$81*Y85 -> 10016.789 | AB85: =X$81*Y85^2 -> 1002248.2
X86: =Q23 -> 148.11745 | Y86: =I23 -> 125.06224 | Z86: =X86-X$81 -> 48.006457 | AA86: =X$81*Y86 -> 12520.105 | AB86: =X$81*Y86^2 -> 1565792.3
...

Sheet Budget PT100
K2: FPA 03-02-LK Rev.2
A3: (Kop dan alamat Laboratorium Kalibrasi pemohon akreditasi) | O3: a
A4: Form A | O4: b
A5: Uncertainty Budget sebagai Pendukung Kemampuan Kalibrasi dan Pengukuran (CMC) | O5: c
A6: Nama laboratorium | C6: Balai Besar Logam dan Mesin
A7: Alamat | C7: Jl Sangkuriang No.12 Bandung
A9: UNCERTAINTY BUDGET SEBAGAI PENDUKUNG KLAIM CMC
A10: Besaran yang diukur | D10: Temperatur
A11: Jenis alat yang dikalibrasi | D11: PT100
A12: Standar yang digunakan | D12: Beamex TC305 dan PT100 Burns Engr
A13: Model matematis pengukuran | D13: t = ts
D14: K = tref. - ta
D15: Dimana :
A16: MPE | D16: K = Koreksi
A17: IC 60751 | D17: tref. = Penunjukan temperatur standar setelah dikoreksi
A18: DIN 4370 | D18: ta = Penunjukan temperatur alat
A21: Rentang ukur PT100 (0~250) ⁰C | C21: ='Olahdata-PT100 C'!I18 -> 0.0043935329
A22: Komponen | B22: Satuan | C22: Distribusi | D22: U | E22: Pembagi | F22: ni | G22: Ui | H22: Ci | I22: UiCi | J22: (UiCi)2 | K22: (UiCi)4/ni
A23: (1) | B23: (2) | C23: (3) | D23: (4) | E23: (5) | F23: (6) | G23: (7) | H23: (8) | I23: (9) | J23: (10) | K23: (11) | N23: T(C) | O23: koreksi | P23: drift beamex pt100
A24: Ketidakpastian Repeatability, u(ta1) | B24: Ω | C24: T.Std | D24: =STDEV('Olahdata-PT100 C'!J18:N18)/SQRT(5) -> 0 | E24: 1 | F24: 4 | G24: =D24/E24 -> 0 | H24: =1/('Olahdata-PT100 C'!Z105-'Olahdata-PT100 C'!Y105) -> 2.5462667 | I24: =G24*H24 -> 0 | J24: =I24^2 -> 0 | K24: =J24^2/F24 -> 0 | N24: ='drift beamex tc305-Pt100'!B5 -> -199.96 | O24: ='drift beamex tc305-Pt100'!C5 -> -0.075 | P24: ='drift beamex tc305-Pt100'!AN5 -> 0.16201722
A25: Ketidakpastian Readability/Resolusi,u(ta2) | B25: Ω | C25: Rect. | D25: =0.005/2 -> 0.0025 | E25: =SQRT(3) -> 1.7320508 | F25: 50 | G25: =D25/E25 -> 0.0014433757 | H25: =H24 -> 2.5462667 | I25: =G25*H25 -> 0.0036752194 | J25: =I25^2 -> 1.3507238e-05 | K25: =J25^2/F25 -> 3.6489094e-12 | N25: ='drift beamex tc305-Pt100'!B6 -> -150 | O25: ='drift beamex tc305-Pt100'!C6 -> -0.084970018 | P25: ='drift beamex tc305-Pt100'!AN6 -> 0.15803653
A26: Ketidakpastian Self-Heating u(tash) | B26: ⁰C | C26: Rect. | D26: =4/10^3 -> 0.004 | E26: =SQRT(3) -> 1.7320508 | F26: 50 | G26: =D26/E26 -> 0.0023094011 | H26: 1 | I26: =G26*H26 -> 0.0023094011 | J26: =I26^2 -> 5.3333333e-06 | K26: =J26^2/F26 -> 5.6888889e-13 | N26: ='drift beamex tc305-Pt100'!B7 -> -100 | O26: ='drift beamex tc305-Pt100'!C7 -> -0.114976 | P26: ='drift beamex tc305-Pt100'!AN7 -> 0.15286012
A27: Ketidakpastian Regresi u(treg) | B27: Ω | C27: Normal | D27: ='Olahdata-PT100 C'!Y$97 -> 0.61915313 | E27: 1 | F27: ='Olahdata-PT100 C'!Y$98 -> 9 | G27: =D27/E27 -> 0.61915313 | H27: =H24 -> 2.5462667 | I27: =G27*H27 -> 1.576529 | J27: =I27^2 -> 2.4854437 | K27: =J27^2/F27 -> 0.68638113 | N27: ='drift beamex tc305-Pt100'!B8 -> -50 | O27: ='drift beamex tc305-Pt100'!C8 -> -0.12996221 | P27: ='drift beamex tc305-Pt100'!AN8 -> 0.086877716
A28: Ketidakpastian Repeatability, u(ts1) | B28: Ω | C28: T.Std | D28: =STDEV('Olahdata-PT100 C'!A18:E18)/SQRT(5) -> 0 | E28: 1 | F28: 4 | G28: =D28/E28 -> 0 | H28: =H32 -> 2.5116509 | I28: =G28*H28 -> 0 | J28: =I28^2 -> 0 | K28: =J28^2/F28 -> 0 | N28: ='drift beamex tc305-Pt100'!B9 -> 0 | O28: ='drift beamex tc305-Pt100'!C9 -> -0.15092664 | P28: ='drift beamex tc305-Pt100'!AN9 -> 0.021417862
A29: Ketidakpastian Indikator Standar, u(tsi) | B29: Ω | C29: Normal | D29: ='Olahdata-PT100 C'!U19 -> 0.0336 | E29: 2 | F29: 60 | G29: =D29/E29 -> 0.0168 | H29: =H32 -> 2.5116509 | I29: =G29*H29 -> 0.042195735 | J29: =I29^2 -> 0.0017804801 | K29: =J29^2/F29 -> 5.2835156e-08 | N29: ='drift beamex tc305-Pt100'!B10 -> 50 | O29: ='drift beamex tc305-Pt100'!C10 -> -0.18559526 | P29: ='drift beamex tc305-Pt100'!AN10 -> 0.023731243
A30: Ketidakpastian Drift Indikator Standar,u(tsidrift) | B30: Ω | C30: Rect. | D30: =ABS('Olahdata-PT100 C'!G18*0.1) -> 0.0038937992 | E30: =SQRT(3) -> 1.7320508 | F30: 50 | G30: =D30/E30 -> 0.002248086 | H30: =H32 -> 2.5116509 | I30: =G30*H30 -> 0.0056464073 | J30: =I30^2 -> 3.1881915e-05 | K30: =J30^2/F30 -> 2.032913e-11 | N30: ='drift beamex tc305-Pt100'!B11 -> 100 | O30: ='drift beamex tc305-Pt100'!C11 -> -0.19624813 | P30: ='drift beamex tc305-Pt100'!AN11 -> 0.024286863
A31: Ketidakpastian sensor Standar, u(ts2) | B31: ⁰C | C31: Normal | D31: 0.047 | E31: 2 | F31: 60 | G31: =D31/E31 -> 0.0235 | H31: 1 | I31: =G31*H31 -> 0.0235 | J31: =I31^2 -> 0.00055225 | K31: =J31^2/F31 -> 5.083001e-09 | N31: ='drift beamex tc305-Pt100'!B12 -> 150 | O31: ='drift beamex tc305-Pt100'!C12 -> -0.19672328 | P31: ='drift beamex tc305-Pt100'!AN12 -> 0.022746973
A32: Ketidakpastian Drift sensor Standar,u(tsdrift) | B32: Ω | C32: Rect. | D32: =VLOOKUP(C21,Table1[],7,TRUE) -> 0.026272696 | E32: =SQRT(3) -> 1.7320508 | F32: 50 | G32: =D32/E32 -> 0.015168548 | H32: =VLOOKUP(C21,Table1[#All],8,TRUE) -> 2.5116509 | I32: =G32*H32 -> 0.038098098 | J32: =I32^2 -> 0.0014514651 | K32: =J32^2/F32 -> 4.2135019e-08 | N32: ='drift beamex tc305-Pt100'!B13 -> 200 | O32: ='drift beamex tc305-Pt100'!C13 -> -0.2476977 | P32: ='drift beamex tc305-Pt100'!AN13 -> 0.039348929
A33: Ketidakpastian titik es u(tmed1) | B33: ⁰C | C33: Rect. | D33: =20/10^3 -> 0.02 | E33: =SQRT(3) -> 1.7320508 | F33: 50 | G33: =D33/E33 -> 0.011547005 | H33: 1 | I33: =G33*H33 -> 0.011547005 | J33: =I33^2 -> 0.00013333333 | K33: =J33^2/F33 -> 3.5555556e-10 | N33: ='drift beamex tc305-Pt100'!B14 -> 250 | O33: ='drift beamex tc305-Pt100'!C14 -> -0.19812313 | P33: ='drift beamex tc305-Pt100'!AN14 -> 0.0352811
A34: Ketidakpastian keseragaman media u(tmed2) | B34: ⁰C | C34: Rect. | D34: ='Zero&Air'!B3 -> 0.13561091 | E34: =SQRT(3) -> 1.7320508 | F34: 50 | G34: =D34/E34 -> 0.078294994 | H34: 1 | I34: =G34*H34 -> 0.078294994 | J34: =I34^2 -> 0.0061301061 | K34: =J34^2/F34 -> 7.5156403e-07 | N34: ='drift beamex tc305-Pt100'!B15 -> 300 | O34: ='drift beamex tc305-Pt100'!C15 -> -0.19859828 | P34: ='drift beamex tc305-Pt100'!AN15 -> 0.056195808
A35: Ketidakpastian stabilitas media u(tmed3) | B35: ⁰C | C35: Rect. | D35: ='Zero&Air'!C3 -> 0.11249856 | E35: =SQRT(3) -> 1.7320508 | F35: 50 | G35: =D35/E35 -> 0.064951076 | H35: 1 | I35: =G35*H35 -> 0.064951076 | J35: =I35^2 -> 0.0042186423 | K35: =J35^2/F35 -> 3.5593885e-07 | N35: ='drift beamex tc305-Pt100'!B16 -> 350 | O35: ='drift beamex tc305-Pt100'!C16 -> -0.2493725 | P35: ='drift beamex tc305-Pt100'!AN16 -> 0.032900647
A36: Sums | J36: =SUM(J24:J35) -> 2.4997607 | N36: ='drift beamex tc305-Pt100'!B17 -> 400 | O36: ='drift beamex tc305-Pt100'!C17 -> -0.24980519 | P36: ='drift beamex tc305-Pt100'!AN17 -> 0.027438282
A37: Ketidakpastian baku gabungan, uc, (mg) | J37: =SQRT(J36) -> 1.5810631 | N37: ='drift beamex tc305-Pt100'!B18 -> 450 | O37: ='drift beamex tc305-Pt100'!C18 -> -0.29849401 | P37: ='drift beamex tc305-Pt100'!AN18 -> 0.034259111
A38: Derajat kebebasan efektif, neff | J38: =J37^4/SUM(K24:K35) -> 9.1039687 | N38: ='drift beamex tc305-Pt100'!B19 -> 500 | O38: ='drift beamex tc305-Pt100'!C19 -> -0.3503003 | P38: ='drift beamex tc305-Pt100'!AN19 -> 0.045606378
A39: Faktor cakupan, k-student’s untuk neff dan CL 95 % | J39: =1.95996+2.37356/J38+2.818745/J38^2+2.546662/J38^3+1.761829/J38^4+0.245458/J38^5+1.000764/J38^6 -> 2.2583233 | N39: ='drift beamex tc305-Pt100'!B20 -> 550 | O39: ='drift beamex tc305-Pt100'!C20 -> -0.29975025 | P39: ='drift beamex tc305-Pt100'!AN20 -> 0.021388355
A40: Ketidak pastian bentangan, U = kuc, (°C) | J40: =J37*J39 -> 3.5705517 | K40: 0.22 | N40: ='drift beamex tc305-Pt100'!B21 -> 600 | O40: ='drift beamex tc305-Pt100'!C21 -> -0.35 | P40: ='drift beamex tc305-Pt100'!AN21 -> 0.041675534
A42: =A$21 -> Rentang ukur PT100 (0~250) ⁰C | C42: ='Olahdata-PT100 C'!I19 -> 20.230449
A43: Komponen | B43: Satuan | C43: Distribusi | D43: U | E43: Pembagi | F43: ni | G43: Ui | H43: Ci | I43: UiCi | J43: (UiCi)2 | K43: (UiCi)4/ni
A44: (1) | B44: (2) | C44: (3) | D44: (4) | E44: (5) | F44: (6) | G44: (7) | H44: (8) | I44: (9) | J44: (10) | K44: (11)
A45: Ketidakpastian Repeatability, u(ta1) | B45: Ω | C45: T.Std | D45: =STDEV('Olahdata-PT100 C'!J19:N19)/SQRT(5) -> 0.0012247449 | E45: 1 | F45: 4 | G45: =D45/E45 -> 0.0012247449 | H45: =1/('Olahdata-PT100 C'!AE107-'Olahdata-PT100 C'!AD107) -> 2.5672548 | I45: =G45*H45 -> 0.0031442321 | J45: =I45^2 -> 9.8861955e-06 | K45: =J45^2/F45 -> 2.4434215e-11
...

Sheet THM A21011860&Oakton
A1: Rotronic | F1: 2025 | H1: Oakton | M1: 2024
A2: Temperatur (°C) | C2: Kelembaban Relatif(%RH) | E2: U95% | H2: Temperatur (°C) | J2: Kelembaban Relatif(%RH) | L2: U95%
A3: Alat rata-rata | B3: Koreksi Alat | C3: Alat rata-rata | D3: Koreksi Alat | E3: Temperatur (°C) | F3: Kelembaban Relatif (%RH) | H3: Alat rata-rata | I3: Koreksi Alat | J3: Alat rata-rata | K3: Koreksi Alat | L3: Temperatur (°C) | M3: Kelembaban Relatif (%RH)
A4: 19.67972 | B4: 0.32013972 | C4: 40.7 | D4: -0.7041 | E4: 2 | F4: 2.5130803 | H4: 19.2 | I4: 0.8 | J4: 42 | K4: -2 | L4: 2 | M4: 2.6
A5: 24.8 | B5: 0.19984 | C5: 50.750222 | D5: -0.75254222 | E5: 2 | F5: 2.8377376 | H5: 25 | I5: 0 | J5: 51.5 | K5: -1.5 | L5: 2 | M5: 2.9
A6: 29.7 | B6: 0.29982 | C6: 60.6 | D6: -0.5978 | E6: 2 | F6: 3.2141533 | H6: 30.8 | I6: -0.8 | J6: 61 | K6: -1 | L6: 2 | M6: 3.3
A7: 35.1 | B7: -0.1 | C7: 69.99 | D7: 0.00774 | E7: 2 | F7: 1.9957614 | H7: 34.7 | I7: 0.3 | J7: 69.5 | K7: 0.5 | L7: 2 | M7: 2.1
A8: 40 | B8: 0.00491 | C8: 79.7 | D8: 0.30301 | E8: 2 | F8: 2.5974371 | H8: 40.5 | I8: -0.5 | J8: 73.5 | K8: 6.5 | L8: 2 | M8: 2.7
A10: Rotronic | F10: 2024 | H10: Oakton | M10: 2023
A11: Temperatur (°C) | C11: Kelembaban Relatif(%RH) | E11: U95% | H11: Temperatur (°C) | J11: Kelembaban Relatif(%RH) | L11: U95%
A12: Alat rata-rata | B12: Koreksi Alat | C12: Alat rata-rata | D12: Koreksi Alat | E12: Temperatur (°C) | F12: Kelembaban Relatif (%RH) | H12: Alat rata-rata | I12: Koreksi Alat | J12: Alat rata-rata | K12: Koreksi Alat | L12: Temperatur (°C) | M12: Kelembaban Relatif (%RH)
A13: 19.7 | B13: 0.3 | C13: 40.4 | D13: -0.4 | E13: 2 | F13: 2.5 | H13: 19.2 | I13: 0.8 | J13: 79 | K13: -2 | L13: 2 | M13: 2.9
A14: 25 | B14: 0 | C14: 49.7 | D14: 0.3 | E14: 2 | F14: 2.8 | H14: 24.3 | I14: 0.8 | J14: 70.5 | K14: -0.5 | L14: 2 | M14: 2.4
A15: 30.4 | B15: -0.4 | C15: 59.9 | D15: 0.1 | E15: 2 | F15: 3.2 | H15: 29.5 | I15: 0.5 | J15: 61 | K15: -1 | L15: 2 | M15: 3.5
A16: 35.1 | B16: -0.1 | C16: 69.7 | D16: 0.3 | E16: 2 | F16: 2 | H16: 35 | I16: 0 | J16: 48 | K16: 2 | L16: 2 | M16: 3.1
A17: 40.6 | B17: -0.6 | C17: 78.8 | D17: 1.2 | E17: 2 | F17: 2.6 | H17: 40.3 | I17: -0.2 | J17: 44 | K17: 0 | L17: 2 | M17: 2.8
A19: Rotronic | F19: 2023
A20: Temperatur (°C) | C20: Kelembaban Relatif(%RH) | E20: U95%
A21: Alat rata-rata | B21: Koreksi Alat | C21: Alat rata-rata | D21: Koreksi Alat | E21: Temperatur (°C) | F21: Kelembaban Relatif (%RH)
A22: 19.7 | B22: 0.3 | C22: 80 | D22: 0 | E22: 2 | F22: 2.6
A23: 24.6 | B23: 0.3 | C23: 70.9 | D23: -0.7 | E23: 2 | F23: 2.1
A24: 29.7 | B24: -0.1 | C24: 64.8 | D24: 0.3 | E24: 2 | F24: 3.3
A25: 34.9 | B25: 0.1 | C25: 55 | D25: -1.1 | E25: 2 | F25: 2.9
A26: 40.1 | B26: -0.1 | C26: 42.5 | D26: -1.1 | E26: 2 | F26: 2.6

Sheet data sertifikat PT100
B1: 45474 | C1: 44559 | D1: 36523 | E1: =((B1-C1)+(C1-D1))/2 -> 4475.5 | G1: drift dalam ohm | H1: ci
A2: Suhu | B2: Resistansi 2024 | C2: Resistansi 2021 | D2: Resistansi 1999 | E2: Kalkulasi Drift 1 | F2: Kalkulasi Drift 2 | G2: drift dalam ohm | H2: Koefisien Sensitivitas (CI)
A3: -29.98
A4: -28
A5: -27
A6: -26
A7: -25
A8: -24
A9: -23
A10: -22
A11: -21
A12: -20
A13: -19
A14: -18
... A31: -1
A32: 0 | B32: 99.969313 | C32: =99.97775*(1+0.00398405*A32-5.865*0.0000001*A32^2) -> 99.97775 | D32: 99.998 | E32: =ABS(B32-C32)/(B$1-C$1) -> 9.220765e-06 | F32: =ABS(C32-D32)/(C$1-D$1) -> 2.5199104e-06 | G32: =(E32+F32)/2*E$1 -> 0.026272696 | H32: =1/0.3981445 -> 2.5116509 | I32: =G32*H32 -> 0.065987842
A33: 1 | B33: 100.3674 | C33: =99.97775*(1+0.00398405*A33-5.865*0.0000001*A33^2) -> 100.37601 | D33: 100.397 | E33: =ABS(B33-C33)/(B$1-C$1) -> 9.407342e-06 | F33: =ABS(C33-D33)/(C$1-D$1) -> 2.61228e-06 | G33: =(E33+F33)/2*E$1 -> 0.026896909 | H33: =1/0.3980275 -> 2.5123892
A34: 2 | C34: =99.97775*(1+0.00398405*A34-5.865*0.0000001*A34^2) -> 100.77415 | E34: =ABS(B34-C34)/(B$1-C$1) -> 0.11013568 | F34: =ABS(C34-D34)/(C$1-D$1) -> 0.012540337
A35: 3 | C35: =99.97775*(1+0.00398405*A35-5.865*0.0000001*A35^2) -> 101.17217 | E35: =ABS(B35-C35)/(B$1-C$1) -> 0.11057068 | F35: =ABS(C35-D35)/(C$1-D$1) -> 0.012589867
A36: 4 | C36: =99.97775*(1+0.00398405*A36-5.865*0.0000001*A36^2) -> 101.57008 | E36: =ABS(B36-C36)/(B$1-C$1) -> 0.11100555 | F36: =ABS(C36-D36)/(C$1-D$1) -> 0.012639382
A37: 5 | C37: =99.97775*(1+0.00398405*A37-5.865*0.0000001*A37^2) -> 101.96787 | E37: =ABS(B37-C37)/(B$1-C$1) -> 0.11144029 | F37: =ABS(C37-D37)/(C$1-D$1) -> 0.012688883
A38: 6 | C38: =99.97775*(1+0.00398405*A38-5.865*0.0000001*A38^2) -> 102.36554 | E38: =ABS(B38-C38)/(B$1-C$1) -> 0.1118749 | F38: =ABS(C38-D38)/(C$1-D$1) -> 0.012738369
A39: 7 | C39: =99.97775*(1+0.00398405*A39-5.865*0.0000001*A39^2) -> 102.76309 | E39: =ABS(B39-C39)/(B$1-C$1) -> 0.11230939 | F39: =ABS(C39-D39)/(C$1-D$1) -> 0.012787841
A40: 8 | C40: =99.97775*(1+0.00398405*A40-5.865*0.0000001*A40^2) -> 103.16053 | E40: =ABS(B40-C40)/(B$1-C$1) -> 0.11274375 | F40: =ABS(C40-D40)/(C$1-D$1) -> 0.012837298
A41: 9 | C41: =99.97775*(1+0.00398405*A41-5.865*0.0000001*A41^2) -> 103.55785 | E41: =ABS(B41-C41)/(B$1-C$1) -> 0.11317798 | F41: =ABS(C41-D41)/(C$1-D$1) -> 0.012886741
A42: 10 | B42: 103.94491 | C42: =99.97775*(1+0.00398405*A42-5.865*0.0000001*A42^2) -> 103.95505 | D42: 103.979 | E42: =ABS(B42-C42)/(B$1-C$1) -> 1.1081807e-05 | F42: =ABS(C42-D42)/(C$1-D$1) -> 2.9803567e-06 | G42: =(E42+F42)/2*E$1 -> 0.031467608 | H42: =1/0.3969746 -> 2.5190529
A43: 11 | B43: 104.34182 | C43: =99.97775*(1+0.00398405*A43-5.865*0.0000001*A43^2) -> 104.35213 | D43: 104.377 | E43: =ABS(B43-C43)/(B$1-C$1) -> 1.1273041e-05 | F43: =ABS(C43-D43)/(C$1-D$1) -> 3.0942219e-06 | G43: =(E43+F43)/2*E$1 -> 0.032150343 | H43: =1/0.3968576 -> 2.5197955
A44: 12 | C44: =99.97775*(1+0.00398405*A44-5.865*0.0000001*A44^2) -> 104.7491 | E44: =ABS(B44-C44)/(B$1-C$1) -> 0.11447989 | F44: =ABS(C44-D44)/(C$1-D$1) -> 0.01303498
A45: 13 | C45: =99.97775*(1+0.00398405*A45-5.865*0.0000001*A45^2) -> 105.14595 | E45: =ABS(B45-C45)/(B$1-C$1) -> 0.11491361 | F45: =ABS(C45-D45)/(C$1-D$1) -> 0.013084364
A46: 14 | C46: =99.97775*(1+0.00398405*A46-5.865*0.0000001*A46^2) -> 105.54269 | E46: =ABS(B46-C46)/(B$1-C$1) -> 0.1153472 | F46: =ABS(C46-D46)/(C$1-D$1) -> 0.013133734
A47: 15 | C47: =99.97775*(1+0.00398405*A47-5.865*0.0000001*A47^2) -> 105.9393 | E47: =ABS(B47-C47)/(B$1-C$1) -> 0.11578066 | F47: =ABS(C47-D47)/(C$1-D$1) -> 0.013183089
A48: 16 | C48: =99.97775*(1+0.00398405*A48-5.865*0.0000001*A48^2) -> 106.3358 | E48: =ABS(B48-C48)/(B$1-C$1) -> 0.11621399 | F48: =ABS(C48-D48)/(C$1-D$1) -> 0.013232429
A49: 17 | B49: 106.72086 | C49: =99.97775*(1+0.00398405*A49-5.865*0.0000001*A49^2) -> 106.73218 | D49: 106.753 | E49: =ABS(B49-C49)/(B$1-C$1) -> 1.2373721e-05 | F49: =ABS(C49-D49)/(C$1-D$1) -> 2.590598e-06 | G49: =(E49+F49)/2*E$1 -> 0.033486404
A50: 18 | B50: 107.11896 | C50: =99.97775*(1+0.00398405*A50-5.865*0.0000001*A50^2) -> 107.12845 | D50: 107.155 | E50: =ABS(B50-C50)/(B$1-C$1) -> 1.0367231e-05 | F50: =ABS(C50-D50)/(C$1-D$1) -> 3.3043783e-06 | G50: =(E50+F50)/2*E$1 -> 0.030593643
A51: 19 | B51: 107.51294 | C51: =99.97775*(1+0.00398405*A51-5.865*0.0000001*A51^2) -> 107.52459 | D51: 107.552 | E51: =ABS(B51-C51)/(B$1-C$1) -> 1.2735305e-05 | F51: =ABS(C51-D51)/(C$1-D$1) -> 3.410552e-06 | G51: =(E51+F51)/2*E$1 -> 0.036130391 | H51: =1/0.3959217 -> 2.5257519
A52: 20 | B52: 107.9088 | C52: =99.97775*(1+0.00398405*A52-5.865*0.0000001*A52^2) -> 107.92062 | D52: 107.948 | E52: =ABS(B52-C52)/(B$1-C$1) -> 1.2920566e-05 | F52: =ABS(C52-D52)/(C$1-D$1) -> 3.4068793e-06 | G52: =(E52+F52)/2*E$1 -> 0.03653674 | H52: =1/0.3958047 -> 2.5264985
A53: 21 | B53: 108.30455 | C53: =99.97775*(1+0.00398405*A53-5.865*0.0000001*A53^2) -> 108.31653 | D53: 108.344 | E53: =ABS(B53-C53)/(B$1-C$1) -> 1.3097877e-05 | F53: =ABS(C53-D53)/(C$1-D$1) -> 3.4178002e-06 | G53: =(E53+F53)/2*E$1 -> 0.036957957 | H53: =1/0.3956877 -> 2.5272456
A54: 22 | B54: 108.70018 | C54: =99.97775*(1+0.00398405*A54-5.865*0.0000001*A54^2) -> 108.71233 | D54: 108.741 | E54: =ABS(B54-C54)/(B$1-C$1) -> 1.3278168e-05 | F54: =ABS(C54-D54)/(C$1-D$1) -> 3.5677547e-06 | G54: =(E54+F54)/2*E$1 -> 0.037696963 | H54: =1/0.3955707 -> 2.5279931
A55: 23 | B55: 109.09569 | C55: =99.97775*(1+0.00398405*A55-5.865*0.0000001*A55^2) -> 109.10801 | D55: 109.137 | E55: =ABS(B55-C55)/(B$1-C$1) -> 1.3461438e-05 | F55: =ABS(C55-D55)/(C$1-D$1) -> 3.6078627e-06 | G55: =(E55+F55)/2*E$1 -> 0.038196827 | H55: =1/0.3954531 -> 2.5287449
A56: 24 | B56: 109.49109 | C56: =99.97775*(1+0.00398405*A56-5.865*0.0000001*A56^2) -> 109.50357 | D56: 109.532 | E56: =ABS(B56-C56)/(B$1-C$1) -> 1.3636758e-05 | F56: =ABS(C56-D56)/(C$1-D$1) -> 3.5381242e-06 | G56: =(E56+F56)/2*E$1 -> 0.038433093 | H56: =1/0.3953367 -> 2.5294894
...

Sheet Zero&Air
A1: 2025
A2: Suhu (°C) | B2: Keseragaman Suhu (°C) | C2: Stabilitas Suhu (°C) | D2: Variasi Keseluruhan (°C)
A3: 0 | B3: 0.13561091 | C3: 0.11249856 | D3: 0.25489271
A4: 16 | B4: 0.21160235 | C4: 0.084425153 | D4: 0.2921349
A5: 18 | B5: 0.17079647 | C5: 0.068419004 | D5: 0.29164665
A6: 20 | B6: 0.14098776 | C6: 0.047711444 | D6: 0.19027259
A7: 25 | B7: 0.18793096 | C7: 0.050943573 | D7: 0.21958522
A8: 30 | B8: 0.19386909 | C8: 0.036105639 | D8: 0.19782167
A9: 35 | B9: 0.17492449 | C9: 0.11809913 | D9: 0.23619827
A10: 40 | B10: 0.19972325 | C10: 0.056484377 | D10: 0.22049635
A11: 50 | B11: 0.16551349 | C11: 0.090561483 | D11: 0.2641177

Sheet Oil Bath
A1: 2025
A2: Suhu Setting (°C) | B2: Suhu yang Diukur Indikator Enklosur (°C) | C2: Keseragaman Suhu (°C) | D2: Stabilitas Suhu (°C) | E2: Variasi Keseluruhan (°C)
A3: - | B3: - | C3: 0.26 | D3: 0.05 | E3: 0.32
A4: 35 | B4: 36.9 | C4: 0.1 | D4: 0.11 | E4: 0.06
A5: 40 | B5: 39.92 | C5: 0.11 | D5: 0.07 | E5: 0.18
A6: 60 | B6: 60.04 | C6: 0.16 | D6: 0.1 | E6: 0.31
A7: 90 | B7: 90.09 | C7: 0.13 | D7: 0.15 | E7: 0.4
A8: 120 | B8: 120.13 | C8: 0.21 | D8: 0.21 | E8: 0.53
A9: 150 | B9: 150.15 | C9: 0.2 | D9: 0.24 | E9: 0.62
A10: 180 | B10: 180.14 | C10: 0.26 | D10: 0.2 | E10: 0.71
A11: 210 | B11: 210.16 | C11: 0.25 | D11: 0.2 | E11: 0.75
A12: 240 | B12: 240 | C12: 0.24 | D12: 0.21 | E12: 0.74
A13: 270 | B13: 270 | C13: 0.21 | D13: 0.05 | E13: 0.37
A14: 299.5 | B14: 299.5 | C14: 0.23 | D14: 0.06 | E14: 0.36

Sheet sertbawaan PT100

Sheet Sert PT1002024

Sheet drift beamex tc305-Pt100
A1: Termokopel | B1: 45713 | F1: =B1-G1 -> 498 | G1: 45215 | K1: =G1-L1 -> 769 | L1: 44446 | P1: =L1-Q1 -> 802 | Q1: 43644 | U1: =Q1-V1 -> 1186 | V1: 42458 | Z1: =V1-AA1 -> 1776 | AA1: 40682 | AK1: =P1 -> 802
V2: P.Alat | W2: Koreksi | Y2: Ketidakpastian | AA2: P.Alat | AB2: Koreksi | AD2: Ketidakpastian | AK2: =AVERAGE(Z1,U1,P1,K1,F1) -> 1006.2
C3: m-internal | E3: um | H3: m | J3: um | M3: m | N3: g | O3: um | P3: ug | T3: m | U3: g | W3: m | X3: g | AN3: drift
A4: PT100 | Q4: -200 | R4: -0.02 | S4: 0.21 | T4: 0.23 | U4: 0.15 | V4: -200 | W4: -0.02 | X4: 0.21 | Y4: 0.23 | Z4: 0.15 | AA4: -200 | AB4: -0.02 | AC4: 0.01 | AD4: 0.02 | AE4: 0.02 | AG4: =ABS(C4-H4)/F$1 -> 0 | AH4: =ABS(H4-M4)/K$1 -> 0 | AI4: =ABS(M4-R4)/P$1 -> 2.4937656e-05 | AJ4: =ABS(R4-W4)/U$1 -> 0 | AK4: =ABS(W4-AB4)/Z$1 -> 0 | AM4: =(ABS(AG4)+ABS(AH4)+ABS(AK4)+ABS(AJ4)+ABS(AI4))/5 -> 4.9875312e-06 | AN4: =AM4*AK$2 -> 0.0050184539
B5: =B26 -> -199.96 | C5: =C26 -> -0.075 | E5: =D26 -> 0.080625605 | G5: -199.74 | H5: -0.29 | J5: 0.09 | L5: -197.97 | M5: -0.07 | O5: =O27 -> 0.079122023 | AG5: =ABS(C5-H5)/F$1 -> 0.00043172691 | AH5: =ABS(H5-M5)/K$1 -> 0.00028608583 | AI5: =ABS(M5-R5)/P$1 -> 8.7281796e-05 | AJ5: =ABS(R5-W5)/U$1 -> 0 | AK5: =ABS(W5-AB5)/Z$1 -> 0 | AM5: =(ABS(AG5)+ABS(AH5)+ABS(AK5)+ABS(AJ5)+ABS(AI5))/5 -> 0.00016101891 | AN5: =AM5*AK$2 -> 0.16201722
B6: =G6 -> -150 | C6: =(B6-B27)/(B28-B27)*(C28-C27)+C27 -> -0.084970018 | E6: =D27 -> 0.086687663 | G6: -150 | H6: -0.3 | J6: 0.09 | L6: -150 | M6: =(L6-M27)/(M28-M27)*(N28-N27)+N27 -> -0.089980008 | O6: =(L6-M27)/(M28-M27)*(O28-O27)+O27 -> 0.082197571 | Q6: -150 | R6: -0.03 | S6: 0.2 | V6: -150 | W6: -0.03 | X6: 0.2 | AA6: -150 | AB6: -0.04 | AC6: 0.01 | AG6: =ABS(C6-H6)/F$1 -> 0.00043178711 | AH6: =ABS(H6-M6)/K$1 -> 0.00027310792 | AI6: =ABS(M6-R6)/P$1 -> 7.478804e-05 | AJ6: =ABS(R6-W6)/U$1 -> 0 | AK6: =ABS(W6-AB6)/Z$1 -> 5.6306306e-06 | AM6: =(ABS(AG6)+ABS(AH6)+ABS(AK6)+ABS(AJ6)+ABS(AI6))/5 -> 0.00015706274 | AN6: =AM6*AK$2 -> 0.15803653
B7: =G7 -> -100 | C7: =(B7-B28)/(B29-B28)*(C29-C28)+C28 -> -0.114976 | E7: =D28 -> 0.086631675 | G7: -100 | H7: -0.32 | J7: 0.09 | L7: -100 | M7: =(L7-M27)/(M28-M27)*(N28-N27)+N27 -> -0.10997201 | O7: =(L7-M27)/(M28-M27)*(O28-O27)+O27 -> 0.085274966 | Q7: -100 | R7: -0.05 | S7: 0.2 | V7: -100 | W7: -0.05 | X7: 0.2 | AA7: -100 | AB7: -0.05 | AC7: 0.01 | AG7: =ABS(C7-H7)/F$1 -> 0.00041169477 | AH7: =ABS(H7-M7)/K$1 -> 0.00027311832 | AI7: =ABS(M7-R7)/P$1 -> 7.4778069e-05 | AJ7: =ABS(R7-W7)/U$1 -> 0 | AK7: =ABS(W7-AB7)/Z$1 -> 0 | AM7: =(ABS(AG7)+ABS(AH7)+ABS(AK7)+ABS(AJ7)+ABS(AI7))/5 -> 0.00015191823 | AN7: =AM7*AK$2 -> 0.15286012
B8: =G8 -> -50 | C8: =(B8-B29)/(B30-B29)*(C30-C29)+C29 -> -0.12996221 | E8: =D29 -> 0.090662259 | G8: -50 | H8: -0.24 | J8: 0.09 | L8: -50 | M8: =(L8-M28)/(M29-M28)*(N29-N28)+N28 -> -0.13495502 | O8: =(L8-M28)/(M29-M28)*(O29-O28)+O28 -> 0.087238902 | Q8: -50 | R8: -0.08 | S8: 0.21 | V8: -50 | W8: -0.08 | X8: 0.21 | AA8: -50 | AB8: -0.07 | AC8: 0.01 | AG8: =ABS(C8-H8)/F$1 -> 0.00022095941 | AH8: =ABS(H8-M8)/K$1 -> 0.00013659946 | AI8: =ABS(M8-R8)/P$1 -> 6.8522466e-05 | AJ8: =ABS(R8-W8)/U$1 -> 0 | AK8: =ABS(W8-AB8)/Z$1 -> 5.6306306e-06 | AM8: =(ABS(AG8)+ABS(AH8)+ABS(AK8)+ABS(AJ8)+ABS(AI8))/5 -> 8.6342393e-05 | AN8: =AM8*AK$2 -> 0.086877716
B9: =G9 -> 0 | C9: =(B9-B30)/(B31-B30)*(C31-C30)+C30 -> -0.15092664 | E9: =D30 -> 0.090811203 | G9: 0 | H9: -0.15 | J9: 0.14 | L9: 0 | M9: =(L9-M28)/(M29-M28)*(N29-N28)+N28 -> -0.15994502 | O9: =(L9-M29)/(M30-M29)*(O30-O29)+O29 -> 0.089194791 | Q9: 0 | R9: -0.1 | S9: 0.21 | V9: 0 | W9: -0.1 | X9: 0.21 | AA9: 0 | AB9: -0.07 | AC9: 0.02 | AD9: 0.03 | AE9: 0.02 | AG9: =ABS(C9-H9)/F$1 -> 1.8607327e-06 | AH9: =ABS(H9-M9)/K$1 -> 1.2932408e-05 | AI9: =ABS(M9-R9)/P$1 -> 7.4744416e-05 | AJ9: =ABS(R9-W9)/U$1 -> 0 | AK9: =ABS(W9-AB9)/Z$1 -> 1.6891892e-05 | AM9: =(ABS(AG9)+ABS(AH9)+ABS(AK9)+ABS(AJ9)+ABS(AI9))/5 -> 2.128589e-05 | AN9: =AM9*AK$2 -> 0.021417862
B10: =G10 -> 50 | C10: =(B10-B31)/(B32-B31)*(C32-C31)+C31 -> -0.18559526 | E10: =D31 -> 0.14 | G10: 50 | H10: -0.17 | J10: 0.14 | L10: 50 | M10: =(L10-M29)/(M30-M29)*(N30-N29)+N29 -> -0.16 | O10: =(L10-M30)/(M31-M30)*(O31-O30)+O30 -> 0.094201524 | Q10: 50 | R10: -0.11 | S10: 0.22 | V10: 50 | W10: -0.11 | X10: 0.22 | AA10: 50 | AB10: -0.09 | AC10: 0.015 | AG10: =ABS(C10-H10)/F$1 -> 3.1315775e-05 | AH10: =ABS(H10-M10)/K$1 -> 1.3003901e-05 | AI10: =ABS(M10-R10)/P$1 -> 6.234414e-05 | AJ10: =ABS(R10-W10)/U$1 -> 0 | AK10: =ABS(W10-AB10)/Z$1 -> 1.1261261e-05 | AM10: =(ABS(AG10)+ABS(AH10)+ABS(AK10)+ABS(AJ10)+ABS(AI10))/5 -> 2.3585015e-05 | AN10: =AM10*AK$2 -> 0.023731243
B11: =G11 -> 100 | C11: =(B11-B32)/(B33-B32)*(C33-C32)+C32 -> -0.19624813 | E11: =D32 -> 0.14 | G11: 100 | H11: -0.2 | J11: 0.14 | L11: 100 | M11: =(L11-M29)/(M30-M29)*(N30-N29)+N29 -> -0.16 | O11: =(L11-M31)/(M32-M31)*(O32-O31)+O31 -> 0.093995354 | Q11: 100 | R11: -0.12 | S11: 0.21 | V11: 100 | W11: -0.12 | X11: 0.21 | AA11: 100 | AB11: -0.1 | AC11: 0.01 | AG11: =ABS(C11-H11)/F$1 -> 7.5338855e-06 | AH11: =ABS(H11-M11)/K$1 -> 5.2015605e-05 | AI11: =ABS(M11-R11)/P$1 -> 4.9875312e-05 | AJ11: =ABS(R11-W11)/U$1 -> 0 | AK11: =ABS(W11-AB11)/Z$1 -> 1.1261261e-05 | AM11: =(ABS(AG11)+ABS(AH11)+ABS(AK11)+ABS(AJ11)+ABS(AI11))/5 -> 2.4137213e-05 | AN11: =AM11*AK$2 -> 0.024286863
B12: =G12 -> 150 | C12: =(B12-B33)/(B34-B33)*(C34-C33)+C33 -> -0.19672328 | E12: =D33 -> 0.14 | G12: 150 | H12: -0.2 | J12: 0.14 | L12: 150 | M12: =(L12-M30)/(M31-M30)*(N31-N30)+N30 -> -0.17994602 | O12: =(L12-M30)/(M31-M30)*(O31-O30)+O30 -> 0.10383196 | Q12: 150 | R12: -0.12 | S12: 0.21 | V12: 150 | W12: -0.12 | X12: 0.21 | AA12: 150 | AB12: -0.11 | AC12: 0 | AG12: =ABS(C12-H12)/F$1 -> 6.5797656e-06 | AH12: =ABS(H12-M12)/K$1 -> 2.6078002e-05 | AI12: =ABS(M12-R12)/P$1 -> 7.4745656e-05 | AJ12: =ABS(R12-W12)/U$1 -> 0 | AK12: =ABS(W12-AB12)/Z$1 -> 5.6306306e-06 | AM12: =(ABS(AG12)+ABS(AH12)+ABS(AK12)+ABS(AJ12)+ABS(AI12))/5 -> 2.2606811e-05 | AN12: =AM12*AK$2 -> 0.022746973
B13: =G13 -> 200 | C13: =(B13-B34)/(B35-B34)*(C35-C34)+C34 -> -0.2476977 | E13: =D34 -> 0.14 | G13: 200 | H13: -0.2 | J13: 0.14 | L13: 200 | M13: =(L13-M30)/(M31-M30)*(N31-N30)+N30 -> -0.19994002 | O13: =(L13-M30)/(M31-M30)*(O31-O30)+O30 -> 0.10864718 | Q13: 200 | R13: -0.12 | S13: 0.2 | V13: 200 | W13: -0.12 | X13: 0.2 | AA13: 200 | AB13: -0.12 | AC13: 0 | AG13: =ABS(C13-H13)/F$1 -> 9.5778509e-05 | AH13: =ABS(H13-M13)/K$1 -> 7.8000007e-08 | AI13: =ABS(M13-R13)/P$1 -> 9.9675833e-05 | AJ13: =ABS(R13-W13)/U$1 -> 0 | AK13: =ABS(W13-AB13)/Z$1 -> 0 | AM13: =(ABS(AG13)+ABS(AH13)+ABS(AK13)+ABS(AJ13)+ABS(AI13))/5 -> 3.9106468e-05 | AN13: =AM13*AK$2 -> 0.039348929
B14: =G14 -> 250 | C14: =(B14-B35)/(B36-B35)*(C36-C35)+C35 -> -0.19812313 | E14: =D35 -> 0.14 | G14: 250 | H14: -0.22 | J14: 0.14 | L14: 250 | M14: =(L14-M31)/(M32-M31)*(N32-N31)+N31 -> -0.2 | O14: =(L14-M31)/(M32-M31)*(O32-O31)+O31 -> 0.1159618 | Q14: 250 | R14: -0.12 | S14: 0.19 | V14: 250 | W14: -0.12 | X14: 0.19 | AA14: 250 | AB14: -0.13 | AC14: -0.01 | AG14: =ABS(C14-H14)/F$1 -> 4.3929468e-05 | AH14: =ABS(H14-M14)/K$1 -> 2.6007802e-05 | AI14: =ABS(M14-R14)/P$1 -> 9.9750623e-05 | AJ14: =ABS(R14-W14)/U$1 -> 0 | AK14: =ABS(W14-AB14)/Z$1 -> 5.6306306e-06 | AM14: =(ABS(AG14)+ABS(AH14)+ABS(AK14)+ABS(AJ14)+ABS(AI14))/5 -> 3.5063705e-05 | AN14: =AM14*AK$2 -> 0.0352811
B15: =G15 -> 300 | C15: =(B15-B36)/(B37-B36)*(C37-C36)+C36 -> -0.19859828 | E15: =D36 -> 0.14 | G15: 300 | H15: -0.25 | J15: 0.14 | L15: 300 | M15: =(L15-M31)/(M32-M31)*(N32-N31)+N31 -> -0.2 | O15: =(L15-M31)/(M32-M31)*(O32-O31)+O31 -> 0.12328395 | Q15: 300 | R15: -0.12 | S15: 0.19 | V15: 300 | W15: -0.12 | X15: 0.19 | AA15: 300 | AB15: -0.14 | AC15: -0.01 | AG15: =ABS(C15-H15)/F$1 -> 0.00010321631 | AH15: =ABS(H15-M15)/K$1 -> 6.5019506e-05 | AI15: =ABS(M15-R15)/P$1 -> 9.9750623e-05 | AJ15: =ABS(R15-W15)/U$1 -> 0 | AK15: =ABS(W15-AB15)/Z$1 -> 1.1261261e-05 | AM15: =(ABS(AG15)+ABS(AH15)+ABS(AK15)+ABS(AJ15)+ABS(AI15))/5 -> 5.584954e-05 | AN15: =AM15*AK$2 -> 0.056195808
B16: =G16 -> 350 | C16: =(B16-B37)/(B38-B37)*(C38-C37)+C37 -> -0.2493725 | E16: =D37 -> 0.14 | G16: 350 | H16: -0.25 | J16: 0.14 | L16: 350 | M16: =(L16-M32)/(M33-M32)*(N33-N32)+N32 -> -0.22491254 | O16: =(L16-M32)/(M33-M32)*(O33-O32)+O32 -> 0.12582851 | Q16: 350 | R16: -0.13 | S16: 0.19 | V16: 350 | W16: -0.13 | X16: 0.19 | AA16: 350 | AB16: -0.15 | AC16: -0.02 | AG16: =ABS(C16-H16)/F$1 -> 1.2600402e-06 | AH16: =ABS(H16-M16)/K$1 -> 3.262348e-05 | AI16: =ABS(M16-R16)/P$1 -> 0.00011834482 | AJ16: =ABS(R16-W16)/U$1 -> 0 | AK16: =ABS(W16-AB16)/Z$1 -> 1.1261261e-05 | AM16: =(ABS(AG16)+ABS(AH16)+ABS(AK16)+ABS(AJ16)+ABS(AI16))/5 -> 3.269792e-05 | AN16: =AM16*AK$2 -> 0.032900647
B17: =G17 -> 400 | C17: =(B17-B38)/(B39-B38)*(C39-C38)+C38 -> -0.24980519 | E17: =D38 -> 0.14 | G17: 400 | H17: -0.25 | J17: 0.14 | L17: 400 | M17: =(L17-M32)/(M33-M32)*(N33-N32)+N32 -> -0.24990005 | O17: =(L17-M32)/(M33-M32)*(O33-O32)+O32 -> 0.12835869 | Q17: 400 | R17: -0.15 | S17: 0.19 | V17: 400 | W17: -0.15 | X17: 0.19 | AA17: 400 | AB17: -0.17 | AC17: -0.02 | AG17: =ABS(C17-H17)/F$1 -> 3.9117509e-07 | AH17: =ABS(H17-M17)/K$1 -> 1.2997402e-07 | AI17: =ABS(M17-R17)/P$1 -> 0.00012456365 | AJ17: =ABS(R17-W17)/U$1 -> 0 | AK17: =ABS(W17-AB17)/Z$1 -> 1.1261261e-05 | AM17: =(ABS(AG17)+ABS(AH17)+ABS(AK17)+ABS(AJ17)+ABS(AI17))/5 -> 2.7269213e-05 | AN17: =AM17*AK$2 -> 0.027438282
B18: =G18 -> 450 | C18: =(B18-B39)/(B40-B39)*(C40-C39)+C39 -> -0.29849401 | E18: =D39 -> 0.18294029 | G18: 450 | H18: -0.27 | J18: 0.18 | L18: 450 | M18: =(L18-M33)/(M34-M33)*(N34-N33)+N33 -> -0.254979 | O18: =(L18-M33)/(M34-M33)*(O34-O33)+O33 -> 0.13648057 | Q18: 450 | R18: -0.18 | S18: 0.2 | V18: 450 | W18: -0.18 | X18: 0.2 | AA18: 450 | AB18: -0.18 | AC18: -0.03 | AG18: =ABS(C18-H18)/F$1 -> 5.721688e-05 | AH18: =ABS(H18-M18)/K$1 -> 1.9533154e-05 | AI18: =ABS(M18-R18)/P$1 -> 9.349003e-05 | AJ18: =ABS(R18-W18)/U$1 -> 0 | AK18: =ABS(W18-AB18)/Z$1 -> 0 | AM18: =(ABS(AG18)+ABS(AH18)+ABS(AK18)+ABS(AJ18)+ABS(AI18))/5 -> 3.4048013e-05 | AN18: =AM18*AK$2 -> 0.034259111
B19: =G19 -> 500 | C19: =(B19-B40)/(B41-B40)*(C41-C40)+C40 -> -0.3503003 | E19: =D40 -> 0.18444443 | G19: 500 | H19: -0.3 | J19: 0.18 | L19: 500 | M19: =(L19-M33)/(M34-M33)*(N34-N33)+N33 -> -0.259978 | O19: =(L19-M33)/(M34-M33)*(O34-O33)+O33 -> 0.1446249 | Q19: 500 | R19: -0.21 | S19: 0.2 | V19: 500 | W19: -0.21 | X19: 0.2 | AA19: 500 | AB19: -0.19 | AC19: -0.04 | AG19: =ABS(C19-H19)/F$1 -> 0.00010100462 | AH19: =ABS(H19-M19)/K$1 -> 5.2044208e-05 | AI19: =ABS(M19-R19)/P$1 -> 6.2316714e-05 | AJ19: =ABS(R19-W19)/U$1 -> 0 | AK19: =ABS(W19-AB19)/Z$1 -> 1.1261261e-05 | AM19: =(ABS(AG19)+ABS(AH19)+ABS(AK19)+ABS(AJ19)+ABS(AI19))/5 -> 4.532536e-05 | AN19: =AM19*AK$2 -> 0.045606378
B20: =G20 -> 550 | C20: =(B20-B41)/(B42-B41)*(C42-C41)+C41 -> -0.29975025 | E20: =D41 -> 0.18444057 | G20: 550 | H20: -0.3 | J20: 0.18 | L20: 550 | M20: =(L20-M34)/(M35-M34)*(N35-N34)+N34 -> -0.269955 | O20: =(L20-M34)/(M35-M34)*(O35-O34)+O34 -> 0.15062306 | Q20: 550 | R20: -0.23 | S20: 0.21 | V20: 550 | W20: -0.23 | X20: 0.21 | AA20: 550 | AB20: -0.2 | AC20: -0.05 | AG20: =ABS(C20-H20)/F$1 -> 5.0150653e-07 | AH20: =ABS(H20-M20)/K$1 -> 3.9070215e-05 | AI20: =ABS(M20-R20)/P$1 -> 4.9819208e-05 | AJ20: =ABS(R20-W20)/U$1 -> 0 | AK20: =ABS(W20-AB20)/Z$1 -> 1.6891892e-05 | AM20: =(ABS(AG20)+ABS(AH20)+ABS(AK20)+ABS(AJ20)+ABS(AI20))/5 -> 2.1256564e-05 | AN20: =AM20*AK$2 -> 0.021388355
B21: =G21 -> 600 | C21: =(B21-B42)/(B43-B42)*(C43-C42)+C42 -> -0.35 | E21: =D42 -> 0.18292861 | G21: 600 | H21: -0.29 | J21: 0.18 | L21: 600 | M21: =(L21-M34)/(M35-M34)*(N35-N34)+N34 -> -0.279954 | O21: =(L21-M34)/(M35-M34)*(O35-O34)+O34 -> 0.15661173 | Q21: 600 | R21: -0.23 | S21: 0.2 | V21: 600 | W21: -0.23 | X21: 0.2 | AA21: 600 | AB21: -0.21 | AC21: -0.05 | AG21: =ABS(C21-H21)/F$1 -> 0.00012048193 | AH21: =ABS(H21-M21)/K$1 -> 1.3063713e-05 | AI21: =ABS(M21-R21)/P$1 -> 6.2286789e-05 | AJ21: =ABS(R21-W21)/U$1 -> 0 | AK21: =ABS(W21-AB21)/Z$1 -> 1.1261261e-05 | AM21: =(ABS(AG21)+ABS(AH21)+ABS(AK21)+ABS(AJ21)+ABS(AI21))/5 -> 4.1418738e-05 | AN21: =AM21*AK$2 -> 0.041675534
N24: Koreksi | O24: U 95%
N25: Alat
B26: -199.96 | C26: -0.075 | D26: 0.080625605 | G26: -199.74 | H26: -0.29 | I26: 0.09 | M26: X Rata-rata | N26: (°C) | O26: (°C)
B27: -149.95 | C27: -0.085 | D27: 0.086687663 | G27: -99.72 | H27: -0.32 | I27: 0.09 | M27: -199.97 | N27: -0.07 | O27: 0.079122023
B28: -99.92 | C28: -0.115 | D28: 0.086631675 | G28: 0.1 | H28: -0.15 | I28: 0.14 | M28: -99.93 | N28: -0.11 | O28: 0.085279274
B29: -49.91 | C29: -0.13 | D29: 0.090662259 | G29: 100.15 | H29: -0.2 | I29: 0.14 | M29: 0.11 | N29: -0.16 | O29: 0.089205595
B30: 0.106 | C30: -0.151 | D30: 0.090811203 | G30: 200.15 | H30: -0.2 | I30: 0.14 | M30: 100.12 | N30: -0.16 | O30: 0.099028297
B31: 50.14 | C31: -0.185625 | D31: 0.14 | G31: 300.2 | H31: -0.25 | I31: 0.14 | M31: 200.15 | N31: -0.2 | O31: 0.10866162
B32: 100.15 | C32: -0.19625 | D32: 0.14 | G32: 400.2 | H32: -0.25 | I32: 0.14 | M32: 300.15 | N32: -0.2 | O32: 0.12330592
B33: 150.15 | C33: -0.196875 | D33: 0.14 | G33: 500.25 | H33: -0.3 | I33: 0.18 | M33: 400.2 | N33: -0.25 | O33: 0.12836881
B34: 200.2 | C34: -0.2475 | D34: 0.14 | G34: 600.25 | H34: -0.29 | I34: 0.18 | M34: 500.22 | N34: -0.26 | O34: 0.14466073
B35: 250.15 | C35: -0.198125 | D35: 0.14 | G35: 700.3 | H35: -0.34 | I35: 0.18 | M35: 600.23 | N35: -0.28 | O35: 0.15663928
B36: 300.15 | C36: -0.19875 | D36: 0.14 | G36: 790.3 | H36: -0.34 | I36: 0.18 | M36: 700.25 | N36: -0.29 | O36: 0.17961895
B37: 350.2 | C37: -0.249375 | D37: 0.14 | M37: 800.28 | N37: -0.32 | O37: 0.17981073
B38: 400.2 | C38: -0.25 | D38: 0.14
B39: 450.25 | C39: -0.29875 | D39: 0.18294029
B40: 500.3 | C40: -0.35 | D40: 0.18444443
B41: 550.25 | C41: -0.3 | D41: 0.18444057
B42: 600.3 | C42: -0.35 | D42: 0.18292861
...
