Workbook

Sheet FORM Baru
C7: Form Kalibrasi
AG8: BACKEND
C9: Nomor Order | D9: K085-9 | AF9: 1 | AG9: =D9 -> K085-9
AF10: 2 | AG10: =D11 -> Laboratorium Geoteknik - Universitas Katolik Parahyangan
C11: Pemilik Alat | D11: Laboratorium Geoteknik - Universitas Katolik Parahyangan | AF11: 3 | AG11: =D13 -> Jl. Ciumbuleuit No.94, Hegarmanah, Kec. Cidadap, Kota Bandung, Jawa Barat 40141
AF12: 4 | AG12: =D15 -> Universitas Katolik Parahyangan
C13: Alamat Pemilik Alat | D13: Jl. Ciumbuleuit No.94, Hegarmanah, Kec. Cidadap, Kota Bandung, Jawa Barat 40141 | AF13: 5 | AG13: =D17 -> Timbangan
AF14: 6 | AG14: =D19 -> Mettler Toledo
C15: Lokasi Alat | D15: Universitas Katolik Parahyangan | AF15: 7 | AG15: =D21 -> PL2003
AF16: 9 | AG16: =D23 -> 1230120304
C17: Nama Alat | D17: Timbangan | AF17: 10 | AG17: =D25 -> 3000 g
AF18: 11 | AG18: =D27 -> 0,001 g
C19: Merk | D19: Mettler Toledo | AF19: 12 | AG19: =D29 -> -
AF20: 13 | AG20: =D31 -> 12 Februari 2026
C21: Tipe | D21: PL2003 | AF21: 14 | AG21: =D33 -> 18 Februari 2026
AF22: 15 | AG22: =D35 -> 0021-2.2/KALIBRASI BBLM/III/2026
C23: Nomor Seri | D23: 1230120304 | AF23: 16 | AG23: =D37 -> F1
AF24: 17 | AG24: =D39 -> YCS-01-653-00
C25: Kapasitas | D25: 3000 g | AF25: 18 | AG25: =D41 -> 1 Maret 2026
AF26: 19 | AG26: =D43 -> -
C27: Resolusi | D27: 0,001 g | AF27: 20 | AG27: =D45 -> -
AF28: 21 | AG28: =D47 -> 0
C29: Nomor Identifikasi | D29: -
C31: Tanggal Terima | D31: 12 Februari 2026
C33: Tanggal Kalibrasi | D33: 18 Februari 2026
C35: Nomor Serifikat | D35: 0021-2.2/KALIBRASI BBLM/III/2026
C37: Kalibrator | D37: F1
C39: No Seri Kalibrator | D39: YCS-01-653-00
C41: Tanggal Terbit Sertifikat | D41: 1 Maret 2026
C43: Catatan 1 | D43: -
C45: Catatan 2 | D45: -
C47: Input QR Code
C50: CETAK SERTIFIKAT

Sheet 1,2,3,5
A1: KALIBRASI NERACA / TIMBANGAN LABORATORIUM KALIBRASI BALAI BESAR LOGAM DAN MESIN Jl. Sangkuriang No.12 Bandung 40135 , Tlp 022-2503171 fax :0222508979
A2: No Order | B2: : | C2: ='U95'!#REF! -> #REF!
A3: Merk / Type | B3: : | C3: ='U95'!C3 -> 0
A4: Kapasitas / Graduasi | B4: : | C4: 60 kg / 0,005 kg
A5: No Identitas / No Seri | B5: : | C5: ='U95'!#REF! -> #REF!
A6: Standard Acuan | B6: : | C6: CSIRO 2010 , OIML R111
A7: Kondisi Ruangan | B7: : | C7: Awal | E7: Akhir | F7: Rata Rata
A8: Temperatur ( C ) | B8: : | C8: ='U95'!C8 -> 28.6 | E8: ='U95'!C9 -> 28.6 | F8: ='U95'!C10 -> 28.6
A9: Kelembaban (%) | B9: : | C9: ='U95'!C11 -> 61.2 | E9: ='U95'!C12 -> 61.2 | F9: ='U95'!C13 -> 61.2
A10: Tekanan (mmHg) | B10: : | C10: ='U95'!D14 -> 691.5 | E10: ='U95'!D15 -> 691.5 | F10: ='U95'!D16 -> 691.5
A11: Kalibrator | B11: : | C11: Massa Standard F1 NS : YCS – 01 – 653 - 00 dan M1 20 kg
A12: Tgl Masuk | B12: :
A13: Tgl Kalibrasi | B13: : | C13: ='U95'!#REF! -> #REF!
A17: 1. PREADJUSTMENT / SEBELUM PENYETELAN TIMBANGAN
A19: Titik Ukur | B19: : | C19: ='U95'!D24 -> 200000 | D19: kg
A20: Massa Konvensional | B20: : | C20: ='U95'!D25 -> 100000.04 | D20: kg
C22: Beban | D22: Pembacaan | E22: Rata Rata | F22: Koreksi
E23: ((m1-z1)+(m2-z2))/2 | F23: ( c ) = M-rata rata
C24: =D19 -> kg | D24: =C24 -> kg | E24: =C24 -> kg | F24: =E24 -> kg
C25: ='U95'!C28 -> 0 | D25: ='U95'!D28 -> 0 | E25: =((D26-D25)+(D27-D28))/2 -> 200100 | F25: ='U95'!G30 -> -100099.96
C26: M | D26: ='U95'!D29 -> 200100
C27: M | D27: ='U95'!D30 -> 200100
C28: 0 | D28: ='U95'!D31 -> 0
A31: 2. PENYETELAN TIMBANGAN
A33: Titik Ukur | B33: : | C33: =C19 -> 200000 | D33: =D19 -> kg
A34: Massa Konvensional | B34: : | C34: =C20 -> 100000.04 | D34: =D33 -> kg
C36: Beban | D36: Pembacaan | E36: Rata Rata | F36: Koreksi
E37: ((m1-z1)+(m2-z2))/2 | F37: ( c ) = M-rata rata
C38: =D33 -> kg | D38: =C38 -> kg | E38: =C38 -> kg | F38: =E38 -> kg
C39: ='U95'!C39 -> 1 | D39: ='U95'!K28 -> 0 | E39: =((D40-D39)+(D41-D42))/2 -> 200100 | F39: ='U95'!N30 -> -100099.96
C40: M | D40: ='U95'!K29 -> 200100
C41: M | D41: ='U95'!K30 -> 200100
C42: 0 | D42: ='U95'!K31 -> 0
A52: 5. EFEK PEMBEBANAN TIDAK TERPUSAT
A53: Massa nominal ( 1 Batu timbangan) = antara 1/3 s.d ½ Kapasitas Maks = | F53: 30 kg
C55: Posisi | D55: Pembacaan | E55: Perbedaan terhadap posisi 0 | F55: Maksimum Perbedaan
D56: ( kg ) | E56: ( kg ) | F56: ( kg )
C57: 0 | D57: ='U95'!D139 -> 14.995 | E57: ='U95'!E139 -> 0
C58: 1 | D58: ='U95'!D140 -> 14.978 | E58: ='U95'!E140 -> -0.017
C59: 2 | D59: ='U95'!D141 -> 15 | E59: ='U95'!E141 -> 0.005 | F59: ='U95'!F139 -> 0.023
...

Sheet U95
A1: ISI DATA
A3: Merk | B3: :
A4: Tipe | B4: :
A5: Nomor Seri | B5: :
A6: Nomor Identitas | B6: : | C6: ='FORM Baru'!AG19 -> - | E6: =E7/1000 -> 0.01 | F6: kg | G6: Digit
A7: Kapasitas (g) | B7: : | C7: 200000 | D7: resolusi | E7: 10 | F7: g | G7: =IFERROR(IF($C$20="kg",LEN(E6)-FIND(",",E6),LEN(E7)-FIND(",",E7)),0) -> 2
A8: Temperatur Awal | B8: : | C8: 28.6 | E8: =E7*1000 -> 10000 | F8: mg
A9: Temperatur Akhir | B9: : | C9: 28.6
A10: Temperatur rata rata | B10: : | C10: =(C8+C9)/2 -> 28.6
A11: Kelembaban awal | B11: : | C11: 61.2
A12: Kelembaban Akhir | B12: : | C12: 61.2 | F12: PENGERJAAN UNTUK F1 DAN E2 DAHULUKAN NON BINTANG, LALU BINTANG
A13: Kelembaban Rata rata | B13: : | C13: =(C11+C12)/2 -> 61.2
A14: Tekanan Awal | B14: : | C14: 922 | D14: =C14*0.75 -> 691.5
A15: Tekanan Akhir | B15: : | C15: 922 | D15: =C15*0.75 -> 691.5
A16: Tekanan Rata Rata | B16: : | C16: =(C14+C15)/2 -> 922 | D16: =(D14+D15)/2 -> 691.5 | F16: DIPAKAI JIKA MENGGUNAKAN M1 (Kapasitas Maks)
A17: Prosedur | B17: : | C17: CSIRO 2010 | F17: AT1 | G17: AT2 | H17: AT3 | I17: AT4 | J17: AT5 | K17: AT6 | L17: AT7 | M17: AT8 | N17: AT9 | O17: AT10
A18: Kalibrator | B18: : | C18: M1 | F18: M3 | G18: M5 | H18: M1 | I18: M11 | J18: M12 | K18: M8 | L18: M10 | M18: M6 | N18: M14 | O18: M2
A19: Mode Titik Ukur | B19: : | C19: 10 Titik
A20: Satuan Pembacaan | B20: : | C20: kg
B23: I. | C23: PRE-ADJUSTMENT | J23: ADJUSTMENT
C24: Titik Ukur | D24: =C7 -> 200000 | E24: (max ) | F24: g | J24: Titik Ukur | K24: =C7 -> 200000 | L24: (max )
C25: Beban | D25: {=IF(C18="M1",SUM(IFERROR(INDEX( Database!CB4:CD33, MATCH(F18:J18, Database!CB4:CB33, 0),2),0)), SUM( IFERROR( INDEX(CHOOSE( MATCH(C18,Database!A8:A10,0), Database!BP4:BR21, Database!BT4:BV21, Database!CB4:CD33, Database!BX4:BZ21 ), MATCH( Database!Z11:AI11, INDEX( CHOOSE(MATCH(C18,Database!A8:A10,0), Database!BP4:BR21, Database!BT4:BV21, Database!CB4:CD33, Database!BX4:BZ21 ),,1 ), 0), 2 ), 0 )))} -> 100000.04 | E25: Massa konvensional dari sertifikat | J25: Beban | K25: =D25 -> 100000.04 | L25: Massa konvensional dari sertifikat
C26: Beban | D26: Reading | E26: Means | F26: Difference | G26: Correction | J26: Beban | K26: Reading | L26: Means | M26: Difference | N26: Correction
F27: ri-zi | G27: Mi-(ri-zi) | M27: ri-zi | N27: Mi-(ri-zi)
C28: 0 | D28: 0 | J28: 0 | K28: 0
C29: =D25 -> 100000.04 | D29: 200100 | J29: =K25 -> 100000.04 | K29: 200100 | L29: =(K28+K29)/2 -> 100050
C30: =C29 -> 100000.04 | D30: 200100 | E30: =(D29+D30)/2 -> 200100 | F30: =E30-E31 -> 200100 | G30: =D25-(F30) -> -100099.96 | J30: =J29 -> 100000.04 | K30: 200100 | L30: =(K29+K30)/2 -> 200100 | M30: =L30-L31 -> 200100 | N30: =K25-(M30) -> -100099.96
C31: 0 | D31: 0 | E31: =(D28+D31)/2 -> 0 | K31: =D31 -> 0 | L31: =(K28+K31)/2 -> 0
B34: II. | C34: REPEATABILITY MEASUREMENT
C35: Sres | D35: =0.82*(E7/2) -> 4.1 | E35: g | J35: Sres | K35: =0.82*(E7/2) -> 4.1 | L35: g
C36: Repeat at | D36: =C7/2 -> 100000 | E36: g | J36: Repeat at | K36: =C7 -> 200000 | L36: g
C37: No | D37: Pan Load | E37: Mass Reading | F37: Measurement | J37: No | K37: Pan Load | L37: Mass Reading | M37: Measurement
F38: Mi-(ri-zi) | M38: Mi-(ri-zi)
C39: 1 | D39: 0 | E39: 0 | J39: 1 | K39: 0 | L39: 0
D40: M | E40: 100000 | F40: =E40-E39 -> 100000 | K40: M | L40: 199100 | M40: =L40-L39 -> 199100
C41: 2 | D41: 0 | E41: 0 | J41: 2 | K41: 0 | L41: 0
D42: M | E42: 100000 | F42: =E42-E41 -> 100000 | K42: M | L42: 199000 | M42: =L42-L41 -> 199000
C43: 3 | D43: 0 | E43: 0 | J43: 3 | K43: 0 | L43: 0
D44: M | E44: 100000 | F44: =E44-E43 -> 100000 | K44: M | L44: 199100 | M44: =L44-L43 -> 199100
C45: 4 | D45: 0 | E45: 0 | J45: 4 | K45: 0 | L45: 0
...

Sheet Koreksi themohygro rotronic 202
C2: Suhu (°C) | D2: %RH | E2: Tekanan | F2: Satuan | G2: Thermohygro Rotronic data 2025
B3: Awal | C3: ='U95'!C8 -> 28.6 | D3: ='U95'!C11 -> 61.2 | E3: 1010 | F3: hPa | G3: Koreksi suhu | J3: Koreksi RH
B4: Akhir | C4: ='U95'!C9 -> 28.6 | D4: ='U95'!C12 -> 61.2 | E4: 1009 | F4: hPa | G4: T (°C) | H4: Koreksi | I4: U95 | J4: RH (%) | K4: Koreksi | L4: U95
B5: Rata2 | C5: =AVERAGE(C3:C4) -> 28.6 | D5: =AVERAGE(D3:D4) -> 61.2 | E5: =AVERAGE(E3:E4) -> 1009.5 | F5: hPa | G5: 20 | H5: 0.1 | I5: 2 | J5: 40 | K5: 0.2 | L5: 2.5
B6: Terkoreksi | C6: =C5+FORECAST(C5,H5:H9,G5:G9) -> 28.316 | D6: =D5+FORECAST(D5,K5:K9,J5:J9) -> 60.9632 | E6: =FORECAST(E5,G15:G25,H15:H25)*0.75 -> 759.26295 | F6: mmHg | G6: 25 | H6: -0.2 | I6: 2 | J6: 50 | K6: -0.3 | L6: 2.8
B7: U95 | C7: 2 | D7: =FORECAST(D6,L5:L9,J5:J9) -> 2.6142208 | E7: =I15 -> 1 | F7: mmHg | G7: 30 | H7: -0.3 | I7: 2 | J7: 60 | K7: -0.3 | L7: 3.2
B8: Fluktuasi suhu | C8: =(MAX(C3:C4)-C5+C5-MIN(C3:C4))/2 -> 0 | D8: =(MAX(D3:D4)-D5+D5-MIN(D3:D4))/2 -> 0 | E8: =(MAX(E3:E4)-E5+E5-MIN(E3:E4))/2 -> 0.5 | F8: mmHg | G8: 35 | H8: -0.6 | I8: 2 | J8: 70 | K8: -0.1 | L8: 2
B9: Flu+U95 | C9: =C7+C8 -> 2 | D9: =D7+D8 -> 2.6142208 | E9: =E7+E8 -> 1.5 | F9: mmHg | G9: 40 | H9: -0.7 | I9: 2 | J9: 80 | K9: -0.6 | L9: 2.6
B10: Kondisi Ruang | C10: =FIXED(C6,1) & " ± "&FIXED(C8,1) -> 28,3 ± 0,0 | D10: =FIXED(D6,0) & " ± "&FIXED(D8,0) -> 61 ± 0 | E10: =FIXED(E6,0) & " ± "&FIXED(E8,0) -> 759 ± 1 | F10: mmHg
G12: Data tekanan 2021 SNSU
G14: Instrument reading (hPa) | H14: Actual pressure (hPa) | I14: Uncertainty (hPa)
G15: 940 | H15: 936 | I15: 1
G16: 960 | H16: 957 | I16: 1
G17: 980 | H17: 977 | I17: 1
G18: 990 | H18: 987 | I18: 1
G19: 1000 | H19: 997 | I19: 1
G20: 1010 | H20: 1007 | I20: 1
G21: 1020 | H21: 1017 | I21: 1
G22: 1030 | H22: 1027 | I22: 1
G23: 1040 | H23: 1037 | I23: 1
G24: 1050 | H24: 1048 | I24: 1
G25: 1060 | H25: 1058 | I25: 1
C27: Suhu (°C) | D27: %RH | E27: Tekanan | F27: Satuan | G27: Thermohygro Beurer data 2025
B28: Awal | C28: ='U95'!C8 -> 28.6 | D28: ='U95'!C11 -> 61.2 | E28: 925 | F28: hPa | G28: Koreksi suhu | J28: Koreksi RH
B29: Akhir | C29: ='U95'!C9 -> 28.6 | D29: ='U95'!C12 -> 61.2 | E29: 925 | F29: hPa | G29: T (°C) | H29: Koreksi | I29: U95 | J29: RH (%) | K29: Koreksi | L29: U95
B30: Rata2 | C30: =AVERAGE(C28:C29) -> 28.6 | D30: =AVERAGE(D28:D29) -> 61.2 | E30: =AVERAGE(E28:E29) -> 925 | F30: hPa | G30: 19.7 | H30: 0.3 | I30: 2 | J30: 42 | K30: -2 | L30: 3
B31: Terkoreksi | C31: =C30+FORECAST(C30,H30:H34,G30:G34) -> 29.353334 | D31: =D30+FORECAST(D30,K30:K34,J30:J34) -> 59.589505 | E31: =FORECAST(E30,G15:G25,H15:H25)*0.75 -> 696.60958 | F31: mmHg | G31: 24.6 | H31: 0.4 | I31: 2 | J31: 53 | K31: -3 | L31: 3
B32: U95 | C32: 2 | D32: =FORECAST(D31,L30:L34,J30:J34) -> 2.8178673 | E32: =I15 -> 1 | F32: mmHg | G32: 29.5 | H32: 0.5 | I32: 2 | J32: 61 | K32: -1 | L32: 3
B33: Fluktuasi suhu | C33: =(MAX(C28:C29)-C30+C30-MIN(C28:C29))/2 -> 0 | D33: =(MAX(D28:D29)-D30+D30-MIN(D28:D29))/2 -> 0 | E33: =(MAX(E28:E29)-E30+E30-MIN(E28:E29))/2 -> 0 | F33: mmHg | G33: 33.8 | H33: 1.2 | I33: 2 | J33: 70 | K33: 0 | L33: 2
B34: Flu+U95 | C34: =C32+C33 -> 2 | D34: =D32+D33 -> 2.8178673 | E34: =E32+E33 -> 1 | F34: mmHg | G34: 40 | H34: 1.7 | I34: 2 | J34: 82 | K34: -2 | L34: 3
B35: Kondisi Ruang | C35: =FIXED(C31,1) & " ± "&FIXED(C33,1) -> 29,4 ± 0,0 | D35: =FIXED(D31,1) & " ± "&FIXED(D33,1) -> 59,6 ± 0,0 | E35: =FIXED(E31,0) & " ± "&FIXED(E33,0) -> 697 ± 0 | F35: mmHg

Sheet Sertifikat
A7: S E R T I F I K A T K A L I B R A S I
A8: C A L I B R A T I O N C E R T I F I C A T E
A9: =CONCATENATE("Nomor / Number : ",'FORM Baru'!AG22) -> Nomor / Number : 0021-2.2/KALIBRASI BBLM/III/2026
B14: IDENTITAS ALAT
B15: INSTRUMENT DETAILS
B17: Nama Alat | D17: : | E17: Neraca / Timbangan
B18: Instrument Name
B19: Merek | D19: : | E19: =CONCATENATE(,'U95'!C3)
B20: Brand
B21: Tipe | D21: : | E21: =CONCATENATE('U95'!C4)
B22: Type
B23: Nomor Identifikasi | D23: : | E23: ='U95'!C6 -> -
B24: Identification Number
B25: Nomor Seri | D25: : | E25: =CONCATENATE('U95'!C5)
B26: Serial Number
B27: Lain-lain | D27: : | E27: Kapasitas | G27: =CONCATENATE(":"," ",IF('U95'!C20="kg",'U95'!C7/1000,'U95'!C7)," ",'U95'!C20) -> : 200 kg
B28: Others | E28: Kecermatan | G28: =CONCATENATE(":"," ",IF('U95'!C20="kg",'U95'!E6,'U95'!E7)," ",'U95'!C20) -> : 0,01 kg
B30: IDENTITAS PEMILIK
B31: Owner’s Identification
B33: Nama | D33: : | E33: ='FORM Baru'!AG10 -> Laboratorium Geoteknik - Universitas Katolik Parahyangan
B34: Designation
B36: Alamat | D36: : | E36: ='FORM Baru'!AG11 -> Jl. Ciumbuleuit No.94, Hegarmanah, Kec. Cidadap, Kota Bandung, Jawa Barat 40141
B37: Address
G39: Halaman 1 dari 3 halaman
G40: Page of page
H42: =CONCATENATE("Diterbitkan Tanggal ",'FORM Baru'!AG25) -> Diterbitkan Tanggal 1 Maret 2026
H43: Date of Issue
F46: Ketua Tim Pengujian, Inspeksi dan Kalibrasi
F47: Mahaputra
F48: NIP. 197907232003121004
F61: Nomor | G61: =CONCATENATE(MID(A9,16,LEN(A9)-13)) -> : 0021-2.2/KALIBRASI BBLM/III/2026
F62: No. Order | G62: =CONCATENATE(":"," ",'FORM Baru'!AG9) -> : K085-9
F63: Halaman | G63: : 2 dari 3
B65: SPESIFIKASI ALAT
B66: Nama | D66: =CONCATENATE(": ",E17) -> : Neraca / Timbangan
B67: Merk / Tipe | D67: =CONCATENATE(":"," ",E19," "," / "," ",E21) -> : /
B68: No. Identifikasi | D68: =CONCATENATE(": ",E23) -> : -
B69: No. Seri | D69: =CONCATENATE(": ",E25) -> :
B70: Kapasitas | D70: =G27 -> : 200 kg
B71: Kecermatan | D71: =G28 -> : 0,01 kg | G71: Kondisi ruang
...

Sheet Database
BC2: TABEL CMC KAN | BG2: MPE OIML R111-1 | BP2: E2 | BT2: F1 | BX2: E2 METTLER TOLEDO | CB2: M1
BC3: Range 1 (g) | BD3: Range 2 (g) | BE3: CMC (mg) | BG3: Nominal Value (g) | BH3: Class E1 | BI3: Class E2 | BJ3: Class F1 | BK3: Class F2 | BL3: Class M1 | BM3: Class M2 | BN3: Class M3 | BP3: Nominal (g) | BQ3: Massa konvensional (g) | BR3: U95 (mg) | BT3: Nominal (g) | BU3: Massa konvensional (g) | BV3: U95 (mg) | BX3: Nominal (g) | BY3: Massa konvensional (g) | BZ3: U95 (mg) | CB3: Nominal (g) | CC3: Massa konvensional (g) | CD3: U95 (mg)
BC4: 0 | BD4: 250 | BE4: 0.12 | BG4: 50000 | BH4: 25 | BI4: 75 | BJ4: 250 | BK4: 750 | BL4: 2500 | BM4: 7500 | BN4: 25000 | BP4: 2000 | BQ4: 1999.9985 | BR4: 0.32 | BT4: 20000 | BU4: 20000.026 | BV4: 14 | BX4: 0.001 | BY4: 0.001003 | BZ4: 0.002 | CB4: M1 | CC4: 20000.154 | CD4: 45
BC5: 250 | BD5: 500 | BE5: 0.82 | BG5: 20000 | BH5: 10 | BI5: 30 | BJ5: 100 | BK5: 300 | BL5: 1000 | BM5: 3000 | BN5: 10000 | BP5: 1000 | BQ5: 1000.0005 | BR5: 0.14 | BT5: 10000 | BU5: 10000.041 | BV5: 6 | BX5: 0.002 | BY5: 0.002003 | BZ5: 0.002 | CB5: M2 | CC5: 19999.992 | CD5: 45
BC6: 500 | BD6: 2000 | BE6: 1.1 | BG6: 10000 | BH6: 5 | BI6: 15 | BJ6: 50 | BK6: 150 | BL6: 500 | BM6: 1500 | BN6: 5000 | BP6: 500 | BQ6: 500.00001 | BR6: 0.08 | BT6: 5000 | BU6: 5000.0163 | BV6: 2.6 | BX6: 0,002t | BY6: 0.002001 | BZ6: 0.002 | CB6: M3 | CC6: 19999.946 | CD6: 45
A7: Kalibrator | B7: Merek | C7: Nomor Seri | D7: Titik Ukur | E7: Range C.L | F7: Satuan | BC7: 2000 | BD7: 5000 | BE7: 1.7 | BG7: 5000 | BH7: 2.5 | BI7: 7.5 | BJ7: 25 | BK7: 75 | BL7: 250 | BM7: 750 | BN7: 2500 | BP7: 200 | BQ7: 200.00001 | BR7: 0.04 | BT7: 2000t | BU7: 2000.0015 | BV7: 1.4 | BX7: 0.005 | BY7: 0.005004 | BZ7: 0.002 | CB7: M4 | CC7: 20000.046 | CD7: 45
A8: E2 | B8: Kern Germany | C8: G982106 | D8: 10 Titik | E8: Sepertiga | F8: kg | I8: Database Possibility | BC8: 5000 | BD8: 10000 | BE8: 13 | BG8: 2000 | BH8: 1 | BI8: 3 | BJ8: 10 | BK8: 30 | BL8: 100 | BM8: 300 | BN8: 1000 | BP8: 200t | BQ8: 200.00005 | BR8: 0.04 | BT8: 2000 | BU8: 1999.9994 | BV8: 1.4 | BX8: 0.01 | BY8: 0.010002 | BZ8: 0.003 | CB8: M5 | CC8: 20000.032 | CD8: 45
A9: F1 | B9: YCS | C9: YCS-01-653-00 | D9: custom | E9: Setengah | F9: g | I9: Nominal (g) | J9: AT1 | K9: AT2 | L9: AT3 | M9: AT4 | N9: AT5 | O9: AT6 | P9: AT7 | Q9: AT8 | R9: AT9 | S9: AT10 | Y9: Data seleksi adjustment | BC9: 10000 | BD9: 20000 | BE9: 22 | BG9: 1000 | BH9: 0.5 | BI9: 1.5 | BJ9: 5 | BK9: 15 | BL9: 50 | BM9: 150 | BN9: 500 | BP9: 100 | BQ9: 100.00008 | BR9: 0.03 | BT9: 1000 | BU9: 1000.001 | BV9: 1.1 | BX9: 0.02 | BY9: 0.020003 | BZ9: 0.003 | CB9: M6 | CC9: 19999.95 | CD9: 45
A10: E2 METTLER TOLEDO | B10: Mettler Toledo | C10: 158856 | F10: mg | I10: 1 | J10: 1 | K10: 0 | L10: 0 | M10: 0 | N10: 0 | O10: 0 | P10: 0 | Q10: 0 | R10: 0 | S10: 0 | Y10: Nomor | Z10: AT | AA10: AT | AB10: AT | AC10: AT | AD10: AT | AE10: AT | AF10: AT | AG10: AT | AH10: AT | AI10: AT | BC10: 20000 | BD10: 50000 | BE10: 8100 | BG10: 500 | BH10: 0.25 | BI10: 0.75 | BJ10: 2.5 | BK10: 7.5 | BL10: 25 | BM10: 75 | BN10: 250 | BP10: 50 | BQ10: 50.00002 | BR10: 0.02 | BT10: 500 | BU10: 499.99861 | BV10: 1 | BX10: 0,02t | BY10: 0.020005 | BZ10: 0.003 | CB10: M7 | CC10: 19999.158 | CD10: 45
A11: M1 | B11: - | C11: - | I11: 2 | J11: 2 | K11: 0 | L11: 0 | M11: 0 | N11: 0 | O11: 0 | P11: 0 | Q11: 0 | R11: 0 | S11: 0 | Y11: 1 | Z11: =INDEX($J$9:$S$349,MATCH('U95'!$D$24,$I$9:$I$349,0),1) -> #N/A | AA11: =INDEX($J$9:$S$349,MATCH('U95'!$D$24,$I$9:$I$349,0),2) -> #N/A | AB11: =INDEX($J$9:$S$349,MATCH('U95'!$D$24,$I$9:$I$349,0),3) -> #N/A | AC11: =INDEX($J$9:$S$349,MATCH('U95'!$D$24,$I$9:$I$349,0),4) -> #N/A | AD11: =INDEX($J$9:$S$349,MATCH('U95'!$D$24,$I$9:$I$349,0),5) -> #N/A | AE11: =INDEX($J$9:$S$349,MATCH('U95'!$D$24,$I$9:$I$349,0),6) -> #N/A | AF11: =INDEX($J$9:$S$349,MATCH('U95'!$D$24,$I$9:$I$349,0),7) -> #N/A | AG11: =INDEX($J$9:$S$349,MATCH('U95'!$D$24,$I$9:$I$349,0),8) -> #N/A | AH11: =INDEX($J$9:$S$349,MATCH('U95'!$D$24,$I$9:$I$349,0),9) -> #N/A | AI11: =INDEX($J$9:$S$349,MATCH('U95'!$D$24,$I$9:$I$349,0),10) -> #N/A | BC11: 50000 | BD11: 500000 | BE11: 80000 | BG11: 200 | BH11: 0.01 | BI11: 0.3 | BJ11: 1 | BK11: 3 | BL11: 10 | BM11: 30 | BN11: 100 | BP11: 20 | BQ11: 19.999978 | BR11: 0.009 | BT11: 200 | BU11: 199.99968 | BV11: 0.11 | BX11: 0.05 | BY11: 0.050005 | BZ11: 0.003 | CB11: M8 | CC11: 19999.925 | CD11: 45
I12: 3 | J12: 1 | K12: 2 | L12: 0 | M12: 0 | N12: 0 | O12: 0 | P12: 0 | Q12: 0 | R12: 0 | S12: 0 | BG12: 100 | BH12: 0.05 | BI12: 0.15 | BJ12: 0.5 | BK12: 1.5 | BL12: 5 | BM12: 15 | BN12: 50 | BP12: 20t | BQ12: 19.999977 | BR12: 0.009 | BT12: 200t | BU12: 199.99882 | BV12: 0.11 | BX12: 0.1 | BY12: 0.100008 | BZ12: 0.003 | CB12: M9 | CC12: 19999.663 | CD12: 45
I13: 4 | J13: 2 | K13: 2 | L13: 0 | M13: 0 | N13: 0 | O13: 0 | P13: 0 | Q13: 0 | R13: 0 | S13: 0 | BG13: 50 | BH13: 0.03 | BI13: 0.1 | BJ13: 0.3 | BK13: 1 | BL13: 3 | BM13: 10 | BN13: 30 | BP13: 10 | BQ13: 9.999976 | BR13: 0.008 | BT13: 100 | BU13: 99.999763 | BV13: 0.067 | BX13: 0.2 | BY13: 0.200009 | BZ13: 0.005 | CB13: M10 | CC13: 19999.618 | CD13: 45
I14: 5 | J14: 5 | K14: 0 | L14: 0 | M14: 0 | N14: 0 | O14: 0 | P14: 0 | Q14: 0 | R14: 0 | S14: 0 | BG14: 20 | BH14: 0.025 | BI14: 0.08 | BJ14: 0.25 | BK14: 0.8 | BL14: 2.5 | BM14: 8 | BN14: 25 | BP14: 5 | BQ14: 5.000006 | BR14: 0.007 | BT14: 50 | BU14: 49.999814 | BV14: 0.042 | BX14: 0,2t | BY14: 0.200002 | BZ14: 0.005 | CB14: M11 | CC14: 19999.924 | CD14: 45
I15: 6 | J15: 5 | K15: 1 | L15: 0 | M15: 0 | N15: 0 | O15: 0 | P15: 0 | Q15: 0 | R15: 0 | S15: 0 | BG15: 10 | BH15: 0.02 | BI15: 0.06 | BJ15: 0.2 | BK15: 0.6 | BL15: 2 | BM15: 6 | BN15: 20 | BP15: 2 | BQ15: 2.000013 | BR15: 0.005 | BT15: 20 | BU15: 20.000009 | BV15: 0.036 | BX15: 0.5 | BY15: 0.500006 | BZ15: 0.006 | CB15: M12 | CC15: 19999.988 | CD15: 45
I16: 7 | J16: 5 | K16: 2 | L16: 0 | M16: 0 | N16: 0 | O16: 0 | P16: 0 | Q16: 0 | R16: 0 | S16: 0 | AP16: harus sampai 16 | BG16: 5 | BH16: 0.015 | BI16: 0.05 | BJ16: 0.15 | BK16: 0.5 | BL16: 1.5 | BM16: 5 | BN16: 15 | BP16: 2t | BQ16: 2.000015 | BR16: 0.005 | BT16: 20t | BU16: 20.000048 | BV16: 0.036 | BX16: 1 | BY16: 1.000016 | BZ16: 0.007 | CB16: M13 | CC16: 20000.776 | CD16: 45
I17: 8 | J17: 5 | K17: 2 | L17: 1 | M17: 0 | N17: 0 | O17: 0 | P17: 0 | Q17: 0 | R17: 0 | S17: 0 | U17: -------------> Realisasi Posibility | BG17: 2 | BH17: 0.012 | BI17: 0.04 | BJ17: 0.12 | BK17: 0.4 | BL17: 1.2 | BM17: 4 | BN17: 12 | BP17: 1 | BQ17: 0.999997 | BR17: 0.005 | BT17: 10 | BU17: 10.000017 | BV17: 0.032 | BX17: 2 | BY17: 1.999992 | BZ17: 0.009 | CB17: M14 | CC17: 20000.038 | CD17: 45
I18: 9 | J18: 5 | K18: 2 | L18: 2 | M18: 0 | N18: 0 | O18: 0 | P18: 0 | Q18: 0 | R18: 0 | S18: 0 | Y18: Data seleksi Titik Ukur | AL18: Transpose | BG18: 1 | BH18: 0.01 | BI18: 0.03 | BJ18: 0.1 | BK18: 0.3 | BL18: 1 | BM18: 3 | BN18: 10 | BP18: 0.5 | BQ18: 0.500018 | BR18: 0.004 | BT18: 5 | BU18: 4.99994 | BV18: 0.05 | BX18: 2t | BY18: 1.999991 | BZ18: 0.009 | CB18: M15 | CC18: 20000.134 | CD18: 45
I19: 10 | J19: 10 | K19: 0 | L19: 0 | M19: 0 | N19: 0 | O19: 0 | P19: 0 | Q19: 0 | R19: 0 | S19: 0 | Z19: 1 | AA19: 2 | AB19: 3 | AC19: 4 | AD19: 5 | AE19: 6 | AF19: 7 | AG19: 8 | AH19: 9 | AI19: 10 | BG19: 0.5 | BH19: 0.008 | BI19: 0.025 | BJ19: 0.08 | BK19: 0.25 | BL19: 0.8 | BM19: 2.5 | BN19: - | BP19: 0.2 | BQ19: 0.200013 | BR19: 0.003 | BT19: 2 | BU19: 2 | BV19: 0.04 | BX19: 5 | BY19: 0.500006 | BZ19: 0.011 | CB19: M16 | CC19: 20000.665 | CD19: 45
I20: 20 | J20: 20 | K20: 0 | L20: 0 | M20: 0 | N20: 0 | O20: 0 | P20: 0 | Q20: 0 | R20: 0 | S20: 0 | Y20: Nomor | Z20: AT | AA20: AT | AB20: AT | AC20: AT | AD20: AT | AE20: AT | AF20: AT | AG20: AT | AH20: AT | AI20: AT | AL20: AT 1 | AM20: AT 2 | AN20: AT 3 | AO20: AT 4 | AP20: AT 5 | AQ20: AT 6 | AR20: AT 7 | AS20: AT 8 | AT20: AT 9 | AU20: AT 10 | AV20: AT 11 | AW20: AT 12 | AX20: AT 13 | AY20: AT 14 | AZ20: AT 15 | BA20: AT 16 | BG20: 0.2 | BH20: 0.006 | BI20: 0.02 | BJ20: 0.06 | BK20: 0.2 | BL20: 0.6 | BM20: 2 | BN20: - | BP20: 0,2t | BQ20: 0.200015 | BR20: 0.003 | BT20: 2t | BU20: 1.99998 | BV20: 0.04 | BX20: 10 | BY20: 10.000033 | BZ20: 0.014 | CB20: 20LZ1 | CC20: 20001.643 | CD20: 45
I21: 30 | J21: 20 | K21: 10 | L21: 0 | M21: 0 | N21: 0 | O21: 0 | P21: 0 | Q21: 0 | R21: 0 | S21: 0 | Y21: 1 | Z21: {=IF('U95'!$C$19="custom", INDEX($J$9:$S$349,MATCH('U95'!$B$69,$I$9:$I$349,0),Z19), INDEX($J$9:$S$349,MATCH('U95'!$B$68,$I$9:$I$349,0),Z19))} -> 20000 | AA21: {=IF('U95'!$C$19="custom", INDEX($J$9:$S$349,MATCH('U95'!$B$69,$I$9:$I$349,0),AA19),INDEX($J$9:$S$349,MATCH('U95'!$B$68,$I$9:$I$349,0),AA19))} -> 0 | AB21: {=IF('U95'!$C$19="custom", INDEX($J$9:$S$349,MATCH('U95'!$B$69,$I$9:$I$349,0),AB19),INDEX($J$9:$S$349,MATCH('U95'!$B$68,$I$9:$I$349,0),AB19))} -> 0 | AC21: {=IF('U95'!$C$19="custom", INDEX($J$9:$S$349,MATCH('U95'!$B$69,$I$9:$I$349,0),AC19),INDEX($J$9:$S$349,MATCH('U95'!$B$68,$I$9:$I$349,0),AC19))} -> 0 | AD21: {=IF('U95'!$C$19="custom", INDEX($J$9:$S$349,MATCH('U95'!$B$69,$I$9:$I$349,0),AD19),INDEX($J$9:$S$349,MATCH('U95'!$B$68,$I$9:$I$349,0),AD19))} -> 0 | AE21: {=IF('U95'!$C$19="custom", INDEX($J$9:$S$349,MATCH('U95'!$B$69,$I$9:$I$349,0),AE19),INDEX($J$9:$S$349,MATCH('U95'!$B$68,$I$9:$I$349,0),AE19))} -> 0 | AF21: {=IF('U95'!$C$19="custom", INDEX($J$9:$S$349,MATCH('U95'!$B$69,$I$9:$I$349,0),AF19),INDEX($J$9:$S$349,MATCH('U95'!$B$68,$I$9:$I$349,0),AF19))} -> 0 | AG21: {=IF('U95'!$C$19="custom", INDEX($J$9:$S$349,MATCH('U95'!$B$69,$I$9:$I$349,0),AG19),INDEX($J$9:$S$349,MATCH('U95'!$B$68,$I$9:$I$349,0),AG19))} -> 0 | AH21: {=IF('U95'!$C$19="custom", INDEX($J$9:$S$349,MATCH('U95'!$B$69,$I$9:$I$349,0),AH19),INDEX($J$9:$S$349,MATCH('U95'!$B$68,$I$9:$I$349,0),AH19))} -> 0 | AI21: {=IF('U95'!$C$19="custom", INDEX($J$9:$S$349,MATCH('U95'!$B$69,$I$9:$I$349,0),AI19),INDEX($J$9:$S$349,MATCH('U95'!$B$68,$I$9:$I$349,0),AI19))} -> 0 | AL21: {=TRANSPOSE(Z21:AI21)} -> 20000 | AM21: {=TRANSPOSE(Z22:AI22)} -> 20000 | AN21: {=TRANSPOSE(Z23:AI23)} -> 20000 | AO21: {=TRANSPOSE(Z24:AI24)} -> 0 | AP21: {=TRANSPOSE(Z25:AI25)} -> 0 | AQ21: {=TRANSPOSE(Z26:AI26)} -> 0 | AR21: {=TRANSPOSE(Z27:AI27)} -> 0 | AS21: {=TRANSPOSE(Z28:AI28)} -> #N/A | AT21: {=TRANSPOSE(Z29:AI29)} -> #N/A | AU21: {=TRANSPOSE(Z30:AI30)} -> #N/A | AV21: {=TRANSPOSE(Z31:AI31)} -> 20000 | AW21: {=TRANSPOSE(Z32:AI32)} -> 20000 | AX21: {=TRANSPOSE($Z$33:$AI$33)} -> 20000 | AY21: {=TRANSPOSE($Z$34:$AI$34)} -> 20000 | AZ21: {=TRANSPOSE($Z$35:$AI$35)} -> 20000 | BA21: {=TRANSPOSE($Z$36:$AI$36)} -> 20000 | BG21: 0.1 | BH21: 0.005 | BI21: 0.015 | BJ21: 0.05 | BK21: 0.15 | BL21: 0.5 | BM21: 1.5 | BN21: - | BP21: 0.1 | BQ21: 0.100003 | BR21: 0.002 | BT21: 1 | BU21: 1 | BV21: 0.03 | BX21: 20 | BY21: 20.000035 | BZ21: 0.018 | CB21: 10LZ1 | CC21: 10001.52 | CD21: 26
I22: 40 | J22: 20 | K22: 20t | L22: 0 | M22: 0 | N22: 0 | O22: 0 | P22: 0 | Q22: 0 | R22: 0 | S22: 0 | Y22: =Y21+1 -> 2 | Z22: {=IF('U95'!$C$19="custom", INDEX($J$9:$S$349,MATCH('U95'!$B$73,$I$9:$I$349,0),Z19), INDEX($J$9:$S$349,MATCH('U95'!$B$72,$I$9:$I$349,0),Z19))} -> 20000 | AA22: {=IF('U95'!$C$19="custom", INDEX($J$9:$S$349,MATCH('U95'!$B$73,$I$9:$I$349,0),AA19), INDEX($J$9:$S$349,MATCH('U95'!$B$72,$I$9:$I$349,0),AA19))} -> 20000 | AB22: {=IF('U95'!$C$19="custom", INDEX($J$9:$S$349,MATCH('U95'!$B$73,$I$9:$I$349,0),AB19), INDEX($J$9:$S$349,MATCH('U95'!$B$72,$I$9:$I$349,0),AB19))} -> 0 | AC22: {=IF('U95'!$C$19="custom", INDEX($J$9:$S$349,MATCH('U95'!$B$73,$I$9:$I$349,0),AC19), INDEX($J$9:$S$349,MATCH('U95'!$B$72,$I$9:$I$349,0),AC19))} -> 0 | AD22: {=IF('U95'!$C$19="custom", INDEX($J$9:$S$349,MATCH('U95'!$B$73,$I$9:$I$349,0),AD19), INDEX($J$9:$S$349,MATCH('U95'!$B$72,$I$9:$I$349,0),AD19))} -> 0 | AE22: {=IF('U95'!$C$19="custom", INDEX($J$9:$S$349,MATCH('U95'!$B$73,$I$9:$I$349,0),AE19), INDEX($J$9:$S$349,MATCH('U95'!$B$72,$I$9:$I$349,0),AE19))} -> 0 | AF22: {=IF('U95'!$C$19="custom", INDEX($J$9:$S$349,MATCH('U95'!$B$73,$I$9:$I$349,0),AF19), INDEX($J$9:$S$349,MATCH('U95'!$B$72,$I$9:$I$349,0),AF19))} -> 0 | AG22: {=IF('U95'!$C$19="custom", INDEX($J$9:$S$349,MATCH('U95'!$B$73,$I$9:$I$349,0),AG19), INDEX($J$9:$S$349,MATCH('U95'!$B$72,$I$9:$I$349,0),AG19))} -> 0 | ... AI22: {=IF('U95'!$C$19="custom", INDEX($J$9:$S$349,MATCH('U95'!$B$73,$I$9:$I$349,0),AI19), INDEX($J$9:$S$349,MATCH('U95'!$B$72,$I$9:$I$349,0),AI19))} -> 0 | AL22: 0 | AM22: 20000 | AN22: 20000 | AO22: 0 | AP22: 0 | AQ22: 0 | AR22: 0 | AS22: #N/A | AT22: #N/A | AU22: #N/A | AV22: 0 | AW22: 0 | AX22: {=TRANSPOSE($Z$33:$AI$33)} -> 20000 | AY22: {=TRANSPOSE($Z$34:$AI$34)} -> 20000 | AZ22: {=TRANSPOSE($Z$35:$AI$35)} -> 20000 | BA22: {=TRANSPOSE($Z$36:$AI$36)} -> 20000 | BG22: 0.05 | BH22: 0.004 | BI22: 0.012 | BJ22: 0.04 | BK22: 0.12 | BL22: 0.4 | BM22: - | BN22: - | BX22: 20t | BY22: 20.000038 | BZ22: 0.018 | CB22: 5A | CC22: 4998.918 | CD22: 13.6
I23: 50 | J23: 50 | K23: 0 | L23: 0 | M23: 0 | N23: 0 | O23: 0 | P23: 0 | Q23: 0 | R23: 0 | S23: 0 | Y23: =Y22+1 -> 3 | Z23: {=IF('U95'!$C$19="custom", INDEX($J$9:$S$349,MATCH('U95'!$B$77,$I$9:$I$349,0),Z19), INDEX($J$9:$S$349,MATCH('U95'!$B$76,$I$9:$I$349,0),Z19))} -> 20000 | AA23: {=IF('U95'!$C$19="custom", INDEX($J$9:$S$349,MATCH('U95'!$B$77,$I$9:$I$349,0),AA19), INDEX($J$9:$S$349,MATCH('U95'!$B$76,$I$9:$I$349,0),AA19))} -> 20000 | AB23: {=IF('U95'!$C$19="custom", INDEX($J$9:$S$349,MATCH('U95'!$B$77,$I$9:$I$349,0),AB19), INDEX($J$9:$S$349,MATCH('U95'!$B$76,$I$9:$I$349,0),AB19))} -> 20000 | AC23: {=IF('U95'!$C$19="custom", INDEX($J$9:$S$349,MATCH('U95'!$B$77,$I$9:$I$349,0),AC19), INDEX($J$9:$S$349,MATCH('U95'!$B$76,$I$9:$I$349,0),AC19))} -> 0 | AD23: {=IF('U95'!$C$19="custom", INDEX($J$9:$S$349,MATCH('U95'!$B$77,$I$9:$I$349,0),AD19), INDEX($J$9:$S$349,MATCH('U95'!$B$76,$I$9:$I$349,0),AD19))} -> 0 | AE23: {=IF('U95'!$C$19="custom", INDEX($J$9:$S$349,MATCH('U95'!$B$77,$I$9:$I$349,0),AE19), INDEX($J$9:$S$349,MATCH('U95'!$B$76,$I$9:$I$349,0),AE19))} -> 0 | AF23: {=IF('U95'!$C$19="custom", INDEX($J$9:$S$349,MATCH('U95'!$B$77,$I$9:$I$349,0),AF19), INDEX($J$9:$S$349,MATCH('U95'!$B$76,$I$9:$I$349,0),AF19))} -> 0 | AG23: {=IF('U95'!$C$19="custom", INDEX($J$9:$S$349,MATCH('U95'!$B$77,$I$9:$I$349,0),AG19), INDEX($J$9:$S$349,MATCH('U95'!$B$76,$I$9:$I$349,0),AG19))} -> 0 | ... AI23: {=IF('U95'!$C$19="custom", INDEX($J$9:$S$349,MATCH('U95'!$B$77,$I$9:$I$349,0),AI19), INDEX($J$9:$S$349,MATCH('U95'!$B$76,$I$9:$I$349,0),AI19))} -> 0 | AL23: 0 | AM23: 0 | AN23: 20000 | AO23: 0 | AP23: 0 | AQ23: 0 | AR23: 0 | AS23: #N/A | AT23: #N/A | AU23: #N/A | AV23: 0 | AW23: 0 | AX23: {=TRANSPOSE($Z$33:$AI$33)} -> 20000 | AY23: {=TRANSPOSE($Z$34:$AI$34)} -> 20000 | AZ23: {=TRANSPOSE($Z$35:$AI$35)} -> 20000 | BA23: {=TRANSPOSE($Z$36:$AI$36)} -> 20000 | BG23: 0.02 | BH23: 0.003 | BI23: 0.01 | BJ23: 0.03 | BK23: 0.1 | BL23: 0.3 | BM23: - | BN23: - | BX23: 50 | BY23: 50.00002 | BZ23: 0.03 | CB23: 10A | CC23: 9999.404 | CD23: 26
I24: 60 | J24: 50 | K24: 10 | L24: 0 | M24: 0 | N24: 0 | O24: 0 | P24: 0 | Q24: 0 | R24: 0 | S24: 0 | Y24: =Y23+1 -> 4 | Z24: {=IF('U95'!$C$19="custom", INDEX($J$9:$S$349,MATCH('U95'!$B$81,$I$9:$I$349,0),Z19), INDEX($J$9:$S$349,MATCH('U95'!$B$80,$I$9:$I$349,0),Z19))} -> 0 | AA24: {=IF('U95'!$C$19="custom", INDEX($J$9:$S$349,MATCH('U95'!$B$81,$I$9:$I$349,0),AA19), INDEX($J$9:$S$349,MATCH('U95'!$B$80,$I$9:$I$349,0),AA19))} -> 0 | AB24: {=IF('U95'!$C$19="custom", INDEX($J$9:$S$349,MATCH('U95'!$B$81,$I$9:$I$349,0),AB19), INDEX($J$9:$S$349,MATCH('U95'!$B$80,$I$9:$I$349,0),AB19))} -> 0 | AC24: {=IF('U95'!$C$19="custom", INDEX($J$9:$S$349,MATCH('U95'!$B$81,$I$9:$I$349,0),AC19), INDEX($J$9:$S$349,MATCH('U95'!$B$80,$I$9:$I$349,0),AC19))} -> 0 | AD24: {=IF('U95'!$C$19="custom", INDEX($J$9:$S$349,MATCH('U95'!$B$81,$I$9:$I$349,0),AD19), INDEX($J$9:$S$349,MATCH('U95'!$B$80,$I$9:$I$349,0),AD19))} -> 0 | AE24: {=IF('U95'!$C$19="custom", INDEX($J$9:$S$349,MATCH('U95'!$B$81,$I$9:$I$349,0),AE19), INDEX($J$9:$S$349,MATCH('U95'!$B$80,$I$9:$I$349,0),AE19))} -> 0 | AF24: {=IF('U95'!$C$19="custom", INDEX($J$9:$S$349,MATCH('U95'!$B$81,$I$9:$I$349,0),AF19), INDEX($J$9:$S$349,MATCH('U95'!$B$80,$I$9:$I$349,0),AF19))} -> 0 | AG24: {=IF('U95'!$C$19="custom", INDEX($J$9:$S$349,MATCH('U95'!$B$81,$I$9:$I$349,0),AG19), INDEX($J$9:$S$349,MATCH('U95'!$B$80,$I$9:$I$349,0),AG19))} -> 0 | ... AI24: {=IF('U95'!$C$19="custom", INDEX($J$9:$S$349,MATCH('U95'!$B$81,$I$9:$I$349,0),AI19), INDEX($J$9:$S$349,MATCH('U95'!$B$80,$I$9:$I$349,0),AI19))} -> 0 | AL24: 0 | AM24: 0 | AN24: 0 | AO24: 0 | AP24: 0 | AQ24: 0 | AR24: 0 | AS24: #N/A | AT24: #N/A | AU24: #N/A | AV24: 0 | AW24: 0 | AX24: {=TRANSPOSE($Z$33:$AI$33)} -> 20000 | AY24: {=TRANSPOSE($Z$34:$AI$34)} -> 20000 | AZ24: {=TRANSPOSE($Z$35:$AI$35)} -> 20000 | BA24: {=TRANSPOSE($Z$36:$AI$36)} -> 20000 | BG24: 0.01 | BH24: 0.002 | BI24: 0.008 | BJ24: 0.025 | BK24: 0.08 | BL24: 0.25 | BM24: - | BN24: - | BX24: 100 | BY24: 100.00029 | BZ24: 0.05 | CB24: A | CC24: 19999.366 | CD24: 45
I25: 70 | J25: 50 | K25: 20 | L25: 0 | M25: 0 | N25: 0 | O25: 0 | P25: 0 | Q25: 0 | R25: 0 | S25: 0 | Y25: =Y24+1 -> 5 | Z25: {=IF('U95'!$C$19="custom", INDEX($J$9:$S$349,MATCH('U95'!$B$85,$I$9:$I$349,0),Z19), INDEX($J$9:$S$349,MATCH('U95'!$B$84,$I$9:$I$349,0),Z19))} -> 0 | AA25: {=IF('U95'!$C$19="custom", INDEX($J$9:$S$349,MATCH('U95'!$B$85,$I$9:$I$349,0),AA19), INDEX($J$9:$S$349,MATCH('U95'!$B$84,$I$9:$I$349,0),AA19))} -> 0 | AB25: {=IF('U95'!$C$19="custom", INDEX($J$9:$S$349,MATCH('U95'!$B$85,$I$9:$I$349,0),AB19), INDEX($J$9:$S$349,MATCH('U95'!$B$84,$I$9:$I$349,0),AB19))} -> 0 | AC25: {=IF('U95'!$C$19="custom", INDEX($J$9:$S$349,MATCH('U95'!$B$85,$I$9:$I$349,0),AC19), INDEX($J$9:$S$349,MATCH('U95'!$B$84,$I$9:$I$349,0),AC19))} -> 0 | AD25: {=IF('U95'!$C$19="custom", INDEX($J$9:$S$349,MATCH('U95'!$B$85,$I$9:$I$349,0),AD19), INDEX($J$9:$S$349,MATCH('U95'!$B$84,$I$9:$I$349,0),AD19))} -> 0 | AE25: {=IF('U95'!$C$19="custom", INDEX($J$9:$S$349,MATCH('U95'!$B$85,$I$9:$I$349,0),AE19), INDEX($J$9:$S$349,MATCH('U95'!$B$84,$I$9:$I$349,0),AE19))} -> 0 | AF25: {=IF('U95'!$C$19="custom", INDEX($J$9:$S$349,MATCH('U95'!$B$85,$I$9:$I$349,0),AF19), INDEX($J$9:$S$349,MATCH('U95'!$B$84,$I$9:$I$349,0),AF19))} -> 0 | AG25: {=IF('U95'!$C$19="custom", INDEX($J$9:$S$349,MATCH('U95'!$B$85,$I$9:$I$349,0),AG19), INDEX($J$9:$S$349,MATCH('U95'!$B$84,$I$9:$I$349,0),AG19))} -> 0 | ... AI25: {=IF('U95'!$C$19="custom", INDEX($J$9:$S$349,MATCH('U95'!$B$85,$I$9:$I$349,0),AI19), INDEX($J$9:$S$349,MATCH('U95'!$B$84,$I$9:$I$349,0),AI19))} -> 0 | AL25: 0 | AM25: 0 | AN25: 0 | AO25: 0 | AP25: 0 | AQ25: 0 | AR25: 0 | AS25: #N/A | AT25: #N/A | AU25: #N/A | AV25: 0 | AW25: 0 | AX25: {=TRANSPOSE($Z$33:$AI$33)} -> 20000 | AY25: {=TRANSPOSE($Z$34:$AI$34)} -> 20000 | AZ25: {=TRANSPOSE($Z$35:$AI$35)} -> 20000 | BA25: {=TRANSPOSE($Z$36:$AI$36)} -> 20000 | BG25: 0.005 | BH25: 0.002 | BI25: 0.006 | BJ25: 0.02 | BK25: 0.06 | BL25: 0.2 | BM25: - | BN25: - | BX25: 200 | BY25: 200.00025 | BZ25: 0.08 | CB25: B | CC25: 19999.188 | CD25: 45
I26: 80 | J26: 50 | K26: 20 | L26: 10 | M26: 0 | N26: 0 | O26: 0 | P26: 0 | Q26: 0 | R26: 0 | S26: 0 | Y26: =Y25+1 -> 6 | Z26: {=IF('U95'!$C$19="custom", INDEX($J$9:$S$349,MATCH('U95'!$B$89,$I$9:$I$349,0),Z19), INDEX($J$9:$S$349,MATCH('U95'!$B$88,$I$9:$I$349,0),Z19))} -> 0 | AA26: {=IF('U95'!$C$19="custom", INDEX($J$9:$S$349,MATCH('U95'!$B$89,$I$9:$I$349,0),AA19), INDEX($J$9:$S$349,MATCH('U95'!$B$88,$I$9:$I$349,0),AA19))} -> 0 | AB26: {=IF('U95'!$C$19="custom", INDEX($J$9:$S$349,MATCH('U95'!$B$89,$I$9:$I$349,0),AB19), INDEX($J$9:$S$349,MATCH('U95'!$B$88,$I$9:$I$349,0),AB19))} -> 0 | AC26: {=IF('U95'!$C$19="custom", INDEX($J$9:$S$349,MATCH('U95'!$B$89,$I$9:$I$349,0),AC19), INDEX($J$9:$S$349,MATCH('U95'!$B$88,$I$9:$I$349,0),AC19))} -> 0 | AD26: {=IF('U95'!$C$19="custom", INDEX($J$9:$S$349,MATCH('U95'!$B$89,$I$9:$I$349,0),AD19), INDEX($J$9:$S$349,MATCH('U95'!$B$88,$I$9:$I$349,0),AD19))} -> 0 | AE26: {=IF('U95'!$C$19="custom", INDEX($J$9:$S$349,MATCH('U95'!$B$89,$I$9:$I$349,0),AE19), INDEX($J$9:$S$349,MATCH('U95'!$B$88,$I$9:$I$349,0),AE19))} -> 0 | AF26: {=IF('U95'!$C$19="custom", INDEX($J$9:$S$349,MATCH('U95'!$B$89,$I$9:$I$349,0),AF19), INDEX($J$9:$S$349,MATCH('U95'!$B$88,$I$9:$I$349,0),AF19))} -> 0 | AG26: {=IF('U95'!$C$19="custom", INDEX($J$9:$S$349,MATCH('U95'!$B$89,$I$9:$I$349,0),AG19), INDEX($J$9:$S$349,MATCH('U95'!$B$88,$I$9:$I$349,0),AG19))} -> 0 | ... AI26: {=IF('U95'!$C$19="custom", INDEX($J$9:$S$349,MATCH('U95'!$B$89,$I$9:$I$349,0),AI19), INDEX($J$9:$S$349,MATCH('U95'!$B$88,$I$9:$I$349,0),AI19))} -> 0 | AL26: 0 | AM26: 0 | AN26: 0 | AO26: 0 | AP26: 0 | AQ26: 0 | AR26: 0 | AS26: #N/A | AT26: #N/A | AU26: #N/A | AV26: 0 | AW26: 0 | AX26: {=TRANSPOSE($Z$33:$AI$33)} -> 20000 | AY26: {=TRANSPOSE($Z$34:$AI$34)} -> 20000 | AZ26: {=TRANSPOSE($Z$35:$AI$35)} -> 20000 | BA26: {=TRANSPOSE($Z$36:$AI$36)} -> 20000 | BG26: 0.002 | BH26: 0.002 | BI26: 0.006 | BJ26: 0.02 | BK26: 0.06 | BL26: 0.2 | BM26: - | BN26: - | BX26: 200t | BY26: 200.00025 | BZ26: 0.08 | CB26: C | CC26: 19999.021 | CD26: 45
I27: 90 | J27: 50 | K27: 20 | L27: 20t | M27: 0 | N27: 0 | O27: 0 | P27: 0 | Q27: 0 | R27: 0 | S27: 0 | Y27: =Y26+1 -> 7 | Z27: {=IF('U95'!$C$19="custom", INDEX($J$9:$S$349,MATCH('U95'!$B$93,$I$9:$I$349,0),Z19), INDEX($J$9:$S$349,MATCH('U95'!$B$92,$I$9:$I$349,0),Z19))} -> 0 | AA27: {=IF('U95'!$C$19="custom", INDEX($J$9:$S$349,MATCH('U95'!$B$93,$I$9:$I$349,0),AA19), INDEX($J$9:$S$349,MATCH('U95'!$B$92,$I$9:$I$349,0),AA19))} -> 0 | AB27: {=IF('U95'!$C$19="custom", INDEX($J$9:$S$349,MATCH('U95'!$B$93,$I$9:$I$349,0),AB19), INDEX($J$9:$S$349,MATCH('U95'!$B$92,$I$9:$I$349,0),AB19))} -> 0 | AC27: {=IF('U95'!$C$19="custom", INDEX($J$9:$S$349,MATCH('U95'!$B$93,$I$9:$I$349,0),AC19), INDEX($J$9:$S$349,MATCH('U95'!$B$92,$I$9:$I$349,0),AC19))} -> 0 | AD27: {=IF('U95'!$C$19="custom", INDEX($J$9:$S$349,MATCH('U95'!$B$93,$I$9:$I$349,0),AD19), INDEX($J$9:$S$349,MATCH('U95'!$B$92,$I$9:$I$349,0),AD19))} -> 0 | AE27: {=IF('U95'!$C$19="custom", INDEX($J$9:$S$349,MATCH('U95'!$B$93,$I$9:$I$349,0),AE19), INDEX($J$9:$S$349,MATCH('U95'!$B$92,$I$9:$I$349,0),AE19))} -> 0 | AF27: {=IF('U95'!$C$19="custom", INDEX($J$9:$S$349,MATCH('U95'!$B$93,$I$9:$I$349,0),AF19), INDEX($J$9:$S$349,MATCH('U95'!$B$92,$I$9:$I$349,0),AF19))} -> 0 | AG27: {=IF('U95'!$C$19="custom", INDEX($J$9:$S$349,MATCH('U95'!$B$93,$I$9:$I$349,0),AG19), INDEX($J$9:$S$349,MATCH('U95'!$B$92,$I$9:$I$349,0),AG19))} -> 0 | ... AI27: {=IF('U95'!$C$19="custom", INDEX($J$9:$S$349,MATCH('U95'!$B$93,$I$9:$I$349,0),AI19), INDEX($J$9:$S$349,MATCH('U95'!$B$92,$I$9:$I$349,0),AI19))} -> 0 | AL27: 0 | AM27: 0 | AN27: 0 | AO27: 0 | AP27: 0 | AQ27: 0 | AR27: 0 | AS27: #N/A | AT27: #N/A | AU27: #N/A | AV27: 0 | AW27: 0 | AX27: {=TRANSPOSE($Z$33:$AI$33)} -> 20000 | AY27: {=TRANSPOSE($Z$34:$AI$34)} -> 20000 | AZ27: {=TRANSPOSE($Z$35:$AI$35)} -> 20000 | BA27: {=TRANSPOSE($Z$36:$AI$36)} -> 20000 | BG27: 0.001 | BH27: 0.002 | BI27: 0.006 | BJ27: 0.02 | BK27: 0.06 | BL27: 0.2 | BM27: - | BN27: - | BX27: 500 | BY27: 500.00075 | BZ27: 0.16 | CB27: D | CC27: 19999.273 | CD27: 45
I28: 100 | J28: 100 | K28: 0 | L28: 0 | M28: 0 | N28: 0 | O28: 0 | P28: 0 | Q28: 0 | R28: 0 | S28: 0 | Y28: =Y27+1 -> 8 | Z28: {=IF('U95'!$C$19="custom", INDEX($J$9:$S$349,MATCH('U95'!$B$97,$I$9:$I$349,0),Z19), INDEX($J$9:$S$349,MATCH('U95'!$B$96,$I$9:$I$349,0),Z19))} -> #N/A | AA28: {=IF('U95'!$C$19="custom", INDEX($J$9:$S$349,MATCH('U95'!$B$97,$I$9:$I$349,0),AA19), INDEX($J$9:$S$349,MATCH('U95'!$B$96,$I$9:$I$349,0),AA19))} -> #N/A | AB28: {=IF('U95'!$C$19="custom", INDEX($J$9:$S$349,MATCH('U95'!$B$97,$I$9:$I$349,0),AB19), INDEX($J$9:$S$349,MATCH('U95'!$B$96,$I$9:$I$349,0),AB19))} -> #N/A | AC28: {=IF('U95'!$C$19="custom", INDEX($J$9:$S$349,MATCH('U95'!$B$97,$I$9:$I$349,0),AC19), INDEX($J$9:$S$349,MATCH('U95'!$B$96,$I$9:$I$349,0),AC19))} -> #N/A | AD28: {=IF('U95'!$C$19="custom", INDEX($J$9:$S$349,MATCH('U95'!$B$97,$I$9:$I$349,0),AD19), INDEX($J$9:$S$349,MATCH('U95'!$B$96,$I$9:$I$349,0),AD19))} -> #N/A | AE28: {=IF('U95'!$C$19="custom", INDEX($J$9:$S$349,MATCH('U95'!$B$97,$I$9:$I$349,0),AE19), INDEX($J$9:$S$349,MATCH('U95'!$B$96,$I$9:$I$349,0),AE19))} -> #N/A | AF28: {=IF('U95'!$C$19="custom", INDEX($J$9:$S$349,MATCH('U95'!$B$97,$I$9:$I$349,0),AF19), INDEX($J$9:$S$349,MATCH('U95'!$B$96,$I$9:$I$349,0),AF19))} -> #N/A | AG28: {=IF('U95'!$C$19="custom", INDEX($J$9:$S$349,MATCH('U95'!$B$97,$I$9:$I$349,0),AG19), INDEX($J$9:$S$349,MATCH('U95'!$B$96,$I$9:$I$349,0),AG19))} -> #N/A | ... AI28: {=IF('U95'!$C$19="custom", INDEX($J$9:$S$349,MATCH('U95'!$B$97,$I$9:$I$349,0),AI19), INDEX($J$9:$S$349,MATCH('U95'!$B$96,$I$9:$I$349,0),AI19))} -> #N/A | AL28: 0 | AM28: 0 | AN28: 0 | AO28: 0 | AP28: 0 | AQ28: 0 | AR28: 0 | AS28: #N/A | AT28: #N/A | AU28: #N/A | AV28: 0 | AW28: 0 | AX28: {=TRANSPOSE($Z$33:$AI$33)} -> 20000 | AY28: {=TRANSPOSE($Z$34:$AI$34)} -> 20000 | AZ28: {=TRANSPOSE($Z$35:$AI$35)} -> 20000 | BA28: {=TRANSPOSE($Z$36:$AI$36)} -> 20000 | BX28: 1000 | BY28: 1000.0009 | BZ28: 0.16 | CB28: E | CC28: 19999.15 | CD28: 45
I29: 110 | J29: 100 | K29: 10 | L29: 0 | M29: 0 | N29: 0 | O29: 0 | P29: 0 | Q29: 0 | R29: 0 | S29: 0 | Y29: =Y28+1 -> 9 | Z29: {=IF('U95'!$C$19="custom", INDEX($J$9:$S$349,MATCH('U95'!$B$101,$I$9:$I$349,0),Z19), INDEX($J$9:$S$349,MATCH('U95'!$B$100,$I$9:$I$349,0),Z19))} -> #N/A | AA29: {=IF('U95'!$C$19="custom", INDEX($J$9:$S$349,MATCH('U95'!$B$101,$I$9:$I$349,0),AA19), INDEX($J$9:$S$349,MATCH('U95'!$B$100,$I$9:$I$349,0),AA19))} -> #N/A | AB29: {=IF('U95'!$C$19="custom", INDEX($J$9:$S$349,MATCH('U95'!$B$101,$I$9:$I$349,0),AB19), INDEX($J$9:$S$349,MATCH('U95'!$B$100,$I$9:$I$349,0),AB19))} -> #N/A | AC29: {=IF('U95'!$C$19="custom", INDEX($J$9:$S$349,MATCH('U95'!$B$101,$I$9:$I$349,0),AC19), INDEX($J$9:$S$349,MATCH('U95'!$B$100,$I$9:$I$349,0),AC19))} -> #N/A | AD29: {=IF('U95'!$C$19="custom", INDEX($J$9:$S$349,MATCH('U95'!$B$101,$I$9:$I$349,0),AD19), INDEX($J$9:$S$349,MATCH('U95'!$B$100,$I$9:$I$349,0),AD19))} -> #N/A | AE29: {=IF('U95'!$C$19="custom", INDEX($J$9:$S$349,MATCH('U95'!$B$101,$I$9:$I$349,0),AE19), INDEX($J$9:$S$349,MATCH('U95'!$B$100,$I$9:$I$349,0),AE19))} -> #N/A | AF29: {=IF('U95'!$C$19="custom", INDEX($J$9:$S$349,MATCH('U95'!$B$101,$I$9:$I$349,0),AF19), INDEX($J$9:$S$349,MATCH('U95'!$B$100,$I$9:$I$349,0),AF19))} -> #N/A | AG29: {=IF('U95'!$C$19="custom", INDEX($J$9:$S$349,MATCH('U95'!$B$101,$I$9:$I$349,0),AG19), INDEX($J$9:$S$349,MATCH('U95'!$B$100,$I$9:$I$349,0),AG19))} -> #N/A | ... AI29: {=IF('U95'!$C$19="custom", INDEX($J$9:$S$349,MATCH('U95'!$B$101,$I$9:$I$349,0),AI19), INDEX($J$9:$S$349,MATCH('U95'!$B$100,$I$9:$I$349,0),AI19))} -> #N/A | AL29: 0 | AM29: 0 | AN29: 0 | AO29: 0 | AP29: 0 | AQ29: 0 | AR29: 0 | AS29: #N/A | AT29: #N/A | AU29: #N/A | AV29: 0 | AW29: 0 | AX29: {=TRANSPOSE($Z$33:$AI$33)} -> 20000 | AY29: {=TRANSPOSE($Z$34:$AI$34)} -> 20000 | AZ29: {=TRANSPOSE($Z$35:$AI$35)} -> 20000 | BA29: {=TRANSPOSE($Z$36:$AI$36)} -> 20000 | CB29: F | CC29: 19999.731 | CD29: 45
I30: 120 | J30: 100 | K30: 20 | L30: 0 | M30: 0 | N30: 0 | O30: 0 | P30: 0 | Q30: 0 | R30: 0 | S30: 0 | Y30: =Y29+1 -> 10 | Z30: {=IF('U95'!$C$19="custom", INDEX($J$9:$S$349,MATCH('U95'!$B$105,$I$9:$I$349,0),Z19), INDEX($J$9:$S$349,MATCH('U95'!$B$104,$I$9:$I$349,0),Z19))} -> #N/A | AA30: {=IF('U95'!$C$19="custom", INDEX($J$9:$S$349,MATCH('U95'!$B$105,$I$9:$I$349,0),AA19), INDEX($J$9:$S$349,MATCH('U95'!$B$104,$I$9:$I$349,0),AA19))} -> #N/A | AB30: {=IF('U95'!$C$19="custom", INDEX($J$9:$S$349,MATCH('U95'!$B$105,$I$9:$I$349,0),AB19), INDEX($J$9:$S$349,MATCH('U95'!$B$104,$I$9:$I$349,0),AB19))} -> #N/A | AC30: {=IF('U95'!$C$19="custom", INDEX($J$9:$S$349,MATCH('U95'!$B$105,$I$9:$I$349,0),AC19), INDEX($J$9:$S$349,MATCH('U95'!$B$104,$I$9:$I$349,0),AC19))} -> #N/A | AD30: {=IF('U95'!$C$19="custom", INDEX($J$9:$S$349,MATCH('U95'!$B$105,$I$9:$I$349,0),AD19), INDEX($J$9:$S$349,MATCH('U95'!$B$104,$I$9:$I$349,0),AD19))} -> #N/A | AE30: {=IF('U95'!$C$19="custom", INDEX($J$9:$S$349,MATCH('U95'!$B$105,$I$9:$I$349,0),AE19), INDEX($J$9:$S$349,MATCH('U95'!$B$104,$I$9:$I$349,0),AE19))} -> #N/A | AF30: {=IF('U95'!$C$19="custom", INDEX($J$9:$S$349,MATCH('U95'!$B$105,$I$9:$I$349,0),AF19), INDEX($J$9:$S$349,MATCH('U95'!$B$104,$I$9:$I$349,0),AF19))} -> #N/A | AG30: {=IF('U95'!$C$19="custom", INDEX($J$9:$S$349,MATCH('U95'!$B$105,$I$9:$I$349,0),AG19), INDEX($J$9:$S$349,MATCH('U95'!$B$104,$I$9:$I$349,0),AG19))} -> #N/A | ... AI30: {=IF('U95'!$C$19="custom", INDEX($J$9:$S$349,MATCH('U95'!$B$105,$I$9:$I$349,0),AI19), INDEX($J$9:$S$349,MATCH('U95'!$B$104,$I$9:$I$349,0),AI19))} -> #N/A | AL30: 0 | AM30: 0 | AN30: 0 | AO30: 0 | AP30: 0 | AQ30: 0 | AR30: 0 | AS30: #N/A | AT30: #N/A | AU30: #N/A | AV30: 0 | AW30: 0 | AX30: {=TRANSPOSE($Z$33:$AI$33)} -> 20000 | AY30: {=TRANSPOSE($Z$34:$AI$34)} -> 20000 | AZ30: {=TRANSPOSE($Z$35:$AI$35)} -> 20000 | BA30: {=TRANSPOSE($Z$36:$AI$36)} -> 20000 | CB30: G | CC30: 19999.555 | CD30: 45
I31: 130 | J31: 100 | K31: 20 | L31: 10 | M31: 0 | N31: 0 | O31: 0 | P31: 0 | Q31: 0 | R31: 0 | S31: 0 | Y31: =Y30+1 -> 11 | Z31: {=IF('U95'!$C$19="custom", INDEX($J$9:$S$349,MATCH('U95'!$B$109,$I$9:$I$349,0),Z19), INDEX($J$9:$S$349,MATCH('U95'!$B$108,$I$9:$I$349,0),Z19))} -> 20000 | AA31: {=IF('U95'!$C$19="custom", INDEX($J$9:$S$349,MATCH('U95'!$B$109,$I$9:$I$349,0),AA19), INDEX($J$9:$S$349,MATCH('U95'!$B$108,$I$9:$I$349,0),AA19))} -> 0 | AB31: {=IF('U95'!$C$19="custom", INDEX($J$9:$S$349,MATCH('U95'!$B$109,$I$9:$I$349,0),AB19), INDEX($J$9:$S$349,MATCH('U95'!$B$108,$I$9:$I$349,0),AB19))} -> 0 | AC31: {=IF('U95'!$C$19="custom", INDEX($J$9:$S$349,MATCH('U95'!$B$109,$I$9:$I$349,0),AC19), INDEX($J$9:$S$349,MATCH('U95'!$B$108,$I$9:$I$349,0),AC19))} -> 0 | AD31: {=IF('U95'!$C$19="custom", INDEX($J$9:$S$349,MATCH('U95'!$B$109,$I$9:$I$349,0),AD19), INDEX($J$9:$S$349,MATCH('U95'!$B$108,$I$9:$I$349,0),AD19))} -> 0 | AE31: {=IF('U95'!$C$19="custom", INDEX($J$9:$S$349,MATCH('U95'!$B$109,$I$9:$I$349,0),AE19), INDEX($J$9:$S$349,MATCH('U95'!$B$108,$I$9:$I$349,0),AE19))} -> 0 | AF31: {=IF('U95'!$C$19="custom", INDEX($J$9:$S$349,MATCH('U95'!$B$109,$I$9:$I$349,0),AF19), INDEX($J$9:$S$349,MATCH('U95'!$B$108,$I$9:$I$349,0),AF19))} -> 0 | AG31: {=IF('U95'!$C$19="custom", INDEX($J$9:$S$349,MATCH('U95'!$B$109,$I$9:$I$349,0),AG19), INDEX($J$9:$S$349,MATCH('U95'!$B$108,$I$9:$I$349,0),AG19))} -> 0 | ... AI31: {=IF('U95'!$C$19="custom", INDEX($J$9:$S$349,MATCH('U95'!$B$109,$I$9:$I$349,0),AI19), INDEX($J$9:$S$349,MATCH('U95'!$B$108,$I$9:$I$349,0),AI19))} -> 0 | CB31: H | CC31: 19999.732 | CD31: 45
I32: 140 | J32: 100 | K32: 20 | L32: 20t | M32: 0 | N32: 0 | O32: 0 | P32: 0 | Q32: 0 | R32: 0 | S32: 0 | Y32: =Y31+1 -> 12 | Z32: {=IF('U95'!$C$19="custom", INDEX($J$9:$S$349,MATCH('U95'!$B$113,$I$9:$I$349,0),Z19), INDEX($J$9:$S$349,MATCH('U95'!$B$112,$I$9:$I$349,0),Z19))} -> 20000 | AA32: {=IF('U95'!$C$19="custom", INDEX($J$9:$S$349,MATCH('U95'!$B$113,$I$9:$I$349,0),AA19), INDEX($J$9:$S$349,MATCH('U95'!$B$112,$I$9:$I$349,0),AA19))} -> 0 | AB32: {=IF('U95'!$C$19="custom", INDEX($J$9:$S$349,MATCH('U95'!$B$113,$I$9:$I$349,0),AB19), INDEX($J$9:$S$349,MATCH('U95'!$B$112,$I$9:$I$349,0),AB19))} -> 0 | AC32: {=IF('U95'!$C$19="custom", INDEX($J$9:$S$349,MATCH('U95'!$B$113,$I$9:$I$349,0),AC19), INDEX($J$9:$S$349,MATCH('U95'!$B$112,$I$9:$I$349,0),AC19))} -> 0 | AD32: {=IF('U95'!$C$19="custom", INDEX($J$9:$S$349,MATCH('U95'!$B$113,$I$9:$I$349,0),AD19), INDEX($J$9:$S$349,MATCH('U95'!$B$112,$I$9:$I$349,0),AD19))} -> 0 | AE32: {=IF('U95'!$C$19="custom", INDEX($J$9:$S$349,MATCH('U95'!$B$113,$I$9:$I$349,0),AE19), INDEX($J$9:$S$349,MATCH('U95'!$B$112,$I$9:$I$349,0),AE19))} -> 0 | AF32: {=IF('U95'!$C$19="custom", INDEX($J$9:$S$349,MATCH('U95'!$B$113,$I$9:$I$349,0),AF19), INDEX($J$9:$S$349,MATCH('U95'!$B$112,$I$9:$I$349,0),AF19))} -> 0 | AG32: {=IF('U95'!$C$19="custom", INDEX($J$9:$S$349,MATCH('U95'!$B$113,$I$9:$I$349,0),AG19), INDEX($J$9:$S$349,MATCH('U95'!$B$112,$I$9:$I$349,0),AG19))} -> 0 | ... AI32: {=IF('U95'!$C$19="custom", INDEX($J$9:$S$349,MATCH('U95'!$B$113,$I$9:$I$349,0),AI19), INDEX($J$9:$S$349,MATCH('U95'!$B$112,$I$9:$I$349,0),AI19))} -> 0 | CB32: I | CC32: 19999.123 | CD32: 45
I33: 150 | J33: 100 | K33: 50 | L33: 0 | M33: 0 | N33: 0 | O33: 0 | P33: 0 | Q33: 0 | R33: 0 | S33: 0 | Y33: =Y32+1 -> 13 | Z33: {=IF('U95'!$C$19="custom", INDEX($J$9:$S$349,MATCH('U95'!$B$117,$I$9:$I$349,0),Z19), INDEX($J$9:$S$349,MATCH('U95'!$B$116,$I$9:$I$349,0),Z19))} -> 20000 | AA33: {=IF('U95'!$C$19="custom", INDEX($J$9:$S$349,MATCH('U95'!$B$117,$I$9:$I$349,0),AA19), INDEX($J$9:$S$349,MATCH('U95'!$B$116,$I$9:$I$349,0),AA19))} -> 0 | AB33: {=IF('U95'!$C$19="custom", INDEX($J$9:$S$349,MATCH('U95'!$B$117,$I$9:$I$349,0),AB19), INDEX($J$9:$S$349,MATCH('U95'!$B$116,$I$9:$I$349,0),AB19))} -> 0 | AC33: {=IF('U95'!$C$19="custom", INDEX($J$9:$S$349,MATCH('U95'!$B$117,$I$9:$I$349,0),AC19), INDEX($J$9:$S$349,MATCH('U95'!$B$116,$I$9:$I$349,0),AC19))} -> 0 | AD33: {=IF('U95'!$C$19="custom", INDEX($J$9:$S$349,MATCH('U95'!$B$117,$I$9:$I$349,0),AD19), INDEX($J$9:$S$349,MATCH('U95'!$B$116,$I$9:$I$349,0),AD19))} -> 0 | AE33: {=IF('U95'!$C$19="custom", INDEX($J$9:$S$349,MATCH('U95'!$B$117,$I$9:$I$349,0),AE19), INDEX($J$9:$S$349,MATCH('U95'!$B$116,$I$9:$I$349,0),AE19))} -> 0 | AF33: {=IF('U95'!$C$19="custom", INDEX($J$9:$S$349,MATCH('U95'!$B$117,$I$9:$I$349,0),AF19), INDEX($J$9:$S$349,MATCH('U95'!$B$116,$I$9:$I$349,0),AF19))} -> 0 | AG33: {=IF('U95'!$C$19="custom", INDEX($J$9:$S$349,MATCH('U95'!$B$117,$I$9:$I$349,0),AG19), INDEX($J$9:$S$349,MATCH('U95'!$B$116,$I$9:$I$349,0),AG19))} -> 0 | ... AI33: {=IF('U95'!$C$19="custom", INDEX($J$9:$S$349,MATCH('U95'!$B$117,$I$9:$I$349,0),AI19), INDEX($J$9:$S$349,MATCH('U95'!$B$116,$I$9:$I$349,0),AI19))} -> 0 | CB33: 0 | CC33: 0 | CD33: 0
I34: 160 | J34: 100 | K34: 50 | L34: 10 | M34: 0 | N34: 0 | O34: 0 | P34: 0 | Q34: 0 | R34: 0 | S34: 0 | Y34: =Y33+1 -> 14 | Z34: {=IF('U95'!$C$19="custom", INDEX($J$9:$S$349,MATCH('U95'!$B$121,$I$9:$I$349,0),Z19), INDEX($J$9:$S$349,MATCH('U95'!$B$120,$I$9:$I$349,0),Z19))} -> 20000 | AA34: {=IF('U95'!$C$19="custom", INDEX($J$9:$S$349,MATCH('U95'!$B$121,$I$9:$I$349,0),AA19), INDEX($J$9:$S$349,MATCH('U95'!$B$120,$I$9:$I$349,0),AA19))} -> 0 | AB34: {=IF('U95'!$C$19="custom", INDEX($J$9:$S$349,MATCH('U95'!$B$121,$I$9:$I$349,0),AB19), INDEX($J$9:$S$349,MATCH('U95'!$B$120,$I$9:$I$349,0),AB19))} -> 0 | AC34: {=IF('U95'!$C$19="custom", INDEX($J$9:$S$349,MATCH('U95'!$B$121,$I$9:$I$349,0),AC19), INDEX($J$9:$S$349,MATCH('U95'!$B$120,$I$9:$I$349,0),AC19))} -> 0 | AD34: {=IF('U95'!$C$19="custom", INDEX($J$9:$S$349,MATCH('U95'!$B$121,$I$9:$I$349,0),AD19), INDEX($J$9:$S$349,MATCH('U95'!$B$120,$I$9:$I$349,0),AD19))} -> 0 | AE34: {=IF('U95'!$C$19="custom", INDEX($J$9:$S$349,MATCH('U95'!$B$121,$I$9:$I$349,0),AE19), INDEX($J$9:$S$349,MATCH('U95'!$B$120,$I$9:$I$349,0),AE19))} -> 0 | AF34: {=IF('U95'!$C$19="custom", INDEX($J$9:$S$349,MATCH('U95'!$B$121,$I$9:$I$349,0),AF19), INDEX($J$9:$S$349,MATCH('U95'!$B$120,$I$9:$I$349,0),AF19))} -> 0 | AG34: {=IF('U95'!$C$19="custom", INDEX($J$9:$S$349,MATCH('U95'!$B$121,$I$9:$I$349,0),AG19), INDEX($J$9:$S$349,MATCH('U95'!$B$120,$I$9:$I$349,0),AG19))} -> 0 | ... AI34: {=IF('U95'!$C$19="custom", INDEX($J$9:$S$349,MATCH('U95'!$B$121,$I$9:$I$349,0),AI19), INDEX($J$9:$S$349,MATCH('U95'!$B$120,$I$9:$I$349,0),AI19))} -> 0
I35: 170 | J35: 100 | K35: 50 | L35: 20 | M35: 0 | N35: 0 | O35: 0 | P35: 0 | Q35: 0 | R35: 0 | S35: 0 | Y35: =Y34+1 -> 15 | Z35: {=IF('U95'!$C$19="custom", INDEX($J$9:$S$349,MATCH('U95'!$B$125,$I$9:$I$349,0),Z19), INDEX($J$9:$S$349,MATCH('U95'!$B$124,$I$9:$I$349,0),Z19))} -> 20000 | AA35: {=IF('U95'!$C$19="custom", INDEX($J$9:$S$349,MATCH('U95'!$B$125,$I$9:$I$349,0),AA19), INDEX($J$9:$S$349,MATCH('U95'!$B$124,$I$9:$I$349,0),AA19))} -> 0 | AB35: {=IF('U95'!$C$19="custom", INDEX($J$9:$S$349,MATCH('U95'!$B$125,$I$9:$I$349,0),AB19), INDEX($J$9:$S$349,MATCH('U95'!$B$124,$I$9:$I$349,0),AB19))} -> 0 | AC35: {=IF('U95'!$C$19="custom", INDEX($J$9:$S$349,MATCH('U95'!$B$125,$I$9:$I$349,0),AC19), INDEX($J$9:$S$349,MATCH('U95'!$B$124,$I$9:$I$349,0),AC19))} -> 0 | AD35: {=IF('U95'!$C$19="custom", INDEX($J$9:$S$349,MATCH('U95'!$B$125,$I$9:$I$349,0),AD19), INDEX($J$9:$S$349,MATCH('U95'!$B$124,$I$9:$I$349,0),AD19))} -> 0 | AE35: {=IF('U95'!$C$19="custom", INDEX($J$9:$S$349,MATCH('U95'!$B$125,$I$9:$I$349,0),AE19), INDEX($J$9:$S$349,MATCH('U95'!$B$124,$I$9:$I$349,0),AE19))} -> 0 | AF35: {=IF('U95'!$C$19="custom", INDEX($J$9:$S$349,MATCH('U95'!$B$125,$I$9:$I$349,0),AF19), INDEX($J$9:$S$349,MATCH('U95'!$B$124,$I$9:$I$349,0),AF19))} -> 0 | AG35: {=IF('U95'!$C$19="custom", INDEX($J$9:$S$349,MATCH('U95'!$B$125,$I$9:$I$349,0),AG19), INDEX($J$9:$S$349,MATCH('U95'!$B$124,$I$9:$I$349,0),AG19))} -> 0 | ... AI35: {=IF('U95'!$C$19="custom", INDEX($J$9:$S$349,MATCH('U95'!$B$125,$I$9:$I$349,0),AI19), INDEX($J$9:$S$349,MATCH('U95'!$B$124,$I$9:$I$349,0),AI19))} -> 0
I36: 180 | J36: 100 | K36: 50 | L36: 20 | M36: 10 | N36: 0 | O36: 0 | P36: 0 | Q36: 0 | R36: 0 | S36: 0 | Y36: =Y35+1 -> 16 | Z36: {=IF('U95'!$C$19="custom", INDEX($J$9:$S$349,MATCH('U95'!$B$129,$I$9:$I$349,0),Z19), INDEX($J$9:$S$349,MATCH('U95'!$B$128,$I$9:$I$349,0),Z19))} -> 20000 | AA36: {=IF('U95'!$C$19="custom", INDEX($J$9:$S$349,MATCH('U95'!$B$129,$I$9:$I$349,0),AA19), INDEX($J$9:$S$349,MATCH('U95'!$B$128,$I$9:$I$349,0),AA19))} -> 0 | AB36: {=IF('U95'!$C$19="custom", INDEX($J$9:$S$349,MATCH('U95'!$B$129,$I$9:$I$349,0),AB19), INDEX($J$9:$S$349,MATCH('U95'!$B$128,$I$9:$I$349,0),AB19))} -> 0 | AC36: {=IF('U95'!$C$19="custom", INDEX($J$9:$S$349,MATCH('U95'!$B$129,$I$9:$I$349,0),AC19), INDEX($J$9:$S$349,MATCH('U95'!$B$128,$I$9:$I$349,0),AC19))} -> 0 | AD36: {=IF('U95'!$C$19="custom", INDEX($J$9:$S$349,MATCH('U95'!$B$129,$I$9:$I$349,0),AD19), INDEX($J$9:$S$349,MATCH('U95'!$B$128,$I$9:$I$349,0),AD19))} -> 0 | AE36: {=IF('U95'!$C$19="custom", INDEX($J$9:$S$349,MATCH('U95'!$B$129,$I$9:$I$349,0),AE19), INDEX($J$9:$S$349,MATCH('U95'!$B$128,$I$9:$I$349,0),AE19))} -> 0 | AF36: {=IF('U95'!$C$19="custom", INDEX($J$9:$S$349,MATCH('U95'!$B$129,$I$9:$I$349,0),AF19), INDEX($J$9:$S$349,MATCH('U95'!$B$128,$I$9:$I$349,0),AF19))} -> 0 | AG36: {=IF('U95'!$C$19="custom", INDEX($J$9:$S$349,MATCH('U95'!$B$129,$I$9:$I$349,0),AG19), INDEX($J$9:$S$349,MATCH('U95'!$B$128,$I$9:$I$349,0),AG19))} -> 0 | ... AI36: {=IF('U95'!$C$19="custom", INDEX($J$9:$S$349,MATCH('U95'!$B$129,$I$9:$I$349,0),AI19), INDEX($J$9:$S$349,MATCH('U95'!$B$128,$I$9:$I$349,0),AI19))} -> 0
I37: 190 | J37: 100 | K37: 50 | L37: 20 | M37: 20t | N37: 0 | O37: 0 | P37: 0 | Q37: 0 | R37: 0 | S37: 0
I38: 200 | J38: 200 | K38: 0 | L38: 0 | M38: 0 | N38: 0 | O38: 0 | P38: 0 | Q38: 0 | R38: 0 | S38: 0
I39: 210 | J39: 200 | K39: 10 | L39: 0 | M39: 0 | N39: 0 | O39: 0 | P39: 0 | Q39: 0 | R39: 0 | S39: 0
I40: 220 | J40: 200 | K40: 20 | L40: 0 | M40: 0 | N40: 0 | O40: 0 | P40: 0 | Q40: 0 | R40: 0 | S40: 0
I41: 230 | J41: 200 | K41: 10 | L41: 20 | M41: 0 | N41: 0 | O41: 0 | P41: 0 | Q41: 0 | R41: 0 | S41: 0
...
