Workbook

Sheet Isian 
A1: Deskripsi | B1: Isi
A2: No Order | B2: K683-1
A3: Pemilik Alat | B3: UPTD. Laboratorium Lingkungan Hidup, DLH Jawa Barat
A4: Alamat Pemilik Alat | B4: Jl. A. H. Nasution No. 117, Pasir Endah, Kec. ujung Berung, Bandung 40619
A5: Lokasi Alat | B5: Jl. A. H. Nasution No. 117, Pasir Endah, Kec. ujung Berung, Bandung 40619
A6: Nama Alat | B6: Gelas Ukur | C6: <-------------dropdown perlu disesuaikan
A7: Merk | B7: Iwaki
A8: Tipe | B8: -
A9: No Seri | B9: -
A10: Kapasitas | B10: 10 | C10: ml | D10: <----- Isi angka saja
A11: Graduasi | B11: - | C11: ml | D11: <----- Isi angka saja
A12: No. Identifikasi | B12: 1
A13: Tanggal Terima | B13: 24 November 2025
A14: Tanggal Kalibrasi | B14: 1 Desember 2025
A15: Kalibrator
A16: Timbangan | B16: AND HM 300 | C16: <-------------dropdown perlu disesuaikan
A17: Thermometer | B17: Testo 110 | C17: <-------------dropdown perlu disesuaikan
A18: Thermohygro | B18: Rotronik | C18: <-------------dropdown perlu disesuaikan

Sheet Pengambilan Data 
A1: Kondisi Ruangan | B1: Awal | C1: Akhir | G1: PRE-ADJUSTMENT | H1: E2
A2: Suhu | B2: 20.1 | C2: 20.7 | G2: AT Standar | H2: =IF('Isian '!B16 = 'Database '!AG2, 200, IF('Isian '!B16='Database '!AG3, 5000,IF('Isian '!B16='Database '!AG4,2000,0))) -> 200 | I2: (max ) | J2: g | O2: ℃
A3: Kelembaban | B3: 60.5 | C3: 60 | G3: Beban | H3: =VLOOKUP(H2,A112:C131,2,FALSE) -> 199.99982 | I3: Massa konvensional dari sertifikat | O3: ℃
A4: Tekanan | B4: 925 | C4: 927 | G4: Beban | H4: Reading | I4: Means | J4: Difference ri-zi | K4: Correction Mi-(ri-zi)
C5: ` | G5: 0 | H5: 0
G6: =H3 -> 199.99982 | H6: 199.9973
A7: Penimbangan Bejana Kosong (A) | G7: =H3 -> 199.99982 | H7: 199.9974 | I7: =(H6+H7)/2 -> 199.99735 | J7: =I7-I8 -> 199.99735 | K7: =H3-(J7) -> 0.00247
A8: Penimbangan Ke - | B8: Nominal (ml) | C8: Zero (g) | D8: Load(g) | E8: Zero(g) | G8: 0 | H8: 0 | I8: =(H5+H8)/2 -> 0
A9: X1 | B9: =CONCATENATE('Isian '!$B$10/5," ml") -> 2 ml | C9: 0 | D9: 17.0763 | E9: 0
A10: X2 | B10: =CONCATENATE('Isian '!$B$10/5," ml") -> 2 ml | C10: 0 | D10: 17.0759 | E10: 0 | G10: ADJUSTMENT
A11: X3 | B11: =CONCATENATE('Isian '!$B$10/5," ml") -> 2 ml | C11: 0 | D11: 17.0756 | E11: 0 | G11: AT Standar | H11: =IF('Isian '!B16 = 'Database '!AG2, 200, IF('Isian '!B16='Database '!AG3, 5000,IF('Isian '!B16='Database '!AG4,2000,0))) -> 200 | I11: (max )
A12: X4 | B12: =CONCATENATE('Isian '!$B$10/5," ml") -> 2 ml | C12: 0 | D12: 17.0759 | E12: 0 | G12: Beban | H12: =VLOOKUP(H2,A112:C131,2,FALSE) -> 199.99982 | I12: Massa konvensional dari sertifikat
A13: X5 | B13: =CONCATENATE('Isian '!$B$10/5," ml") -> 2 ml | C13: 0 | D13: 17.0756 | E13: 0 | G13: Beban | H13: Reading | I13: Means | J13: Difference ri-zi | K13: Correction Mi-(ri-zi)
G14: 0 | H14: 0
A15: X6 | B15: =CONCATENATE('Isian '!$B$10*2/5," ml") -> 4 ml | C15: 0 | D15: 17.0763 | E15: 0 | G15: =H12 -> 199.99982 | H15: 200.0002
A16: X7 | B16: =CONCATENATE('Isian '!$B$10*2/5," ml") -> 4 ml | C16: 0 | D16: 17.0759 | E16: 0 | G16: =H12 -> 199.99982 | H16: 200.0001 | I16: =(H15+H16)/2 -> 200.00015 | J16: =I16-I17 -> 200.00015 | K16: =H12-(I16) -> -0.00033
A17: X8 | B17: =CONCATENATE('Isian '!$B$10*2/5," ml") -> 4 ml | C17: 0 | D17: 17.0756 | E17: 0 | H17: 0 | I17: =(H14+H17)/2 -> 0
A18: X9 | B18: =CONCATENATE('Isian '!$B$10*2/5," ml") -> 4 ml | C18: 0 | D18: 17.0759 | E18: 0
A19: X10 | B19: =CONCATENATE('Isian '!$B$10*2/5," ml") -> 4 ml | C19: 0 | D19: 17.0756 | E19: 0
A21: X11 | B21: =CONCATENATE('Isian '!$B$10*3/5," ml") -> 6 ml | C21: 0 | D21: 17.0763 | E21: 0
A22: X12 | B22: =CONCATENATE('Isian '!$B$10*3/5," ml") -> 6 ml | C22: 0 | D22: 17.0759 | E22: 0
A23: X13 | B23: =CONCATENATE('Isian '!$B$10*3/5," ml") -> 6 ml | C23: 0 | D23: 17.0756 | E23: 0
A24: X14 | B24: =CONCATENATE('Isian '!$B$10*3/5," ml") -> 6 ml | C24: 0 | D24: 17.0759 | E24: 0
A25: X15 | B25: =CONCATENATE('Isian '!$B$10*3/5," ml") -> 6 ml | C25: 0 | D25: 17.0756 | E25: 0
A27: X16 | B27: =CONCATENATE('Isian '!$B$10*4/5," ml") -> 8 ml | C27: 0 | D27: 17.0763 | E27: 0
A28: X17 | B28: =CONCATENATE('Isian '!$B$10*4/5," ml") -> 8 ml | C28: 0 | D28: 17.0759 | E28: 0
A29: X18 | B29: =CONCATENATE('Isian '!$B$10*4/5," ml") -> 8 ml | C29: 0 | D29: 17.0756 | E29: 0
A30: X19 | B30: =CONCATENATE('Isian '!$B$10*4/5," ml") -> 8 ml | C30: 0 | D30: 17.0759 | E30: 0
A31: X20 | B31: =CONCATENATE('Isian '!$B$10*4/5," ml") -> 8 ml | C31: 0 | D31: 17.0756 | E31: 0
A33: X21 | B33: =CONCATENATE('Isian '!$B$10*5/5," ml") -> 10 ml | C33: 0 | D33: 17.0763 | E33: 0
A34: X22 | B34: =CONCATENATE('Isian '!$B$10*5/5," ml") -> 10 ml | C34: 0 | D34: 17.0759 | E34: 0
A35: X23 | B35: =CONCATENATE('Isian '!$B$10*5/5," ml") -> 10 ml | C35: 0 | D35: 17.0756 | E35: 0
A36: X24 | B36: =CONCATENATE('Isian '!$B$10*5/5," ml") -> 10 ml | C36: 0 | D36: 17.0759 | E36: 0
A37: X25 | B37: =CONCATENATE('Isian '!$B$10*5/5," ml") -> 10 ml | C37: 0 | D37: 17.0756 | E37: 0
A40: Penimbangan berisi air destilasi (B)
A41: Penimbangan Ke - | B41: Nominal (ml) | C41: Zero (g) | D41: Load (g) | E41: Zero(g) | F41: Suhu Cairan (g)
A42: X1 | B42: =CONCATENATE('Isian '!$B$10/5," ml") -> 2 ml | C42: 0 | D42: 18.0641 | E42: 0 | F42: 20
A43: X2 | B43: =CONCATENATE('Isian '!$B$10/5," ml") -> 2 ml | C43: 0 | D43: 18.0641 | E43: 0 | F43: 20
A44: X3 | B44: =CONCATENATE('Isian '!$B$10/5," ml") -> 2 ml | C44: 0 | D44: 18.0708 | E44: 0 | F44: 20.2
A45: X4 | B45: =CONCATENATE('Isian '!$B$10/5," ml") -> 2 ml | C45: 0 | D45: 18.0641 | E45: 0 | F45: 20.2
...

Sheet Peralatan & Koefisien  
I1: =CONCATENATE('Isian '!$B$10/5," ml") -> 2 ml
B2: Peralatan | C2: Resolusi | D2: Ketidakpastian | E2: Konversi | F2: Satuan | I2: Komponen | J2: Koefisien | K2: Simbol koef | L2: Nilai koef | M2: Ketidakpastian baku (U) | N2: nilai U | O2: Koefisien Sesitivitas (ci) | P2: Satuan | V2: =CONCATENATE('Isian '!$B$10/5," ml") -> 2 ml | X2: =CONCATENATE('Isian '!$B$10*2/5," ml") -> 4 ml | Z2: =CONCATENATE('Isian '!$B$10*3/5," ml") -> 6 ml | AB2: =CONCATENATE('Isian '!$B$10*4/5," ml") -> 8 ml | AD2: =CONCATENATE('Isian '!$B$10*5/5," ml") -> 10 ml
B3: Timbangan | C3: =VLOOKUP('Isian '!B16,'Database '!AG1:AJ4,3,FALSE) -> 0.0001 | D3: =VLOOKUP('Isian '!B16,'Database '!AG1:AJ4,4,FALSE) -> 0.00082 | F3: mg | H3: 1 | I3: Massa | K3: Ul | L3: =SQRT(($D$3/2)^2 +((($C$3/2)/SQRT(3))^2 )) -> 0.000411015 | M3: Um | N3: =SQRT(L3^2 +L3^2+((L4/2)/SQRT(3))^2) -> 0.00058287363 | O3: =$C$18*$C$19*$C$20 -> 1.0027534 | P3: ml/g | U3: Komponen | V3: Nilai U | W3: Koefiesien Sensitivitas | X3: Nilai U | Y3: Koefiesien Sensitivitas | Z3: Nilai U | AA3: Koefiesien Sensitivitas | AB3: Nilai U | AC3: Koefiesien Sensitivitas | AD3: Nilai U | AE3: Koefiesien Sensitivitas
B4: Thermometer Cairan | C4: 0.1 | D4: 0.4 | F4: C | K4: dm | L4: 0.00015 | U4: Massa | V4: =N3 -> 0.00058287363 | W4: =O3 -> 1.0027534 | X4: =$N$3 -> 0.00058287363 | Y4: =O31 -> 1.0027534 | Z4: =$N$3 -> 0.00058287363 | AA4: =O59 -> 1.0027534 | AB4: =$N$3 -> 0.00058287363 | AC4: =O87 -> 1.0027534 | AD4: =$N$3 -> 0.00058287363 | AE4: =O115 -> 1.0027534
B5: Thermometer lingkungan | C5: 0.01 | D5: 3.2 | F5: C | U5: Suhu air destilasi | V5: =N6 -> 0.25367877 | W5: =O6 -> -9.8371166e-06 | X5: =SQRT((SQRT((D4/2)^2 +((C4/2)/SQRT(3))^2 + ((L6/2)/SQRT(3))^2 +('Pengambilan Data '!L90/SQRT(5))^2))^2+L8^2) -> 0.25367877 | Y5: =O34 -> -9.8371166e-06 | Z5: =SQRT((SQRT((D4/2)^2 +((C4/2)/SQRT(3))^2 + ((L6/2)/SQRT(3))^2 +('Pengambilan Data '!S90/SQRT(5))^2))^2+L8^2) -> 0.25367877 | AA5: =O62 -> -9.8371166e-06 | AB5: =SQRT((SQRT((D4/2)^2 +((C4/2)/SQRT(3))^2 + ((L6/2)/SQRT(3))^2 +('Pengambilan Data '!Z90/SQRT(5))^2))^2+L8^2) -> 0.25367877 | AC5: =O90 -> -9.8371166e-06 | AD5: =SQRT((SQRT((D4/2)^2 +((C4/2)/SQRT(3))^2 + ((L6/2)/SQRT(3))^2 +('Pengambilan Data '!AG90/SQRT(5))^2))^2+L8^2) -> 0.25367877 | AE5: =O118 -> -9.8371166e-06
B6: Higrometer | C6: 0.1 | D6: 2.3 | E6: =D6/100 -> 0.023 | F6: % | H6: 2 | I6: Suhu air destilasi | K6: dt | L6: 0.06 | M6: Ut | N6: =SQRT(L7^2+L8^2) -> 0.25367877 | O6: =$C$21*$C$18*$C$19*(-$L$23) -> -9.8371166e-06 | P6: ml/C | U6: Densitas air destilasi | V6: =N10 -> 4.421272e-05 | W6: =O10 -> -0.99652155 | X6: =N38 -> 4.421272e-05 | Y6: =O38 -> -0.99652155 | Z6: =N66 -> 4.421272e-05 | AA6: =O66 -> -0.99652155 | AB6: =N94 -> 4.421272e-05 | AC6: =O94 -> -0.99652155 | AD6: =N122 -> 4.421272e-05 | AE6: =O122 -> -0.99652155
B7: Barometer | C7: 0.1 | D7: 1 | E7: =D7*100 -> 100 | F7: Pa | K7: U(tw) | L7: =SQRT(($D$4/2)^2 +(($C$4/2)/SQRT(3))^2 + (($L$6/2)/SQRT(3))^2 +('Pengambilan Data '!$E$90/SQRT(5))^2) -> 0.20861348 | U7: Densitas udara | V7: =N15 -> 1.4091221e-05 | W7: =O15 -> 0.87153432 | X7: =$N$15 -> 1.4091221e-05 | Y7: =O43 -> 0.87153432 | Z7: =$N$15 -> 1.4091221e-05 | AA7: =O71 -> 0.87153432 | AB7: =$N$15 -> 1.4091221e-05 | AC7: =O99 -> 0.87153432 | AD7: =$N$15 -> 1.4091221e-05 | AE7: =O127 -> 0.87153432
B8: Note: Angka diambil dari contoh standar acuan SNSU PK M-05:2023 | K8: U(ts) | L8: =(0.5/2)/SQRT(3) -> 0.14433757 | R8: -----------------> REKAP NILAI | U8: Densitas AT acuan | V8: =N21 -> 0.14 | W8: =O21 -> 1.7252161e-05 | X8: =$N$21 -> 0.14 | Y8: =O49 -> 1.7252161e-05 | Z8: =$N$21 -> 0.14 | AA8: =O77 -> 1.7252161e-05 | AB8: =$N$21 -> 0.14 | AC8: =O105 -> 1.7252161e-05 | AD8: =$N$21 -> 0.14 | AE8: =O133 -> 1.7252161e-05
U9: Koefisien muai termal | V9: =N23 -> 5.7157677e-07 | W9: =O23 -> -19.83721 | X9: =$N$23 -> 5.7157677e-07 | Y9: =O51 -> -19.83721 | Z9: =$N$23 -> 5.7157677e-07 | AA9: =O79 -> -19.83721 | AB9: =$N$23 -> 5.7157677e-07 | AC9: =O107 -> -19.83721 | AD9: =$N$23 -> 5.7157677e-07 | AE9: =O135 -> -19.83721
B10: Tekanan Terkoreksi | C10: =AVERAGE('Pengambilan Data '!B4,'Pengambilan Data '!C4)+FORECAST(AVERAGE('Pengambilan Data '!B4,'Pengambilan Data '!C4),'Database '!M3:M13,'Database '!L3:L13) -> 929.80139 | H10: 3 | I10: Densitas air destilasi | K10: U(pwform) | L10: =4.5 *10^-7 -> 4.5e-07 | M10: Upw(tw) | N10: =SQRT(L10^2 +L12^2 +L13^2) -> 4.421272e-05 | O10: =-$C$21*($C$18^2)*$C$19*$C$20 -> -0.99652155 | P10: ml2/g | U10: Meniskus | V10: =N25 -> 0.00062333924 | W10: 1 | X10: =N53 -> 0.00062333924 | Y10: 1 | Z10: =N81 -> 0.00062333924 | AA10: 1 | AB10: =N109 -> 0.00062333924 | AC10: 1 | AD10: =N137 -> 0.00062333924 | AE10: 1
B11: Humidity terkoreksi | C11: =AVERAGE('Pengambilan Data '!B3,'Pengambilan Data '!D3)+FORECAST(AVERAGE('Pengambilan Data '!B3,'Pengambilan Data '!D3),'Database '!H3:H7,'Database '!G3:G7) -> 60.276093 | K11: B | L11: =(-0.1176*'Pengambilan Data '!E89^2 +15.846*'Pengambilan Data '!E89 - 62.677)*10^-6 -> 0.00020680194 | U11: Repeatability | V11: =N27 -> 0.0017555011 | W11: 1 | X11: =N55 -> 0.0017555011 | Y11: 1 | Z11: =N83 -> 0.0017555011 | AA11: 1 | AB11: =N111 -> 0.0017555011 | AC11: 1 | AD11: =N139 -> 0.0017555011 | AE11: 1
B12: Suhu terkoreksi | C12: =AVERAGE('Pengambilan Data '!B2,'Pengambilan Data '!C2)+FORECAST(AVERAGE('Pengambilan Data '!B2,'Pengambilan Data '!C2),'Database '!C3:C7,'Database '!B3:B7) -> 20.442732 | K12: U(pwt) | L12: =L7*L11*'Pengambilan Data '!$F$89 -> 4.3064627e-05
B13: =CONCATENATE('Isian '!$B$10/5," ml") -> 2 ml | K13: U(dpw) | L13: =1*10^-5 -> 1e-05
B14: Koefiesen | C14: Nilai | D14: Konversi
B15: pb | C15: 7950 | D15: =C15*1000/1000000 -> 7.95 | H15: 4 | I15: Densitas udara | K15: pa | L15: =(((0.34848*$C$10 - 0.009*$C$11*EXP(0.061*$C$12)) / ($C$12 + 273.15)))/1000 -> 0.0010971981 | M15: U(pa) | N15: =L15*SQRT(((L16*$E$7)^2)+((L17*$D$5)^2)+((L18*$E$6)^2)+(L19^2)) -> 1.4091221e-05 | O15: =$C$21*$C$18*$C$20*($C$19*($C$18-1/$D$15)) -> 0.87153432 | P15: ml2/g
B16: pa | C16: =(((0.34848*$C$10 - 0.009*$C$11*EXP(0.061*$C$12)) / ($C$12 + 273.15)))/1000 -> 0.0010971981 | K16: PP | L16: =1*10^-5 -> 1e-05
B17: pw | C17: ='Pengambilan Data '!$F$89 -> 0.99821412 | K17: TT | L17: =-4*10^-3 -> -0.004
B18: A | C18: =1/(C17-C16) -> 1.0028914 | K18: HH | L18: =-9*10^-3 -> -0.009
B19: B | C19: =1-(C16/D15) -> 0.99986199 | K19: Uform | L19: =2.4*10^-4 -> 0.00024
B20: C | C20: =1-$L$23*('Pengambilan Data '!$E$89-20) -> 1.0000004
B21: m | C21: ='Pengambilan Data '!$D$89 -> 0.99092014 | H21: 5 | I21: Densitas AT acuan | K21: U(b) | L21: 0.14 | M21: U(pb) | N21: =L21 -> 0.14 | O21: =$C$21*$C$18*$C$20*$C$16/($D$15^2) -> 1.7252161e-05 | P21: ml2/g
B23: =CONCATENATE('Isian '!$B$10*2/5," ml") -> 4 ml | H23: 6 | I23: Koefisien muai termal | K23: y | L23: =9.9*10^-6 -> 9.9e-06 | M23: Uy | N23: =(L23/SQRT(3))*10/100 -> 5.7157677e-07 | O23: =$C$21*$C$18*$C$19*(-'Pengambilan Data '!E89) -> -19.83721 | P23: C.ml
B24: Koefiesen | C24: Nilai | D24: Konversi
B25: pb | C25: 7950 | D25: =C25*1000/1000000 -> 7.95 | H25: 7 | I25: Meniskus | K25: pi | L25: =22/7 -> 3.1428571 | M25: Umeniskus | N25: =(((0.5*'Pengambilan Data '!C79)*(0.25*L25*'Pengambilan Data '!B79^2))/SQRT(3))*10^-3 -> 0.00062333924 | O25: 1
B26: pa | C26: =(((0.34848*$C$10 - 0.009*$C$11*EXP(0.061*$C$12)) / ($C$12 + 273.15)))/1000 -> 0.0010971981
B27: pw | C27: ='Pengambilan Data '!$M$89 -> 0.99821412 | H27: 8 | I27: Repeatability | K27: - | L27: - | M27: Urepeat | N27: ='Pengambilan Data '!G90/SQRT(5) -> 0.0017555011 | O27: 1
B28: A | C28: =1/(C27-C26) -> 1.0028914
B29: B | C29: =1-(C26/D25) -> 0.99986199 | I29: =CONCATENATE('Isian '!$B$10*2/5," ml") -> 4 ml
B30: C | C30: =1-$L$23*('Pengambilan Data '!L89-20) -> 1.0000004 | I30: Komponen | J30: Koefisien | K30: Simbol koef | L30: Nilai koef | M30: Ketidakpastian baku (U) | N30: nilai U | O30: Koefisien Sesitivitas (ci) | P30: Satuan
B31: m | C31: ='Pengambilan Data '!K89 -> 0.99092014 | H31: 1 | I31: Massa | K31: Ul | L31: =SQRT(($D$3/2)^2 +((($C$3/2)/SQRT(3))^2 )) -> 0.000411015 | M31: Um | N31: =SQRT(L31^2 +L31^2+((L32/2)/SQRT(3))^2) -> 0.00058287363 | O31: =(1/('Pengambilan Data '!M89-C16))*$C$19*(1-L23*('Pengambilan Data '!L89-20)) -> 1.0027534 | P31: ml/g
K32: dm | L32: 0.00015
B33: =CONCATENATE('Isian '!$B$10*3/5," ml") -> 6 ml
B34: Koefiesen | C34: Nilai | D34: Konversi | H34: 2 | I34: Suhu air destilasi | K34: dt | L34: 0.06 | M34: Ut | N34: =SQRT(L35^2+L36^2) -> 0.25367877 | O34: ='Pengambilan Data '!K89*(1/('Pengambilan Data '!M89-C16))*$C$19*(-$L$51) -> -9.8371166e-06 | P34: ml/C
B35: pb | C35: 7950 | D35: =C35*1000/1000000 -> 7.95 | K35: U(tw) | L35: =SQRT(($D$4/2)^2 +(($C$4/2)/SQRT(3))^2 + (($L$6/2)/SQRT(3))^2 +('Pengambilan Data '!L90/SQRT(5))^2) -> 0.20861348
B36: pa | C36: =(((0.34848*$C$10 - 0.009*$C$11*EXP(0.061*$C$12)) / ($C$12 + 273.15)))/1000 -> 0.0010971981 | K36: U(ts) | L36: =(0.5/2)/SQRT(3) -> 0.14433757
B37: pw | C37: ='Pengambilan Data '!T89 -> 0.99821412
B38: A | C38: =1/(C37-C36) -> 1.0028914 | H38: 3 | I38: Densitas air destilasi | K38: U(pwform) | L38: =4.5 *10^-7 -> 4.5e-07 | M38: Upw(tw) | N38: =SQRT(L38^2 +L40^2 +L41^2) -> 4.421272e-05 | O38: =-$C$31*($C$28^2)*$C$29*$C$30 -> -0.99652155 | P38: ml2/g
B39: B | C39: =1-(C36/D35) -> 0.99986199 | K39: B | L39: =(-0.1176*'Pengambilan Data '!L89^2 +15.846*'Pengambilan Data '!L89 - 62.677)*10^-6 -> 0.00020680194
B40: C | C40: =1-$L$23*('Pengambilan Data '!S89-20) -> 1.0000004 | K40: U(pwt) | L40: =L35*L39*'Pengambilan Data '!M89 -> 4.3064627e-05
B41: m | C41: ='Pengambilan Data '!R89 -> 0.99092014 | K41: U(dpw) | L41: =1*10^-5 -> 1e-05
...

Sheet Budget Ketidakpastian 
B8: UNCERTAINTY BUDGET SEBAGAI PENDUKUNG KLAIM CMC
B9: Besaran yang diukur : | C9: Volume
B10: Jenis alat yang dikalibrasi : | C10: =CONCATENATE('Isian '!$B$6,) -> Gelas Ukur | D10: ='Isian '!$B$10/5 -> 2 | E10: ml
B11: Model matematis :
R12: Database CMC
B13: Komponen | C13: Satuan | D13: Distribusi | E13: U | F13: Pembagi | G13: vi | H13: ui | I13: ci | J13: uici | K13: (uici)2 | L13: (uici)4/vi | R13: Tipe | S13: Range 1 | T13: Range 2 | U13: CMC
B14: 1 | C14: 2 | D14: 3 | E14: 4 | F14: 5 | G14: 6 | H14: 7 | I14: 8 | J14: 9 | K14: 10 | L14: 11 | R14: Gelas Ukur | S14: 2 | T14: 10 | U14: 0.021
A15: 1 | B15: Massa | C15: mg | D15: Normal | E15: ='Peralatan & Koefisien '!N3 -> 0.00058287363 | F15: 1 | G15: 60 | H15: =E15/F15 -> 0.00058287363 | I15: ='Peralatan & Koefisien '!O3 -> 1.0027534 | J15: =H15*I15 -> 0.00058447849 | K15: =J15^2 -> 3.4161511e-07 | L15: =K15^2/G15 -> 1.9450147e-15 | R15: Gelas Ukur | S15: 11 | T15: 50 | U15: 0.049
A16: 2 | B16: Suhu air destilasi | C16: mg | D16: Normal | E16: ='Peralatan & Koefisien '!N6 -> 0.25367877 | F16: 1 | G16: 60 | H16: =E16/F16 -> 0.25367877 | I16: ='Peralatan & Koefisien '!O6 -> -9.8371166e-06 | J16: =H16*I16 -> -2.4954676e-06 | K16: =J16^2 -> 6.2273586e-12 | L16: =K16^2/G16 -> 6.4633326e-25 | R16: Gelas Ukur | S16: 51 | T16: 100 | U16: 0.079
A17: 3 | B17: Densitas air destilasi | C17: mg | D17: Normal | E17: ='Peralatan & Koefisien '!N10 -> 4.421272e-05 | F17: 1 | G17: 60 | H17: =E17/F17 -> 4.421272e-05 | I17: ='Peralatan & Koefisien '!O10 -> -0.99652155 | J17: =H17*I17 -> -4.4058928e-05 | K17: =J17^2 -> 1.9411891e-09 | L17: =K17^2/G17 -> 6.2803588e-20 | R17: Gelas Ukur | S17: 101 | T17: 500 | U17: 0.25
A18: 4 | B18: Densitas udara | C18: mg | D18: t-student | E18: ='Peralatan & Koefisien '!N15 -> 1.4091221e-05 | F18: 1 | G18: 60 | H18: =E18/F18 -> 1.4091221e-05 | I18: ='Peralatan & Koefisien '!O15 -> 0.87153432 | J18: =H18*I18 -> 1.2280983e-05 | K18: =J18^2 -> 1.5082254e-10 | L18: =K18^2/G18 -> 3.7912398e-22 | R18: Buret | S18: 2 | T18: 10 | U18: 0.008
A19: 5 | B19: Densitas AT acuan | C19: mg | D19: Normal | E19: ='Peralatan & Koefisien '!N21 -> 0.14 | F19: 2 | G19: 60 | H19: =E19/F19 -> 0.07 | I19: ='Peralatan & Koefisien '!O21 -> 1.7252161e-05 | J19: =H19*I19 -> 1.2076513e-06 | K19: =J19^2 -> 1.4584217e-12 | L19: =K19^2/G19 -> 3.5449896e-26 | R19: Buret | S19: 11 | T19: 25 | U19: 0.011
A20: 6 | B20: Koefisien muai termal | C20: mg | D20: Rect | E20: ='Peralatan & Koefisien '!N23 -> 5.7157677e-07 | F20: 1 | G20: 50 | H20: =E20/F20 -> 5.7157677e-07 | I20: ='Peralatan & Koefisien '!O23 -> -19.83721 | J20: =H20*I20 -> -1.1338488e-05 | K20: =J20^2 -> 1.2856132e-10 | L20: =K20^2/G20 -> 3.3056025e-22 | R20: Buret | S20: 26 | T20: 50 | U20: 0.014
A21: 7 | B21: Meniskus | C21: mg | D21: Rect | E21: ='Peralatan & Koefisien '!N25 -> 0.00062333924 | F21: 1 | G21: 50 | H21: =E21/F21 -> 0.00062333924 | I21: 1 | J21: =H21*I21 -> 0.00062333924 | K21: =J21^2 -> 3.8855181e-07 | L21: =K21^2/G21 -> 3.0194502e-15 | R21: Buret | S21: 51 | T21: 100 | U21: 0.027
A22: 8 | B22: Repeatability | C22: mg | D22: Normal | E22: ='Peralatan & Koefisien '!N27 -> 0.0017555011 | F22: 1 | G22: 4 | H22: =E22/F22 -> 0.0017555011 | I22: 1 | J22: =H22*I22 -> 0.0017555011 | K22: =J22^2 -> 3.081784e-06 | L22: =K22^2/G22 -> 2.3743482e-12 | R22: Pipet Ukur | S22: 1 | T22: 5 | U22: 0.0035
B23: Sums | K23: =SUM(K15:K22) -> 3.8141792e-06 | L23: =SUM(L15:L22) -> 2.3793127e-12 | R23: Pipet Ukur | S23: 6 | T23: 10 | U23: 0.0056
B24: Ketidakpastian baku gabungan, uc, mg | K24: =SQRT(K23) -> 0.0019529924 | R24: Pipet Ukur | S24: 11 | T24: 25 | U24: 0.0097
B25: Dearajat kebebasan efektif, veff | K25: =(K24^4)/L23 -> 6.1143551 | R25: Pipet Ukur | S25: 26 | T25: 50 | U25: 0.018
B26: Faktor cakupan, k-student for veff and CL 95% | K26: =TINV(0.05,K25) -> 2.4469119 | R26: Pipet Ukur | S26: 51 | T26: 100 | U26: 0.053
B27: Ketidakpastian bentangan, U = kuc, mg | K27: =K26*K24 -> 0.0047788002 | R27: Labu Ukur | S27: 25 | T27: 25 | U27: 0.01
B28: Atau ketidakpastian bentangan, U = kuc, mg | K28: =K26*K24 -> 0.0047788002 | L28: ml | R28: Labu Ukur | S28: 50 | T28: 50 | U28: 0.017
B29: Atau ketidakpastian bentangan, U = kuc, g | K29: =K28/1000 -> 4.7788002e-06 | L29: l | R29: Labu Ukur | S29: 100 | T29: 100 | U29: 0.023
B30: CMC | K30: {=IFERROR(INDEX($U$14:$U$34, MATCH(1, (D10>=$S$14:$S$34)*(D10<=$T$14:$T$34)*(C10=$R$14:$R$34), 0)),"Bintang")} -> 0.021 | L30: ml | R30: Labu Ukur | S30: 250 | T30: 250 | U30: 0.041
R31: Labu Ukur | S31: 500 | T31: 500 | U31: 0.074
R32: Pipet Volume | S32: 5 | T32: 5 | U32: 0.0024
R33: Pipet Volume | S33: 10 | T33: 10 | U33: 0.0025
B34: UNCERTAINTY BUDGET SEBAGAI PENDUKUNG KLAIM CMC | R34: Pipet Volume | S34: 20 | T34: 20 | U34: 0.0035
B35: Besaran yang diukur : | C35: Volume
B36: Jenis alat yang dikalibrasi : | C36: =CONCATENATE('Isian '!$B$6,) -> Gelas Ukur | D36: ='Isian '!$B$10*2/5 -> 4 | E36: ml
B37: Model matematis :
B39: Komponen | C39: Satuan | D39: Distribusi | E39: U | F39: Pembagi | G39: vi | H39: ui | I39: ci | J39: uici | K39: (uici)2 | L39: (uici)4/vi
B40: 1 | C40: 2 | D40: 3 | E40: 4 | F40: 5 | G40: 6 | H40: 7 | I40: 8 | J40: 9 | K40: 10 | L40: 11
B41: Massa | C41: mg | D41: Normal | E41: ='Peralatan & Koefisien '!X4 -> 0.00058287363 | F41: 1 | G41: 60 | H41: =E41/F41 -> 0.00058287363 | I41: ='Peralatan & Koefisien '!Y4 -> 1.0027534 | J41: =H41*I41 -> 0.00058447849 | K41: =J41^2 -> 3.4161511e-07 | L41: =K41^2/G41 -> 1.9450147e-15
B42: Suhu air destilasi | C42: mg | D42: Normal | E42: ='Peralatan & Koefisien '!X5 -> 0.25367877 | F42: 1 | G42: 60 | H42: =E42/F42 -> 0.25367877 | I42: ='Peralatan & Koefisien '!Y5 -> -9.8371166e-06 | J42: =H42*I42 -> -2.4954676e-06 | K42: =J42^2 -> 6.2273586e-12 | L42: =K42^2/G42 -> 6.4633326e-25
B43: Densitas air destilasi | C43: mg | D43: Normal | E43: ='Peralatan & Koefisien '!X6 -> 4.421272e-05 | F43: 1 | G43: 60 | H43: =E43/F43 -> 4.421272e-05 | I43: ='Peralatan & Koefisien '!Y6 -> -0.99652155 | J43: =H43*I43 -> -4.4058928e-05 | K43: =J43^2 -> 1.9411891e-09 | L43: =K43^2/G43 -> 6.2803588e-20
B44: Densitas udara | C44: mg | D44: t-student | E44: ='Peralatan & Koefisien '!X7 -> 1.4091221e-05 | F44: 1 | G44: 60 | H44: =E44/F44 -> 1.4091221e-05 | I44: ='Peralatan & Koefisien '!Y7 -> 0.87153432 | J44: =H44*I44 -> 1.2280983e-05 | K44: =J44^2 -> 1.5082254e-10 | L44: =K44^2/G44 -> 3.7912398e-22
B45: Densitas AT acuan | C45: mg | D45: Normal | E45: ='Peralatan & Koefisien '!X8 -> 0.14 | F45: 2 | G45: 60 | H45: =E45/F45 -> 0.07 | I45: ='Peralatan & Koefisien '!Y8 -> 1.7252161e-05 | J45: =H45*I45 -> 1.2076513e-06 | K45: =J45^2 -> 1.4584217e-12 | L45: =K45^2/G45 -> 3.5449896e-26
B46: Koefisien muai termal | C46: mg | D46: Rect | E46: ='Peralatan & Koefisien '!X9 -> 5.7157677e-07 | F46: 1 | G46: 50 | H46: =E46/F46 -> 5.7157677e-07 | I46: ='Peralatan & Koefisien '!Y9 -> -19.83721 | J46: =H46*I46 -> -1.1338488e-05 | K46: =J46^2 -> 1.2856132e-10 | L46: =K46^2/G46 -> 3.3056025e-22
B47: Meniskus | C47: mg | D47: Rect | E47: ='Peralatan & Koefisien '!X10 -> 0.00062333924 | F47: 1 | G47: 50 | H47: =E47/F47 -> 0.00062333924 | I47: ='Peralatan & Koefisien '!Y10 -> 1 | J47: =H47*I47 -> 0.00062333924 | K47: =J47^2 -> 3.8855181e-07 | L47: =K47^2/G47 -> 3.0194502e-15
B48: Repeatability | C48: mg | D48: Normal | E48: ='Peralatan & Koefisien '!X11 -> 0.0017555011 | F48: 1 | G48: 4 | H48: =E48/F48 -> 0.0017555011 | I48: ='Peralatan & Koefisien '!Y11 -> 1 | J48: =H48*I48 -> 0.0017555011 | K48: =J48^2 -> 3.081784e-06 | L48: =K48^2/G48 -> 2.3743482e-12
...

Sheet Sertifikat 
A7: S E R T I F I K A T K A L I B R A S I
A8: C A L I B R A T I O N C E R T I F I C A T E
A9: Nomor / Number : 0187-2.3/KALIBRASI BBLM/XII/2025
B13: IDENTITAS ALAT
B14: INSTRUMENT DETAILS
B16: Nama Alat | D16: : | E16: ='Isian '!B6 -> Gelas Ukur
B17: Instrument Name
B18: Merek | D18: : | E18: ='Isian '!B7 -> Iwaki
B19: Brand
B20: Tipe | D20: : | E20: ='Isian '!B8 -> -
B21: Type
B22: Nomor Identifikasi | D22: : | E22: ='Isian '!B12 -> 1
B23: Identification Number
B24: Nomor Seri | D24: : | E24: ='Isian '!B9 -> -
B25: Serial Number
B26: Lain-lain | D26: : | E26: Kapasitas | G26: =CONCATENATE(": ",'Isian '!B10," ",'Isian '!C10) -> : 10 ml
B27: Others | E27: Kecermatan | G27: =CONCATENATE(": ",'Isian '!B11) -> : -
B29: IDENTITAS PEMILIK
B30: Owner’s Identification
B32: Nama | D32: : | E32: ='Isian '!B3 -> UPTD. Laboratorium Lingkungan Hidup, DLH Jawa Barat
B33: Designation
B34: Alamat | D34: : | E34: ='Isian '!B4 -> Jl. A. H. Nasution No. 117, Pasir Endah, Kec. ujung Berung, Bandung 40619
B35: Address
H38: Halaman 1 dari 2 halaman
H39: Page of page
H41: Diterbitkan Tanggal 17 Desember 2025
H42: Date of Issue
F44: Penguji Mutu Barang Ahli Madya
F45: Elis Sofianti
F46: NIP. 197109301994032002
F64: Nomor | G64: =CONCATENATE(MID(A9,16,100)) -> : 0187-2.3/KALIBRASI BBLM/XII/2025
F65: No. Order | G65: =CONCATENATE(": ",'Isian '!B2) -> : K683-1
F66: Halaman | G66: : 2 dari 2
B68: SPESIFIKASI ALAT
B69: Nama | E69: =CONCATENATE(": ",E16) -> : Gelas Ukur
B70: Merek / Tipe | E70: =CONCATENATE(":"," ",E18," ","/"," ",E20) -> : Iwaki / -
B71: No. Identifikasi / No. Seri | E71: =CONCATENATE(": ",E22," / ",E24) -> : 1 / -
B72: Kapasitas | E72: =G26 -> : 10 ml
B73: Kecermatan | E73: =G27 -> : - | H73: Kondisi ruang
B74: Prosedur Kalibrasi | E74: : SNSU PK.M-05:2023 | H74: Temperatur | J74: =CONCATENATE(": ","(",'Thermohygro '!B10,") °C") -> : (20,4 ± 0,3) °C
...

Sheet Thermohygro 
B2: Suhu (°C) | C2: %RH | D2: Tekanan | F2: Thermohygro Rotronic data 2025
A3: Awal | B3: ='Pengambilan Data '!B2 -> 20.1 | C3: =Table5[[#This Row],[Awal ]] -> 60.5 | D3: ='Pengambilan Data '!B4/1.333 -> 693.92348 | F3: Koreksi suhu | I3: Koreksi RH | L3: Koreksi Tekanan
A4: Akhir | B4: ='Pengambilan Data '!C2 -> 20.7 | C4: ='Pengambilan Data '!C3 -> 60 | D4: =Table5[[#This Row],[Akhir ]]/1.3333 -> 695.26738 | F4: T (°C) | G4: Koreksi | H4: U95 | I4: RH (%) | J4: Koreksi | K4: U95 | L4: Tekanan | M4: Koreksi | N4: U95
A5: Rata2 | B5: =AVERAGE(B3:B4) -> 20.4 | C5: =AVERAGE(C3:C4) -> 60.25 | D5: =AVERAGE(D3:D4) -> 694.59543 | F5: 20 | G5: 0.1 | H5: 2 | I5: 40 | J5: 0.2 | K5: 2.5 | L5: 940 | M5: 4 | N5: 1
A6: Terkoreksi | B6: =B5+FORECAST(B5,G5:G9,F5:F9) -> 20.444 | C6: =C5+FORECAST(C5,J5:J9,I5:I9) -> 60.0265 | D6: =D5+FORECAST(D5,M5:M15,L5:L15)/1.3333 -> 699.46132 | F6: 25 | G6: -0.2 | H6: 2 | I6: 50 | J6: -0.3 | K6: 2.8 | L6: 960 | M6: 3 | N6: 1
A7: U95 | B7: 2 | C7: =FORECAST(C6,K5:K9,I5:I9) -> 2.619841 | D7: =FORECAST(D6,N5:N15,L5:L15)/1.3333 -> 0.75001875 | F7: 30 | G7: -0.3 | H7: 2 | I7: 60 | J7: -0.3 | K7: 3.2 | L7: 980 | M7: 3 | N7: 1
A8: Fluktuasi suhu | B8: =(MAX(B3:B4)-B5+B5-MIN(B3:B4))/2 -> 0.3 | C8: =(MAX(C3:C4)-C5+C5-MIN(C3:C4))/2 -> 0.25 | D8: =(MAX(D3:D4)-D5+D5-MIN(D3:D4))/2 -> 0.67195041 | F8: 35 | G8: -0.6 | H8: 2 | I8: 70 | J8: -0.1 | K8: 2 | L8: 990 | M8: 3 | N8: 1
A9: Flu+U95 | B9: =B7+B8 -> 2.3 | C9: =C7+C8 -> 2.869841 | D9: =D7+D8 -> 1.4219692 | F9: 40 | G9: -0.7 | H9: 2 | I9: 80 | J9: -0.6 | K9: 2.6 | L9: 1000 | M9: 3 | N9: 1
A10: Kondisi Ruang | B10: =FIXED(B6,1)&" ± "&FIXED(B8,1) -> 20,4 ± 0,3 | C10: =FIXED(C6,1)&" ± "&FIXED(C8,1) -> 60,0 ± 0,3 | D10: =FIXED(D6,0)&" ± "&FIXED(D8,0) -> 699 ± 1 | L10: 1010 | M10: 3 | N10: 1
L11: 1020 | M11: 3 | N11: 1
L12: 1030 | M12: 3 | N12: 1
L13: 1040 | M13: 3 | N13: 1
L14: 1050 | M14: 2 | N14: 1
L15: 1060 | M15: 2 | N15: 1

Sheet Database 
A1: Rotronik Suhu | F1: Rotronik Kelembaban | K1: Rotronik tekanan | P1: Testo | T1: Timbangan HM | X1: Timbangan Scientech | AB1: Timbangan Sartorius LC5101S | AG1: Merek | AH1: N/S | AI1: Resolusi | AJ1: Ketidakpastian
A2: Standar Terkoreksi | B2: Pembacaan alat | C2: Koreksi | D2: Uncertainty | F2: Standar Terkoreksi | G2: Pembacaan | H2: Koreksi | I2: Ketidakpastian | K2: Pembacaan | L2: Aktual | M2: Koreksi | N2: U95 | P2: Pembacaan Alat | Q2: Koreksi | R2: Ketidakpastian | T2: Beban | U2: Koreksi (g) | V2: U95 (mg) | X2: Beban | Y2: Koreksi (g) | Z2: U95 (mg) | AB2: Beban | AC2: Koreksi (g) | AD2: U95 (mg) | AG2: AND HM 300 | AH2: 13504868 | AI2: 0.0001 | AJ2: 0.00082
A3: 20 | B3: 19.9 | C3: 0.1 | D3: 2 | F3: 40 | G3: 39.8 | H3: 0.2 | I3: 2.5 | K3: 940 | L3: 936 | M3: =K3-L3 -> 4 | N3: 1 | P3: 16.3 | Q3: 0.1 | R3: 0.4 | T3: 30 | U3: 5e-05 | V3: 0.12 | X3: 50 | Y3: 0 | Z3: 2.7 | AB3: 250 | AC3: -0.002 | AD3: 2.1 | AG3: Sartorius 5101S | AH3: 90602105 | AI3: 0.001 | AJ3: 0.0085
A4: 25 | B4: 25.2 | C4: -0.2 | D4: 2 | F4: 50 | G4: 50.3 | H4: -0.3 | I4: 2.8 | K4: 960 | L4: 957 | M4: =K4-L4 -> 3 | N4: 1 | P4: 18 | Q4: -0.2 | R4: 0.4 | T4: 60 | U4: 0.0003 | V4: 0.12 | X4: 100 | Y4: -0.001 | Z4: 2.7 | AB4: 500 | AC4: -0.01 | AD4: 2.3 | AG4: Scientech SP 2050D | AH4: 9249 | AI4: 0.001 | AJ4: 0.0027
A5: 30 | B5: 30.3 | C5: -0.3 | D5: 2 | F5: 60 | G5: 60.3 | H5: -0.3 | I5: 3.2 | K5: 980 | L5: 977 | M5: =K5-L5 -> 3 | N5: 1 | P5: 19.3 | Q5: -0.2 | R5: 0.4 | T5: 90 | U5: 0.00048 | V5: 0.12 | X5: 150 | Y5: -0.002 | Z5: 2.7 | AB5: 1000 | AC5: -0.018 | AD5: 2.7
A6: 35 | B6: 35.6 | C6: -0.6 | D6: 2 | F6: 70 | G6: 70.1 | H6: -0.1 | I6: 2 | K6: 990 | L6: 987 | M6: =K6-L6 -> 3 | N6: 1 | P6: 20.1 | Q6: -0.2 | R6: 0.4 | T6: 120 | U6: 0.00056 | V6: 0.12 | X6: 200 | Y6: -0.001 | Z6: 2.7 | AB6: 1500 | AC6: -0.023 | AD6: 3.5 | AG6: Testo 110
A7: 40 | B7: 40.7 | C7: -0.7 | D7: 2 | F7: 80 | G7: 80.6 | H7: -0.6 | I7: 2.6 | K7: 1000 | L7: 997 | M7: =K7-L7 -> 3 | N7: 1 | P7: 21.1 | Q7: -0.1 | R7: 0.4 | T7: 150 | U7: 0.00055 | V7: 0.12 | X7: 250 | Y7: -0.002 | Z7: 2.7 | AB7: 2000 | AC7: -0.029 | AD7: 3.9
K8: 1010 | L8: 1007 | M8: =K8-L8 -> 3 | N8: 1 | P8: 24.2 | Q8: -0.2 | R8: 0.4 | T8: 180 | U8: 0.00035 | V8: 0.15 | X8: 300 | Y8: -0.004 | Z8: 1.9 | AB8: 2500 | AC8: -0.029 | AD8: 4.8 | AG8: Rotronik
K9: 1020 | L9: 1017 | M9: =K9-L9 -> 3 | N9: 1 | P9: 25.1 | Q9: -0.1 | R9: 0.4 | T9: 210 | U9: 0.00033 | V9: 0.14 | X9: 350 | Y9: -0.008 | Z9: 1.9 | AB9: 3000 | AC9: -0.03 | AD9: 4.5
K10: 1030 | L10: 1027 | M10: =K10-L10 -> 3 | N10: 1 | P10: 26.1 | Q10: -0.1 | R10: 0.4 | T10: 240 | U10: 5e-05 | V10: 0.15 | X10: 400 | Y10: -0.004 | Z10: 1.9 | AB10: 3500 | AC10: -0.024 | AD10: 6.3
K11: 1040 | L11: 1037 | M11: =K11-L11 -> 3 | N11: 1 | P11: 30.1 | Q11: -0.1 | R11: 0.3 | T11: 270 | U11: 0.00015 | V11: 0.82 | X11: 450 | Y11: -0.006 | Z11: 1.9 | AB11: 4000 | AC11: -0.027 | AD11: 6.7
K12: 1050 | L12: 1048 | M12: =K12-L12 -> 2 | N12: 1 | T12: 300 | U12: 0.00058 | V12: 0.82 | X12: 500 | Y12: -0.008 | Z12: 2.1 | AB12: 5000 | AC12: -0.035 | AD12: 8.5
K13: 1060 | L13: 1058 | M13: =K13-L13 -> 2 | N13: 1
A35: List | B35: CMC Gelas Ukur | F35: CMC Labu Ukur | I35: Buret | M35: Pipet Ukur | Q35: Pipet Volume | T35: IF
A36: Gelas Ukur | B36: Range | D36: CMC | F36: kap | G36: CMC | I36: Range | K36: CMC | M36: Range | O36: cmc | Q36: kap | R36: CMC
A37: Labu Ukur | B37: 2 | C37: 10 | D37: 0.021 | F37: 25 | G37: 0.01 | I37: 2 | J37: 10 | K37: 0.008 | M37: 1 | N37: 5 | O37: 0.0035 | Q37: 5 | R37: 0.0024
A38: Buret | B38: 11 | C38: 50 | D38: 0.049 | F38: 50 | G38: 0.017 | I38: 11 | J38: 25 | K38: 0.011 | M38: 6 | N38: 10 | O38: 0.0056 | Q38: 10 | R38: 0.0025
A39: Pipet Ukur | B39: 51 | C39: 100 | D39: 0.079 | F39: 100 | G39: 0.023 | I39: 26 | J39: 50 | K39: 0.014 | M39: 11 | N39: 25 | O39: 0.0097 | Q39: 20 | R39: 0.0035
A40: Pipet Volume | B40: 101 | C40: 500 | D40: 0.25 | F40: 250 | G40: 0.041 | I40: 51 | J40: 100 | K40: 0.027 | M40: 26 | N40: 50 | O40: 0.018
F41: 500 | G41: 0.074 | M41: 51 | N41: 100 | O41: 0.053
B46: Tipe | C46: Range 1 | D46: Range 2 | E46: CMC | I46: 25 | J46: Labu Ukur
B47: Gelas Ukur | C47: 2 | D47: 10 | E47: 0.021
B48: Gelas Ukur | C48: 11 | D48: 50 | E48: 0.049 | I48: Output
B49: Gelas Ukur | C49: 51 | D49: 100 | E49: 0.079 | I49: {=IFERROR(INDEX($E$47:$E$67, MATCH(1, (I46>=$C$47:$C$67)*(I46<=$D$47:$D$67)*(J46=B47:B67), 0)),0)} -> 0.01
B50: Gelas Ukur | C50: 101 | D50: 500 | E50: 0.25
B51: Buret | C51: 2 | D51: 10 | E51: 0.008
B52: Buret | C52: 11 | D52: 25 | E52: 0.011
B53: Buret | C53: 26 | D53: 50 | E53: 0.014
B54: Buret | C54: 51 | D54: 100 | E54: 0.027
B55: Pipet Ukur | C55: 1 | D55: 5 | E55: 0.0035
B56: Pipet Ukur | C56: 6 | D56: 10 | E56: 0.0056
B57: Pipet Ukur | C57: 11 | D57: 25 | E57: 0.0097
B58: Pipet Ukur | C58: 26 | D58: 50 | E58: 0.018
B59: Pipet Ukur | C59: 51 | D59: 100 | E59: 0.053
B60: Labu Ukur | C60: 25 | D60: 25 | E60: 0.01
B61: Labu Ukur | C61: 50 | D61: 50 | E61: 0.017
... B67: Pipet Volume | C67: 20 | D67: 20 | E67: 0.0035
